Workbook

Sheet Project Overview
A1: Amended RFP Exhibit I — Project Overview
A2: Westfield | 2026-03-31 | ANC Proposal Engine
B4: PROJECT INFORMATION
B5: Client | C5: Westfield
B6: Project Name | C6: Amended RFP Exhibit I
B7: Location | C7: WTC
B8: Date Created | C8: 2026-03-31
B9: Currency | C9: USD
B10: Environment | C10: Indoor
B11: Union Labor | C11: No
B12: Bond Required | C12: No
B13: Number of Displays | C13: =SUM('LED Cost Sheet'!I4:I13) -> 10
B15: FINANCIAL PARAMETERS
B16: LED Hardware Margin | C16: 15%
B17: Install / Services Margin | C17: 15%
B18: Engineering Margin | C18: 15%
B19: Equipment Margin | C19: 15%
B20: CMS Margin | C20: 15%
B21: Bond Rate | C21: N/A
B22: Tax Rate | C22: Per zone (editable on MA)
B23: Tariff Rate | C23: Per zone (editable on MA)
B25: SUMMARY TOTALS
B26: Total Cost | C26: ='Margin Analysis'!C145 -> 2338109.6
B27: Total Selling Price | C27: ='Margin Analysis'!D145 -> 2685228.3
B28: Project Margin $ | C28: ='Margin Analysis'!E145 -> 347118.63
B29: Project Margin % | C29: ='Margin Analysis'!F145 -> 0.13
B30: DOCUMENT TOTAL | C30: ='Margin Analysis'!D145 -> 2685228.3

Sheet Margin Analysis
A1: Amended RFP Exhibit I — Margin Analysis
A2: Westfield | 2026-03-31 | ANC Proposal Engine
B4: Zone / Category | C4: Cost | D4: Selling Price | E4: Margin $ | F4: Margin %
B5: 9A Underpass 1 — Underpass 1 | D5: Selling Price
B6: LED Hardware | C6: ='LED Cost Sheet'!T4 -> 29515.17 | D6: ='LED Cost Sheet'!V4 -> 34723.73 | E6: =IFERROR(D6-C6,0) -> 5208.56 | F6: 0.15
B7: Structural Materials | C7: ='9A Underpass 1 - Install'!I26 -> 1312.5 | D7: =IFERROR(C7/(1-F7),0) -> 1544.12 | E7: =IFERROR(D7-C7,0) -> 231.62 | F7: 0.15
B8: Structural Labor & LED Installation | C8: ='9A Underpass 1 - Install'!I35-'9A Underpass 1 - Install'!I34 -> 5468.75 | D8: =IFERROR(C8/(1-F8),0) -> 6433.82 | E8: =IFERROR(D8-C8,0) -> 965.07 | F8: 0.15
B9: Electrical & Data | C9: ='9A Underpass 1 - Install'!I44 -> 5468.75 | D9: =IFERROR(C9/(1-F9),0) -> 6433.82 | E9: =IFERROR(D9-C9,0) -> 965.07 | F9: 0.15
B10: PM / General Conditions / Travel | C10: ='9A Underpass 1 - Install'!I34 -> 20882.35 | D10: =IFERROR(C10/(1-F10),0) -> 24567.47 | E10: =IFERROR(D10-C10,0) -> 3685.12 | F10: 0.15
B11: Engineering & Permits | C11: ='9A Underpass 1 - Install'!I52 -> 4705.88 | D11: =IFERROR(C11/(1-F11),0) -> 5536.33 | E11: =IFERROR(D11-C11,0) -> 830.45 | F11: 0.15
B12: SUBTOTAL | C12: =SUM(C6:C11) -> 67353.4 | D12: =SUM(D6:D11) -> 77897.05 | E12: =IFERROR(D12-C12,0) -> 10543.65 | F12: =IFERROR(1-C12/D12,0) -> 0.135354
B13: TAX | C13: 0 | D13: 0 | E13: 0 | G13: 0
B14: BOND | C14: 0 | D14: 0 | E14: 0 | G14: 0
B15: TARIFF | C15: 0 | D15: 0 | E15: 0 | G15: 0
B16: GRAND TOTAL | C16: =C12+C13+C14+C15 -> 67353.4 | D16: =D12+D13+D14+D15 -> 77897.05 | E16: =IFERROR(D16-C16,0) -> 10543.65 | F16: =IFERROR(1-C16/D16,0) -> 0.13535365
B18: 9A Underpass 2 — Underpass 2 | D18: Selling Price
B19: LED Hardware | C19: ='LED Cost Sheet'!T5 -> 57464.5 | D19: ='LED Cost Sheet'!V5 -> 67605.29 | E19: =IFERROR(D19-C19,0) -> 10140.79 | F19: 0.15
B20: Structural Materials | C20: ='9A Underpass 2 - Install'!I26 -> 2580 | D20: =IFERROR(C20/(1-F20),0) -> 3035.29 | E20: =IFERROR(D20-C20,0) -> 455.29 | F20: 0.15
B21: Structural Labor & LED Installation | C21: ='9A Underpass 2 - Install'!I35-'9A Underpass 2 - Install'!I34 -> 10750 | D21: =IFERROR(C21/(1-F21),0) -> 12647.06 | E21: =IFERROR(D21-C21,0) -> 1897.06 | F21: 0.15
B22: Electrical & Data | C22: ='9A Underpass 2 - Install'!I44 -> 10750 | D22: =IFERROR(C22/(1-F22),0) -> 12647.06 | E22: =IFERROR(D22-C22,0) -> 1897.06 | F22: 0.15
B23: PM / General Conditions / Travel | C23: ='9A Underpass 2 - Install'!I34 -> 20882.35 | D23: =IFERROR(C23/(1-F23),0) -> 24567.47 | E23: =IFERROR(D23-C23,0) -> 3685.12 | F23: 0.15
B24: Engineering & Permits | C24: ='9A Underpass 2 - Install'!I52 -> 4705.88 | D24: =IFERROR(C24/(1-F24),0) -> 5536.33 | E24: =IFERROR(D24-C24,0) -> 830.45 | F24: 0.15
B25: SUBTOTAL | C25: =SUM(C19:C24) -> 107132.73 | D25: =SUM(D19:D24) -> 123405.56 | E25: =IFERROR(D25-C25,0) -> 16272.83 | F25: =IFERROR(1-C25/D25,0) -> 0.131865
B26: TAX | C26: 0 | D26: 0 | E26: 0 | G26: 0
B27: BOND | C27: 0 | D27: 0 | E27: 0 | G27: 0
B28: TARIFF | C28: 0 | D28: 0 | E28: 0 | G28: 0
B29: GRAND TOTAL | C29: =C25+C26+C27+C28 -> 107132.73 | D29: =D25+D26+D27+D28 -> 123405.56 | E29: =IFERROR(D29-C29,0) -> 16272.83 | F29: =IFERROR(1-C29/D29,0) -> 0.13186464
B31: 9A Underpass 3 — Underpass 3 | D31: Selling Price
B32: LED Hardware | C32: ='LED Cost Sheet'!T6 -> 57464.5 | D32: ='LED Cost Sheet'!V6 -> 67605.29 | E32: =IFERROR(D32-C32,0) -> 10140.79 | F32: 0.15
B33: Structural Materials | C33: ='9A Underpass 3 - Install'!I26 -> 2580 | D33: =IFERROR(C33/(1-F33),0) -> 3035.29 | E33: =IFERROR(D33-C33,0) -> 455.29 | F33: 0.15
B34: Structural Labor & LED Installation | C34: ='9A Underpass 3 - Install'!I35-'9A Underpass 3 - Install'!I34 -> 10750 | D34: =IFERROR(C34/(1-F34),0) -> 12647.06 | E34: =IFERROR(D34-C34,0) -> 1897.06 | F34: 0.15
B35: Electrical & Data | C35: ='9A Underpass 3 - Install'!I44 -> 10750 | D35: =IFERROR(C35/(1-F35),0) -> 12647.06 | E35: =IFERROR(D35-C35,0) -> 1897.06 | F35: 0.15
B36: PM / General Conditions / Travel | C36: ='9A Underpass 3 - Install'!I34 -> 20882.35 | D36: =IFERROR(C36/(1-F36),0) -> 24567.47 | E36: =IFERROR(D36-C36,0) -> 3685.12 | F36: 0.15
B37: Engineering & Permits | C37: ='9A Underpass 3 - Install'!I52 -> 4705.88 | D37: =IFERROR(C37/(1-F37),0) -> 5536.33 | E37: =IFERROR(D37-C37,0) -> 830.45 | F37: 0.15
B38: SUBTOTAL | C38: =SUM(C32:C37) -> 107132.73 | D38: =SUM(D32:D37) -> 123405.56 | E38: =IFERROR(D38-C38,0) -> 16272.83 | F38: =IFERROR(1-C38/D38,0) -> 0.131865
B39: TAX | C39: 0 | D39: 0 | E39: 0 | G39: 0
B40: BOND | C40: 0 | D40: 0 | E40: 0 | G40: 0
B41: TARIFF | C41: 0 | D41: 0 | E41: 0 | G41: 0
B42: GRAND TOTAL | C42: =C38+C39+C40+C41 -> 107132.73 | D42: =D38+D39+D40+D41 -> 123405.56 | E42: =IFERROR(D42-C42,0) -> 16272.83 | F42: =IFERROR(1-C42/D42,0) -> 0.13186464
B44: 9A Underpass 4 — Underpass 4 | D44: Selling Price
...

Sheet Budget Summary
A1: Amended RFP Exhibit I — Budget Summary
A2: Westfield | 2026-03-31 | By Category
B4: Category | C4: Cost | D4: Selling Price | E4: Margin $ | F4: Margin % | G4: Price / SqFt
B5: LED Hardware (all displays) | C5: =SUM('LED Cost Sheet'!Q4:Q13) -> 1498517.3 | D5: =SUM('LED Cost Sheet'!S4:S13) -> 1762961.6 | E5: =IFERROR(D5-C5,0) -> 264444.23 | F5: 0.15 | G5: =IFERROR(C5/5566.5599999999995,0) -> 269.2
B6: Structural Materials | C6: =SUM('9A Underpass 1 - Install'!I26:I26)+SUM('9A Underpass 2 - Install'!I26:I26)+SUM('9A Underpass 3 - Install'!I26:I26)+SUM('9A Underpass 4 - Install'!I26:I26)+SUM('Concourse - Install'!I26:I26)+SUM('T4 Elevator - Install'!I26:I26)+SUM('New Path Hall Option 1 - Instal'!I26:I26)+SUM('New Path Hall Option 2 - Instal'!I26:I26)+SUM('One Train - Install'!I26:I26)+SUM('T4-B2 - Install'!I26:I26) -> 64147.5 | D6: =SUM('9A Underpass 1 - Install'!K26:K26)+SUM('9A Underpass 2 - Install'!K26:K26)+SUM('9A Underpass 3 - Install'!K26:K26)+SUM('9A Underpass 4 - Install'!K26:K26)+SUM('Concourse - Install'!K26:K26)+SUM('T4 Elevator - Install'!K26:K26)+SUM('New Path Hall Option 1 - Instal'!K26:K26)+SUM('New Path Hall Option 2 - Instal'!K26:K26)+SUM('One Train - Install'!K26:K26)+SUM('T4-B2 - Install'!K26:K26) -> 75467.65 | E6: =IFERROR(D6-C6,0) -> 11320.15 | F6: 0.15 | G6: =IFERROR(C6/5566.5599999999995,0) -> 11.52
B7: Structural Labor & LED Installation | C7: =(SUM('9A Underpass 1 - Install'!I35:I35)-SUM('9A Underpass 1 - Install'!I34:I34))+(SUM('9A Underpass 2 - Install'!I35:I35)-SUM('9A Underpass 2 - Install'!I34:I34))+(SUM('9A Underpass 3 - Install'!I35:I35)-SUM('9A Underpass 3 - Install'!I34:I34))+(SUM('9A Underpass 4 - Install'!I35:I35)-SUM('9A Underpass 4 - Install'!I34:I34))+(SUM('Concourse - Install'!I35:I35)-SUM('Concourse - Install'!I34:I34))+(SUM('T4 Elevator - Install'!I35:I35)-SUM('T4 Elevator - Install'!I34:I34))+(SUM('New Path Hall Option 1 - Instal'!I35:I35)-SUM('New Path Hall Option 1 - Instal'!I34:I34))+(SUM('New Path Hall Option 2 - Instal'!I35:I35)-SUM('New Path Hall Option 2 - Instal'!I34:I34))+(SUM('One Train - Install'!I35:I35)-SUM('One Train - Install'!I34:I34))+(SUM('T4-B2 - Install'!I35:I35)-SUM('T4-B2 - Install'!I34:I34)) -> 267281.26 | D7: =(SUM('9A Underpass 1 - Install'!K35:K35)-SUM('9A Underpass 1 - Install'!K34:K34))+(SUM('9A Underpass 2 - Install'!K35:K35)-SUM('9A Underpass 2 - Install'!K34:K34))+(SUM('9A Underpass 3 - Install'!K35:K35)-SUM('9A Underpass 3 - Install'!K34:K34))+(SUM('9A Underpass 4 - Install'!K35:K35)-SUM('9A Underpass 4 - Install'!K34:K34))+(SUM('Concourse - Install'!K35:K35)-SUM('Concourse - Install'!K34:K34))+(SUM('T4 Elevator - Install'!K35:K35)-SUM('T4 Elevator - Install'!K34:K34))+(SUM('New Path Hall Option 1 - Instal'!K35:K35)-SUM('New Path Hall Option 1 - Instal'!K34:K34))+(SUM('New Path Hall Option 2 - Instal'!K35:K35)-SUM('New Path Hall Option 2 - Instal'!K34:K34))+(SUM('One Train - Install'!K35:K35)-SUM('One Train - Install'!K34:K34))+(SUM('T4-B2 - Install'!K35:K35)-SUM('T4-B2 - Install'!K34:K34)) -> 314448.54 | E7: =IFERROR(D7-C7,0) -> 47167.28 | F7: 0.15 | G7: =IFERROR(C7/5566.5599999999995,0) -> 48.02
B8: Electrical & Data | C8: =SUM('9A Underpass 1 - Install'!I44:I44)+SUM('9A Underpass 2 - Install'!I44:I44)+SUM('9A Underpass 3 - Install'!I44:I44)+SUM('9A Underpass 4 - Install'!I44:I44)+SUM('Concourse - Install'!I44:I44)+SUM('T4 Elevator - Install'!I44:I44)+SUM('New Path Hall Option 1 - Instal'!I44:I44)+SUM('New Path Hall Option 2 - Instal'!I44:I44)+SUM('One Train - Install'!I44:I44)+SUM('T4-B2 - Install'!I44:I44) -> 267281.26 | D8: =SUM('9A Underpass 1 - Install'!K44:K44)+SUM('9A Underpass 2 - Install'!K44:K44)+SUM('9A Underpass 3 - Install'!K44:K44)+SUM('9A Underpass 4 - Install'!K44:K44)+SUM('Concourse - Install'!K44:K44)+SUM('T4 Elevator - Install'!K44:K44)+SUM('New Path Hall Option 1 - Instal'!K44:K44)+SUM('New Path Hall Option 2 - Instal'!K44:K44)+SUM('One Train - Install'!K44:K44)+SUM('T4-B2 - Install'!K44:K44) -> 314448.54 | E8: =IFERROR(D8-C8,0) -> 47167.28 | F8: 0.15 | G8: =IFERROR(C8/5566.5599999999995,0) -> 48.02
B9: PM / General Conditions / Travel | C9: =SUM('9A Underpass 1 - Install'!I34:I34)+SUM('9A Underpass 2 - Install'!I34:I34)+SUM('9A Underpass 3 - Install'!I34:I34)+SUM('9A Underpass 4 - Install'!I34:I34)+SUM('Concourse - Install'!I34:I34)+SUM('T4 Elevator - Install'!I34:I34)+SUM('New Path Hall Option 1 - Instal'!I34:I34)+SUM('New Path Hall Option 2 - Instal'!I34:I34)+SUM('One Train - Install'!I34:I34)+SUM('T4-B2 - Install'!I34:I34) -> 193823.5 | D9: =SUM('9A Underpass 1 - Install'!K34:K34)+SUM('9A Underpass 2 - Install'!K34:K34)+SUM('9A Underpass 3 - Install'!K34:K34)+SUM('9A Underpass 4 - Install'!K34:K34)+SUM('Concourse - Install'!K34:K34)+SUM('T4 Elevator - Install'!K34:K34)+SUM('New Path Hall Option 1 - Instal'!K34:K34)+SUM('New Path Hall Option 2 - Instal'!K34:K34)+SUM('One Train - Install'!K34:K34)+SUM('T4-B2 - Install'!K34:K34) -> 228027.65 | E9: =IFERROR(D9-C9,0) -> 34204.15 | F9: 0.15
B10: Engineering & Permits | C10: =SUM('9A Underpass 1 - Install'!I52:I52)+SUM('9A Underpass 2 - Install'!I52:I52)+SUM('9A Underpass 3 - Install'!I52:I52)+SUM('9A Underpass 4 - Install'!I52:I52)+SUM('Concourse - Install'!I52:I52)+SUM('T4 Elevator - Install'!I52:I52)+SUM('New Path Hall Option 1 - Instal'!I52:I52)+SUM('New Path Hall Option 2 - Instal'!I52:I52)+SUM('One Train - Install'!I52:I52)+SUM('T4-B2 - Install'!I52:I52) -> 47058.8 | D10: =SUM('9A Underpass 1 - Install'!K52:K52)+SUM('9A Underpass 2 - Install'!K52:K52)+SUM('9A Underpass 3 - Install'!K52:K52)+SUM('9A Underpass 4 - Install'!K52:K52)+SUM('Concourse - Install'!K52:K52)+SUM('T4 Elevator - Install'!K52:K52)+SUM('New Path Hall Option 1 - Instal'!K52:K52)+SUM('New Path Hall Option 2 - Instal'!K52:K52)+SUM('One Train - Install'!K52:K52)+SUM('T4-B2 - Install'!K52:K52) -> 55363.29 | E10: =IFERROR(D10-C10,0) -> 8304.49 | F10: 0.15
B11: CMS (Content Management System) | C11: =SUM(CMS!F26:F26) -> 0 | D11: =SUM(CMS!H26:H26) -> 0 | E11: =IFERROR(D11-C11,0) -> 0 | F11: 0.15
B12: Scoring System | C12: =SUM(Scoring!F27:F27) -> 0 | D12: =SUM(Scoring!H27:H27) -> 0 | E12: =IFERROR(D12-C12,0) -> 0 | F12: 0.15
B13: Venue Services | C13: =SUM('Venue Services'!B17:B17) -> 0 | D13: =SUM('Venue Services'!C17:C17) -> 0 | E13: =IFERROR(D13-C13,0) -> 0 | F13: 0.15
B14: Game Clock | C14: =SUM('Additional Items'!F5:F5) -> 0 | D14: =SUM('Additional Items'!H5:H5) -> 0 | E14: =IFERROR(D14-C14,0) -> 0 | F14: 0.15
B15: Pitch Clocks | C15: =SUM('Additional Items'!F6:F6) -> 0 | D15: =SUM('Additional Items'!H6:H6) -> 0 | E15: =IFERROR(D15-C15,0) -> 0 | F15: 0.15
B16: OES / MIS / Timing | C16: =SUM('Additional Items'!F7:F7) -> 0 | D16: =SUM('Additional Items'!H7:H7) -> 0 | E16: =IFERROR(D16-C16,0) -> 0 | F16: 0.15
B17: DMX / Misc Equipment | C17: =SUM('Additional Items'!F8:F8) -> 0 | D17: =SUM('Additional Items'!H8:H8) -> 0 | E17: =IFERROR(D17-C17,0) -> 0 | F17: 0.15
B19: SUBTOTAL | C19: =SUM(C5:C17) -> 2338109.6 | D19: =SUM(D5:D17) -> 2685228.3 | E19: =IFERROR(D19-C19,0) -> 347118.63 | F19: =IFERROR(1-C19/D19,0) -> 0.13 | G19: =IFERROR(C19/5566.5599999999995,0) -> 420.03
B20: TAX | C20: 0 | D20: 0 | E20: 0 | F20: 0
B21: BOND | C21: 0 | D21: 0 | E21: 0 | F21: 0
B22: GRAND TOTAL | C22: =C19+C20+C21 -> 2338109.6 | D22: =D19+D20+D21 -> 2685228.3 | E22: =IFERROR(D22-C22,0) -> 347118.63 | F22: =IFERROR(1-C22/D22,0) -> 0.13 | G22: =IFERROR(C22/5566.5599999999995,0) -> 420.03

Sheet LED Cost Sheet
A1: Amended RFP Exhibit I — LED Cost Sheet
U2: LED Margin Override → | V2: 0.15
A3: Display | B3: RFP H (ft) | C3: RFP W (ft) | D3: RFP NITs | E3: Vendor | F3: Product | G3: Pitch | H3: H (ft) | I3: W (ft) | J3: H (px) | K3: W (px) | L3: Qty | M3: Total SqFt | N3: Product NITs | O3: Service | P3: $/SqFt | Q3: Display Cost | R3: Processor | S3: Shipping | T3: Total Cost | U3: Margin % | V3: Selling Price | W3: ANC Margin | X3: Weight (lbs) | Y3: Total Power (W) | Z3: BTU/hr
A4: 9A Underpass 1 — Underpass 1 | B4: 6.3 | C4: 18.11 | D4: 8000 | E4: LG/Yaham | F4: C2.5-MIP 2.5mm Indoor (Alt) | G4: 3.9mm | H4: 6.3 | I4: 18.11 | J4: 492 | K4: 1415 | L4: 1 | M4: =H4*I4*L4 -> 114.09 | N4: 7500 | O4: Front | P4: 244.16 | Q4: 27855.82 | R4: =SUM('Bundle Equipment'!E10:E10) -> 518.45 | S4: 1140.9 | T4: 29515.17 | U4: =V$2 -> 0.135354 | V4: 77897.05 | W4: 10543.65 | X4: 577 | Y4: 5234 | Z4: =Y4*3.412 -> 17858
A5: 9A Underpass 2 — Underpass 2 | B5: 7.48 | C5: 29.92 | D5: 8000 | E5: LG/Yaham | F5: C2.5-MIP 2.5mm Indoor (Alt) | G5: 3.9mm | H5: 7.48 | I5: 29.92 | J5: 585 | K5: 2338 | L5: 1 | M5: =H5*I5*L5 -> 223.8 | N5: 7500 | O5: Front | P5: 244.16 | Q5: 54642.22 | R5: =SUM('Bundle Equipment'!E15:E15) -> 584.28 | S5: 2238 | T5: 57464.5 | U5: =V$2 -> 0.131865 | V5: 123405.56 | W5: 16272.83 | X5: 1132 | Y5: 10268 | Z5: =Y5*3.412 -> 35034
A6: 9A Underpass 3 — Underpass 3 | B6: 7.48 | C6: 29.92 | D6: 8000 | E6: LG/Yaham | F6: C2.5-MIP 2.5mm Indoor (Alt) | G6: 3.9mm | H6: 7.48 | I6: 29.92 | J6: 585 | K6: 2338 | L6: 1 | M6: =H6*I6*L6 -> 223.8 | N6: 7500 | O6: Front | P6: 244.16 | Q6: 54642.22 | R6: =SUM('Bundle Equipment'!E20:E20) -> 584.28 | S6: 2238 | T6: 57464.5 | U6: =V$2 -> 0.131865 | V6: 123405.56 | W6: 16272.83 | X6: 1132 | Y6: 10268 | Z6: =Y6*3.412 -> 35034
A7: 9A Underpass 4 — Underpass 4 | B7: 12.6 | C7: 29.92 | D7: 8000 | E7: LG/Yaham | F7: C2.5-MIP 2.5mm Indoor (Alt) | G7: 3.9mm | H7: 12.6 | I7: 29.92 | J7: 985 | K7: 2338 | L7: 1 | M7: =H7*I7*L7 -> 376.99 | N7: 7500 | O7: Front | P7: 244.16 | Q7: 92044.55 | R7: =SUM('Bundle Equipment'!E26:E26) -> 12676.19 | S7: 3769.9 | T7: 108490.64 | U7: =V$2 -> 0.131243 | V7: 200987.02 | W7: 26378.15 | X7: 1907 | Y7: 17296 | Z7: =Y7*3.412 -> 59014
A8: Concourse — Concourse | B8: 9.45 | C8: 280.31 | D8: 8000 | E8: LG/Yaham | F8: C2.5-MIP 2.5mm Indoor (Alt) | G8: 3.9mm | H8: 9.45 | I8: 280.31 | J8: 739 | K8: 21907 | L8: 1 | M8: =H8*I8*L8 -> 2648.93 | N8: 7500 | O8: Front | P8: 244.16 | Q8: 646753.47 | R8: =SUM('Bundle Equipment'!E32:E32) -> 30389.36 | S8: 26489.3 | T8: 703632.13 | U8: =V$2 -> 0.127205 | V8: 1162042.4 | W8: 147817.07 | X8: 13398 | Y8: 121528 | Z8: =Y8*3.412 -> 414654
A9: T4 Elevator — T4 Lobby Elevator | B9: 71.6 | C9: 5.5 | D9: 8000 | E9: LG/Yaham | F9: C2.5-MIP 2.5mm Indoor (Alt) | G9: 3.9mm | H9: 71.6 | I9: 5.5 | J9: 5596 | K9: 430 | L9: 1 | M9: =H9*I9*L9 -> 393.8 | N9: 7500 | O9: Front | P9: 244.16 | Q9: 96148.83 | R9: =SUM('Bundle Equipment'!E38:E38) -> 12686.28 | S9: 3938 | T9: 112773.11 | U9: =V$2 -> 0.131064 | V9: 207968.64 | W9: 27257.3 | X9: 1992 | Y9: 18067 | Z9: =Y9*3.412 -> 61645
A10: New Path Hall Option 1 — Path Hall | B10: 48 | C10: 14 | D10: 8000 | E10: LG/Yaham | F10: C2.5-MIP 2.5mm Indoor (Alt) | G10: 3.9mm | H10: 48 | I10: 14 | J10: 3751 | K10: 1094 | L10: 1 | M10: =H10*I10*L10 -> 672 | N10: 7500 | O10: Front | P10: 244.16 | Q10: 164073.17 | R10: =SUM('Bundle Equipment'!E44:E44) -> 12853.2 | S10: 6720 | T10: 183646.37 | U10: =V$2 -> 0.129211 | V10: 323240.71 | W10: 41766.11 | X10: 3399 | Y10: 30830 | Z10: =Y10*3.412 -> 105192
A11: New Path Hall Option 2 — Path Hall | B11: 65 | C11: 13 | D11: 8000 | E11: LG/Yaham | F11: C2.5-MIP 2.5mm Indoor (Alt) | G11: 3.9mm | H11: 65 | I11: 13 | J11: 5080 | K11: 1016 | L11: 1 | M11: =H11*I11*L11 -> 845 | N11: 7500 | O11: Front | P11: 244.16 | Q11: 206312.24 | R11: =SUM('Bundle Equipment'!E50:E50) -> 12957 | S11: 8450 | T11: 227719.24 | U11: =V$2 -> 0.128606 | V11: 394961.73 | W11: 50794.26 | X11: 4274 | Y11: 38767 | Z11: =Y11*3.412 -> 132273
A12: One Train — One Train | D12: 8000 | E12: LG/Yaham | F12: C2.5-MIP 2.5mm Indoor (Alt) | G12: 3.9mm | H12: 0 | I12: 0 | J12: 0 | K12: 0 | L12: 1 | M12: =H12*I12*L12 -> 0 | N12: 7500 | O12: Front | P12: 0 | Q12: 0 | R12: =SUM('Bundle Equipment'!E54:E54) -> 0 | S12: 0 | T12: 0 | U12: =V$2 -> 0.15 | V12: 12456.74 | W12: 1868.51
A13: T4-B2 — T4-B2 | B13: 7.87 | C13: 8.66 | D13: 8000 | E13: LG/Yaham | F13: C2.5-MIP 2.5mm Indoor (Alt) | G13: 3.9mm | H13: 7.87 | I13: 8.66 | J13: 615 | K13: 677 | L13: 1 | M13: =H13*I13*L13 -> 68.15 | N13: 7500 | O13: Front | P13: 244.16 | Q13: 16639.27 | R13: =SUM('Bundle Equipment'!E59:E59) -> 490.89 | S13: 681.5 | T13: 17811.66 | U13: =V$2 -> 0.138422 | V13: 58862.82 | W13: 8147.92 | X13: 345 | Y13: 3127 | Z13: =Y13*3.412 -> 10669
A15: TOTAL (10 displays) | M15: =M4+M5+M6+M7+M8+M9+M10+M11+M12+M13 -> 5566.56 | Q15: =Q4+Q5+Q6+Q7+Q8+Q9+Q10+Q11+Q12+Q13 -> 1359111.8 | R15: =R4+R5+R6+R7+R8+R9+R10+R11+R12+R13 -> 83739.93 | S15: =S4+S5+S6+S7+S8+S9+S10+S11+S12+S13 -> 55665.6 | T15: =T4+T5+T6+T7+T8+T9+T10+T11+T12+T13 -> 1498517.3 | U15: =IFERROR(1-T15/V15,0) -> 0.15 | V15: =V4+V5+V6+V7+V8+V9+V10+V11+V12+V13 -> 1762961.6 | W15: =W4+W5+W6+W7+W8+W9+W10+W11+W12+W13 -> 264444.23 | X15: =X4+X5+X6+X7+X8+X9+X10+X11+X12+X13 -> 38032 | Y15: =Y4+Y5+Y6+Y7+Y8+Y9+Y10+Y11+Y12+Y13 -> 718675 | Z15: =Z4+Z5+Z6+Z7+Z8+Z9+Z10+Z11+Z12+Z13 -> 2452119

Sheet Tech Specs (Installers)
A1: Amended RFP Exhibit I — LED Technical Specifications (No Pricing)
A2: Technical specifications only — no pricing data. Safe for installer/subcontractor distribution.
A4: Display Name | B4: Qty | C4: Pixel Pitch | D4: Height (ft) | E4: Width (ft) | F4: Pixels H | G4: Pixels W | H4: Sq Ft | I4: Brightness (nits) | J4: Service | K4: Environment | L4: Weight (lbs) | M4: Total Power (W) | N4: Fiber Strands | O4: BTU/hr
A5: ='LED Cost Sheet'!A4 -> 9A Underpass 1 — Underpass 1 | B5: ='LED Cost Sheet'!I4 -> 1 | C5: ='LED Cost Sheet'!D4 -> 3.9mm | D5: ='LED Cost Sheet'!E4 -> 6.3 | E5: ='LED Cost Sheet'!F4 -> 18.11 | F5: ='LED Cost Sheet'!G4 -> 492 | G5: ='LED Cost Sheet'!H4 -> 1415 | H5: =D5*E5*B5 -> 114.09 | I5: ='LED Cost Sheet'!K4 -> 8000 | J5: ='LED Cost Sheet'!L4 -> Front | K5: indoor | L5: ='LED Cost Sheet'!U4 -> 577 | M5: ='LED Cost Sheet'!V4 -> 5234 | N5: =IFERROR((F5*G5*B5)/400000,0) -> 1.74 | O5: ='LED Cost Sheet'!W4 -> 17858
A6: ='LED Cost Sheet'!A5 -> 9A Underpass 2 — Underpass 2 | B6: ='LED Cost Sheet'!I5 -> 1 | C6: ='LED Cost Sheet'!D5 -> 3.9mm | D6: ='LED Cost Sheet'!E5 -> 7.48 | E6: ='LED Cost Sheet'!F5 -> 29.92 | F6: ='LED Cost Sheet'!G5 -> 585 | G6: ='LED Cost Sheet'!H5 -> 2338 | H6: =D6*E6*B6 -> 223.8 | I6: ='LED Cost Sheet'!K5 -> 8000 | J6: ='LED Cost Sheet'!L5 -> Front | K6: indoor | L6: ='LED Cost Sheet'!U5 -> 1132 | M6: ='LED Cost Sheet'!V5 -> 10268 | N6: =IFERROR((F6*G6*B6)/400000,0) -> 3.42 | O6: ='LED Cost Sheet'!W5 -> 35034
A7: ='LED Cost Sheet'!A6 -> 9A Underpass 3 — Underpass 3 | B7: ='LED Cost Sheet'!I6 -> 1 | C7: ='LED Cost Sheet'!D6 -> 3.9mm | D7: ='LED Cost Sheet'!E6 -> 7.48 | E7: ='LED Cost Sheet'!F6 -> 29.92 | F7: ='LED Cost Sheet'!G6 -> 585 | G7: ='LED Cost Sheet'!H6 -> 2338 | H7: =D7*E7*B7 -> 223.8 | I7: ='LED Cost Sheet'!K6 -> 8000 | J7: ='LED Cost Sheet'!L6 -> Front | K7: indoor | L7: ='LED Cost Sheet'!U6 -> 1132 | M7: ='LED Cost Sheet'!V6 -> 10268 | N7: =IFERROR((F7*G7*B7)/400000,0) -> 3.42 | O7: ='LED Cost Sheet'!W6 -> 35034
A8: ='LED Cost Sheet'!A7 -> 9A Underpass 4 — Underpass 4 | B8: ='LED Cost Sheet'!I7 -> 1 | C8: ='LED Cost Sheet'!D7 -> 3.9mm | D8: ='LED Cost Sheet'!E7 -> 12.6 | E8: ='LED Cost Sheet'!F7 -> 29.92 | F8: ='LED Cost Sheet'!G7 -> 985 | G8: ='LED Cost Sheet'!H7 -> 2338 | H8: =D8*E8*B8 -> 376.99 | I8: ='LED Cost Sheet'!K7 -> 8000 | J8: ='LED Cost Sheet'!L7 -> Front | K8: indoor | L8: ='LED Cost Sheet'!U7 -> 1907 | M8: ='LED Cost Sheet'!V7 -> 17296 | N8: =IFERROR((F8*G8*B8)/400000,0) -> 5.76 | O8: ='LED Cost Sheet'!W7 -> 59014
A9: ='LED Cost Sheet'!A8 -> Concourse — Concourse | B9: ='LED Cost Sheet'!I8 -> 1 | C9: ='LED Cost Sheet'!D8 -> 3.9mm | D9: ='LED Cost Sheet'!E8 -> 9.45 | E9: ='LED Cost Sheet'!F8 -> 280.31 | F9: ='LED Cost Sheet'!G8 -> 739 | G9: ='LED Cost Sheet'!H8 -> 21907 | H9: =D9*E9*B9 -> 2648.93 | I9: ='LED Cost Sheet'!K8 -> 8000 | J9: ='LED Cost Sheet'!L8 -> Front | K9: indoor | L9: ='LED Cost Sheet'!U8 -> 13398 | M9: ='LED Cost Sheet'!V8 -> 121528 | N9: =IFERROR((F9*G9*B9)/400000,0) -> 40.47 | O9: ='LED Cost Sheet'!W8 -> 414654
A10: ='LED Cost Sheet'!A9 -> T4 Elevator — T4 Lobby Elevator | B10: ='LED Cost Sheet'!I9 -> 1 | C10: ='LED Cost Sheet'!D9 -> 3.9mm | D10: ='LED Cost Sheet'!E9 -> 71.6 | E10: ='LED Cost Sheet'!F9 -> 5.5 | F10: ='LED Cost Sheet'!G9 -> 5596 | G10: ='LED Cost Sheet'!H9 -> 430 | H10: =D10*E10*B10 -> 393.8 | I10: ='LED Cost Sheet'!K9 -> 8000 | J10: ='LED Cost Sheet'!L9 -> Front | K10: indoor | L10: ='LED Cost Sheet'!U9 -> 1992 | M10: ='LED Cost Sheet'!V9 -> 18067 | N10: =IFERROR((F10*G10*B10)/400000,0) -> 6.02 | O10: ='LED Cost Sheet'!W9 -> 61645
A11: ='LED Cost Sheet'!A10 -> New Path Hall Option 1 — Path Hall | B11: ='LED Cost Sheet'!I10 -> 1 | C11: ='LED Cost Sheet'!D10 -> 3.9mm | D11: ='LED Cost Sheet'!E10 -> 48 | E11: ='LED Cost Sheet'!F10 -> 14 | F11: ='LED Cost Sheet'!G10 -> 3751 | G11: ='LED Cost Sheet'!H10 -> 1094 | H11: =D11*E11*B11 -> 672 | I11: ='LED Cost Sheet'!K10 -> 8000 | J11: ='LED Cost Sheet'!L10 -> Front | K11: indoor | L11: ='LED Cost Sheet'!U10 -> 3399 | M11: ='LED Cost Sheet'!V10 -> 30830 | N11: =IFERROR((F11*G11*B11)/400000,0) -> 10.26 | O11: ='LED Cost Sheet'!W10 -> 105192
A12: ='LED Cost Sheet'!A11 -> New Path Hall Option 2 — Path Hall | B12: ='LED Cost Sheet'!I11 -> 1 | C12: ='LED Cost Sheet'!D11 -> 3.9mm | D12: ='LED Cost Sheet'!E11 -> 65 | E12: ='LED Cost Sheet'!F11 -> 13 | F12: ='LED Cost Sheet'!G11 -> 5080 | G12: ='LED Cost Sheet'!H11 -> 1016 | H12: =D12*E12*B12 -> 845 | I12: ='LED Cost Sheet'!K11 -> 8000 | J12: ='LED Cost Sheet'!L11 -> Front | K12: indoor | L12: ='LED Cost Sheet'!U11 -> 4274 | M12: ='LED Cost Sheet'!V11 -> 38767 | N12: =IFERROR((F12*G12*B12)/400000,0) -> 12.9 | O12: ='LED Cost Sheet'!W11 -> 132273
A13: ='LED Cost Sheet'!A12 -> One Train — One Train | B13: ='LED Cost Sheet'!I12 -> 1 | C13: ='LED Cost Sheet'!D12 -> 3.9mm | D13: ='LED Cost Sheet'!E12 -> 0 | E13: ='LED Cost Sheet'!F12 -> 0 | F13: ='LED Cost Sheet'!G12 -> 0 | G13: ='LED Cost Sheet'!H12 -> 0 | H13: =D13*E13*B13 -> 0 | I13: ='LED Cost Sheet'!K12 -> 8000 | J13: ='LED Cost Sheet'!L12 -> Front | K13: indoor | L13: ='LED Cost Sheet'!U12 -> 0 | M13: ='LED Cost Sheet'!V12 -> 0 | N13: =IFERROR((F13*G13*B13)/400000,0) -> 0 | O13: ='LED Cost Sheet'!W12 -> 0
A14: ='LED Cost Sheet'!A13 -> T4-B2 — T4-B2 | B14: ='LED Cost Sheet'!I13 -> 1 | C14: ='LED Cost Sheet'!D13 -> 3.9mm | D14: ='LED Cost Sheet'!E13 -> 7.87 | E14: ='LED Cost Sheet'!F13 -> 8.66 | F14: ='LED Cost Sheet'!G13 -> 615 | G14: ='LED Cost Sheet'!H13 -> 677 | H14: =D14*E14*B14 -> 68.15 | I14: ='LED Cost Sheet'!K13 -> 8000 | J14: ='LED Cost Sheet'!L13 -> Front | K14: indoor | L14: ='LED Cost Sheet'!U13 -> 345 | M14: ='LED Cost Sheet'!V13 -> 3127 | N14: =IFERROR((F14*G14*B14)/400000,0) -> 1.04 | O14: ='LED Cost Sheet'!W13 -> 10669

Sheet 9A Underpass 1 - Install
A3: Project Name: Amended RFP Exhibit I
A4: 2026-03-31
A5: Revised By: ANC Proposal Engine
C7: Linked Margin Assignment
C8: Install Margin | D8: 0.15
C9: Electrical Margin | D9: 0.15
C10: ANC Margin | D10: 0.15
C11: Engineering and Permits | D11: 0.15
B15: 9A Underpass 1
B16: Height | C16: Width | D16: Total Sq. Ft | E16: QTY
B17: 6.3 | C17: 18.11 | D17: 114.09 | E17: 1
B19: Structural Materials: | C19: Subcontractor 1 | D19: Subcontractor 2 | E19: Subcontractor 3 | F19: Selected | G19: Additional Contingency | I19: Total Cost | J19: Install Margin | K19: Selling Price
B20: FABRICATE PRIMARY STEEL | C20: 0 | D20: 0 | E20: 0 | F20: 0 | G20: 0 | I20: =SUM(C20:G20) -> 0 | J20: =$D$8 -> 0.15 | K20: =I20/(1-J20) -> 0
B21: SUPPLY AND INSTALL PRIMARY PLYWOOD | C21: 0 | D21: 0 | E21: 0 | F21: 0 | G21: 0 | I21: =SUM(C21:G21) -> 0 | J21: =$D$8 -> 0.15 | K21: =I21/(1-J21) -> 0
B22: FABRICATE SECONDARY STEEL SUBSTRUCTURE | C22: 1312.5 | D22: 0 | E22: 0 | F22: 0 | G22: 0 | I22: =SUM(C22:G22) -> 1312.5 | J22: =$D$8 -> 0.15 | K22: =I22/(1-J22) -> 1544.12
B23: FABRICATE CLADDING AND TRIM | C23: 0 | D23: 0 | E23: 0 | F23: 0 | G23: 0 | I23: =SUM(C23:G23) -> 0 | J23: =$D$8 -> 0.15 | K23: =I23/(1-J23) -> 0
B24: OTHER SCOPE ITEM | C24: 0 | D24: 0 | E24: 0 | F24: 0 | G24: 0 | I24: =SUM(C24:G24) -> 0 | J24: =$D$8 -> 0.15 | K24: =I24/(1-J24) -> 0
B25: OTHER SCOPE ITEM | C25: 0 | D25: 0 | E25: 0 | F25: 0 | G25: 0 | I25: =SUM(C25:G25) -> 0 | J25: =$D$8 -> 0.15 | K25: =I25/(1-J25) -> 0
B26: SUBTOTAL | I26: =SUM(I20:I25) -> 1312.5 | K26: =SUM(K20:K25) -> 1544.12
B28: Structural Labor and LED Installation | C28: Subcontractor 1 | D28: Subcontractor 2 | E28: Subcontractor 3 | F28: Selected | G28: Additional Contingency | I28: Total Cost | J28: Install Margin | K28: Selling Price
B29: REMOVAL AND DISPOSAL | C29: 0 | D29: 0 | E29: 0 | F29: 0 | G29: 0 | I29: =SUM(C29:G29) -> 0 | J29: =$D$8 -> 0.15 | K29: =I29/(1-J29) -> 0
B30: INSTALL SECONDARY STEEL SUBSTRUCTURE | C30: 0 | D30: 0 | E30: 0 | F30: 0 | G30: 0 | I30: =SUM(C30:G30) -> 0 | J30: =$D$8 -> 0.15 | K30: =I30/(1-J30) -> 0
B31: INSTALL LED DISPLAYS | C31: 5468.75 | D31: 0 | E31: 0 | F31: 0 | G31: 0 | I31: =SUM(C31:G31) -> 5468.75 | J31: =$D$8 -> 0.15 | K31: =I31/(1-J31) -> 6433.82
B32: INSTALL CLADDING AND TRIM | C32: 0 | D32: 0 | E32: 0 | F32: 0 | G32: 0 | I32: =SUM(C32:G32) -> 0 | J32: =$D$8 -> 0.15 | K32: =I32/(1-J32) -> 0
B33: HEAVY EQUIPMENT | C33: 0 | D33: 0 | E33: 0 | F33: 0 | G33: 0 | I33: =SUM(C33:G33) -> 0 | J33: =$D$8 -> 0.15 | K33: =I33/(1-J33) -> 0
B34: PM/GENERAL CONDITIONS/TRAVEL | C34: 20882.35 | D34: 0 | E34: 0 | F34: 0 | G34: 0 | I34: =SUM(C34:G34) -> 20882.35 | J34: =$D$8 -> 0.15 | K34: =I34/(1-J34) -> 24567.47
B35: SUBTOTAL | I35: =SUM(I29:I34) -> 26351.1 | K35: =SUM(K29:K34) -> 31001.29
B37: Electrical and Data - Materials and Subcontracting | C37: Subcontractor 1 | D37: Subcontractor 2 | E37: Subcontractor 3 | F37: Selected | G37: Additional Contingency | I37: Total Cost | J37: Install Margin | K37: Selling Price
B38: ELECTRICAL MATERIALS | C38: 5468.75 | D38: 0 | E38: 0 | F38: 0 | G38: 0 | I38: =SUM(C38:G38) -> 5468.75 | J38: =$D$9 -> 0.15 | K38: =I38/(1-J38) -> 6433.82
B39: DATA MATERIALS | C39: 0 | D39: 0 | E39: 0 | F39: 0 | G39: 0 | I39: =SUM(C39:G39) -> 0 | J39: =$D$9 -> 0.15 | K39: =I39/(1-J39) -> 0
B40: ELECTRICAL LABOR | C40: 0 | D40: 0 | E40: 0 | F40: 0 | G40: 0 | I40: =SUM(C40:G40) -> 0 | J40: =$D$9 -> 0.15 | K40: =I40/(1-J40) -> 0
B41: DATA LABOR | C41: 0 | D41: 0 | E41: 0 | F41: 0 | G41: 0 | I41: =SUM(C41:G41) -> 0 | J41: =$D$9 -> 0.15 | K41: =I41/(1-J41) -> 0
B42: SUB PANEL | C42: 0 | D42: 0 | E42: 0 | F42: 0 | G42: 0 | I42: =SUM(C42:G42) -> 0 | J42: =$D$9 -> 0.15 | K42: =I42/(1-J42) -> 0
B43: MISC | C43: 0 | D43: 0 | E43: 0 | F43: 0 | G43: 0 | I43: =SUM(C43:G43) -> 0 | J43: =$D$9 -> 0.15 | K43: =I43/(1-J43) -> 0
B44: SUBTOTAL | I44: =SUM(I38:I43) -> 5468.75 | K44: =SUM(K38:K43) -> 6433.82
B46: Submittals, Engineering, and Permits | C46: Subcontractor 1 | D46: Subcontractor 2 | E46: Subcontractor 3 | F46: Selected | G46: Additional Contingency | I46: Total Cost | J46: Install Margin | K46: Selling Price
B47: STRUCTURAL ENGINEERING | C47: 4705.88 | D47: 0 | E47: 0 | F47: 0 | G47: 0 | I47: =SUM(C47:G47) -> 4705.88 | J47: =$D$11 -> 0.15 | K47: =I47/(1-J47) -> 5536.33
B48: STRUCTURAL CERTIFICATION | C48: 0 | D48: 0 | E48: 0 | F48: 0 | G48: 0 | I48: =SUM(C48:G48) -> 0 | J48: =$D$11 -> 0.15 | K48: =I48/(1-J48) -> 0
B49: ELECTRICAL ENGINEERING | C49: 0 | D49: 0 | E49: 0 | F49: 0 | G49: 0 | I49: =SUM(C49:G49) -> 0 | J49: =$D$11 -> 0.15 | K49: =I49/(1-J49) -> 0
B50: ELECTRICAL CERTIFICATION | C50: 0 | D50: 0 | E50: 0 | F50: 0 | G50: 0 | I50: =SUM(C50:G50) -> 0 | J50: =$D$11 -> 0.15 | K50: =I50/(1-J50) -> 0
...

Sheet 9A Underpass 2 - Install
A3: Project Name: Amended RFP Exhibit I
A4: 2026-03-31
A5: Revised By: ANC Proposal Engine
C7: Linked Margin Assignment
C8: Install Margin | D8: 0.15
C9: Electrical Margin | D9: 0.15
C10: ANC Margin | D10: 0.15
C11: Engineering and Permits | D11: 0.15
B15: 9A Underpass 2
B16: Height | C16: Width | D16: Total Sq. Ft | E16: QTY
B17: 7.48 | C17: 29.92 | D17: 223.8 | E17: 1
B19: Structural Materials: | C19: Subcontractor 1 | D19: Subcontractor 2 | E19: Subcontractor 3 | F19: Selected | G19: Additional Contingency | I19: Total Cost | J19: Install Margin | K19: Selling Price
B20: FABRICATE PRIMARY STEEL | C20: 0 | D20: 0 | E20: 0 | F20: 0 | G20: 0 | I20: =SUM(C20:G20) -> 0 | J20: =$D$8 -> 0.15 | K20: =I20/(1-J20) -> 0
B21: SUPPLY AND INSTALL PRIMARY PLYWOOD | C21: 0 | D21: 0 | E21: 0 | F21: 0 | G21: 0 | I21: =SUM(C21:G21) -> 0 | J21: =$D$8 -> 0.15 | K21: =I21/(1-J21) -> 0
B22: FABRICATE SECONDARY STEEL SUBSTRUCTURE | C22: 2580 | D22: 0 | E22: 0 | F22: 0 | G22: 0 | I22: =SUM(C22:G22) -> 2580 | J22: =$D$8 -> 0.15 | K22: =I22/(1-J22) -> 3035.29
B23: FABRICATE CLADDING AND TRIM | C23: 0 | D23: 0 | E23: 0 | F23: 0 | G23: 0 | I23: =SUM(C23:G23) -> 0 | J23: =$D$8 -> 0.15 | K23: =I23/(1-J23) -> 0
B24: OTHER SCOPE ITEM | C24: 0 | D24: 0 | E24: 0 | F24: 0 | G24: 0 | I24: =SUM(C24:G24) -> 0 | J24: =$D$8 -> 0.15 | K24: =I24/(1-J24) -> 0
B25: OTHER SCOPE ITEM | C25: 0 | D25: 0 | E25: 0 | F25: 0 | G25: 0 | I25: =SUM(C25:G25) -> 0 | J25: =$D$8 -> 0.15 | K25: =I25/(1-J25) -> 0
B26: SUBTOTAL | I26: =SUM(I20:I25) -> 2580 | K26: =SUM(K20:K25) -> 3035.29
B28: Structural Labor and LED Installation | C28: Subcontractor 1 | D28: Subcontractor 2 | E28: Subcontractor 3 | F28: Selected | G28: Additional Contingency | I28: Total Cost | J28: Install Margin | K28: Selling Price
B29: REMOVAL AND DISPOSAL | C29: 0 | D29: 0 | E29: 0 | F29: 0 | G29: 0 | I29: =SUM(C29:G29) -> 0 | J29: =$D$8 -> 0.15 | K29: =I29/(1-J29) -> 0
B30: INSTALL SECONDARY STEEL SUBSTRUCTURE | C30: 0 | D30: 0 | E30: 0 | F30: 0 | G30: 0 | I30: =SUM(C30:G30) -> 0 | J30: =$D$8 -> 0.15 | K30: =I30/(1-J30) -> 0
B31: INSTALL LED DISPLAYS | C31: 10750 | D31: 0 | E31: 0 | F31: 0 | G31: 0 | I31: =SUM(C31:G31) -> 10750 | J31: =$D$8 -> 0.15 | K31: =I31/(1-J31) -> 12647.06
B32: INSTALL CLADDING AND TRIM | C32: 0 | D32: 0 | E32: 0 | F32: 0 | G32: 0 | I32: =SUM(C32:G32) -> 0 | J32: =$D$8 -> 0.15 | K32: =I32/(1-J32) -> 0
B33: HEAVY EQUIPMENT | C33: 0 | D33: 0 | E33: 0 | F33: 0 | G33: 0 | I33: =SUM(C33:G33) -> 0 | J33: =$D$8 -> 0.15 | K33: =I33/(1-J33) -> 0
B34: PM/GENERAL CONDITIONS/TRAVEL | C34: 20882.35 | D34: 0 | E34: 0 | F34: 0 | G34: 0 | I34: =SUM(C34:G34) -> 20882.35 | J34: =$D$8 -> 0.15 | K34: =I34/(1-J34) -> 24567.47
B35: SUBTOTAL | I35: =SUM(I29:I34) -> 31632.35 | K35: =SUM(K29:K34) -> 37214.53
B37: Electrical and Data - Materials and Subcontracting | C37: Subcontractor 1 | D37: Subcontractor 2 | E37: Subcontractor 3 | F37: Selected | G37: Additional Contingency | I37: Total Cost | J37: Install Margin | K37: Selling Price
B38: ELECTRICAL MATERIALS | C38: 10750 | D38: 0 | E38: 0 | F38: 0 | G38: 0 | I38: =SUM(C38:G38) -> 10750 | J38: =$D$9 -> 0.15 | K38: =I38/(1-J38) -> 12647.06
B39: DATA MATERIALS | C39: 0 | D39: 0 | E39: 0 | F39: 0 | G39: 0 | I39: =SUM(C39:G39) -> 0 | J39: =$D$9 -> 0.15 | K39: =I39/(1-J39) -> 0
B40: ELECTRICAL LABOR | C40: 0 | D40: 0 | E40: 0 | F40: 0 | G40: 0 | I40: =SUM(C40:G40) -> 0 | J40: =$D$9 -> 0.15 | K40: =I40/(1-J40) -> 0
B41: DATA LABOR | C41: 0 | D41: 0 | E41: 0 | F41: 0 | G41: 0 | I41: =SUM(C41:G41) -> 0 | J41: =$D$9 -> 0.15 | K41: =I41/(1-J41) -> 0
B42: SUB PANEL | C42: 0 | D42: 0 | E42: 0 | F42: 0 | G42: 0 | I42: =SUM(C42:G42) -> 0 | J42: =$D$9 -> 0.15 | K42: =I42/(1-J42) -> 0
B43: MISC | C43: 0 | D43: 0 | E43: 0 | F43: 0 | G43: 0 | I43: =SUM(C43:G43) -> 0 | J43: =$D$9 -> 0.15 | K43: =I43/(1-J43) -> 0
B44: SUBTOTAL | I44: =SUM(I38:I43) -> 10750 | K44: =SUM(K38:K43) -> 12647.06
B46: Submittals, Engineering, and Permits | C46: Subcontractor 1 | D46: Subcontractor 2 | E46: Subcontractor 3 | F46: Selected | G46: Additional Contingency | I46: Total Cost | J46: Install Margin | K46: Selling Price
B47: STRUCTURAL ENGINEERING | C47: 4705.88 | D47: 0 | E47: 0 | F47: 0 | G47: 0 | I47: =SUM(C47:G47) -> 4705.88 | J47: =$D$11 -> 0.15 | K47: =I47/(1-J47) -> 5536.33
B48: STRUCTURAL CERTIFICATION | C48: 0 | D48: 0 | E48: 0 | F48: 0 | G48: 0 | I48: =SUM(C48:G48) -> 0 | J48: =$D$11 -> 0.15 | K48: =I48/(1-J48) -> 0
B49: ELECTRICAL ENGINEERING | C49: 0 | D49: 0 | E49: 0 | F49: 0 | G49: 0 | I49: =SUM(C49:G49) -> 0 | J49: =$D$11 -> 0.15 | K49: =I49/(1-J49) -> 0
B50: ELECTRICAL CERTIFICATION | C50: 0 | D50: 0 | E50: 0 | F50: 0 | G50: 0 | I50: =SUM(C50:G50) -> 0 | J50: =$D$11 -> 0.15 | K50: =I50/(1-J50) -> 0
...

Sheet 9A Underpass 3 - Install
A3: Project Name: Amended RFP Exhibit I
A4: 2026-03-31
A5: Revised By: ANC Proposal Engine
C7: Linked Margin Assignment
C8: Install Margin | D8: 0.15
C9: Electrical Margin | D9: 0.15
C10: ANC Margin | D10: 0.15
C11: Engineering and Permits | D11: 0.15
B15: 9A Underpass 3
B16: Height | C16: Width | D16: Total Sq. Ft | E16: QTY
B17: 7.48 | C17: 29.92 | D17: 223.8 | E17: 1
B19: Structural Materials: | C19: Subcontractor 1 | D19: Subcontractor 2 | E19: Subcontractor 3 | F19: Selected | G19: Additional Contingency | I19: Total Cost | J19: Install Margin | K19: Selling Price
B20: FABRICATE PRIMARY STEEL | C20: 0 | D20: 0 | E20: 0 | F20: 0 | G20: 0 | I20: =SUM(C20:G20) -> 0 | J20: =$D$8 -> 0.15 | K20: =I20/(1-J20) -> 0
B21: SUPPLY AND INSTALL PRIMARY PLYWOOD | C21: 0 | D21: 0 | E21: 0 | F21: 0 | G21: 0 | I21: =SUM(C21:G21) -> 0 | J21: =$D$8 -> 0.15 | K21: =I21/(1-J21) -> 0
B22: FABRICATE SECONDARY STEEL SUBSTRUCTURE | C22: 2580 | D22: 0 | E22: 0 | F22: 0 | G22: 0 | I22: =SUM(C22:G22) -> 2580 | J22: =$D$8 -> 0.15 | K22: =I22/(1-J22) -> 3035.29
B23: FABRICATE CLADDING AND TRIM | C23: 0 | D23: 0 | E23: 0 | F23: 0 | G23: 0 | I23: =SUM(C23:G23) -> 0 | J23: =$D$8 -> 0.15 | K23: =I23/(1-J23) -> 0
B24: OTHER SCOPE ITEM | C24: 0 | D24: 0 | E24: 0 | F24: 0 | G24: 0 | I24: =SUM(C24:G24) -> 0 | J24: =$D$8 -> 0.15 | K24: =I24/(1-J24) -> 0
B25: OTHER SCOPE ITEM | C25: 0 | D25: 0 | E25: 0 | F25: 0 | G25: 0 | I25: =SUM(C25:G25) -> 0 | J25: =$D$8 -> 0.15 | K25: =I25/(1-J25) -> 0
B26: SUBTOTAL | I26: =SUM(I20:I25) -> 2580 | K26: =SUM(K20:K25) -> 3035.29
B28: Structural Labor and LED Installation | C28: Subcontractor 1 | D28: Subcontractor 2 | E28: Subcontractor 3 | F28: Selected | G28: Additional Contingency | I28: Total Cost | J28: Install Margin | K28: Selling Price
B29: REMOVAL AND DISPOSAL | C29: 0 | D29: 0 | E29: 0 | F29: 0 | G29: 0 | I29: =SUM(C29:G29) -> 0 | J29: =$D$8 -> 0.15 | K29: =I29/(1-J29) -> 0
B30: INSTALL SECONDARY STEEL SUBSTRUCTURE | C30: 0 | D30: 0 | E30: 0 | F30: 0 | G30: 0 | I30: =SUM(C30:G30) -> 0 | J30: =$D$8 -> 0.15 | K30: =I30/(1-J30) -> 0
B31: INSTALL LED DISPLAYS | C31: 10750 | D31: 0 | E31: 0 | F31: 0 | G31: 0 | I31: =SUM(C31:G31) -> 10750 | J31: =$D$8 -> 0.15 | K31: =I31/(1-J31) -> 12647.06
B32: INSTALL CLADDING AND TRIM | C32: 0 | D32: 0 | E32: 0 | F32: 0 | G32: 0 | I32: =SUM(C32:G32) -> 0 | J32: =$D$8 -> 0.15 | K32: =I32/(1-J32) -> 0
B33: HEAVY EQUIPMENT | C33: 0 | D33: 0 | E33: 0 | F33: 0 | G33: 0 | I33: =SUM(C33:G33) -> 0 | J33: =$D$8 -> 0.15 | K33: =I33/(1-J33) -> 0
B34: PM/GENERAL CONDITIONS/TRAVEL | C34: 20882.35 | D34: 0 | E34: 0 | F34: 0 | G34: 0 | I34: =SUM(C34:G34) -> 20882.35 | J34: =$D$8 -> 0.15 | K34: =I34/(1-J34) -> 24567.47
B35: SUBTOTAL | I35: =SUM(I29:I34) -> 31632.35 | K35: =SUM(K29:K34) -> 37214.53
B37: Electrical and Data - Materials and Subcontracting | C37: Subcontractor 1 | D37: Subcontractor 2 | E37: Subcontractor 3 | F37: Selected | G37: Additional Contingency | I37: Total Cost | J37: Install Margin | K37: Selling Price
B38: ELECTRICAL MATERIALS | C38: 10750 | D38: 0 | E38: 0 | F38: 0 | G38: 0 | I38: =SUM(C38:G38) -> 10750 | J38: =$D$9 -> 0.15 | K38: =I38/(1-J38) -> 12647.06
B39: DATA MATERIALS | C39: 0 | D39: 0 | E39: 0 | F39: 0 | G39: 0 | I39: =SUM(C39:G39) -> 0 | J39: =$D$9 -> 0.15 | K39: =I39/(1-J39) -> 0
B40: ELECTRICAL LABOR | C40: 0 | D40: 0 | E40: 0 | F40: 0 | G40: 0 | I40: =SUM(C40:G40) -> 0 | J40: =$D$9 -> 0.15 | K40: =I40/(1-J40) -> 0
B41: DATA LABOR | C41: 0 | D41: 0 | E41: 0 | F41: 0 | G41: 0 | I41: =SUM(C41:G41) -> 0 | J41: =$D$9 -> 0.15 | K41: =I41/(1-J41) -> 0
B42: SUB PANEL | C42: 0 | D42: 0 | E42: 0 | F42: 0 | G42: 0 | I42: =SUM(C42:G42) -> 0 | J42: =$D$9 -> 0.15 | K42: =I42/(1-J42) -> 0
B43: MISC | C43: 0 | D43: 0 | E43: 0 | F43: 0 | G43: 0 | I43: =SUM(C43:G43) -> 0 | J43: =$D$9 -> 0.15 | K43: =I43/(1-J43) -> 0
B44: SUBTOTAL | I44: =SUM(I38:I43) -> 10750 | K44: =SUM(K38:K43) -> 12647.06
B46: Submittals, Engineering, and Permits | C46: Subcontractor 1 | D46: Subcontractor 2 | E46: Subcontractor 3 | F46: Selected | G46: Additional Contingency | I46: Total Cost | J46: Install Margin | K46: Selling Price
B47: STRUCTURAL ENGINEERING | C47: 4705.88 | D47: 0 | E47: 0 | F47: 0 | G47: 0 | I47: =SUM(C47:G47) -> 4705.88 | J47: =$D$11 -> 0.15 | K47: =I47/(1-J47) -> 5536.33
B48: STRUCTURAL CERTIFICATION | C48: 0 | D48: 0 | E48: 0 | F48: 0 | G48: 0 | I48: =SUM(C48:G48) -> 0 | J48: =$D$11 -> 0.15 | K48: =I48/(1-J48) -> 0
B49: ELECTRICAL ENGINEERING | C49: 0 | D49: 0 | E49: 0 | F49: 0 | G49: 0 | I49: =SUM(C49:G49) -> 0 | J49: =$D$11 -> 0.15 | K49: =I49/(1-J49) -> 0
B50: ELECTRICAL CERTIFICATION | C50: 0 | D50: 0 | E50: 0 | F50: 0 | G50: 0 | I50: =SUM(C50:G50) -> 0 | J50: =$D$11 -> 0.15 | K50: =I50/(1-J50) -> 0
...

Sheet 9A Underpass 4 - Install
A3: Project Name: Amended RFP Exhibit I
A4: 2026-03-31
A5: Revised By: ANC Proposal Engine
C7: Linked Margin Assignment
C8: Install Margin | D8: 0.15
C9: Electrical Margin | D9: 0.15
C10: ANC Margin | D10: 0.15
C11: Engineering and Permits | D11: 0.15
B15: 9A Underpass 4
B16: Height | C16: Width | D16: Total Sq. Ft | E16: QTY
B17: 12.6 | C17: 29.92 | D17: 376.99 | E17: 1
B19: Structural Materials: | C19: Subcontractor 1 | D19: Subcontractor 2 | E19: Subcontractor 3 | F19: Selected | G19: Additional Contingency | I19: Total Cost | J19: Install Margin | K19: Selling Price
B20: FABRICATE PRIMARY STEEL | C20: 0 | D20: 0 | E20: 0 | F20: 0 | G20: 0 | I20: =SUM(C20:G20) -> 0 | J20: =$D$8 -> 0.15 | K20: =I20/(1-J20) -> 0
B21: SUPPLY AND INSTALL PRIMARY PLYWOOD | C21: 0 | D21: 0 | E21: 0 | F21: 0 | G21: 0 | I21: =SUM(C21:G21) -> 0 | J21: =$D$8 -> 0.15 | K21: =I21/(1-J21) -> 0
B22: FABRICATE SECONDARY STEEL SUBSTRUCTURE | C22: 4342.5 | D22: 0 | E22: 0 | F22: 0 | G22: 0 | I22: =SUM(C22:G22) -> 4342.5 | J22: =$D$8 -> 0.15 | K22: =I22/(1-J22) -> 5108.82
B23: FABRICATE CLADDING AND TRIM | C23: 0 | D23: 0 | E23: 0 | F23: 0 | G23: 0 | I23: =SUM(C23:G23) -> 0 | J23: =$D$8 -> 0.15 | K23: =I23/(1-J23) -> 0
B24: OTHER SCOPE ITEM | C24: 0 | D24: 0 | E24: 0 | F24: 0 | G24: 0 | I24: =SUM(C24:G24) -> 0 | J24: =$D$8 -> 0.15 | K24: =I24/(1-J24) -> 0
B25: OTHER SCOPE ITEM | C25: 0 | D25: 0 | E25: 0 | F25: 0 | G25: 0 | I25: =SUM(C25:G25) -> 0 | J25: =$D$8 -> 0.15 | K25: =I25/(1-J25) -> 0
B26: SUBTOTAL | I26: =SUM(I20:I25) -> 4342.5 | K26: =SUM(K20:K25) -> 5108.82
B28: Structural Labor and LED Installation | C28: Subcontractor 1 | D28: Subcontractor 2 | E28: Subcontractor 3 | F28: Selected | G28: Additional Contingency | I28: Total Cost | J28: Install Margin | K28: Selling Price
B29: REMOVAL AND DISPOSAL | C29: 0 | D29: 0 | E29: 0 | F29: 0 | G29: 0 | I29: =SUM(C29:G29) -> 0 | J29: =$D$8 -> 0.15 | K29: =I29/(1-J29) -> 0
B30: INSTALL SECONDARY STEEL SUBSTRUCTURE | C30: 0 | D30: 0 | E30: 0 | F30: 0 | G30: 0 | I30: =SUM(C30:G30) -> 0 | J30: =$D$8 -> 0.15 | K30: =I30/(1-J30) -> 0
B31: INSTALL LED DISPLAYS | C31: 18093.75 | D31: 0 | E31: 0 | F31: 0 | G31: 0 | I31: =SUM(C31:G31) -> 18093.75 | J31: =$D$8 -> 0.15 | K31: =I31/(1-J31) -> 21286.76
B32: INSTALL CLADDING AND TRIM | C32: 0 | D32: 0 | E32: 0 | F32: 0 | G32: 0 | I32: =SUM(C32:G32) -> 0 | J32: =$D$8 -> 0.15 | K32: =I32/(1-J32) -> 0
B33: HEAVY EQUIPMENT | C33: 0 | D33: 0 | E33: 0 | F33: 0 | G33: 0 | I33: =SUM(C33:G33) -> 0 | J33: =$D$8 -> 0.15 | K33: =I33/(1-J33) -> 0
B34: PM/GENERAL CONDITIONS/TRAVEL | C34: 20882.35 | D34: 0 | E34: 0 | F34: 0 | G34: 0 | I34: =SUM(C34:G34) -> 20882.35 | J34: =$D$8 -> 0.15 | K34: =I34/(1-J34) -> 24567.47
B35: SUBTOTAL | I35: =SUM(I29:I34) -> 38976.1 | K35: =SUM(K29:K34) -> 45854.24
B37: Electrical and Data - Materials and Subcontracting | C37: Subcontractor 1 | D37: Subcontractor 2 | E37: Subcontractor 3 | F37: Selected | G37: Additional Contingency | I37: Total Cost | J37: Install Margin | K37: Selling Price
B38: ELECTRICAL MATERIALS | C38: 18093.75 | D38: 0 | E38: 0 | F38: 0 | G38: 0 | I38: =SUM(C38:G38) -> 18093.75 | J38: =$D$9 -> 0.15 | K38: =I38/(1-J38) -> 21286.76
B39: DATA MATERIALS | C39: 0 | D39: 0 | E39: 0 | F39: 0 | G39: 0 | I39: =SUM(C39:G39) -> 0 | J39: =$D$9 -> 0.15 | K39: =I39/(1-J39) -> 0
B40: ELECTRICAL LABOR | C40: 0 | D40: 0 | E40: 0 | F40: 0 | G40: 0 | I40: =SUM(C40:G40) -> 0 | J40: =$D$9 -> 0.15 | K40: =I40/(1-J40) -> 0
B41: DATA LABOR | C41: 0 | D41: 0 | E41: 0 | F41: 0 | G41: 0 | I41: =SUM(C41:G41) -> 0 | J41: =$D$9 -> 0.15 | K41: =I41/(1-J41) -> 0
B42: SUB PANEL | C42: 0 | D42: 0 | E42: 0 | F42: 0 | G42: 0 | I42: =SUM(C42:G42) -> 0 | J42: =$D$9 -> 0.15 | K42: =I42/(1-J42) -> 0
B43: MISC | C43: 0 | D43: 0 | E43: 0 | F43: 0 | G43: 0 | I43: =SUM(C43:G43) -> 0 | J43: =$D$9 -> 0.15 | K43: =I43/(1-J43) -> 0
B44: SUBTOTAL | I44: =SUM(I38:I43) -> 18093.75 | K44: =SUM(K38:K43) -> 21286.76
B46: Submittals, Engineering, and Permits | C46: Subcontractor 1 | D46: Subcontractor 2 | E46: Subcontractor 3 | F46: Selected | G46: Additional Contingency | I46: Total Cost | J46: Install Margin | K46: Selling Price
B47: STRUCTURAL ENGINEERING | C47: 4705.88 | D47: 0 | E47: 0 | F47: 0 | G47: 0 | I47: =SUM(C47:G47) -> 4705.88 | J47: =$D$11 -> 0.15 | K47: =I47/(1-J47) -> 5536.33
B48: STRUCTURAL CERTIFICATION | C48: 0 | D48: 0 | E48: 0 | F48: 0 | G48: 0 | I48: =SUM(C48:G48) -> 0 | J48: =$D$11 -> 0.15 | K48: =I48/(1-J48) -> 0
B49: ELECTRICAL ENGINEERING | C49: 0 | D49: 0 | E49: 0 | F49: 0 | G49: 0 | I49: =SUM(C49:G49) -> 0 | J49: =$D$11 -> 0.15 | K49: =I49/(1-J49) -> 0
B50: ELECTRICAL CERTIFICATION | C50: 0 | D50: 0 | E50: 0 | F50: 0 | G50: 0 | I50: =SUM(C50:G50) -> 0 | J50: =$D$11 -> 0.15 | K50: =I50/(1-J50) -> 0
...

Sheet Concourse - Install
A3: Project Name: Amended RFP Exhibit I
A4: 2026-03-31
A5: Revised By: ANC Proposal Engine
C7: Linked Margin Assignment
C8: Install Margin | D8: 0.15
C9: Electrical Margin | D9: 0.15
C10: ANC Margin | D10: 0.15
C11: Engineering and Permits | D11: 0.15
B15: Concourse
B16: Height | C16: Width | D16: Total Sq. Ft | E16: QTY
B17: 9.45 | C17: 280.31 | D17: 2648.93 | E17: 1
B19: Structural Materials: | C19: Subcontractor 1 | D19: Subcontractor 2 | E19: Subcontractor 3 | F19: Selected | G19: Additional Contingency | I19: Total Cost | J19: Install Margin | K19: Selling Price
B20: FABRICATE PRIMARY STEEL | C20: 0 | D20: 0 | E20: 0 | F20: 0 | G20: 0 | I20: =SUM(C20:G20) -> 0 | J20: =$D$8 -> 0.15 | K20: =I20/(1-J20) -> 0
B21: SUPPLY AND INSTALL PRIMARY PLYWOOD | C21: 0 | D21: 0 | E21: 0 | F21: 0 | G21: 0 | I21: =SUM(C21:G21) -> 0 | J21: =$D$8 -> 0.15 | K21: =I21/(1-J21) -> 0
B22: FABRICATE SECONDARY STEEL SUBSTRUCTURE | C22: 30536.25 | D22: 0 | E22: 0 | F22: 0 | G22: 0 | I22: =SUM(C22:G22) -> 30536.25 | J22: =$D$8 -> 0.15 | K22: =I22/(1-J22) -> 35925
B23: FABRICATE CLADDING AND TRIM | C23: 0 | D23: 0 | E23: 0 | F23: 0 | G23: 0 | I23: =SUM(C23:G23) -> 0 | J23: =$D$8 -> 0.15 | K23: =I23/(1-J23) -> 0
B24: OTHER SCOPE ITEM | C24: 0 | D24: 0 | E24: 0 | F24: 0 | G24: 0 | I24: =SUM(C24:G24) -> 0 | J24: =$D$8 -> 0.15 | K24: =I24/(1-J24) -> 0
B25: OTHER SCOPE ITEM | C25: 0 | D25: 0 | E25: 0 | F25: 0 | G25: 0 | I25: =SUM(C25:G25) -> 0 | J25: =$D$8 -> 0.15 | K25: =I25/(1-J25) -> 0
B26: SUBTOTAL | I26: =SUM(I20:I25) -> 30536.25 | K26: =SUM(K20:K25) -> 35925
B28: Structural Labor and LED Installation | C28: Subcontractor 1 | D28: Subcontractor 2 | E28: Subcontractor 3 | F28: Selected | G28: Additional Contingency | I28: Total Cost | J28: Install Margin | K28: Selling Price
B29: REMOVAL AND DISPOSAL | C29: 0 | D29: 0 | E29: 0 | F29: 0 | G29: 0 | I29: =SUM(C29:G29) -> 0 | J29: =$D$8 -> 0.15 | K29: =I29/(1-J29) -> 0
B30: INSTALL SECONDARY STEEL SUBSTRUCTURE | C30: 0 | D30: 0 | E30: 0 | F30: 0 | G30: 0 | I30: =SUM(C30:G30) -> 0 | J30: =$D$8 -> 0.15 | K30: =I30/(1-J30) -> 0
B31: INSTALL LED DISPLAYS | C31: 127234.38 | D31: 0 | E31: 0 | F31: 0 | G31: 0 | I31: =SUM(C31:G31) -> 127234.38 | J31: =$D$8 -> 0.15 | K31: =I31/(1-J31) -> 149687.51
B32: INSTALL CLADDING AND TRIM | C32: 0 | D32: 0 | E32: 0 | F32: 0 | G32: 0 | I32: =SUM(C32:G32) -> 0 | J32: =$D$8 -> 0.15 | K32: =I32/(1-J32) -> 0
B33: HEAVY EQUIPMENT | C33: 0 | D33: 0 | E33: 0 | F33: 0 | G33: 0 | I33: =SUM(C33:G33) -> 0 | J33: =$D$8 -> 0.15 | K33: =I33/(1-J33) -> 0
B34: PM/GENERAL CONDITIONS/TRAVEL | C34: 20882.35 | D34: 0 | E34: 0 | F34: 0 | G34: 0 | I34: =SUM(C34:G34) -> 20882.35 | J34: =$D$8 -> 0.15 | K34: =I34/(1-J34) -> 24567.47
B35: SUBTOTAL | I35: =SUM(I29:I34) -> 148116.73 | K35: =SUM(K29:K34) -> 174254.98
B37: Electrical and Data - Materials and Subcontracting | C37: Subcontractor 1 | D37: Subcontractor 2 | E37: Subcontractor 3 | F37: Selected | G37: Additional Contingency | I37: Total Cost | J37: Install Margin | K37: Selling Price
B38: ELECTRICAL MATERIALS | C38: 127234.38 | D38: 0 | E38: 0 | F38: 0 | G38: 0 | I38: =SUM(C38:G38) -> 127234.38 | J38: =$D$9 -> 0.15 | K38: =I38/(1-J38) -> 149687.51
B39: DATA MATERIALS | C39: 0 | D39: 0 | E39: 0 | F39: 0 | G39: 0 | I39: =SUM(C39:G39) -> 0 | J39: =$D$9 -> 0.15 | K39: =I39/(1-J39) -> 0
B40: ELECTRICAL LABOR | C40: 0 | D40: 0 | E40: 0 | F40: 0 | G40: 0 | I40: =SUM(C40:G40) -> 0 | J40: =$D$9 -> 0.15 | K40: =I40/(1-J40) -> 0
B41: DATA LABOR | C41: 0 | D41: 0 | E41: 0 | F41: 0 | G41: 0 | I41: =SUM(C41:G41) -> 0 | J41: =$D$9 -> 0.15 | K41: =I41/(1-J41) -> 0
B42: SUB PANEL | C42: 0 | D42: 0 | E42: 0 | F42: 0 | G42: 0 | I42: =SUM(C42:G42) -> 0 | J42: =$D$9 -> 0.15 | K42: =I42/(1-J42) -> 0
B43: MISC | C43: 0 | D43: 0 | E43: 0 | F43: 0 | G43: 0 | I43: =SUM(C43:G43) -> 0 | J43: =$D$9 -> 0.15 | K43: =I43/(1-J43) -> 0
B44: SUBTOTAL | I44: =SUM(I38:I43) -> 127234.38 | K44: =SUM(K38:K43) -> 149687.51
B46: Submittals, Engineering, and Permits | C46: Subcontractor 1 | D46: Subcontractor 2 | E46: Subcontractor 3 | F46: Selected | G46: Additional Contingency | I46: Total Cost | J46: Install Margin | K46: Selling Price
B47: STRUCTURAL ENGINEERING | C47: 4705.88 | D47: 0 | E47: 0 | F47: 0 | G47: 0 | I47: =SUM(C47:G47) -> 4705.88 | J47: =$D$11 -> 0.15 | K47: =I47/(1-J47) -> 5536.33
B48: STRUCTURAL CERTIFICATION | C48: 0 | D48: 0 | E48: 0 | F48: 0 | G48: 0 | I48: =SUM(C48:G48) -> 0 | J48: =$D$11 -> 0.15 | K48: =I48/(1-J48) -> 0
B49: ELECTRICAL ENGINEERING | C49: 0 | D49: 0 | E49: 0 | F49: 0 | G49: 0 | I49: =SUM(C49:G49) -> 0 | J49: =$D$11 -> 0.15 | K49: =I49/(1-J49) -> 0
B50: ELECTRICAL CERTIFICATION | C50: 0 | D50: 0 | E50: 0 | F50: 0 | G50: 0 | I50: =SUM(C50:G50) -> 0 | J50: =$D$11 -> 0.15 | K50: =I50/(1-J50) -> 0
...

Sheet T4 Elevator - Install
A3: Project Name: Amended RFP Exhibit I
A4: 2026-03-31
A5: Revised By: ANC Proposal Engine
C7: Linked Margin Assignment
C8: Install Margin | D8: 0.15
C9: Electrical Margin | D9: 0.15
C10: ANC Margin | D10: 0.15
C11: Engineering and Permits | D11: 0.15
B15: T4 Elevator
B16: Height | C16: Width | D16: Total Sq. Ft | E16: QTY
B17: 71.6 | C17: 5.5 | D17: 393.8 | E17: 1
B19: Structural Materials: | C19: Subcontractor 1 | D19: Subcontractor 2 | E19: Subcontractor 3 | F19: Selected | G19: Additional Contingency | I19: Total Cost | J19: Install Margin | K19: Selling Price
B20: FABRICATE PRIMARY STEEL | C20: 0 | D20: 0 | E20: 0 | F20: 0 | G20: 0 | I20: =SUM(C20:G20) -> 0 | J20: =$D$8 -> 0.15 | K20: =I20/(1-J20) -> 0
B21: SUPPLY AND INSTALL PRIMARY PLYWOOD | C21: 0 | D21: 0 | E21: 0 | F21: 0 | G21: 0 | I21: =SUM(C21:G21) -> 0 | J21: =$D$8 -> 0.15 | K21: =I21/(1-J21) -> 0
B22: FABRICATE SECONDARY STEEL SUBSTRUCTURE | C22: 4537.5 | D22: 0 | E22: 0 | F22: 0 | G22: 0 | I22: =SUM(C22:G22) -> 4537.5 | J22: =$D$8 -> 0.15 | K22: =I22/(1-J22) -> 5338.24
B23: FABRICATE CLADDING AND TRIM | C23: 0 | D23: 0 | E23: 0 | F23: 0 | G23: 0 | I23: =SUM(C23:G23) -> 0 | J23: =$D$8 -> 0.15 | K23: =I23/(1-J23) -> 0
B24: OTHER SCOPE ITEM | C24: 0 | D24: 0 | E24: 0 | F24: 0 | G24: 0 | I24: =SUM(C24:G24) -> 0 | J24: =$D$8 -> 0.15 | K24: =I24/(1-J24) -> 0
B25: OTHER SCOPE ITEM | C25: 0 | D25: 0 | E25: 0 | F25: 0 | G25: 0 | I25: =SUM(C25:G25) -> 0 | J25: =$D$8 -> 0.15 | K25: =I25/(1-J25) -> 0
B26: SUBTOTAL | I26: =SUM(I20:I25) -> 4537.5 | K26: =SUM(K20:K25) -> 5338.24
B28: Structural Labor and LED Installation | C28: Subcontractor 1 | D28: Subcontractor 2 | E28: Subcontractor 3 | F28: Selected | G28: Additional Contingency | I28: Total Cost | J28: Install Margin | K28: Selling Price
B29: REMOVAL AND DISPOSAL | C29: 0 | D29: 0 | E29: 0 | F29: 0 | G29: 0 | I29: =SUM(C29:G29) -> 0 | J29: =$D$8 -> 0.15 | K29: =I29/(1-J29) -> 0
B30: INSTALL SECONDARY STEEL SUBSTRUCTURE | C30: 0 | D30: 0 | E30: 0 | F30: 0 | G30: 0 | I30: =SUM(C30:G30) -> 0 | J30: =$D$8 -> 0.15 | K30: =I30/(1-J30) -> 0
B31: INSTALL LED DISPLAYS | C31: 18906.25 | D31: 0 | E31: 0 | F31: 0 | G31: 0 | I31: =SUM(C31:G31) -> 18906.25 | J31: =$D$8 -> 0.15 | K31: =I31/(1-J31) -> 22242.65
B32: INSTALL CLADDING AND TRIM | C32: 0 | D32: 0 | E32: 0 | F32: 0 | G32: 0 | I32: =SUM(C32:G32) -> 0 | J32: =$D$8 -> 0.15 | K32: =I32/(1-J32) -> 0
B33: HEAVY EQUIPMENT | C33: 0 | D33: 0 | E33: 0 | F33: 0 | G33: 0 | I33: =SUM(C33:G33) -> 0 | J33: =$D$8 -> 0.15 | K33: =I33/(1-J33) -> 0
B34: PM/GENERAL CONDITIONS/TRAVEL | C34: 20882.35 | D34: 0 | E34: 0 | F34: 0 | G34: 0 | I34: =SUM(C34:G34) -> 20882.35 | J34: =$D$8 -> 0.15 | K34: =I34/(1-J34) -> 24567.47
B35: SUBTOTAL | I35: =SUM(I29:I34) -> 39788.6 | K35: =SUM(K29:K34) -> 46810.12
B37: Electrical and Data - Materials and Subcontracting | C37: Subcontractor 1 | D37: Subcontractor 2 | E37: Subcontractor 3 | F37: Selected | G37: Additional Contingency | I37: Total Cost | J37: Install Margin | K37: Selling Price
B38: ELECTRICAL MATERIALS | C38: 18906.25 | D38: 0 | E38: 0 | F38: 0 | G38: 0 | I38: =SUM(C38:G38) -> 18906.25 | J38: =$D$9 -> 0.15 | K38: =I38/(1-J38) -> 22242.65
B39: DATA MATERIALS | C39: 0 | D39: 0 | E39: 0 | F39: 0 | G39: 0 | I39: =SUM(C39:G39) -> 0 | J39: =$D$9 -> 0.15 | K39: =I39/(1-J39) -> 0
B40: ELECTRICAL LABOR | C40: 0 | D40: 0 | E40: 0 | F40: 0 | G40: 0 | I40: =SUM(C40:G40) -> 0 | J40: =$D$9 -> 0.15 | K40: =I40/(1-J40) -> 0
B41: DATA LABOR | C41: 0 | D41: 0 | E41: 0 | F41: 0 | G41: 0 | I41: =SUM(C41:G41) -> 0 | J41: =$D$9 -> 0.15 | K41: =I41/(1-J41) -> 0
B42: SUB PANEL | C42: 0 | D42: 0 | E42: 0 | F42: 0 | G42: 0 | I42: =SUM(C42:G42) -> 0 | J42: =$D$9 -> 0.15 | K42: =I42/(1-J42) -> 0
B43: MISC | C43: 0 | D43: 0 | E43: 0 | F43: 0 | G43: 0 | I43: =SUM(C43:G43) -> 0 | J43: =$D$9 -> 0.15 | K43: =I43/(1-J43) -> 0
B44: SUBTOTAL | I44: =SUM(I38:I43) -> 18906.25 | K44: =SUM(K38:K43) -> 22242.65
B46: Submittals, Engineering, and Permits | C46: Subcontractor 1 | D46: Subcontractor 2 | E46: Subcontractor 3 | F46: Selected | G46: Additional Contingency | I46: Total Cost | J46: Install Margin | K46: Selling Price
B47: STRUCTURAL ENGINEERING | C47: 4705.88 | D47: 0 | E47: 0 | F47: 0 | G47: 0 | I47: =SUM(C47:G47) -> 4705.88 | J47: =$D$11 -> 0.15 | K47: =I47/(1-J47) -> 5536.33
B48: STRUCTURAL CERTIFICATION | C48: 0 | D48: 0 | E48: 0 | F48: 0 | G48: 0 | I48: =SUM(C48:G48) -> 0 | J48: =$D$11 -> 0.15 | K48: =I48/(1-J48) -> 0
B49: ELECTRICAL ENGINEERING | C49: 0 | D49: 0 | E49: 0 | F49: 0 | G49: 0 | I49: =SUM(C49:G49) -> 0 | J49: =$D$11 -> 0.15 | K49: =I49/(1-J49) -> 0
B50: ELECTRICAL CERTIFICATION | C50: 0 | D50: 0 | E50: 0 | F50: 0 | G50: 0 | I50: =SUM(C50:G50) -> 0 | J50: =$D$11 -> 0.15 | K50: =I50/(1-J50) -> 0
...

Sheet New Path Hall Option 1 - Instal
A3: Project Name: Amended RFP Exhibit I
A4: 2026-03-31
A5: Revised By: ANC Proposal Engine
C7: Linked Margin Assignment
C8: Install Margin | D8: 0.15
C9: Electrical Margin | D9: 0.15
C10: ANC Margin | D10: 0.15
C11: Engineering and Permits | D11: 0.15
B15: New Path Hall Option 1
B16: Height | C16: Width | D16: Total Sq. Ft | E16: QTY
B17: 48 | C17: 14 | D17: 672 | E17: 1
B19: Structural Materials: | C19: Subcontractor 1 | D19: Subcontractor 2 | E19: Subcontractor 3 | F19: Selected | G19: Additional Contingency | I19: Total Cost | J19: Install Margin | K19: Selling Price
B20: FABRICATE PRIMARY STEEL | C20: 0 | D20: 0 | E20: 0 | F20: 0 | G20: 0 | I20: =SUM(C20:G20) -> 0 | J20: =$D$8 -> 0.15 | K20: =I20/(1-J20) -> 0
B21: SUPPLY AND INSTALL PRIMARY PLYWOOD | C21: 0 | D21: 0 | E21: 0 | F21: 0 | G21: 0 | I21: =SUM(C21:G21) -> 0 | J21: =$D$8 -> 0.15 | K21: =I21/(1-J21) -> 0
B22: FABRICATE SECONDARY STEEL SUBSTRUCTURE | C22: 7740 | D22: 0 | E22: 0 | F22: 0 | G22: 0 | I22: =SUM(C22:G22) -> 7740 | J22: =$D$8 -> 0.15 | K22: =I22/(1-J22) -> 9105.88
B23: FABRICATE CLADDING AND TRIM | C23: 0 | D23: 0 | E23: 0 | F23: 0 | G23: 0 | I23: =SUM(C23:G23) -> 0 | J23: =$D$8 -> 0.15 | K23: =I23/(1-J23) -> 0
B24: OTHER SCOPE ITEM | C24: 0 | D24: 0 | E24: 0 | F24: 0 | G24: 0 | I24: =SUM(C24:G24) -> 0 | J24: =$D$8 -> 0.15 | K24: =I24/(1-J24) -> 0
B25: OTHER SCOPE ITEM | C25: 0 | D25: 0 | E25: 0 | F25: 0 | G25: 0 | I25: =SUM(C25:G25) -> 0 | J25: =$D$8 -> 0.15 | K25: =I25/(1-J25) -> 0
B26: SUBTOTAL | I26: =SUM(I20:I25) -> 7740 | K26: =SUM(K20:K25) -> 9105.88
B28: Structural Labor and LED Installation | C28: Subcontractor 1 | D28: Subcontractor 2 | E28: Subcontractor 3 | F28: Selected | G28: Additional Contingency | I28: Total Cost | J28: Install Margin | K28: Selling Price
B29: REMOVAL AND DISPOSAL | C29: 0 | D29: 0 | E29: 0 | F29: 0 | G29: 0 | I29: =SUM(C29:G29) -> 0 | J29: =$D$8 -> 0.15 | K29: =I29/(1-J29) -> 0
B30: INSTALL SECONDARY STEEL SUBSTRUCTURE | C30: 0 | D30: 0 | E30: 0 | F30: 0 | G30: 0 | I30: =SUM(C30:G30) -> 0 | J30: =$D$8 -> 0.15 | K30: =I30/(1-J30) -> 0
B31: INSTALL LED DISPLAYS | C31: 32250 | D31: 0 | E31: 0 | F31: 0 | G31: 0 | I31: =SUM(C31:G31) -> 32250 | J31: =$D$8 -> 0.15 | K31: =I31/(1-J31) -> 37941.18
B32: INSTALL CLADDING AND TRIM | C32: 0 | D32: 0 | E32: 0 | F32: 0 | G32: 0 | I32: =SUM(C32:G32) -> 0 | J32: =$D$8 -> 0.15 | K32: =I32/(1-J32) -> 0
B33: HEAVY EQUIPMENT | C33: 0 | D33: 0 | E33: 0 | F33: 0 | G33: 0 | I33: =SUM(C33:G33) -> 0 | J33: =$D$8 -> 0.15 | K33: =I33/(1-J33) -> 0
B34: PM/GENERAL CONDITIONS/TRAVEL | C34: 20882.35 | D34: 0 | E34: 0 | F34: 0 | G34: 0 | I34: =SUM(C34:G34) -> 20882.35 | J34: =$D$8 -> 0.15 | K34: =I34/(1-J34) -> 24567.47
B35: SUBTOTAL | I35: =SUM(I29:I34) -> 53132.35 | K35: =SUM(K29:K34) -> 62508.65
B37: Electrical and Data - Materials and Subcontracting | C37: Subcontractor 1 | D37: Subcontractor 2 | E37: Subcontractor 3 | F37: Selected | G37: Additional Contingency | I37: Total Cost | J37: Install Margin | K37: Selling Price
B38: ELECTRICAL MATERIALS | C38: 32250 | D38: 0 | E38: 0 | F38: 0 | G38: 0 | I38: =SUM(C38:G38) -> 32250 | J38: =$D$9 -> 0.15 | K38: =I38/(1-J38) -> 37941.18
B39: DATA MATERIALS | C39: 0 | D39: 0 | E39: 0 | F39: 0 | G39: 0 | I39: =SUM(C39:G39) -> 0 | J39: =$D$9 -> 0.15 | K39: =I39/(1-J39) -> 0
B40: ELECTRICAL LABOR | C40: 0 | D40: 0 | E40: 0 | F40: 0 | G40: 0 | I40: =SUM(C40:G40) -> 0 | J40: =$D$9 -> 0.15 | K40: =I40/(1-J40) -> 0
B41: DATA LABOR | C41: 0 | D41: 0 | E41: 0 | F41: 0 | G41: 0 | I41: =SUM(C41:G41) -> 0 | J41: =$D$9 -> 0.15 | K41: =I41/(1-J41) -> 0
B42: SUB PANEL | C42: 0 | D42: 0 | E42: 0 | F42: 0 | G42: 0 | I42: =SUM(C42:G42) -> 0 | J42: =$D$9 -> 0.15 | K42: =I42/(1-J42) -> 0
B43: MISC | C43: 0 | D43: 0 | E43: 0 | F43: 0 | G43: 0 | I43: =SUM(C43:G43) -> 0 | J43: =$D$9 -> 0.15 | K43: =I43/(1-J43) -> 0
B44: SUBTOTAL | I44: =SUM(I38:I43) -> 32250 | K44: =SUM(K38:K43) -> 37941.18
B46: Submittals, Engineering, and Permits | C46: Subcontractor 1 | D46: Subcontractor 2 | E46: Subcontractor 3 | F46: Selected | G46: Additional Contingency | I46: Total Cost | J46: Install Margin | K46: Selling Price
B47: STRUCTURAL ENGINEERING | C47: 4705.88 | D47: 0 | E47: 0 | F47: 0 | G47: 0 | I47: =SUM(C47:G47) -> 4705.88 | J47: =$D$11 -> 0.15 | K47: =I47/(1-J47) -> 5536.33
B48: STRUCTURAL CERTIFICATION | C48: 0 | D48: 0 | E48: 0 | F48: 0 | G48: 0 | I48: =SUM(C48:G48) -> 0 | J48: =$D$11 -> 0.15 | K48: =I48/(1-J48) -> 0
B49: ELECTRICAL ENGINEERING | C49: 0 | D49: 0 | E49: 0 | F49: 0 | G49: 0 | I49: =SUM(C49:G49) -> 0 | J49: =$D$11 -> 0.15 | K49: =I49/(1-J49) -> 0
B50: ELECTRICAL CERTIFICATION | C50: 0 | D50: 0 | E50: 0 | F50: 0 | G50: 0 | I50: =SUM(C50:G50) -> 0 | J50: =$D$11 -> 0.15 | K50: =I50/(1-J50) -> 0
...

Sheet New Path Hall Option 2 - Instal
A3: Project Name: Amended RFP Exhibit I
A4: 2026-03-31
A5: Revised By: ANC Proposal Engine
C7: Linked Margin Assignment
C8: Install Margin | D8: 0.15
C9: Electrical Margin | D9: 0.15
C10: ANC Margin | D10: 0.15
C11: Engineering and Permits | D11: 0.15
B15: New Path Hall Option 2
B16: Height | C16: Width | D16: Total Sq. Ft | E16: QTY
B17: 65 | C17: 13 | D17: 845 | E17: 1
B19: Structural Materials: | C19: Subcontractor 1 | D19: Subcontractor 2 | E19: Subcontractor 3 | F19: Selected | G19: Additional Contingency | I19: Total Cost | J19: Install Margin | K19: Selling Price
B20: FABRICATE PRIMARY STEEL | C20: 0 | D20: 0 | E20: 0 | F20: 0 | G20: 0 | I20: =SUM(C20:G20) -> 0 | J20: =$D$8 -> 0.15 | K20: =I20/(1-J20) -> 0
B21: SUPPLY AND INSTALL PRIMARY PLYWOOD | C21: 0 | D21: 0 | E21: 0 | F21: 0 | G21: 0 | I21: =SUM(C21:G21) -> 0 | J21: =$D$8 -> 0.15 | K21: =I21/(1-J21) -> 0
B22: FABRICATE SECONDARY STEEL SUBSTRUCTURE | C22: 9735 | D22: 0 | E22: 0 | F22: 0 | G22: 0 | I22: =SUM(C22:G22) -> 9735 | J22: =$D$8 -> 0.15 | K22: =I22/(1-J22) -> 11452.94
B23: FABRICATE CLADDING AND TRIM | C23: 0 | D23: 0 | E23: 0 | F23: 0 | G23: 0 | I23: =SUM(C23:G23) -> 0 | J23: =$D$8 -> 0.15 | K23: =I23/(1-J23) -> 0
B24: OTHER SCOPE ITEM | C24: 0 | D24: 0 | E24: 0 | F24: 0 | G24: 0 | I24: =SUM(C24:G24) -> 0 | J24: =$D$8 -> 0.15 | K24: =I24/(1-J24) -> 0
B25: OTHER SCOPE ITEM | C25: 0 | D25: 0 | E25: 0 | F25: 0 | G25: 0 | I25: =SUM(C25:G25) -> 0 | J25: =$D$8 -> 0.15 | K25: =I25/(1-J25) -> 0
B26: SUBTOTAL | I26: =SUM(I20:I25) -> 9735 | K26: =SUM(K20:K25) -> 11452.94
B28: Structural Labor and LED Installation | C28: Subcontractor 1 | D28: Subcontractor 2 | E28: Subcontractor 3 | F28: Selected | G28: Additional Contingency | I28: Total Cost | J28: Install Margin | K28: Selling Price
