Workbook

Sheet Project Overview
A1: WTC Digital Signage Upgrade — Project Overview
A2: Westfield | 2026-03-31 | ANC Proposal Engine
B4: PROJECT INFORMATION
B5: Client | C5: Westfield
B6: Project Name | C6: WTC Digital Signage Upgrade
B7: Location | C7: New York, NY
B8: Date Created | C8: 2026-03-31
B9: Currency | C9: USD
B10: Environment | C10: Indoor
B11: Union Labor | C11: No
B12: Bond Required | C12: No
B13: Number of Displays | C13: =SUM('LED Cost Sheet'!I4:I14) -> 447.24
B15: FINANCIAL PARAMETERS
B16: LED Hardware Margin | C16: 15%
B17: Install / Services Margin | C17: 15%
B18: Engineering Margin | C18: 15%
B19: Equipment Margin | C19: 15%
B20: CMS Margin | C20: 15%
B21: Bond Rate | C21: N/A
B22: Tax Rate | C22: Per zone (editable on MA)
B23: Tariff Rate | C23: Per zone (editable on MA)
B25: SUMMARY TOTALS
B26: Total Cost | C26: ='Margin Analysis'!C158 -> 2829644.1
B27: Total Selling Price | C27: ='Margin Analysis'!D158 -> 4636569.2
B28: Project Margin $ | C28: ='Margin Analysis'!E158 -> 1806925.1
B29: Project Margin % | C29: ='Margin Analysis'!F158 -> 0.38971166
B30: DOCUMENT TOTAL | C30: ='Margin Analysis'!D158 -> 4636569.2

Sheet Margin Analysis
A1: WTC Digital Signage Upgrade — Margin Analysis
A2: Westfield | 2026-03-31 | ANC Proposal Engine
B4: Zone / Category | C4: Cost | D4: Selling Price | E4: Margin $ | F4: Margin %
B5: Underpass 1 — 9A Underpass 1-4 | D5: Selling Price
B6: LED Hardware | C6: ='LED Cost Sheet'!T4 -> 34909.51 | D6: ='LED Cost Sheet'!V4 -> 92766.89 | E6: =IFERROR(D6-C6,0) -> 57857.38 | F6: 0.15
B7: Structural Materials | C7: ='Underpass 1 - Install'!I26 -> 2088.75 | D7: =IFERROR(C7/(1-F7),0) -> 2457.3529 | E7: =IFERROR(D7-C7,0) -> 368.60294 | F7: 0.15
B8: Structural Labor & LED Installation | C8: ='Underpass 1 - Install'!I35-'Underpass 1 - Install'!I34 -> 8703.13 | D8: =IFERROR(C8/(1-F8),0) -> 10238.976 | E8: =IFERROR(D8-C8,0) -> 1535.8465 | F8: 0.15
B9: Electrical & Data | C9: ='Underpass 1 - Install'!I44 -> 8703.13 | D9: =IFERROR(C9/(1-F9),0) -> 10238.976 | E9: =IFERROR(D9-C9,0) -> 1535.8465 | F9: 0.15
B10: PM / General Conditions / Travel | C10: ='Underpass 1 - Install'!I34 -> 20882.35 | D10: =IFERROR(C10/(1-F10),0) -> 24567.471 | E10: =IFERROR(D10-C10,0) -> 3685.1206 | F10: 0.15
B11: Engineering & Permits | C11: ='Underpass 1 - Install'!I52 -> 4705.88 | D11: =IFERROR(C11/(1-F11),0) -> 5536.3294 | E11: =IFERROR(D11-C11,0) -> 830.44941 | F11: 0.15
B12: SUBTOTAL | C12: =SUM(C6:C11) -> 79992.75 | D12: =SUM(D6:D11) -> 145806 | E12: =IFERROR(D12-C12,0) -> 65813.246 | F12: =IFERROR(1-C12/D12,0) -> 0.45137544
B13: TAX | C13: 0 | D13: 0 | E13: 0 | G13: 0
B14: BOND | C14: 0 | D14: 0 | E14: 0 | G14: 0
B15: TARIFF | C15: 0 | D15: 0 | E15: 0 | G15: 0
B16: GRAND TOTAL | C16: =C12+C13+C14+C15 -> 79992.75 | D16: =D12+D13+D14+D15 -> 145806 | E16: =IFERROR(D16-C16,0) -> 65813.246 | F16: =IFERROR(1-C16/D16,0) -> 0.45137544
B18: Underpass 2 — 9A Underpass 1-4 | D18: Selling Price
B19: LED Hardware | C19: ='LED Cost Sheet'!T5 -> 68046.11 | D19: ='LED Cost Sheet'!V5 -> 152572.17 | E19: =IFERROR(D19-C19,0) -> 84526.06 | F19: 0.15
B20: Structural Materials | C20: ='Underpass 2 - Install'!I26 -> 4102.5 | D20: =IFERROR(C20/(1-F20),0) -> 4826.4706 | E20: =IFERROR(D20-C20,0) -> 723.97059 | F20: 0.15
B21: Structural Labor & LED Installation | C21: ='Underpass 2 - Install'!I35-'Underpass 2 - Install'!I34 -> 17093.75 | D21: =IFERROR(C21/(1-F21),0) -> 20110.294 | E21: =IFERROR(D21-C21,0) -> 3016.5441 | F21: 0.15
B22: Electrical & Data | C22: ='Underpass 2 - Install'!I44 -> 17093.75 | D22: =IFERROR(C22/(1-F22),0) -> 20110.294 | E22: =IFERROR(D22-C22,0) -> 3016.5441 | F22: 0.15
B23: PM / General Conditions / Travel | C23: ='Underpass 2 - Install'!I34 -> 20882.35 | D23: =IFERROR(C23/(1-F23),0) -> 24567.471 | E23: =IFERROR(D23-C23,0) -> 3685.1206 | F23: 0.15
B24: Engineering & Permits | C24: ='Underpass 2 - Install'!I52 -> 4705.88 | D24: =IFERROR(C24/(1-F24),0) -> 5536.3294 | E24: =IFERROR(D24-C24,0) -> 830.44941 | F24: 0.15
B25: SUBTOTAL | C25: =SUM(C19:C24) -> 131924.34 | D25: =SUM(D19:D24) -> 227723.03 | E25: =IFERROR(D25-C25,0) -> 95798.689 | F25: =IFERROR(1-C25/D25,0) -> 0.42068072
B26: TAX | C26: 0 | D26: 0 | E26: 0 | G26: 0
B27: BOND | C27: 0 | D27: 0 | E27: 0 | G27: 0
B28: TARIFF | C28: 0 | D28: 0 | E28: 0 | G28: 0
B29: GRAND TOTAL | C29: =C25+C26+C27+C28 -> 131924.34 | D29: =D25+D26+D27+D28 -> 227723.03 | E29: =IFERROR(D29-C29,0) -> 95798.689 | F29: =IFERROR(1-C29/D29,0) -> 0.42068072
B31: Underpass 3 — 9A Underpass 1-4 | D31: Selling Price
B32: LED Hardware | C32: ='LED Cost Sheet'!T6 -> 68046.11 | D32: ='LED Cost Sheet'!V6 -> 152572.17 | E32: =IFERROR(D32-C32,0) -> 84526.06 | F32: 0.15
B33: Structural Materials | C33: ='Underpass 3 - Install'!I26 -> 4102.5 | D33: =IFERROR(C33/(1-F33),0) -> 4826.4706 | E33: =IFERROR(D33-C33,0) -> 723.97059 | F33: 0.15
B34: Structural Labor & LED Installation | C34: ='Underpass 3 - Install'!I35-'Underpass 3 - Install'!I34 -> 17093.75 | D34: =IFERROR(C34/(1-F34),0) -> 20110.294 | E34: =IFERROR(D34-C34,0) -> 3016.5441 | F34: 0.15
B35: Electrical & Data | C35: ='Underpass 3 - Install'!I44 -> 17093.75 | D35: =IFERROR(C35/(1-F35),0) -> 20110.294 | E35: =IFERROR(D35-C35,0) -> 3016.5441 | F35: 0.15
B36: PM / General Conditions / Travel | C36: ='Underpass 3 - Install'!I34 -> 20882.35 | D36: =IFERROR(C36/(1-F36),0) -> 24567.471 | E36: =IFERROR(D36-C36,0) -> 3685.1206 | F36: 0.15
B37: Engineering & Permits | C37: ='Underpass 3 - Install'!I52 -> 4705.88 | D37: =IFERROR(C37/(1-F37),0) -> 5536.3294 | E37: =IFERROR(D37-C37,0) -> 830.44941 | F37: 0.15
B38: SUBTOTAL | C38: =SUM(C32:C37) -> 131924.34 | D38: =SUM(D32:D37) -> 227723.03 | E38: =IFERROR(D38-C38,0) -> 95798.689 | F38: =IFERROR(1-C38/D38,0) -> 0.42068072
B39: TAX | C39: 0 | D39: 0 | E39: 0 | G39: 0
B40: BOND | C40: 0 | D40: 0 | E40: 0 | G40: 0
B41: TARIFF | C41: 0 | D41: 0 | E41: 0 | G41: 0
B42: GRAND TOTAL | C42: =C38+C39+C40+C41 -> 131924.34 | D42: =D38+D39+D40+D41 -> 227723.03 | E42: =IFERROR(D42-C42,0) -> 95798.689 | F42: =IFERROR(1-C42/D42,0) -> 0.42068072
B44: Underpass 4 — 9A Underpass 1-4 | D44: Selling Price
...

Sheet Budget Summary
A1: WTC Digital Signage Upgrade — Budget Summary
A2: Westfield | 2026-03-31 | By Category
B4: Category | C4: Cost | D4: Selling Price | E4: Margin $ | F4: Margin % | G4: Price / SqFt
B5: LED Hardware (all displays) | C5: =SUM('LED Cost Sheet'!Q4:Q14) -> 1502080.2 | D5: =SUM('LED Cost Sheet'!S4:S14) -> 51540.9 | E5: =IFERROR(D5-C5,0) -> -1450539.3 | F5: 0.15 | G5: =IFERROR(C5/5154.09,0) -> 291.43461
B6: Structural Materials | C6: =SUM('Underpass 1 - Install'!I26:I26)+SUM('Underpass 2 - Install'!I26:I26)+SUM('Underpass 3 - Install'!I26:I26)+SUM('Underpass 4 - Install'!I26:I26)+SUM('Concourse - Install'!I26:I26)+SUM('T4-B1 (6-9) - Install'!I26:I26)+SUM('T4-B2 (10-18) - Install'!I26:I26)+SUM('T4 Lobby Elevator - Install'!I26:I26)+SUM('T2-B1M Screen 20 - Install'!I26:I26)+SUM('T2-B1M Screen 21 - Install'!I26:I26)+SUM('T2-B1M Screen 22 - Install'!I26:I26) -> 94447.5 | D6: =SUM('Underpass 1 - Install'!K26:K26)+SUM('Underpass 2 - Install'!K26:K26)+SUM('Underpass 3 - Install'!K26:K26)+SUM('Underpass 4 - Install'!K26:K26)+SUM('Concourse - Install'!K26:K26)+SUM('T4-B1 (6-9) - Install'!K26:K26)+SUM('T4-B2 (10-18) - Install'!K26:K26)+SUM('T4 Lobby Elevator - Install'!K26:K26)+SUM('T2-B1M Screen 20 - Install'!K26:K26)+SUM('T2-B1M Screen 21 - Install'!K26:K26)+SUM('T2-B1M Screen 22 - Install'!K26:K26) -> 111114.71 | E6: =IFERROR(D6-C6,0) -> 16667.206 | F6: 0.15 | G6: =IFERROR(C6/5154.09,0) -> 18.324767
B7: Structural Labor & LED Installation | C7: =(SUM('Underpass 1 - Install'!I35:I35)-SUM('Underpass 1 - Install'!I34:I34))+(SUM('Underpass 2 - Install'!I35:I35)-SUM('Underpass 2 - Install'!I34:I34))+(SUM('Underpass 3 - Install'!I35:I35)-SUM('Underpass 3 - Install'!I34:I34))+(SUM('Underpass 4 - Install'!I35:I35)-SUM('Underpass 4 - Install'!I34:I34))+(SUM('Concourse - Install'!I35:I35)-SUM('Concourse - Install'!I34:I34))+(SUM('T4-B1 (6-9) - Install'!I35:I35)-SUM('T4-B1 (6-9) - Install'!I34:I34))+(SUM('T4-B2 (10-18) - Install'!I35:I35)-SUM('T4-B2 (10-18) - Install'!I34:I34))+(SUM('T4 Lobby Elevator - Install'!I35:I35)-SUM('T4 Lobby Elevator - Install'!I34:I34))+(SUM('T2-B1M Screen 20 - Install'!I35:I35)-SUM('T2-B1M Screen 20 - Install'!I34:I34))+(SUM('T2-B1M Screen 21 - Install'!I35:I35)-SUM('T2-B1M Screen 21 - Install'!I34:I34))+(SUM('T2-B1M Screen 22 - Install'!I35:I35)-SUM('T2-B1M Screen 22 - Install'!I34:I34)) -> 393531.27 | D7: =(SUM('Underpass 1 - Install'!K35:K35)-SUM('Underpass 1 - Install'!K34:K34))+(SUM('Underpass 2 - Install'!K35:K35)-SUM('Underpass 2 - Install'!K34:K34))+(SUM('Underpass 3 - Install'!K35:K35)-SUM('Underpass 3 - Install'!K34:K34))+(SUM('Underpass 4 - Install'!K35:K35)-SUM('Underpass 4 - Install'!K34:K34))+(SUM('Concourse - Install'!K35:K35)-SUM('Concourse - Install'!K34:K34))+(SUM('T4-B1 (6-9) - Install'!K35:K35)-SUM('T4-B1 (6-9) - Install'!K34:K34))+(SUM('T4-B2 (10-18) - Install'!K35:K35)-SUM('T4-B2 (10-18) - Install'!K34:K34))+(SUM('T4 Lobby Elevator - Install'!K35:K35)-SUM('T4 Lobby Elevator - Install'!K34:K34))+(SUM('T2-B1M Screen 20 - Install'!K35:K35)-SUM('T2-B1M Screen 20 - Install'!K34:K34))+(SUM('T2-B1M Screen 21 - Install'!K35:K35)-SUM('T2-B1M Screen 21 - Install'!K34:K34))+(SUM('T2-B1M Screen 22 - Install'!K35:K35)-SUM('T2-B1M Screen 22 - Install'!K34:K34)) -> 462977.96 | E7: =IFERROR(D7-C7,0) -> 69446.695 | F7: 0.15 | G7: =IFERROR(C7/5154.09,0) -> 76.353201
B8: Electrical & Data | C8: =SUM('Underpass 1 - Install'!I44:I44)+SUM('Underpass 2 - Install'!I44:I44)+SUM('Underpass 3 - Install'!I44:I44)+SUM('Underpass 4 - Install'!I44:I44)+SUM('Concourse - Install'!I44:I44)+SUM('T4-B1 (6-9) - Install'!I44:I44)+SUM('T4-B2 (10-18) - Install'!I44:I44)+SUM('T4 Lobby Elevator - Install'!I44:I44)+SUM('T2-B1M Screen 20 - Install'!I44:I44)+SUM('T2-B1M Screen 21 - Install'!I44:I44)+SUM('T2-B1M Screen 22 - Install'!I44:I44) -> 393531.27 | D8: =SUM('Underpass 1 - Install'!K44:K44)+SUM('Underpass 2 - Install'!K44:K44)+SUM('Underpass 3 - Install'!K44:K44)+SUM('Underpass 4 - Install'!K44:K44)+SUM('Concourse - Install'!K44:K44)+SUM('T4-B1 (6-9) - Install'!K44:K44)+SUM('T4-B2 (10-18) - Install'!K44:K44)+SUM('T4 Lobby Elevator - Install'!K44:K44)+SUM('T2-B1M Screen 20 - Install'!K44:K44)+SUM('T2-B1M Screen 21 - Install'!K44:K44)+SUM('T2-B1M Screen 22 - Install'!K44:K44) -> 462977.96 | E8: =IFERROR(D8-C8,0) -> 69446.695 | F8: 0.15 | G8: =IFERROR(C8/5154.09,0) -> 76.353201
B9: PM / General Conditions / Travel | C9: =SUM('Underpass 1 - Install'!I34:I34)+SUM('Underpass 2 - Install'!I34:I34)+SUM('Underpass 3 - Install'!I34:I34)+SUM('Underpass 4 - Install'!I34:I34)+SUM('Concourse - Install'!I34:I34)+SUM('T4-B1 (6-9) - Install'!I34:I34)+SUM('T4-B2 (10-18) - Install'!I34:I34)+SUM('T4 Lobby Elevator - Install'!I34:I34)+SUM('T2-B1M Screen 20 - Install'!I34:I34)+SUM('T2-B1M Screen 21 - Install'!I34:I34)+SUM('T2-B1M Screen 22 - Install'!I34:I34) -> 229705.85 | D9: =SUM('Underpass 1 - Install'!K34:K34)+SUM('Underpass 2 - Install'!K34:K34)+SUM('Underpass 3 - Install'!K34:K34)+SUM('Underpass 4 - Install'!K34:K34)+SUM('Concourse - Install'!K34:K34)+SUM('T4-B1 (6-9) - Install'!K34:K34)+SUM('T4-B2 (10-18) - Install'!K34:K34)+SUM('T4 Lobby Elevator - Install'!K34:K34)+SUM('T2-B1M Screen 20 - Install'!K34:K34)+SUM('T2-B1M Screen 21 - Install'!K34:K34)+SUM('T2-B1M Screen 22 - Install'!K34:K34) -> 270242.18 | E9: =IFERROR(D9-C9,0) -> 40536.326 | F9: 0.15
B10: Engineering & Permits | C10: =SUM('Underpass 1 - Install'!I52:I52)+SUM('Underpass 2 - Install'!I52:I52)+SUM('Underpass 3 - Install'!I52:I52)+SUM('Underpass 4 - Install'!I52:I52)+SUM('Concourse - Install'!I52:I52)+SUM('T4-B1 (6-9) - Install'!I52:I52)+SUM('T4-B2 (10-18) - Install'!I52:I52)+SUM('T4 Lobby Elevator - Install'!I52:I52)+SUM('T2-B1M Screen 20 - Install'!I52:I52)+SUM('T2-B1M Screen 21 - Install'!I52:I52)+SUM('T2-B1M Screen 22 - Install'!I52:I52) -> 51764.68 | D10: =SUM('Underpass 1 - Install'!K52:K52)+SUM('Underpass 2 - Install'!K52:K52)+SUM('Underpass 3 - Install'!K52:K52)+SUM('Underpass 4 - Install'!K52:K52)+SUM('Concourse - Install'!K52:K52)+SUM('T4-B1 (6-9) - Install'!K52:K52)+SUM('T4-B2 (10-18) - Install'!K52:K52)+SUM('T4 Lobby Elevator - Install'!K52:K52)+SUM('T2-B1M Screen 20 - Install'!K52:K52)+SUM('T2-B1M Screen 21 - Install'!K52:K52)+SUM('T2-B1M Screen 22 - Install'!K52:K52) -> 60899.624 | E10: =IFERROR(D10-C10,0) -> 9134.9435 | F10: 0.15
B11: CMS (Content Management System) | C11: =SUM(CMS!F26:F26) -> 0 | D11: =SUM(CMS!H26:H26) -> 0 | E11: =IFERROR(D11-C11,0) -> 0 | F11: 0.15
B12: Scoring System | C12: =SUM(Scoring!F27:F27) -> 0 | D12: =SUM(Scoring!H27:H27) -> 0 | E12: =IFERROR(D12-C12,0) -> 0 | F12: 0.15
B13: Venue Services | C13: =SUM('Venue Services'!B17:B17) -> 0 | D13: =SUM('Venue Services'!C17:C17) -> 0 | E13: =IFERROR(D13-C13,0) -> 0 | F13: 0.15
B14: Game Clock | C14: =SUM('Additional Items'!F5:F5) -> 0 | D14: =SUM('Additional Items'!H5:H5) -> 0 | E14: =IFERROR(D14-C14,0) -> 0 | F14: 0.15
B15: Pitch Clocks | C15: =SUM('Additional Items'!F6:F6) -> 0 | D15: =SUM('Additional Items'!H6:H6) -> 0 | E15: =IFERROR(D15-C15,0) -> 0 | F15: 0.15
B16: OES / MIS / Timing | C16: =SUM('Additional Items'!F7:F7) -> 0 | D16: =SUM('Additional Items'!H7:H7) -> 0 | E16: =IFERROR(D16-C16,0) -> 0 | F16: 0.15
B17: DMX / Misc Equipment | C17: =SUM('Additional Items'!F8:F8) -> 0 | D17: =SUM('Additional Items'!H8:H8) -> 0 | E17: =IFERROR(D17-C17,0) -> 0 | F17: 0.15
B19: SUBTOTAL | C19: =SUM(C5:C17) -> 2665060.8 | D19: =SUM(D5:D17) -> 1419753.3 | E19: =IFERROR(D19-C19,0) -> -1245307.4 | F19: =IFERROR(1-C19/D19,0) -> -0.87712944 | G19: =IFERROR(C19/5154.09,0) -> 517.07688
B20: TAX | C20: 0 | D20: 0 | E20: 0 | F20: 0
B21: BOND | C21: 0 | D21: 0 | E21: 0 | F21: 0
B22: GRAND TOTAL | C22: =C19+C20+C21 -> 2665060.8 | D22: =D19+D20+D21 -> 1419753.3 | E22: =IFERROR(D22-C22,0) -> -1245307.4 | F22: =IFERROR(1-C22/D22,0) -> -0.87712944 | G22: =IFERROR(C22/5154.09,0) -> 517.07688

Sheet LED Cost Sheet
A1: WTC Digital Signage Upgrade — LED Cost Sheet
U2: LED Margin Override → | V2: 0.15
A3: Display | B3: RFP H (ft) | C3: RFP W (ft) | D3: RFP NITs | E3: Vendor | F3: Product | G3: Pitch | H3: H (ft) | I3: W (ft) | J3: H (px) | K3: W (px) | L3: Qty | M3: Total SqFt | N3: Product NITs | O3: Service | P3: $/SqFt | Q3: Display Cost | R3: Processor | S3: Shipping | T3: Total Cost | U3: Margin % | V3: Selling Price | W3: ANC Margin | X3: Weight (lbs) | Y3: Total Power (W) | Z3: BTU/hr
A4: Underpass 1 — 9A Underpass 1-4 | B4: 6.3 | C4: 18.11 | E4: LG/Yaham | F4: C2.5-MIP 2.5mm Indoor (Alt) | G4: 2.5mm | H4: 6.3 | I4: 18.11 | J4: 768 | K4: 2208 | L4: 1 | M4: =H4*I4*L4 -> 114.093 | N4: 2000 | O4: front | P4: 291.44 | Q4: 33250.16 | R4: =SUM('Bundle Equipment'!E10:E10) -> 518.45 | S4: 1140.9 | T4: 34909.51 | U4: =V$2 -> 0.15 | V4: 92766.89 | W4: 12774.14 | X4: 558 | Y4: 4140 | Z4: =Y4*3.412 -> 14125.68
A5: Underpass 2 — 9A Underpass 1-4 | B5: 7.48 | C5: 29.92 | E5: LG/Yaham | F5: C2.5-MIP 2.5mm Indoor (Alt) | G5: 2.5mm | H5: 7.48 | I5: 29.92 | J5: 912 | K5: 3648 | L5: 1 | M5: =H5*I5*L5 -> 223.8016 | N5: 2000 | O5: front | P5: 291.44 | Q5: 65223.83 | R5: =SUM('Bundle Equipment'!E15:E15) -> 584.28 | S5: 2238 | T5: 68046.11 | U5: =V$2 -> 0.15 | V5: 152572.17 | W5: 20647.83 | X5: 1094 | Y5: 8121 | Z5: =Y5*3.412 -> 27708.852
A6: Underpass 3 — 9A Underpass 1-4 | B6: 7.48 | C6: 29.92 | E6: LG/Yaham | F6: C2.5-MIP 2.5mm Indoor (Alt) | G6: 2.5mm | H6: 7.48 | I6: 29.92 | J6: 912 | K6: 3648 | L6: 1 | M6: =H6*I6*L6 -> 223.8016 | N6: 2000 | O6: front | P6: 291.44 | Q6: 65223.83 | R6: =SUM('Bundle Equipment'!E20:E20) -> 584.28 | S6: 2238 | T6: 68046.11 | U6: =V$2 -> 0.15 | V6: 152572.17 | W6: 20647.83 | X6: 1094 | Y6: 8121 | Z6: =Y6*3.412 -> 27708.852
A7: Underpass 4 — 9A Underpass 1-4 | B7: 12.6 | C7: 29.92 | E7: LG/Yaham | F7: C2.5-MIP 2.5mm Indoor (Alt) | G7: 2.5mm | H7: 12.6 | I7: 29.92 | J7: 1536 | K7: 3648 | L7: 1 | M7: =H7*I7*L7 -> 376.992 | N7: 2000 | O7: front | P7: 291.44 | Q7: 109869.21 | R7: =SUM('Bundle Equipment'!E26:E26) -> 20626.19 | S7: 3769.9 | T7: 134265.3 | U7: =V$2 -> 0.15 | V7: 259474.86 | W7: 35151.33 | X7: 1842 | Y7: 13680 | Z7: =Y7*3.412 -> 46676.16
A8: Concourse — Concourse | B8: 9.45 | C8: 280.31 | E8: LG/Yaham | F8: C2.5-MIP 2.5mm Indoor (Alt) | G8: 2.5mm | H8: 9.45 | I8: 280.31 | J8: 1152 | K8: 34175 | L8: 1 | M8: =H8*I8*L8 -> 2648.9295 | N8: 2000 | O8: front | P8: 291.44 | Q8: 771998.86 | R8: =SUM('Bundle Equipment'!E32:E32) -> 47189.36 | S8: 26489.3 | T8: 845677.52 | U8: =V$2 -> 0.15 | V8: 1526801.7 | W8: 202530.95 | X8: 12945 | Y8: 96124 | Z8: =Y8*3.412 -> 327975.09
A9: T4-B1 (6-9) — T4-B1 | B9: 7.87 | C9: 8.66 | E9: LG/Yaham | F9: C2.5-MIP 2.5mm Indoor (Alt) | G9: 2.5mm | H9: 7.87 | I9: 8.66 | J9: 960 | K9: 1056 | L9: 4 | M9: =H9*I9*L9 -> 272.6168 | N9: 2000 | O9: front | P9: 291.42 | Q9: 79446 | R9: =SUM('Bundle Equipment'!E37:E37) -> 613.57 | S9: 2726.2 | T9: 82785.77 | U9: =V$2 -> 0.15 | V9: 179138.59 | W9: 24144.59 | X9: 1332 | Y9: 9893 | Z9: =Y9*3.412 -> 33754.916
A10: T4-B2 (10-18) — T4-B2 | B10: 7.87 | C10: 8.66 | E10: LG/Yaham | F10: C2.5-MIP 2.5mm Indoor (Alt) | G10: 2.5mm | H10: 7.87 | I10: 8.66 | J10: 960 | K10: 1056 | L10: 9 | M10: =H10*I10*L10 -> 613.3878 | N10: 2000 | O10: front | P10: 291.42 | Q10: 178753.5 | R10: =SUM('Bundle Equipment'!E43:E43) -> 20768.03 | S10: 6133.9 | T10: 205655.43 | U10: =V$2 -> 0.15 | V10: 388240.91 | W10: 52102.24 | X10: 2997 | Y10: 22259 | Z10: =Y10*3.412 -> 75947.708
A11: T4 Lobby Elevator — T4 Lobby Elevator | B11: 71.6 | C11: 5.5 | E11: LG/Yaham | F11: C2.5-MIP 2.5mm Indoor (Alt) | G11: 2.5mm | H11: 71.6 | I11: 5.5 | J11: 8729 | K11: 671 | L11: 1 | M11: =H11*I11*L11 -> 393.8 | N11: 2000 | O11: front | P11: 291.44 | Q11: 114768.29 | R11: =SUM('Bundle Equipment'!E49:E49) -> 20636.28 | S11: 3938 | T11: 139342.57 | U11: =V$2 -> 0.15 | V11: 268709.18 | W11: 36368.38 | X11: 1924 | Y11: 14290 | Z11: =Y11*3.412 -> 48757.48
A12: T2-B1M Screen 20 — T2-B1M | B12: 7.91 | C12: 16.5 | E12: LG/Yaham | F12: C2.5-MIP 2.5mm Indoor (Alt) | G12: 2.5mm | H12: 7.91 | I12: 16.5 | J12: 964 | K12: 2012 | L12: 1 | M12: =H12*I12*L12 -> 130.515 | N12: 2000 | O12: front | P12: 291.44 | Q12: 38038.49 | R12: =SUM('Bundle Equipment'!E54:E54) -> 528.31 | S12: 1305.2 | T12: 39872 | U12: =V$2 -> 0.15 | V12: 101747.09 | W12: 13956.86 | X12: 638 | Y12: 4736 | Z12: =Y12*3.412 -> 16159.232
A13: T2-B1M Screen 21 — T2-B1M | B13: 7.91 | C13: 11.83 | E13: LG/Yaham | F13: C2.5-MIP 2.5mm Indoor (Alt) | G13: 2.5mm | H13: 7.91 | I13: 11.83 | J13: 964 | K13: 1442 | L13: 1 | M13: =H13*I13*L13 -> 93.5753 | N13: 2000 | O13: front | P13: 291.44 | Q13: 27272.76 | R13: =SUM('Bundle Equipment'!E59:E59) -> 506.15 | S13: 935.8 | T13: 28714.71 | U13: =V$2 -> 0.15 | V13: 81602.53 | W13: 11304.58 | X13: 457 | Y13: 3396 | Z13: =Y13*3.412 -> 11587.152
A14: T2-B1M Screen 22 — T2-B1M | B14: 7.91 | C14: 7.91 | E14: LG/Yaham | F14: C2.5-MIP 2.5mm Indoor (Alt) | G14: 2.5mm | H14: 7.91 | I14: 7.91 | J14: 964 | K14: 964 | L14: 1 | M14: =H14*I14*L14 -> 62.5681 | N14: 2000 | O14: front | P14: 291.44 | Q14: 18235.28 | R14: =SUM('Bundle Equipment'!E64:E64) -> 487.54 | S14: 625.7 | T14: 19348.52 | U14: =V$2 -> 0.15 | V14: 64730.65 | W14: 9083.9 | X14: 306 | Y14: 2271 | Z14: =Y14*3.412 -> 7748.652
A16: TOTAL (11 displays) | M16: =M4+M5+M6+M7+M8+M9+M10+M11+M12+M13+M14 -> 5154.0807 | Q16: =Q4+Q5+Q6+Q7+Q8+Q9+Q10+Q11+Q12+Q13+Q14 -> 1502080.2 | R16: =R4+R5+R6+R7+R8+R9+R10+R11+R12+R13+R14 -> 113042.44 | S16: =S4+S5+S6+S7+S8+S9+S10+S11+S12+S13+S14 -> 51540.9 | T16: =T4+T5+T6+T7+T8+T9+T10+T11+T12+T13+T14 -> 1666663.6 | U16: =IFERROR(1-T16/V16,0) -> 0.4900607 | V16: =V4+V5+V6+V7+V8+V9+V10+V11+V12+V13+V14 -> 3268356.7 | W16: =W4+W5+W6+W7+W8+W9+W10+W11+W12+W13+W14 -> 438712.63 | X16: =X4+X5+X6+X7+X8+X9+X10+X11+X12+X13+X14 -> 25187 | Y16: =Y4+Y5+Y6+Y7+Y8+Y9+Y10+Y11+Y12+Y13+Y14 -> 187031 | Z16: =Z4+Z5+Z6+Z7+Z8+Z9+Z10+Z11+Z12+Z13+Z14 -> 638149.77

Sheet Tech Specs (Installers)
A1: WTC Digital Signage Upgrade — LED Technical Specifications (No Pricing)
A2: Technical specifications only — no pricing data. Safe for installer/subcontractor distribution.
A4: Display Name | B4: Qty | C4: Pixel Pitch | D4: Height (ft) | E4: Width (ft) | F4: Pixels H | G4: Pixels W | H4: Sq Ft | I4: Brightness (nits) | J4: Service | K4: Environment | L4: Weight (lbs) | M4: Total Power (W) | N4: Fiber Strands | O4: BTU/hr
A5: ='LED Cost Sheet'!A4 -> Underpass 1 — 9A Underpass 1-4 | B5: ='LED Cost Sheet'!I4 -> 18.11 | C5: ='LED Cost Sheet'!D4 | D5: ='LED Cost Sheet'!E4 -> LG/Yaham | E5: ='LED Cost Sheet'!F4 -> C2.5-MIP 2.5mm Indoor (Alt) | F5: ='LED Cost Sheet'!G4 -> 2.5mm | G5: ='LED Cost Sheet'!H4 -> 6.3 | H5: =D5*E5*B5 -> #VALUE! | I5: ='LED Cost Sheet'!K4 -> 2208 | J5: ='LED Cost Sheet'!L4 -> 1 | K5: indoor | L5: ='LED Cost Sheet'!U4 -> 0.15 | M5: ='LED Cost Sheet'!V4 -> 92766.89 | N5: =IFERROR((F5*G5*B5)/400000,0) -> 0 | O5: ='LED Cost Sheet'!W4 -> 12774.14
A6: ='LED Cost Sheet'!A5 -> Underpass 2 — 9A Underpass 1-4 | B6: ='LED Cost Sheet'!I5 -> 29.92 | C6: ='LED Cost Sheet'!D5 | D6: ='LED Cost Sheet'!E5 -> LG/Yaham | E6: ='LED Cost Sheet'!F5 -> C2.5-MIP 2.5mm Indoor (Alt) | F6: ='LED Cost Sheet'!G5 -> 2.5mm | G6: ='LED Cost Sheet'!H5 -> 7.48 | H6: =D6*E6*B6 -> #VALUE! | I6: ='LED Cost Sheet'!K5 -> 3648 | J6: ='LED Cost Sheet'!L5 -> 1 | K6: indoor | L6: ='LED Cost Sheet'!U5 -> 0.15 | M6: ='LED Cost Sheet'!V5 -> 152572.17 | N6: =IFERROR((F6*G6*B6)/400000,0) -> 0 | O6: ='LED Cost Sheet'!W5 -> 20647.83
A7: ='LED Cost Sheet'!A6 -> Underpass 3 — 9A Underpass 1-4 | B7: ='LED Cost Sheet'!I6 -> 29.92 | C7: ='LED Cost Sheet'!D6 | D7: ='LED Cost Sheet'!E6 -> LG/Yaham | E7: ='LED Cost Sheet'!F6 -> C2.5-MIP 2.5mm Indoor (Alt) | F7: ='LED Cost Sheet'!G6 -> 2.5mm | G7: ='LED Cost Sheet'!H6 -> 7.48 | H7: =D7*E7*B7 -> #VALUE! | I7: ='LED Cost Sheet'!K6 -> 3648 | J7: ='LED Cost Sheet'!L6 -> 1 | K7: indoor | L7: ='LED Cost Sheet'!U6 -> 0.15 | M7: ='LED Cost Sheet'!V6 -> 152572.17 | N7: =IFERROR((F7*G7*B7)/400000,0) -> 0 | O7: ='LED Cost Sheet'!W6 -> 20647.83
A8: ='LED Cost Sheet'!A7 -> Underpass 4 — 9A Underpass 1-4 | B8: ='LED Cost Sheet'!I7 -> 29.92 | C8: ='LED Cost Sheet'!D7 | D8: ='LED Cost Sheet'!E7 -> LG/Yaham | E8: ='LED Cost Sheet'!F7 -> C2.5-MIP 2.5mm Indoor (Alt) | F8: ='LED Cost Sheet'!G7 -> 2.5mm | G8: ='LED Cost Sheet'!H7 -> 12.6 | H8: =D8*E8*B8 -> #VALUE! | I8: ='LED Cost Sheet'!K7 -> 3648 | J8: ='LED Cost Sheet'!L7 -> 1 | K8: indoor | L8: ='LED Cost Sheet'!U7 -> 0.15 | M8: ='LED Cost Sheet'!V7 -> 259474.86 | N8: =IFERROR((F8*G8*B8)/400000,0) -> 0 | O8: ='LED Cost Sheet'!W7 -> 35151.33
A9: ='LED Cost Sheet'!A8 -> Concourse — Concourse | B9: ='LED Cost Sheet'!I8 -> 280.31 | C9: ='LED Cost Sheet'!D8 | D9: ='LED Cost Sheet'!E8 -> LG/Yaham | E9: ='LED Cost Sheet'!F8 -> C2.5-MIP 2.5mm Indoor (Alt) | F9: ='LED Cost Sheet'!G8 -> 2.5mm | G9: ='LED Cost Sheet'!H8 -> 9.45 | H9: =D9*E9*B9 -> #VALUE! | I9: ='LED Cost Sheet'!K8 -> 34175 | J9: ='LED Cost Sheet'!L8 -> 1 | K9: indoor | L9: ='LED Cost Sheet'!U8 -> 0.15 | M9: ='LED Cost Sheet'!V8 -> 1526801.7 | N9: =IFERROR((F9*G9*B9)/400000,0) -> 0 | O9: ='LED Cost Sheet'!W8 -> 202530.95
A10: ='LED Cost Sheet'!A9 -> T4-B1 (6-9) — T4-B1 | B10: ='LED Cost Sheet'!I9 -> 8.66 | C10: ='LED Cost Sheet'!D9 | D10: ='LED Cost Sheet'!E9 -> LG/Yaham | E10: ='LED Cost Sheet'!F9 -> C2.5-MIP 2.5mm Indoor (Alt) | F10: ='LED Cost Sheet'!G9 -> 2.5mm | G10: ='LED Cost Sheet'!H9 -> 7.87 | H10: =D10*E10*B10 -> #VALUE! | I10: ='LED Cost Sheet'!K9 -> 1056 | J10: ='LED Cost Sheet'!L9 -> 4 | K10: indoor | L10: ='LED Cost Sheet'!U9 -> 0.15 | M10: ='LED Cost Sheet'!V9 -> 179138.59 | N10: =IFERROR((F10*G10*B10)/400000,0) -> 0 | O10: ='LED Cost Sheet'!W9 -> 24144.59
A11: ='LED Cost Sheet'!A10 -> T4-B2 (10-18) — T4-B2 | B11: ='LED Cost Sheet'!I10 -> 8.66 | C11: ='LED Cost Sheet'!D10 | D11: ='LED Cost Sheet'!E10 -> LG/Yaham | E11: ='LED Cost Sheet'!F10 -> C2.5-MIP 2.5mm Indoor (Alt) | F11: ='LED Cost Sheet'!G10 -> 2.5mm | G11: ='LED Cost Sheet'!H10 -> 7.87 | H11: =D11*E11*B11 -> #VALUE! | I11: ='LED Cost Sheet'!K10 -> 1056 | J11: ='LED Cost Sheet'!L10 -> 9 | K11: indoor | L11: ='LED Cost Sheet'!U10 -> 0.15 | M11: ='LED Cost Sheet'!V10 -> 388240.91 | N11: =IFERROR((F11*G11*B11)/400000,0) -> 0 | O11: ='LED Cost Sheet'!W10 -> 52102.24
A12: ='LED Cost Sheet'!A11 -> T4 Lobby Elevator — T4 Lobby Elevator | B12: ='LED Cost Sheet'!I11 -> 5.5 | C12: ='LED Cost Sheet'!D11 | D12: ='LED Cost Sheet'!E11 -> LG/Yaham | E12: ='LED Cost Sheet'!F11 -> C2.5-MIP 2.5mm Indoor (Alt) | F12: ='LED Cost Sheet'!G11 -> 2.5mm | G12: ='LED Cost Sheet'!H11 -> 71.6 | H12: =D12*E12*B12 -> #VALUE! | I12: ='LED Cost Sheet'!K11 -> 671 | J12: ='LED Cost Sheet'!L11 -> 1 | K12: indoor | L12: ='LED Cost Sheet'!U11 -> 0.15 | M12: ='LED Cost Sheet'!V11 -> 268709.18 | N12: =IFERROR((F12*G12*B12)/400000,0) -> 0 | O12: ='LED Cost Sheet'!W11 -> 36368.38
A13: ='LED Cost Sheet'!A12 -> T2-B1M Screen 20 — T2-B1M | B13: ='LED Cost Sheet'!I12 -> 16.5 | C13: ='LED Cost Sheet'!D12 | D13: ='LED Cost Sheet'!E12 -> LG/Yaham | E13: ='LED Cost Sheet'!F12 -> C2.5-MIP 2.5mm Indoor (Alt) | F13: ='LED Cost Sheet'!G12 -> 2.5mm | G13: ='LED Cost Sheet'!H12 -> 7.91 | H13: =D13*E13*B13 -> #VALUE! | I13: ='LED Cost Sheet'!K12 -> 2012 | J13: ='LED Cost Sheet'!L12 -> 1 | K13: indoor | L13: ='LED Cost Sheet'!U12 -> 0.15 | M13: ='LED Cost Sheet'!V12 -> 101747.09 | N13: =IFERROR((F13*G13*B13)/400000,0) -> 0 | O13: ='LED Cost Sheet'!W12 -> 13956.86
A14: ='LED Cost Sheet'!A13 -> T2-B1M Screen 21 — T2-B1M | B14: ='LED Cost Sheet'!I13 -> 11.83 | C14: ='LED Cost Sheet'!D13 | D14: ='LED Cost Sheet'!E13 -> LG/Yaham | E14: ='LED Cost Sheet'!F13 -> C2.5-MIP 2.5mm Indoor (Alt) | F14: ='LED Cost Sheet'!G13 -> 2.5mm | G14: ='LED Cost Sheet'!H13 -> 7.91 | H14: =D14*E14*B14 -> #VALUE! | I14: ='LED Cost Sheet'!K13 -> 1442 | J14: ='LED Cost Sheet'!L13 -> 1 | K14: indoor | L14: ='LED Cost Sheet'!U13 -> 0.15 | M14: ='LED Cost Sheet'!V13 -> 81602.53 | N14: =IFERROR((F14*G14*B14)/400000,0) -> 0 | O14: ='LED Cost Sheet'!W13 -> 11304.58
A15: ='LED Cost Sheet'!A14 -> T2-B1M Screen 22 — T2-B1M | B15: ='LED Cost Sheet'!I14 -> 7.91 | C15: ='LED Cost Sheet'!D14 | D15: ='LED Cost Sheet'!E14 -> LG/Yaham | E15: ='LED Cost Sheet'!F14 -> C2.5-MIP 2.5mm Indoor (Alt) | F15: ='LED Cost Sheet'!G14 -> 2.5mm | G15: ='LED Cost Sheet'!H14 -> 7.91 | H15: =D15*E15*B15 -> #VALUE! | I15: ='LED Cost Sheet'!K14 -> 964 | J15: ='LED Cost Sheet'!L14 -> 1 | K15: indoor | L15: ='LED Cost Sheet'!U14 -> 0.15 | M15: ='LED Cost Sheet'!V14 -> 64730.65 | N15: =IFERROR((F15*G15*B15)/400000,0) -> 0 | O15: ='LED Cost Sheet'!W14 -> 9083.9

Sheet Underpass 1 - Install
A3: Project Name: WTC Digital Signage Upgrade
A4: 2026-03-31
A5: Revised By: ANC Proposal Engine
C7: Linked Margin Assignment
C8: Install Margin | D8: 0.15
C9: Electrical Margin | D9: 0.15
C10: ANC Margin | D10: 0.15
C11: Engineering and Permits | D11: 0.15
B15: Underpass 1
B16: Height | C16: Width | D16: Total Sq. Ft | E16: QTY
B17: 6.3 | C17: 18.11 | D17: 114.09 | E17: 1
B19: Structural Materials: | C19: Subcontractor 1 | D19: Subcontractor 2 | E19: Subcontractor 3 | F19: Selected | G19: Additional Contingency | I19: Total Cost | J19: Install Margin | K19: Selling Price
B20: FABRICATE PRIMARY STEEL | C20: 0 | D20: 0 | E20: 0 | F20: 0 | G20: 0 | I20: =SUM(C20:G20) -> 0 | J20: =$D$8 -> 0.15 | K20: =I20/(1-J20) -> 0
B21: SUPPLY AND INSTALL PRIMARY PLYWOOD | C21: 0 | D21: 0 | E21: 0 | F21: 0 | G21: 0 | I21: =SUM(C21:G21) -> 0 | J21: =$D$8 -> 0.15 | K21: =I21/(1-J21) -> 0
B22: FABRICATE SECONDARY STEEL SUBSTRUCTURE | C22: 2088.75 | D22: 0 | E22: 0 | F22: 0 | G22: 0 | I22: =SUM(C22:G22) -> 2088.75 | J22: =$D$8 -> 0.15 | K22: =I22/(1-J22) -> 2457.3529
B23: FABRICATE CLADDING AND TRIM | C23: 0 | D23: 0 | E23: 0 | F23: 0 | G23: 0 | I23: =SUM(C23:G23) -> 0 | J23: =$D$8 -> 0.15 | K23: =I23/(1-J23) -> 0
B24: OTHER SCOPE ITEM | C24: 0 | D24: 0 | E24: 0 | F24: 0 | G24: 0 | I24: =SUM(C24:G24) -> 0 | J24: =$D$8 -> 0.15 | K24: =I24/(1-J24) -> 0
B25: OTHER SCOPE ITEM | C25: 0 | D25: 0 | E25: 0 | F25: 0 | G25: 0 | I25: =SUM(C25:G25) -> 0 | J25: =$D$8 -> 0.15 | K25: =I25/(1-J25) -> 0
B26: SUBTOTAL | I26: =SUM(I20:I25) -> 2088.75 | K26: =SUM(K20:K25) -> 2457.3529
B28: Structural Labor and LED Installation | C28: Subcontractor 1 | D28: Subcontractor 2 | E28: Subcontractor 3 | F28: Selected | G28: Additional Contingency | I28: Total Cost | J28: Install Margin | K28: Selling Price
B29: REMOVAL AND DISPOSAL | C29: 0 | D29: 0 | E29: 0 | F29: 0 | G29: 0 | I29: =SUM(C29:G29) -> 0 | J29: =$D$8 -> 0.15 | K29: =I29/(1-J29) -> 0
B30: INSTALL SECONDARY STEEL SUBSTRUCTURE | C30: 0 | D30: 0 | E30: 0 | F30: 0 | G30: 0 | I30: =SUM(C30:G30) -> 0 | J30: =$D$8 -> 0.15 | K30: =I30/(1-J30) -> 0
B31: INSTALL LED DISPLAYS | C31: 8703.13 | D31: 0 | E31: 0 | F31: 0 | G31: 0 | I31: =SUM(C31:G31) -> 8703.13 | J31: =$D$8 -> 0.15 | K31: =I31/(1-J31) -> 10238.976
B32: INSTALL CLADDING AND TRIM | C32: 0 | D32: 0 | E32: 0 | F32: 0 | G32: 0 | I32: =SUM(C32:G32) -> 0 | J32: =$D$8 -> 0.15 | K32: =I32/(1-J32) -> 0
B33: HEAVY EQUIPMENT | C33: 0 | D33: 0 | E33: 0 | F33: 0 | G33: 0 | I33: =SUM(C33:G33) -> 0 | J33: =$D$8 -> 0.15 | K33: =I33/(1-J33) -> 0
B34: PM/GENERAL CONDITIONS/TRAVEL | C34: 20882.35 | D34: 0 | E34: 0 | F34: 0 | G34: 0 | I34: =SUM(C34:G34) -> 20882.35 | J34: =$D$8 -> 0.15 | K34: =I34/(1-J34) -> 24567.471
B35: SUBTOTAL | I35: =SUM(I29:I34) -> 29585.48 | K35: =SUM(K29:K34) -> 34806.447
B37: Electrical and Data - Materials and Subcontracting | C37: Subcontractor 1 | D37: Subcontractor 2 | E37: Subcontractor 3 | F37: Selected | G37: Additional Contingency | I37: Total Cost | J37: Install Margin | K37: Selling Price
B38: ELECTRICAL MATERIALS | C38: 8703.13 | D38: 0 | E38: 0 | F38: 0 | G38: 0 | I38: =SUM(C38:G38) -> 8703.13 | J38: =$D$9 -> 0.15 | K38: =I38/(1-J38) -> 10238.976
B39: DATA MATERIALS | C39: 0 | D39: 0 | E39: 0 | F39: 0 | G39: 0 | I39: =SUM(C39:G39) -> 0 | J39: =$D$9 -> 0.15 | K39: =I39/(1-J39) -> 0
B40: ELECTRICAL LABOR | C40: 0 | D40: 0 | E40: 0 | F40: 0 | G40: 0 | I40: =SUM(C40:G40) -> 0 | J40: =$D$9 -> 0.15 | K40: =I40/(1-J40) -> 0
B41: DATA LABOR | C41: 0 | D41: 0 | E41: 0 | F41: 0 | G41: 0 | I41: =SUM(C41:G41) -> 0 | J41: =$D$9 -> 0.15 | K41: =I41/(1-J41) -> 0
B42: SUB PANEL | C42: 0 | D42: 0 | E42: 0 | F42: 0 | G42: 0 | I42: =SUM(C42:G42) -> 0 | J42: =$D$9 -> 0.15 | K42: =I42/(1-J42) -> 0
B43: MISC | C43: 0 | D43: 0 | E43: 0 | F43: 0 | G43: 0 | I43: =SUM(C43:G43) -> 0 | J43: =$D$9 -> 0.15 | K43: =I43/(1-J43) -> 0
B44: SUBTOTAL | I44: =SUM(I38:I43) -> 8703.13 | K44: =SUM(K38:K43) -> 10238.976
B46: Submittals, Engineering, and Permits | C46: Subcontractor 1 | D46: Subcontractor 2 | E46: Subcontractor 3 | F46: Selected | G46: Additional Contingency | I46: Total Cost | J46: Install Margin | K46: Selling Price
B47: STRUCTURAL ENGINEERING | C47: 4705.88 | D47: 0 | E47: 0 | F47: 0 | G47: 0 | I47: =SUM(C47:G47) -> 4705.88 | J47: =$D$11 -> 0.15 | K47: =I47/(1-J47) -> 5536.3294
B48: STRUCTURAL CERTIFICATION | C48: 0 | D48: 0 | E48: 0 | F48: 0 | G48: 0 | I48: =SUM(C48:G48) -> 0 | J48: =$D$11 -> 0.15 | K48: =I48/(1-J48) -> 0
B49: ELECTRICAL ENGINEERING | C49: 0 | D49: 0 | E49: 0 | F49: 0 | G49: 0 | I49: =SUM(C49:G49) -> 0 | J49: =$D$11 -> 0.15 | K49: =I49/(1-J49) -> 0
B50: ELECTRICAL CERTIFICATION | C50: 0 | D50: 0 | E50: 0 | F50: 0 | G50: 0 | I50: =SUM(C50:G50) -> 0 | J50: =$D$11 -> 0.15 | K50: =I50/(1-J50) -> 0
...

Sheet Underpass 2 - Install
A3: Project Name: WTC Digital Signage Upgrade
A4: 2026-03-31
A5: Revised By: ANC Proposal Engine
C7: Linked Margin Assignment
C8: Install Margin | D8: 0.15
C9: Electrical Margin | D9: 0.15
C10: ANC Margin | D10: 0.15
C11: Engineering and Permits | D11: 0.15
B15: Underpass 2
B16: Height | C16: Width | D16: Total Sq. Ft | E16: QTY
B17: 7.48 | C17: 29.92 | D17: 223.8 | E17: 1
B19: Structural Materials: | C19: Subcontractor 1 | D19: Subcontractor 2 | E19: Subcontractor 3 | F19: Selected | G19: Additional Contingency | I19: Total Cost | J19: Install Margin | K19: Selling Price
B20: FABRICATE PRIMARY STEEL | C20: 0 | D20: 0 | E20: 0 | F20: 0 | G20: 0 | I20: =SUM(C20:G20) -> 0 | J20: =$D$8 -> 0.15 | K20: =I20/(1-J20) -> 0
B21: SUPPLY AND INSTALL PRIMARY PLYWOOD | C21: 0 | D21: 0 | E21: 0 | F21: 0 | G21: 0 | I21: =SUM(C21:G21) -> 0 | J21: =$D$8 -> 0.15 | K21: =I21/(1-J21) -> 0
B22: FABRICATE SECONDARY STEEL SUBSTRUCTURE | C22: 4102.5 | D22: 0 | E22: 0 | F22: 0 | G22: 0 | I22: =SUM(C22:G22) -> 4102.5 | J22: =$D$8 -> 0.15 | K22: =I22/(1-J22) -> 4826.4706
B23: FABRICATE CLADDING AND TRIM | C23: 0 | D23: 0 | E23: 0 | F23: 0 | G23: 0 | I23: =SUM(C23:G23) -> 0 | J23: =$D$8 -> 0.15 | K23: =I23/(1-J23) -> 0
B24: OTHER SCOPE ITEM | C24: 0 | D24: 0 | E24: 0 | F24: 0 | G24: 0 | I24: =SUM(C24:G24) -> 0 | J24: =$D$8 -> 0.15 | K24: =I24/(1-J24) -> 0
B25: OTHER SCOPE ITEM | C25: 0 | D25: 0 | E25: 0 | F25: 0 | G25: 0 | I25: =SUM(C25:G25) -> 0 | J25: =$D$8 -> 0.15 | K25: =I25/(1-J25) -> 0
B26: SUBTOTAL | I26: =SUM(I20:I25) -> 4102.5 | K26: =SUM(K20:K25) -> 4826.4706
B28: Structural Labor and LED Installation | C28: Subcontractor 1 | D28: Subcontractor 2 | E28: Subcontractor 3 | F28: Selected | G28: Additional Contingency | I28: Total Cost | J28: Install Margin | K28: Selling Price
B29: REMOVAL AND DISPOSAL | C29: 0 | D29: 0 | E29: 0 | F29: 0 | G29: 0 | I29: =SUM(C29:G29) -> 0 | J29: =$D$8 -> 0.15 | K29: =I29/(1-J29) -> 0
B30: INSTALL SECONDARY STEEL SUBSTRUCTURE | C30: 0 | D30: 0 | E30: 0 | F30: 0 | G30: 0 | I30: =SUM(C30:G30) -> 0 | J30: =$D$8 -> 0.15 | K30: =I30/(1-J30) -> 0
B31: INSTALL LED DISPLAYS | C31: 17093.75 | D31: 0 | E31: 0 | F31: 0 | G31: 0 | I31: =SUM(C31:G31) -> 17093.75 | J31: =$D$8 -> 0.15 | K31: =I31/(1-J31) -> 20110.294
B32: INSTALL CLADDING AND TRIM | C32: 0 | D32: 0 | E32: 0 | F32: 0 | G32: 0 | I32: =SUM(C32:G32) -> 0 | J32: =$D$8 -> 0.15 | K32: =I32/(1-J32) -> 0
B33: HEAVY EQUIPMENT | C33: 0 | D33: 0 | E33: 0 | F33: 0 | G33: 0 | I33: =SUM(C33:G33) -> 0 | J33: =$D$8 -> 0.15 | K33: =I33/(1-J33) -> 0
B34: PM/GENERAL CONDITIONS/TRAVEL | C34: 20882.35 | D34: 0 | E34: 0 | F34: 0 | G34: 0 | I34: =SUM(C34:G34) -> 20882.35 | J34: =$D$8 -> 0.15 | K34: =I34/(1-J34) -> 24567.471
B35: SUBTOTAL | I35: =SUM(I29:I34) -> 37976.1 | K35: =SUM(K29:K34) -> 44677.765
B37: Electrical and Data - Materials and Subcontracting | C37: Subcontractor 1 | D37: Subcontractor 2 | E37: Subcontractor 3 | F37: Selected | G37: Additional Contingency | I37: Total Cost | J37: Install Margin | K37: Selling Price
B38: ELECTRICAL MATERIALS | C38: 17093.75 | D38: 0 | E38: 0 | F38: 0 | G38: 0 | I38: =SUM(C38:G38) -> 17093.75 | J38: =$D$9 -> 0.15 | K38: =I38/(1-J38) -> 20110.294
B39: DATA MATERIALS | C39: 0 | D39: 0 | E39: 0 | F39: 0 | G39: 0 | I39: =SUM(C39:G39) -> 0 | J39: =$D$9 -> 0.15 | K39: =I39/(1-J39) -> 0
B40: ELECTRICAL LABOR | C40: 0 | D40: 0 | E40: 0 | F40: 0 | G40: 0 | I40: =SUM(C40:G40) -> 0 | J40: =$D$9 -> 0.15 | K40: =I40/(1-J40) -> 0
B41: DATA LABOR | C41: 0 | D41: 0 | E41: 0 | F41: 0 | G41: 0 | I41: =SUM(C41:G41) -> 0 | J41: =$D$9 -> 0.15 | K41: =I41/(1-J41) -> 0
B42: SUB PANEL | C42: 0 | D42: 0 | E42: 0 | F42: 0 | G42: 0 | I42: =SUM(C42:G42) -> 0 | J42: =$D$9 -> 0.15 | K42: =I42/(1-J42) -> 0
B43: MISC | C43: 0 | D43: 0 | E43: 0 | F43: 0 | G43: 0 | I43: =SUM(C43:G43) -> 0 | J43: =$D$9 -> 0.15 | K43: =I43/(1-J43) -> 0
B44: SUBTOTAL | I44: =SUM(I38:I43) -> 17093.75 | K44: =SUM(K38:K43) -> 20110.294
B46: Submittals, Engineering, and Permits | C46: Subcontractor 1 | D46: Subcontractor 2 | E46: Subcontractor 3 | F46: Selected | G46: Additional Contingency | I46: Total Cost | J46: Install Margin | K46: Selling Price
B47: STRUCTURAL ENGINEERING | C47: 4705.88 | D47: 0 | E47: 0 | F47: 0 | G47: 0 | I47: =SUM(C47:G47) -> 4705.88 | J47: =$D$11 -> 0.15 | K47: =I47/(1-J47) -> 5536.3294
B48: STRUCTURAL CERTIFICATION | C48: 0 | D48: 0 | E48: 0 | F48: 0 | G48: 0 | I48: =SUM(C48:G48) -> 0 | J48: =$D$11 -> 0.15 | K48: =I48/(1-J48) -> 0
B49: ELECTRICAL ENGINEERING | C49: 0 | D49: 0 | E49: 0 | F49: 0 | G49: 0 | I49: =SUM(C49:G49) -> 0 | J49: =$D$11 -> 0.15 | K49: =I49/(1-J49) -> 0
B50: ELECTRICAL CERTIFICATION | C50: 0 | D50: 0 | E50: 0 | F50: 0 | G50: 0 | I50: =SUM(C50:G50) -> 0 | J50: =$D$11 -> 0.15 | K50: =I50/(1-J50) -> 0
...

Sheet Underpass 3 - Install
A3: Project Name: WTC Digital Signage Upgrade
A4: 2026-03-31
A5: Revised By: ANC Proposal Engine
C7: Linked Margin Assignment
C8: Install Margin | D8: 0.15
C9: Electrical Margin | D9: 0.15
C10: ANC Margin | D10: 0.15
C11: Engineering and Permits | D11: 0.15
B15: Underpass 3
B16: Height | C16: Width | D16: Total Sq. Ft | E16: QTY
B17: 7.48 | C17: 29.92 | D17: 223.8 | E17: 1
B19: Structural Materials: | C19: Subcontractor 1 | D19: Subcontractor 2 | E19: Subcontractor 3 | F19: Selected | G19: Additional Contingency | I19: Total Cost | J19: Install Margin | K19: Selling Price
B20: FABRICATE PRIMARY STEEL | C20: 0 | D20: 0 | E20: 0 | F20: 0 | G20: 0 | I20: =SUM(C20:G20) -> 0 | J20: =$D$8 -> 0.15 | K20: =I20/(1-J20) -> 0
B21: SUPPLY AND INSTALL PRIMARY PLYWOOD | C21: 0 | D21: 0 | E21: 0 | F21: 0 | G21: 0 | I21: =SUM(C21:G21) -> 0 | J21: =$D$8 -> 0.15 | K21: =I21/(1-J21) -> 0
B22: FABRICATE SECONDARY STEEL SUBSTRUCTURE | C22: 4102.5 | D22: 0 | E22: 0 | F22: 0 | G22: 0 | I22: =SUM(C22:G22) -> 4102.5 | J22: =$D$8 -> 0.15 | K22: =I22/(1-J22) -> 4826.4706
B23: FABRICATE CLADDING AND TRIM | C23: 0 | D23: 0 | E23: 0 | F23: 0 | G23: 0 | I23: =SUM(C23:G23) -> 0 | J23: =$D$8 -> 0.15 | K23: =I23/(1-J23) -> 0
B24: OTHER SCOPE ITEM | C24: 0 | D24: 0 | E24: 0 | F24: 0 | G24: 0 | I24: =SUM(C24:G24) -> 0 | J24: =$D$8 -> 0.15 | K24: =I24/(1-J24) -> 0
B25: OTHER SCOPE ITEM | C25: 0 | D25: 0 | E25: 0 | F25: 0 | G25: 0 | I25: =SUM(C25:G25) -> 0 | J25: =$D$8 -> 0.15 | K25: =I25/(1-J25) -> 0
B26: SUBTOTAL | I26: =SUM(I20:I25) -> 4102.5 | K26: =SUM(K20:K25) -> 4826.4706
B28: Structural Labor and LED Installation | C28: Subcontractor 1 | D28: Subcontractor 2 | E28: Subcontractor 3 | F28: Selected | G28: Additional Contingency | I28: Total Cost | J28: Install Margin | K28: Selling Price
B29: REMOVAL AND DISPOSAL | C29: 0 | D29: 0 | E29: 0 | F29: 0 | G29: 0 | I29: =SUM(C29:G29) -> 0 | J29: =$D$8 -> 0.15 | K29: =I29/(1-J29) -> 0
B30: INSTALL SECONDARY STEEL SUBSTRUCTURE | C30: 0 | D30: 0 | E30: 0 | F30: 0 | G30: 0 | I30: =SUM(C30:G30) -> 0 | J30: =$D$8 -> 0.15 | K30: =I30/(1-J30) -> 0
B31: INSTALL LED DISPLAYS | C31: 17093.75 | D31: 0 | E31: 0 | F31: 0 | G31: 0 | I31: =SUM(C31:G31) -> 17093.75 | J31: =$D$8 -> 0.15 | K31: =I31/(1-J31) -> 20110.294
B32: INSTALL CLADDING AND TRIM | C32: 0 | D32: 0 | E32: 0 | F32: 0 | G32: 0 | I32: =SUM(C32:G32) -> 0 | J32: =$D$8 -> 0.15 | K32: =I32/(1-J32) -> 0
B33: HEAVY EQUIPMENT | C33: 0 | D33: 0 | E33: 0 | F33: 0 | G33: 0 | I33: =SUM(C33:G33) -> 0 | J33: =$D$8 -> 0.15 | K33: =I33/(1-J33) -> 0
B34: PM/GENERAL CONDITIONS/TRAVEL | C34: 20882.35 | D34: 0 | E34: 0 | F34: 0 | G34: 0 | I34: =SUM(C34:G34) -> 20882.35 | J34: =$D$8 -> 0.15 | K34: =I34/(1-J34) -> 24567.471
B35: SUBTOTAL | I35: =SUM(I29:I34) -> 37976.1 | K35: =SUM(K29:K34) -> 44677.765
B37: Electrical and Data - Materials and Subcontracting | C37: Subcontractor 1 | D37: Subcontractor 2 | E37: Subcontractor 3 | F37: Selected | G37: Additional Contingency | I37: Total Cost | J37: Install Margin | K37: Selling Price
B38: ELECTRICAL MATERIALS | C38: 17093.75 | D38: 0 | E38: 0 | F38: 0 | G38: 0 | I38: =SUM(C38:G38) -> 17093.75 | J38: =$D$9 -> 0.15 | K38: =I38/(1-J38) -> 20110.294
B39: DATA MATERIALS | C39: 0 | D39: 0 | E39: 0 | F39: 0 | G39: 0 | I39: =SUM(C39:G39) -> 0 | J39: =$D$9 -> 0.15 | K39: =I39/(1-J39) -> 0
B40: ELECTRICAL LABOR | C40: 0 | D40: 0 | E40: 0 | F40: 0 | G40: 0 | I40: =SUM(C40:G40) -> 0 | J40: =$D$9 -> 0.15 | K40: =I40/(1-J40) -> 0
B41: DATA LABOR | C41: 0 | D41: 0 | E41: 0 | F41: 0 | G41: 0 | I41: =SUM(C41:G41) -> 0 | J41: =$D$9 -> 0.15 | K41: =I41/(1-J41) -> 0
B42: SUB PANEL | C42: 0 | D42: 0 | E42: 0 | F42: 0 | G42: 0 | I42: =SUM(C42:G42) -> 0 | J42: =$D$9 -> 0.15 | K42: =I42/(1-J42) -> 0
B43: MISC | C43: 0 | D43: 0 | E43: 0 | F43: 0 | G43: 0 | I43: =SUM(C43:G43) -> 0 | J43: =$D$9 -> 0.15 | K43: =I43/(1-J43) -> 0
B44: SUBTOTAL | I44: =SUM(I38:I43) -> 17093.75 | K44: =SUM(K38:K43) -> 20110.294
B46: Submittals, Engineering, and Permits | C46: Subcontractor 1 | D46: Subcontractor 2 | E46: Subcontractor 3 | F46: Selected | G46: Additional Contingency | I46: Total Cost | J46: Install Margin | K46: Selling Price
B47: STRUCTURAL ENGINEERING | C47: 4705.88 | D47: 0 | E47: 0 | F47: 0 | G47: 0 | I47: =SUM(C47:G47) -> 4705.88 | J47: =$D$11 -> 0.15 | K47: =I47/(1-J47) -> 5536.3294
B48: STRUCTURAL CERTIFICATION | C48: 0 | D48: 0 | E48: 0 | F48: 0 | G48: 0 | I48: =SUM(C48:G48) -> 0 | J48: =$D$11 -> 0.15 | K48: =I48/(1-J48) -> 0
B49: ELECTRICAL ENGINEERING | C49: 0 | D49: 0 | E49: 0 | F49: 0 | G49: 0 | I49: =SUM(C49:G49) -> 0 | J49: =$D$11 -> 0.15 | K49: =I49/(1-J49) -> 0
B50: ELECTRICAL CERTIFICATION | C50: 0 | D50: 0 | E50: 0 | F50: 0 | G50: 0 | I50: =SUM(C50:G50) -> 0 | J50: =$D$11 -> 0.15 | K50: =I50/(1-J50) -> 0
...

Sheet Underpass 4 - Install
A3: Project Name: WTC Digital Signage Upgrade
A4: 2026-03-31
A5: Revised By: ANC Proposal Engine
C7: Linked Margin Assignment
C8: Install Margin | D8: 0.15
C9: Electrical Margin | D9: 0.15
C10: ANC Margin | D10: 0.15
C11: Engineering and Permits | D11: 0.15
B15: Underpass 4
B16: Height | C16: Width | D16: Total Sq. Ft | E16: QTY
B17: 12.6 | C17: 29.92 | D17: 376.99 | E17: 1
B19: Structural Materials: | C19: Subcontractor 1 | D19: Subcontractor 2 | E19: Subcontractor 3 | F19: Selected | G19: Additional Contingency | I19: Total Cost | J19: Install Margin | K19: Selling Price
B20: FABRICATE PRIMARY STEEL | C20: 0 | D20: 0 | E20: 0 | F20: 0 | G20: 0 | I20: =SUM(C20:G20) -> 0 | J20: =$D$8 -> 0.15 | K20: =I20/(1-J20) -> 0
B21: SUPPLY AND INSTALL PRIMARY PLYWOOD | C21: 0 | D21: 0 | E21: 0 | F21: 0 | G21: 0 | I21: =SUM(C21:G21) -> 0 | J21: =$D$8 -> 0.15 | K21: =I21/(1-J21) -> 0
B22: FABRICATE SECONDARY STEEL SUBSTRUCTURE | C22: 6907.5 | D22: 0 | E22: 0 | F22: 0 | G22: 0 | I22: =SUM(C22:G22) -> 6907.5 | J22: =$D$8 -> 0.15 | K22: =I22/(1-J22) -> 8126.4706
B23: FABRICATE CLADDING AND TRIM | C23: 0 | D23: 0 | E23: 0 | F23: 0 | G23: 0 | I23: =SUM(C23:G23) -> 0 | J23: =$D$8 -> 0.15 | K23: =I23/(1-J23) -> 0
B24: OTHER SCOPE ITEM | C24: 0 | D24: 0 | E24: 0 | F24: 0 | G24: 0 | I24: =SUM(C24:G24) -> 0 | J24: =$D$8 -> 0.15 | K24: =I24/(1-J24) -> 0
B25: OTHER SCOPE ITEM | C25: 0 | D25: 0 | E25: 0 | F25: 0 | G25: 0 | I25: =SUM(C25:G25) -> 0 | J25: =$D$8 -> 0.15 | K25: =I25/(1-J25) -> 0
B26: SUBTOTAL | I26: =SUM(I20:I25) -> 6907.5 | K26: =SUM(K20:K25) -> 8126.4706
B28: Structural Labor and LED Installation | C28: Subcontractor 1 | D28: Subcontractor 2 | E28: Subcontractor 3 | F28: Selected | G28: Additional Contingency | I28: Total Cost | J28: Install Margin | K28: Selling Price
B29: REMOVAL AND DISPOSAL | C29: 0 | D29: 0 | E29: 0 | F29: 0 | G29: 0 | I29: =SUM(C29:G29) -> 0 | J29: =$D$8 -> 0.15 | K29: =I29/(1-J29) -> 0
B30: INSTALL SECONDARY STEEL SUBSTRUCTURE | C30: 0 | D30: 0 | E30: 0 | F30: 0 | G30: 0 | I30: =SUM(C30:G30) -> 0 | J30: =$D$8 -> 0.15 | K30: =I30/(1-J30) -> 0
B31: INSTALL LED DISPLAYS | C31: 28781.25 | D31: 0 | E31: 0 | F31: 0 | G31: 0 | I31: =SUM(C31:G31) -> 28781.25 | J31: =$D$8 -> 0.15 | K31: =I31/(1-J31) -> 33860.294
B32: INSTALL CLADDING AND TRIM | C32: 0 | D32: 0 | E32: 0 | F32: 0 | G32: 0 | I32: =SUM(C32:G32) -> 0 | J32: =$D$8 -> 0.15 | K32: =I32/(1-J32) -> 0
B33: HEAVY EQUIPMENT | C33: 0 | D33: 0 | E33: 0 | F33: 0 | G33: 0 | I33: =SUM(C33:G33) -> 0 | J33: =$D$8 -> 0.15 | K33: =I33/(1-J33) -> 0
B34: PM/GENERAL CONDITIONS/TRAVEL | C34: 20882.35 | D34: 0 | E34: 0 | F34: 0 | G34: 0 | I34: =SUM(C34:G34) -> 20882.35 | J34: =$D$8 -> 0.15 | K34: =I34/(1-J34) -> 24567.471
B35: SUBTOTAL | I35: =SUM(I29:I34) -> 49663.6 | K35: =SUM(K29:K34) -> 58427.765
B37: Electrical and Data - Materials and Subcontracting | C37: Subcontractor 1 | D37: Subcontractor 2 | E37: Subcontractor 3 | F37: Selected | G37: Additional Contingency | I37: Total Cost | J37: Install Margin | K37: Selling Price
B38: ELECTRICAL MATERIALS | C38: 28781.25 | D38: 0 | E38: 0 | F38: 0 | G38: 0 | I38: =SUM(C38:G38) -> 28781.25 | J38: =$D$9 -> 0.15 | K38: =I38/(1-J38) -> 33860.294
B39: DATA MATERIALS | C39: 0 | D39: 0 | E39: 0 | F39: 0 | G39: 0 | I39: =SUM(C39:G39) -> 0 | J39: =$D$9 -> 0.15 | K39: =I39/(1-J39) -> 0
B40: ELECTRICAL LABOR | C40: 0 | D40: 0 | E40: 0 | F40: 0 | G40: 0 | I40: =SUM(C40:G40) -> 0 | J40: =$D$9 -> 0.15 | K40: =I40/(1-J40) -> 0
B41: DATA LABOR | C41: 0 | D41: 0 | E41: 0 | F41: 0 | G41: 0 | I41: =SUM(C41:G41) -> 0 | J41: =$D$9 -> 0.15 | K41: =I41/(1-J41) -> 0
B42: SUB PANEL | C42: 0 | D42: 0 | E42: 0 | F42: 0 | G42: 0 | I42: =SUM(C42:G42) -> 0 | J42: =$D$9 -> 0.15 | K42: =I42/(1-J42) -> 0
B43: MISC | C43: 0 | D43: 0 | E43: 0 | F43: 0 | G43: 0 | I43: =SUM(C43:G43) -> 0 | J43: =$D$9 -> 0.15 | K43: =I43/(1-J43) -> 0
B44: SUBTOTAL | I44: =SUM(I38:I43) -> 28781.25 | K44: =SUM(K38:K43) -> 33860.294
B46: Submittals, Engineering, and Permits | C46: Subcontractor 1 | D46: Subcontractor 2 | E46: Subcontractor 3 | F46: Selected | G46: Additional Contingency | I46: Total Cost | J46: Install Margin | K46: Selling Price
B47: STRUCTURAL ENGINEERING | C47: 4705.88 | D47: 0 | E47: 0 | F47: 0 | G47: 0 | I47: =SUM(C47:G47) -> 4705.88 | J47: =$D$11 -> 0.15 | K47: =I47/(1-J47) -> 5536.3294
B48: STRUCTURAL CERTIFICATION | C48: 0 | D48: 0 | E48: 0 | F48: 0 | G48: 0 | I48: =SUM(C48:G48) -> 0 | J48: =$D$11 -> 0.15 | K48: =I48/(1-J48) -> 0
B49: ELECTRICAL ENGINEERING | C49: 0 | D49: 0 | E49: 0 | F49: 0 | G49: 0 | I49: =SUM(C49:G49) -> 0 | J49: =$D$11 -> 0.15 | K49: =I49/(1-J49) -> 0
B50: ELECTRICAL CERTIFICATION | C50: 0 | D50: 0 | E50: 0 | F50: 0 | G50: 0 | I50: =SUM(C50:G50) -> 0 | J50: =$D$11 -> 0.15 | K50: =I50/(1-J50) -> 0
...

Sheet Concourse - Install
A3: Project Name: WTC Digital Signage Upgrade
A4: 2026-03-31
A5: Revised By: ANC Proposal Engine
C7: Linked Margin Assignment
C8: Install Margin | D8: 0.15
C9: Electrical Margin | D9: 0.15
C10: ANC Margin | D10: 0.15
C11: Engineering and Permits | D11: 0.15
B15: Concourse
B16: Height | C16: Width | D16: Total Sq. Ft | E16: QTY
B17: 9.45 | C17: 280.31 | D17: 2648.93 | E17: 1
B19: Structural Materials: | C19: Subcontractor 1 | D19: Subcontractor 2 | E19: Subcontractor 3 | F19: Selected | G19: Additional Contingency | I19: Total Cost | J19: Install Margin | K19: Selling Price
B20: FABRICATE PRIMARY STEEL | C20: 0 | D20: 0 | E20: 0 | F20: 0 | G20: 0 | I20: =SUM(C20:G20) -> 0 | J20: =$D$8 -> 0.15 | K20: =I20/(1-J20) -> 0
B21: SUPPLY AND INSTALL PRIMARY PLYWOOD | C21: 0 | D21: 0 | E21: 0 | F21: 0 | G21: 0 | I21: =SUM(C21:G21) -> 0 | J21: =$D$8 -> 0.15 | K21: =I21/(1-J21) -> 0
B22: FABRICATE SECONDARY STEEL SUBSTRUCTURE | C22: 48536.25 | D22: 0 | E22: 0 | F22: 0 | G22: 0 | I22: =SUM(C22:G22) -> 48536.25 | J22: =$D$8 -> 0.15 | K22: =I22/(1-J22) -> 57101.471
B23: FABRICATE CLADDING AND TRIM | C23: 0 | D23: 0 | E23: 0 | F23: 0 | G23: 0 | I23: =SUM(C23:G23) -> 0 | J23: =$D$8 -> 0.15 | K23: =I23/(1-J23) -> 0
B24: OTHER SCOPE ITEM | C24: 0 | D24: 0 | E24: 0 | F24: 0 | G24: 0 | I24: =SUM(C24:G24) -> 0 | J24: =$D$8 -> 0.15 | K24: =I24/(1-J24) -> 0
B25: OTHER SCOPE ITEM | C25: 0 | D25: 0 | E25: 0 | F25: 0 | G25: 0 | I25: =SUM(C25:G25) -> 0 | J25: =$D$8 -> 0.15 | K25: =I25/(1-J25) -> 0
B26: SUBTOTAL | I26: =SUM(I20:I25) -> 48536.25 | K26: =SUM(K20:K25) -> 57101.471
B28: Structural Labor and LED Installation | C28: Subcontractor 1 | D28: Subcontractor 2 | E28: Subcontractor 3 | F28: Selected | G28: Additional Contingency | I28: Total Cost | J28: Install Margin | K28: Selling Price
B29: REMOVAL AND DISPOSAL | C29: 0 | D29: 0 | E29: 0 | F29: 0 | G29: 0 | I29: =SUM(C29:G29) -> 0 | J29: =$D$8 -> 0.15 | K29: =I29/(1-J29) -> 0
B30: INSTALL SECONDARY STEEL SUBSTRUCTURE | C30: 0 | D30: 0 | E30: 0 | F30: 0 | G30: 0 | I30: =SUM(C30:G30) -> 0 | J30: =$D$8 -> 0.15 | K30: =I30/(1-J30) -> 0
B31: INSTALL LED DISPLAYS | C31: 202234.38 | D31: 0 | E31: 0 | F31: 0 | G31: 0 | I31: =SUM(C31:G31) -> 202234.38 | J31: =$D$8 -> 0.15 | K31: =I31/(1-J31) -> 237922.8
B32: INSTALL CLADDING AND TRIM | C32: 0 | D32: 0 | E32: 0 | F32: 0 | G32: 0 | I32: =SUM(C32:G32) -> 0 | J32: =$D$8 -> 0.15 | K32: =I32/(1-J32) -> 0
B33: HEAVY EQUIPMENT | C33: 0 | D33: 0 | E33: 0 | F33: 0 | G33: 0 | I33: =SUM(C33:G33) -> 0 | J33: =$D$8 -> 0.15 | K33: =I33/(1-J33) -> 0
B34: PM/GENERAL CONDITIONS/TRAVEL | C34: 20882.35 | D34: 0 | E34: 0 | F34: 0 | G34: 0 | I34: =SUM(C34:G34) -> 20882.35 | J34: =$D$8 -> 0.15 | K34: =I34/(1-J34) -> 24567.471
B35: SUBTOTAL | I35: =SUM(I29:I34) -> 223116.73 | K35: =SUM(K29:K34) -> 262490.27
B37: Electrical and Data - Materials and Subcontracting | C37: Subcontractor 1 | D37: Subcontractor 2 | E37: Subcontractor 3 | F37: Selected | G37: Additional Contingency | I37: Total Cost | J37: Install Margin | K37: Selling Price
B38: ELECTRICAL MATERIALS | C38: 202234.38 | D38: 0 | E38: 0 | F38: 0 | G38: 0 | I38: =SUM(C38:G38) -> 202234.38 | J38: =$D$9 -> 0.15 | K38: =I38/(1-J38) -> 237922.8
B39: DATA MATERIALS | C39: 0 | D39: 0 | E39: 0 | F39: 0 | G39: 0 | I39: =SUM(C39:G39) -> 0 | J39: =$D$9 -> 0.15 | K39: =I39/(1-J39) -> 0
B40: ELECTRICAL LABOR | C40: 0 | D40: 0 | E40: 0 | F40: 0 | G40: 0 | I40: =SUM(C40:G40) -> 0 | J40: =$D$9 -> 0.15 | K40: =I40/(1-J40) -> 0
B41: DATA LABOR | C41: 0 | D41: 0 | E41: 0 | F41: 0 | G41: 0 | I41: =SUM(C41:G41) -> 0 | J41: =$D$9 -> 0.15 | K41: =I41/(1-J41) -> 0
B42: SUB PANEL | C42: 0 | D42: 0 | E42: 0 | F42: 0 | G42: 0 | I42: =SUM(C42:G42) -> 0 | J42: =$D$9 -> 0.15 | K42: =I42/(1-J42) -> 0
B43: MISC | C43: 0 | D43: 0 | E43: 0 | F43: 0 | G43: 0 | I43: =SUM(C43:G43) -> 0 | J43: =$D$9 -> 0.15 | K43: =I43/(1-J43) -> 0
B44: SUBTOTAL | I44: =SUM(I38:I43) -> 202234.38 | K44: =SUM(K38:K43) -> 237922.8
B46: Submittals, Engineering, and Permits | C46: Subcontractor 1 | D46: Subcontractor 2 | E46: Subcontractor 3 | F46: Selected | G46: Additional Contingency | I46: Total Cost | J46: Install Margin | K46: Selling Price
B47: STRUCTURAL ENGINEERING | C47: 4705.88 | D47: 0 | E47: 0 | F47: 0 | G47: 0 | I47: =SUM(C47:G47) -> 4705.88 | J47: =$D$11 -> 0.15 | K47: =I47/(1-J47) -> 5536.3294
B48: STRUCTURAL CERTIFICATION | C48: 0 | D48: 0 | E48: 0 | F48: 0 | G48: 0 | I48: =SUM(C48:G48) -> 0 | J48: =$D$11 -> 0.15 | K48: =I48/(1-J48) -> 0
B49: ELECTRICAL ENGINEERING | C49: 0 | D49: 0 | E49: 0 | F49: 0 | G49: 0 | I49: =SUM(C49:G49) -> 0 | J49: =$D$11 -> 0.15 | K49: =I49/(1-J49) -> 0
B50: ELECTRICAL CERTIFICATION | C50: 0 | D50: 0 | E50: 0 | F50: 0 | G50: 0 | I50: =SUM(C50:G50) -> 0 | J50: =$D$11 -> 0.15 | K50: =I50/(1-J50) -> 0
...

Sheet T4-B1 (6-9) - Install
A3: Project Name: WTC Digital Signage Upgrade
A4: 2026-03-31
A5: Revised By: ANC Proposal Engine
C7: Linked Margin Assignment
C8: Install Margin | D8: 0.15
C9: Electrical Margin | D9: 0.15
C10: ANC Margin | D10: 0.15
C11: Engineering and Permits | D11: 0.15
B15: T4-B1 (6-9)
B16: Height | C16: Width | D16: Total Sq. Ft | E16: QTY
B17: 7.87 | C17: 8.66 | D17: 272.62 | E17: 4
B19: Structural Materials: | C19: Subcontractor 1 | D19: Subcontractor 2 | E19: Subcontractor 3 | F19: Selected | G19: Additional Contingency | I19: Total Cost | J19: Install Margin | K19: Selling Price
B20: FABRICATE PRIMARY STEEL | C20: 0 | D20: 0 | E20: 0 | F20: 0 | G20: 0 | I20: =SUM(C20:G20) -> 0 | J20: =$D$8 -> 0.15 | K20: =I20/(1-J20) -> 0
B21: SUPPLY AND INSTALL PRIMARY PLYWOOD | C21: 0 | D21: 0 | E21: 0 | F21: 0 | G21: 0 | I21: =SUM(C21:G21) -> 0 | J21: =$D$8 -> 0.15 | K21: =I21/(1-J21) -> 0
B22: FABRICATE SECONDARY STEEL SUBSTRUCTURE | C22: 4995 | D22: 0 | E22: 0 | F22: 0 | G22: 0 | I22: =SUM(C22:G22) -> 4995 | J22: =$D$8 -> 0.15 | K22: =I22/(1-J22) -> 5876.4706
B23: FABRICATE CLADDING AND TRIM | C23: 0 | D23: 0 | E23: 0 | F23: 0 | G23: 0 | I23: =SUM(C23:G23) -> 0 | J23: =$D$8 -> 0.15 | K23: =I23/(1-J23) -> 0
B24: OTHER SCOPE ITEM | C24: 0 | D24: 0 | E24: 0 | F24: 0 | G24: 0 | I24: =SUM(C24:G24) -> 0 | J24: =$D$8 -> 0.15 | K24: =I24/(1-J24) -> 0
B25: OTHER SCOPE ITEM | C25: 0 | D25: 0 | E25: 0 | F25: 0 | G25: 0 | I25: =SUM(C25:G25) -> 0 | J25: =$D$8 -> 0.15 | K25: =I25/(1-J25) -> 0
B26: SUBTOTAL | I26: =SUM(I20:I25) -> 4995 | K26: =SUM(K20:K25) -> 5876.4706
B28: Structural Labor and LED Installation | C28: Subcontractor 1 | D28: Subcontractor 2 | E28: Subcontractor 3 | F28: Selected | G28: Additional Contingency | I28: Total Cost | J28: Install Margin | K28: Selling Price
B29: REMOVAL AND DISPOSAL | C29: 0 | D29: 0 | E29: 0 | F29: 0 | G29: 0 | I29: =SUM(C29:G29) -> 0 | J29: =$D$8 -> 0.15 | K29: =I29/(1-J29) -> 0
B30: INSTALL SECONDARY STEEL SUBSTRUCTURE | C30: 0 | D30: 0 | E30: 0 | F30: 0 | G30: 0 | I30: =SUM(C30:G30) -> 0 | J30: =$D$8 -> 0.15 | K30: =I30/(1-J30) -> 0
B31: INSTALL LED DISPLAYS | C31: 20812.5 | D31: 0 | E31: 0 | F31: 0 | G31: 0 | I31: =SUM(C31:G31) -> 20812.5 | J31: =$D$8 -> 0.15 | K31: =I31/(1-J31) -> 24485.294
B32: INSTALL CLADDING AND TRIM | C32: 0 | D32: 0 | E32: 0 | F32: 0 | G32: 0 | I32: =SUM(C32:G32) -> 0 | J32: =$D$8 -> 0.15 | K32: =I32/(1-J32) -> 0
B33: HEAVY EQUIPMENT | C33: 0 | D33: 0 | E33: 0 | F33: 0 | G33: 0 | I33: =SUM(C33:G33) -> 0 | J33: =$D$8 -> 0.15 | K33: =I33/(1-J33) -> 0
B34: PM/GENERAL CONDITIONS/TRAVEL | C34: 20882.35 | D34: 0 | E34: 0 | F34: 0 | G34: 0 | I34: =SUM(C34:G34) -> 20882.35 | J34: =$D$8 -> 0.15 | K34: =I34/(1-J34) -> 24567.471
B35: SUBTOTAL | I35: =SUM(I29:I34) -> 41694.85 | K35: =SUM(K29:K34) -> 49052.765
B37: Electrical and Data - Materials and Subcontracting | C37: Subcontractor 1 | D37: Subcontractor 2 | E37: Subcontractor 3 | F37: Selected | G37: Additional Contingency | I37: Total Cost | J37: Install Margin | K37: Selling Price
B38: ELECTRICAL MATERIALS | C38: 20812.5 | D38: 0 | E38: 0 | F38: 0 | G38: 0 | I38: =SUM(C38:G38) -> 20812.5 | J38: =$D$9 -> 0.15 | K38: =I38/(1-J38) -> 24485.294
B39: DATA MATERIALS | C39: 0 | D39: 0 | E39: 0 | F39: 0 | G39: 0 | I39: =SUM(C39:G39) -> 0 | J39: =$D$9 -> 0.15 | K39: =I39/(1-J39) -> 0
B40: ELECTRICAL LABOR | C40: 0 | D40: 0 | E40: 0 | F40: 0 | G40: 0 | I40: =SUM(C40:G40) -> 0 | J40: =$D$9 -> 0.15 | K40: =I40/(1-J40) -> 0
B41: DATA LABOR | C41: 0 | D41: 0 | E41: 0 | F41: 0 | G41: 0 | I41: =SUM(C41:G41) -> 0 | J41: =$D$9 -> 0.15 | K41: =I41/(1-J41) -> 0
B42: SUB PANEL | C42: 0 | D42: 0 | E42: 0 | F42: 0 | G42: 0 | I42: =SUM(C42:G42) -> 0 | J42: =$D$9 -> 0.15 | K42: =I42/(1-J42) -> 0
B43: MISC | C43: 0 | D43: 0 | E43: 0 | F43: 0 | G43: 0 | I43: =SUM(C43:G43) -> 0 | J43: =$D$9 -> 0.15 | K43: =I43/(1-J43) -> 0
B44: SUBTOTAL | I44: =SUM(I38:I43) -> 20812.5 | K44: =SUM(K38:K43) -> 24485.294
B46: Submittals, Engineering, and Permits | C46: Subcontractor 1 | D46: Subcontractor 2 | E46: Subcontractor 3 | F46: Selected | G46: Additional Contingency | I46: Total Cost | J46: Install Margin | K46: Selling Price
B47: STRUCTURAL ENGINEERING | C47: 4705.88 | D47: 0 | E47: 0 | F47: 0 | G47: 0 | I47: =SUM(C47:G47) -> 4705.88 | J47: =$D$11 -> 0.15 | K47: =I47/(1-J47) -> 5536.3294
B48: STRUCTURAL CERTIFICATION | C48: 0 | D48: 0 | E48: 0 | F48: 0 | G48: 0 | I48: =SUM(C48:G48) -> 0 | J48: =$D$11 -> 0.15 | K48: =I48/(1-J48) -> 0
B49: ELECTRICAL ENGINEERING | C49: 0 | D49: 0 | E49: 0 | F49: 0 | G49: 0 | I49: =SUM(C49:G49) -> 0 | J49: =$D$11 -> 0.15 | K49: =I49/(1-J49) -> 0
B50: ELECTRICAL CERTIFICATION | C50: 0 | D50: 0 | E50: 0 | F50: 0 | G50: 0 | I50: =SUM(C50:G50) -> 0 | J50: =$D$11 -> 0.15 | K50: =I50/(1-J50) -> 0
...

Sheet T4-B2 (10-18) - Install
A3: Project Name: WTC Digital Signage Upgrade
A4: 2026-03-31
A5: Revised By: ANC Proposal Engine
C7: Linked Margin Assignment
C8: Install Margin | D8: 0.15
C9: Electrical Margin | D9: 0.15
C10: ANC Margin | D10: 0.15
C11: Engineering and Permits | D11: 0.15
B15: T4-B2 (10-18)
B16: Height | C16: Width | D16: Total Sq. Ft | E16: QTY
B17: 7.87 | C17: 8.66 | D17: 613.39 | E17: 9
B19: Structural Materials: | C19: Subcontractor 1 | D19: Subcontractor 2 | E19: Subcontractor 3 | F19: Selected | G19: Additional Contingency | I19: Total Cost | J19: Install Margin | K19: Selling Price
B20: FABRICATE PRIMARY STEEL | C20: 0 | D20: 0 | E20: 0 | F20: 0 | G20: 0 | I20: =SUM(C20:G20) -> 0 | J20: =$D$8 -> 0.15 | K20: =I20/(1-J20) -> 0
B21: SUPPLY AND INSTALL PRIMARY PLYWOOD | C21: 0 | D21: 0 | E21: 0 | F21: 0 | G21: 0 | I21: =SUM(C21:G21) -> 0 | J21: =$D$8 -> 0.15 | K21: =I21/(1-J21) -> 0
B22: FABRICATE SECONDARY STEEL SUBSTRUCTURE | C22: 11238.75 | D22: 0 | E22: 0 | F22: 0 | G22: 0 | I22: =SUM(C22:G22) -> 11238.75 | J22: =$D$8 -> 0.15 | K22: =I22/(1-J22) -> 13222.059
B23: FABRICATE CLADDING AND TRIM | C23: 0 | D23: 0 | E23: 0 | F23: 0 | G23: 0 | I23: =SUM(C23:G23) -> 0 | J23: =$D$8 -> 0.15 | K23: =I23/(1-J23) -> 0
B24: OTHER SCOPE ITEM | C24: 0 | D24: 0 | E24: 0 | F24: 0 | G24: 0 | I24: =SUM(C24:G24) -> 0 | J24: =$D$8 -> 0.15 | K24: =I24/(1-J24) -> 0
B25: OTHER SCOPE ITEM | C25: 0 | D25: 0 | E25: 0 | F25: 0 | G25: 0 | I25: =SUM(C25:G25) -> 0 | J25: =$D$8 -> 0.15 | K25: =I25/(1-J25) -> 0
B26: SUBTOTAL | I26: =SUM(I20:I25) -> 11238.75 | K26: =SUM(K20:K25) -> 13222.059
B28: Structural Labor and LED Installation | C28: Subcontractor 1 | D28: Subcontractor 2 | E28: Subcontractor 3 | F28: Selected | G28: Additional Contingency | I28: Total Cost | J28: Install Margin | K28: Selling Price
B29: REMOVAL AND DISPOSAL | C29: 0 | D29: 0 | E29: 0 | F29: 0 | G29: 0 | I29: =SUM(C29:G29) -> 0 | J29: =$D$8 -> 0.15 | K29: =I29/(1-J29) -> 0
B30: INSTALL SECONDARY STEEL SUBSTRUCTURE | C30: 0 | D30: 0 | E30: 0 | F30: 0 | G30: 0 | I30: =SUM(C30:G30) -> 0 | J30: =$D$8 -> 0.15 | K30: =I30/(1-J30) -> 0
B31: INSTALL LED DISPLAYS | C31: 46828.13 | D31: 0 | E31: 0 | F31: 0 | G31: 0 | I31: =SUM(C31:G31) -> 46828.13 | J31: =$D$8 -> 0.15 | K31: =I31/(1-J31) -> 55091.918
B32: INSTALL CLADDING AND TRIM | C32: 0 | D32: 0 | E32: 0 | F32: 0 | G32: 0 | I32: =SUM(C32:G32) -> 0 | J32: =$D$8 -> 0.15 | K32: =I32/(1-J32) -> 0
B33: HEAVY EQUIPMENT | C33: 0 | D33: 0 | E33: 0 | F33: 0 | G33: 0 | I33: =SUM(C33:G33) -> 0 | J33: =$D$8 -> 0.15 | K33: =I33/(1-J33) -> 0
B34: PM/GENERAL CONDITIONS/TRAVEL | C34: 20882.35 | D34: 0 | E34: 0 | F34: 0 | G34: 0 | I34: =SUM(C34:G34) -> 20882.35 | J34: =$D$8 -> 0.15 | K34: =I34/(1-J34) -> 24567.471
B35: SUBTOTAL | I35: =SUM(I29:I34) -> 67710.48 | K35: =SUM(K29:K34) -> 79659.388
B37: Electrical and Data - Materials and Subcontracting | C37: Subcontractor 1 | D37: Subcontractor 2 | E37: Subcontractor 3 | F37: Selected | G37: Additional Contingency | I37: Total Cost | J37: Install Margin | K37: Selling Price
B38: ELECTRICAL MATERIALS | C38: 46828.13 | D38: 0 | E38: 0 | F38: 0 | G38: 0 | I38: =SUM(C38:G38) -> 46828.13 | J38: =$D$9 -> 0.15 | K38: =I38/(1-J38) -> 55091.918
B39: DATA MATERIALS | C39: 0 | D39: 0 | E39: 0 | F39: 0 | G39: 0 | I39: =SUM(C39:G39) -> 0 | J39: =$D$9 -> 0.15 | K39: =I39/(1-J39) -> 0
B40: ELECTRICAL LABOR | C40: 0 | D40: 0 | E40: 0 | F40: 0 | G40: 0 | I40: =SUM(C40:G40) -> 0 | J40: =$D$9 -> 0.15 | K40: =I40/(1-J40) -> 0
B41: DATA LABOR | C41: 0 | D41: 0 | E41: 0 | F41: 0 | G41: 0 | I41: =SUM(C41:G41) -> 0 | J41: =$D$9 -> 0.15 | K41: =I41/(1-J41) -> 0
B42: SUB PANEL | C42: 0 | D42: 0 | E42: 0 | F42: 0 | G42: 0 | I42: =SUM(C42:G42) -> 0 | J42: =$D$9 -> 0.15 | K42: =I42/(1-J42) -> 0
B43: MISC | C43: 0 | D43: 0 | E43: 0 | F43: 0 | G43: 0 | I43: =SUM(C43:G43) -> 0 | J43: =$D$9 -> 0.15 | K43: =I43/(1-J43) -> 0
B44: SUBTOTAL | I44: =SUM(I38:I43) -> 46828.13 | K44: =SUM(K38:K43) -> 55091.918
B46: Submittals, Engineering, and Permits | C46: Subcontractor 1 | D46: Subcontractor 2 | E46: Subcontractor 3 | F46: Selected | G46: Additional Contingency | I46: Total Cost | J46: Install Margin | K46: Selling Price
B47: STRUCTURAL ENGINEERING | C47: 4705.88 | D47: 0 | E47: 0 | F47: 0 | G47: 0 | I47: =SUM(C47:G47) -> 4705.88 | J47: =$D$11 -> 0.15 | K47: =I47/(1-J47) -> 5536.3294
B48: STRUCTURAL CERTIFICATION | C48: 0 | D48: 0 | E48: 0 | F48: 0 | G48: 0 | I48: =SUM(C48:G48) -> 0 | J48: =$D$11 -> 0.15 | K48: =I48/(1-J48) -> 0
