Workbook

Sheet Project Overview
A1: Bank of America Stadium Modernization — Project Overview
A2: Panthers Stadium, LLC | 2026-03-31 | ANC Proposal Engine
B4: PROJECT INFORMATION
B5: Client | C5: Panthers Stadium, LLC
B6: Project Name | C6: Bank of America Stadium Modernization
B7: Location | C7: 800 South Mint St., Charlotte, NC 28202
B8: Date Created | C8: 2026-03-31
B9: Currency | C9: USD
B10: Environment | C10: Indoor
B11: Union Labor | C11: No
B12: Bond Required | C12: No
B13: Number of Displays | C13: =SUM('LED Cost Sheet'!I4:I28) -> 34
B15: FINANCIAL PARAMETERS
B16: LED Hardware Margin | C16: 15%
B17: Install / Services Margin | C17: 15%
B18: Engineering Margin | C18: 15%
B19: Equipment Margin | C19: 15%
B20: CMS Margin | C20: 15%
B21: Bond Rate | C21: N/A
B22: Tax Rate | C22: Per zone (editable on MA)
B23: Tariff Rate | C23: Per zone (editable on MA)
B25: SUMMARY TOTALS
B26: Total Cost | C26: ='Margin Analysis'!C340 -> 3218418.2
B27: Total Selling Price | C27: ='Margin Analysis'!D340 -> 3706135.2
B28: Project Margin $ | C28: ='Margin Analysis'!E340 -> 487717
B29: Project Margin % | C29: ='Margin Analysis'!F340 -> 0.13
B30: DOCUMENT TOTAL | C30: ='Margin Analysis'!D340 -> 3706135.2

Sheet Margin Analysis
A1: Bank of America Stadium Modernization — Margin Analysis
A2: Panthers Stadium, LLC | 2026-03-31 | ANC Proposal Engine
B4: Zone / Category | C4: Cost | D4: Selling Price | E4: Margin $ | F4: Margin %
B5: Team Room — Team Room | D5: Selling Price
B6: LED Hardware | C6: ='LED Cost Sheet'!T4 -> 28982.73 | D6: ='LED Cost Sheet'!V4 -> 34097.33 | E6: =IFERROR(D6-C6,0) -> 5114.6 | F6: 0.15
B7: Structural Materials | C7: ='Team Room - Install'!I26 -> 1290 | D7: =IFERROR(C7/(1-F7),0) -> 1517.65 | E7: =IFERROR(D7-C7,0) -> 227.65 | F7: 0.15
B8: Structural Labor & LED Installation | C8: ='Team Room - Install'!I35-'Team Room - Install'!I34 -> 5375 | D8: =IFERROR(C8/(1-F8),0) -> 6323.53 | E8: =IFERROR(D8-C8,0) -> 948.53 | F8: 0.15
B9: Electrical & Data | C9: ='Team Room - Install'!I44 -> 5375 | D9: =IFERROR(C9/(1-F9),0) -> 6323.53 | E9: =IFERROR(D9-C9,0) -> 948.53 | F9: 0.15
B10: PM / General Conditions / Travel | C10: ='Team Room - Install'!I34 -> 20882.35 | D10: =IFERROR(C10/(1-F10),0) -> 24567.47 | E10: =IFERROR(D10-C10,0) -> 3685.12 | F10: 0.15
B11: Engineering & Permits | C11: ='Team Room - Install'!I52 -> 4705.88 | D11: =IFERROR(C11/(1-F11),0) -> 5536.33 | E11: =IFERROR(D11-C11,0) -> 830.45 | F11: 0.15
B12: SUBTOTAL | C12: =SUM(C6:C11) -> 66610.96 | D12: =SUM(D6:D11) -> 77048.19 | E12: =IFERROR(D12-C12,0) -> 10437.23 | F12: =IFERROR(1-C12/D12,0) -> 0.135464
B13: TAX | C13: 0 | D13: 0 | E13: 0 | G13: 0
B14: BOND | C14: 0 | D14: 0 | E14: 0 | G14: 0
B15: TARIFF | C15: 0 | D15: 0 | E15: 0 | G15: 0
B16: GRAND TOTAL | C16: =C12+C13+C14+C15 -> 66610.96 | D16: =D12+D13+D14+D15 -> 77048.19 | E16: =IFERROR(D16-C16,0) -> 10437.23 | F16: =IFERROR(1-C16/D16,0) -> 0.13546366
B18: Incident Command — Incident Command | D18: Selling Price
B19: LED Hardware | C19: ='LED Cost Sheet'!T5 -> 31247.51 | D19: ='LED Cost Sheet'!V5 -> 36761.78 | E19: =IFERROR(D19-C19,0) -> 5514.27 | F19: 0.15
B20: Structural Materials | C20: ='Incident Command - Install'!I26 -> 1391.25 | D20: =IFERROR(C20/(1-F20),0) -> 1636.76 | E20: =IFERROR(D20-C20,0) -> 245.51 | F20: 0.15
B21: Structural Labor & LED Installation | C21: ='Incident Command - Install'!I35-'Incident Command - Install'!I34 -> 5796.88 | D21: =IFERROR(C21/(1-F21),0) -> 6819.86 | E21: =IFERROR(D21-C21,0) -> 1022.98 | F21: 0.15
B22: Electrical & Data | C22: ='Incident Command - Install'!I44 -> 5796.88 | D22: =IFERROR(C22/(1-F22),0) -> 6819.86 | E22: =IFERROR(D22-C22,0) -> 1022.98 | F22: 0.15
B23: PM / General Conditions / Travel | C23: ='Incident Command - Install'!I34 -> 20882.35 | D23: =IFERROR(C23/(1-F23),0) -> 24567.47 | E23: =IFERROR(D23-C23,0) -> 3685.12 | F23: 0.15
B24: Engineering & Permits | C24: ='Incident Command - Install'!I52 -> 4705.88 | D24: =IFERROR(C24/(1-F24),0) -> 5536.33 | E24: =IFERROR(D24-C24,0) -> 830.45 | F24: 0.15
B25: SUBTOTAL | C25: =SUM(C19:C24) -> 69820.75 | D25: =SUM(D19:D24) -> 80719.82 | E25: =IFERROR(D25-C25,0) -> 10899.07 | F25: =IFERROR(1-C25/D25,0) -> 0.135023
B26: TAX | C26: 0 | D26: 0 | E26: 0 | G26: 0
B27: BOND | C27: 0 | D27: 0 | E27: 0 | G27: 0
B28: TARIFF | C28: 0 | D28: 0 | E28: 0 | G28: 0
B29: GRAND TOTAL | C29: =C25+C26+C27+C28 -> 69820.75 | D29: =D25+D26+D27+D28 -> 80719.82 | E29: =IFERROR(D29-C29,0) -> 10899.07 | F29: =IFERROR(1-C29/D29,0) -> 0.13502347
B31: Def. Unit — Def. Unit | D31: Selling Price
B32: LED Hardware | C32: ='LED Cost Sheet'!T6 -> 28982.73 | D32: ='LED Cost Sheet'!V6 -> 34097.33 | E32: =IFERROR(D32-C32,0) -> 5114.6 | F32: 0.15
B33: Structural Materials | C33: ='Def. Unit - Install'!I26 -> 1290 | D33: =IFERROR(C33/(1-F33),0) -> 1517.65 | E33: =IFERROR(D33-C33,0) -> 227.65 | F33: 0.15
B34: Structural Labor & LED Installation | C34: ='Def. Unit - Install'!I35-'Def. Unit - Install'!I34 -> 5375 | D34: =IFERROR(C34/(1-F34),0) -> 6323.53 | E34: =IFERROR(D34-C34,0) -> 948.53 | F34: 0.15
B35: Electrical & Data | C35: ='Def. Unit - Install'!I44 -> 5375 | D35: =IFERROR(C35/(1-F35),0) -> 6323.53 | E35: =IFERROR(D35-C35,0) -> 948.53 | F35: 0.15
B36: PM / General Conditions / Travel | C36: ='Def. Unit - Install'!I34 -> 20882.35 | D36: =IFERROR(C36/(1-F36),0) -> 24567.47 | E36: =IFERROR(D36-C36,0) -> 3685.12 | F36: 0.15
B37: Engineering & Permits | C37: ='Def. Unit - Install'!I52 -> 4705.88 | D37: =IFERROR(C37/(1-F37),0) -> 5536.33 | E37: =IFERROR(D37-C37,0) -> 830.45 | F37: 0.15
B38: SUBTOTAL | C38: =SUM(C32:C37) -> 66610.96 | D38: =SUM(D32:D37) -> 77048.19 | E38: =IFERROR(D38-C38,0) -> 10437.23 | F38: =IFERROR(1-C38/D38,0) -> 0.135464
B39: TAX | C39: 0 | D39: 0 | E39: 0 | G39: 0
B40: BOND | C40: 0 | D40: 0 | E40: 0 | G40: 0
B41: TARIFF | C41: 0 | D41: 0 | E41: 0 | G41: 0
B42: GRAND TOTAL | C42: =C38+C39+C40+C41 -> 66610.96 | D42: =D38+D39+D40+D41 -> 77048.19 | E42: =IFERROR(D42-C42,0) -> 10437.23 | F42: =IFERROR(1-C42/D42,0) -> 0.13546366
B44: North Corridor — North Corridor | D44: Selling Price
...

Sheet Budget Summary
A1: Bank of America Stadium Modernization — Budget Summary
A2: Panthers Stadium, LLC | 2026-03-31 | By Category
B4: Category | C4: Cost | D4: Selling Price | E4: Margin $ | F4: Margin % | G4: Price / SqFt
B5: LED Hardware (all displays) | C5: =SUM('LED Cost Sheet'!Q4:Q28) -> 1853582.4 | D5: =SUM('LED Cost Sheet'!S4:S28) -> 2180685.2 | E5: =IFERROR(D5-C5,0) -> 327102.78 | F5: 0.15 | G5: =IFERROR(C5/6742.33,0) -> 274.92
B6: Structural Materials | C6: =SUM('Team Room - Install'!I26:I26)+SUM('Incident Command - Install'!I26:I26)+SUM('Def. Unit - Install'!I26:I26)+SUM('North Corridor - Install'!I26:I26)+SUM('South Corridor - Install'!I26:I26)+SUM('S.E Corridor - Install'!I26:I26)+SUM('East Corridor - Install'!I26:I26)+SUM('N.E Corridor - Install'!I26:I26)+SUM('Elev Lobby - Install'!I26:I26)+SUM('North Club - Install'!I26:I26)+SUM('Panthers Den - Install'!I26:I26)+SUM('Panthers Den12 - Install'!I26:I26)+SUM('Panthers Den13 - Install'!I26:I26)+SUM('Panthers Den14 - Install'!I26:I26)+SUM('South Club - Install'!I26:I26)+SUM('S.E Corridor16 - Install'!I26:I26)+SUM('N.E Corridor17 - Install'!I26:I26)+SUM('Panthers Den18 - Install'!I26:I26)+SUM('Panthers Den19 - Install'!I26:I26)+SUM('Panthers Den20 - Install'!I26:I26)+SUM('Elev Lobby21 - Install'!I26:I26)+SUM('Elev Lobby22 - Install'!I26:I26)+SUM('Elev Lobby23 - Install'!I26:I26)+SUM('North Club24 - Install'!I26:I26)+SUM('South Club25 - Install'!I26:I26) -> 77692.5 | D6: =SUM('Team Room - Install'!K26:K26)+SUM('Incident Command - Install'!K26:K26)+SUM('Def. Unit - Install'!K26:K26)+SUM('North Corridor - Install'!K26:K26)+SUM('South Corridor - Install'!K26:K26)+SUM('S.E Corridor - Install'!K26:K26)+SUM('East Corridor - Install'!K26:K26)+SUM('N.E Corridor - Install'!K26:K26)+SUM('Elev Lobby - Install'!K26:K26)+SUM('North Club - Install'!K26:K26)+SUM('Panthers Den - Install'!K26:K26)+SUM('Panthers Den12 - Install'!K26:K26)+SUM('Panthers Den13 - Install'!K26:K26)+SUM('Panthers Den14 - Install'!K26:K26)+SUM('South Club - Install'!K26:K26)+SUM('S.E Corridor16 - Install'!K26:K26)+SUM('N.E Corridor17 - Install'!K26:K26)+SUM('Panthers Den18 - Install'!K26:K26)+SUM('Panthers Den19 - Install'!K26:K26)+SUM('Panthers Den20 - Install'!K26:K26)+SUM('Elev Lobby21 - Install'!K26:K26)+SUM('Elev Lobby22 - Install'!K26:K26)+SUM('Elev Lobby23 - Install'!K26:K26)+SUM('North Club24 - Install'!K26:K26)+SUM('South Club25 - Install'!K26:K26) -> 91402.94 | E6: =IFERROR(D6-C6,0) -> 13710.44 | F6: 0.15 | G6: =IFERROR(C6/6742.33,0) -> 11.52
B7: Structural Labor & LED Installation | C7: =(SUM('Team Room - Install'!I35:I35)-SUM('Team Room - Install'!I34:I34))+(SUM('Incident Command - Install'!I35:I35)-SUM('Incident Command - Install'!I34:I34))+(SUM('Def. Unit - Install'!I35:I35)-SUM('Def. Unit - Install'!I34:I34))+(SUM('North Corridor - Install'!I35:I35)-SUM('North Corridor - Install'!I34:I34))+(SUM('South Corridor - Install'!I35:I35)-SUM('South Corridor - Install'!I34:I34))+(SUM('S.E Corridor - Install'!I35:I35)-SUM('S.E Corridor - Install'!I34:I34))+(SUM('East Corridor - Install'!I35:I35)-SUM('East Corridor - Install'!I34:I34))+(SUM('N.E Corridor - Install'!I35:I35)-SUM('N.E Corridor - Install'!I34:I34))+(SUM('Elev Lobby - Install'!I35:I35)-SUM('Elev Lobby - Install'!I34:I34))+(SUM('North Club - Install'!I35:I35)-SUM('North Club - Install'!I34:I34))+(SUM('Panthers Den - Install'!I35:I35)-SUM('Panthers Den - Install'!I34:I34))+(SUM('Panthers Den12 - Install'!I35:I35)-SUM('Panthers Den12 - Install'!I34:I34))+(SUM('Panthers Den13 - Install'!I35:I35)-SUM('Panthers Den13 - Install'!I34:I34))+(SUM('Panthers Den14 - Install'!I35:I35)-SUM('Panthers Den14 - Install'!I34:I34))+(SUM('South Club - Install'!I35:I35)-SUM('South Club - Install'!I34:I34))+(SUM('S.E Corridor16 - Install'!I35:I35)-SUM('S.E Corridor16 - Install'!I34:I34))+(SUM('N.E Corridor17 - Install'!I35:I35)-SUM('N.E Corridor17 - Install'!I34:I34))+(SUM('Panthers Den18 - Install'!I35:I35)-SUM('Panthers Den18 - Install'!I34:I34))+(SUM('Panthers Den19 - Install'!I35:I35)-SUM('Panthers Den19 - Install'!I34:I34))+(SUM('Panthers Den20 - Install'!I35:I35)-SUM('Panthers Den20 - Install'!I34:I34))+(SUM('Elev Lobby21 - Install'!I35:I35)-SUM('Elev Lobby21 - Install'!I34:I34))+(SUM('Elev Lobby22 - Install'!I35:I35)-SUM('Elev Lobby22 - Install'!I34:I34))+(SUM('Elev Lobby23 - Install'!I35:I35)-SUM('Elev Lobby23 - Install'!I34:I34))+(SUM('North Club24 - Install'!I35:I35)-SUM('North Club24 - Install'!I34:I34))+(SUM('South Club25 - Install'!I35:I35)-SUM('South Club25 - Install'!I34:I34)) -> 323718.78 | D7: =(SUM('Team Room - Install'!K35:K35)-SUM('Team Room - Install'!K34:K34))+(SUM('Incident Command - Install'!K35:K35)-SUM('Incident Command - Install'!K34:K34))+(SUM('Def. Unit - Install'!K35:K35)-SUM('Def. Unit - Install'!K34:K34))+(SUM('North Corridor - Install'!K35:K35)-SUM('North Corridor - Install'!K34:K34))+(SUM('South Corridor - Install'!K35:K35)-SUM('South Corridor - Install'!K34:K34))+(SUM('S.E Corridor - Install'!K35:K35)-SUM('S.E Corridor - Install'!K34:K34))+(SUM('East Corridor - Install'!K35:K35)-SUM('East Corridor - Install'!K34:K34))+(SUM('N.E Corridor - Install'!K35:K35)-SUM('N.E Corridor - Install'!K34:K34))+(SUM('Elev Lobby - Install'!K35:K35)-SUM('Elev Lobby - Install'!K34:K34))+(SUM('North Club - Install'!K35:K35)-SUM('North Club - Install'!K34:K34))+(SUM('Panthers Den - Install'!K35:K35)-SUM('Panthers Den - Install'!K34:K34))+(SUM('Panthers Den12 - Install'!K35:K35)-SUM('Panthers Den12 - Install'!K34:K34))+(SUM('Panthers Den13 - Install'!K35:K35)-SUM('Panthers Den13 - Install'!K34:K34))+(SUM('Panthers Den14 - Install'!K35:K35)-SUM('Panthers Den14 - Install'!K34:K34))+(SUM('South Club - Install'!K35:K35)-SUM('South Club - Install'!K34:K34))+(SUM('S.E Corridor16 - Install'!K35:K35)-SUM('S.E Corridor16 - Install'!K34:K34))+(SUM('N.E Corridor17 - Install'!K35:K35)-SUM('N.E Corridor17 - Install'!K34:K34))+(SUM('Panthers Den18 - Install'!K35:K35)-SUM('Panthers Den18 - Install'!K34:K34))+(SUM('Panthers Den19 - Install'!K35:K35)-SUM('Panthers Den19 - Install'!K34:K34))+(SUM('Panthers Den20 - Install'!K35:K35)-SUM('Panthers Den20 - Install'!K34:K34))+(SUM('Elev Lobby21 - Install'!K35:K35)-SUM('Elev Lobby21 - Install'!K34:K34))+(SUM('Elev Lobby22 - Install'!K35:K35)-SUM('Elev Lobby22 - Install'!K34:K34))+(SUM('Elev Lobby23 - Install'!K35:K35)-SUM('Elev Lobby23 - Install'!K34:K34))+(SUM('North Club24 - Install'!K35:K35)-SUM('North Club24 - Install'!K34:K34))+(SUM('South Club25 - Install'!K35:K35)-SUM('South Club25 - Install'!K34:K34)) -> 380845.62 | E7: =IFERROR(D7-C7,0) -> 57126.84 | F7: 0.15 | G7: =IFERROR(C7/6742.33,0) -> 48.01
B8: Electrical & Data | C8: =SUM('Team Room - Install'!I44:I44)+SUM('Incident Command - Install'!I44:I44)+SUM('Def. Unit - Install'!I44:I44)+SUM('North Corridor - Install'!I44:I44)+SUM('South Corridor - Install'!I44:I44)+SUM('S.E Corridor - Install'!I44:I44)+SUM('East Corridor - Install'!I44:I44)+SUM('N.E Corridor - Install'!I44:I44)+SUM('Elev Lobby - Install'!I44:I44)+SUM('North Club - Install'!I44:I44)+SUM('Panthers Den - Install'!I44:I44)+SUM('Panthers Den12 - Install'!I44:I44)+SUM('Panthers Den13 - Install'!I44:I44)+SUM('Panthers Den14 - Install'!I44:I44)+SUM('South Club - Install'!I44:I44)+SUM('S.E Corridor16 - Install'!I44:I44)+SUM('N.E Corridor17 - Install'!I44:I44)+SUM('Panthers Den18 - Install'!I44:I44)+SUM('Panthers Den19 - Install'!I44:I44)+SUM('Panthers Den20 - Install'!I44:I44)+SUM('Elev Lobby21 - Install'!I44:I44)+SUM('Elev Lobby22 - Install'!I44:I44)+SUM('Elev Lobby23 - Install'!I44:I44)+SUM('North Club24 - Install'!I44:I44)+SUM('South Club25 - Install'!I44:I44) -> 323718.78 | D8: =SUM('Team Room - Install'!K44:K44)+SUM('Incident Command - Install'!K44:K44)+SUM('Def. Unit - Install'!K44:K44)+SUM('North Corridor - Install'!K44:K44)+SUM('South Corridor - Install'!K44:K44)+SUM('S.E Corridor - Install'!K44:K44)+SUM('East Corridor - Install'!K44:K44)+SUM('N.E Corridor - Install'!K44:K44)+SUM('Elev Lobby - Install'!K44:K44)+SUM('North Club - Install'!K44:K44)+SUM('Panthers Den - Install'!K44:K44)+SUM('Panthers Den12 - Install'!K44:K44)+SUM('Panthers Den13 - Install'!K44:K44)+SUM('Panthers Den14 - Install'!K44:K44)+SUM('South Club - Install'!K44:K44)+SUM('S.E Corridor16 - Install'!K44:K44)+SUM('N.E Corridor17 - Install'!K44:K44)+SUM('Panthers Den18 - Install'!K44:K44)+SUM('Panthers Den19 - Install'!K44:K44)+SUM('Panthers Den20 - Install'!K44:K44)+SUM('Elev Lobby21 - Install'!K44:K44)+SUM('Elev Lobby22 - Install'!K44:K44)+SUM('Elev Lobby23 - Install'!K44:K44)+SUM('North Club24 - Install'!K44:K44)+SUM('South Club25 - Install'!K44:K44) -> 380845.62 | E8: =IFERROR(D8-C8,0) -> 57126.84 | F8: 0.15 | G8: =IFERROR(C8/6742.33,0) -> 48.01
B9: PM / General Conditions / Travel | C9: =SUM('Team Room - Install'!I34:I34)+SUM('Incident Command - Install'!I34:I34)+SUM('Def. Unit - Install'!I34:I34)+SUM('North Corridor - Install'!I34:I34)+SUM('South Corridor - Install'!I34:I34)+SUM('S.E Corridor - Install'!I34:I34)+SUM('East Corridor - Install'!I34:I34)+SUM('N.E Corridor - Install'!I34:I34)+SUM('Elev Lobby - Install'!I34:I34)+SUM('North Club - Install'!I34:I34)+SUM('Panthers Den - Install'!I34:I34)+SUM('Panthers Den12 - Install'!I34:I34)+SUM('Panthers Den13 - Install'!I34:I34)+SUM('Panthers Den14 - Install'!I34:I34)+SUM('South Club - Install'!I34:I34)+SUM('S.E Corridor16 - Install'!I34:I34)+SUM('N.E Corridor17 - Install'!I34:I34)+SUM('Panthers Den18 - Install'!I34:I34)+SUM('Panthers Den19 - Install'!I34:I34)+SUM('Panthers Den20 - Install'!I34:I34)+SUM('Elev Lobby21 - Install'!I34:I34)+SUM('Elev Lobby22 - Install'!I34:I34)+SUM('Elev Lobby23 - Install'!I34:I34)+SUM('North Club24 - Install'!I34:I34)+SUM('South Club25 - Install'!I34:I34) -> 522058.75 | D9: =SUM('Team Room - Install'!K34:K34)+SUM('Incident Command - Install'!K34:K34)+SUM('Def. Unit - Install'!K34:K34)+SUM('North Corridor - Install'!K34:K34)+SUM('South Corridor - Install'!K34:K34)+SUM('S.E Corridor - Install'!K34:K34)+SUM('East Corridor - Install'!K34:K34)+SUM('N.E Corridor - Install'!K34:K34)+SUM('Elev Lobby - Install'!K34:K34)+SUM('North Club - Install'!K34:K34)+SUM('Panthers Den - Install'!K34:K34)+SUM('Panthers Den12 - Install'!K34:K34)+SUM('Panthers Den13 - Install'!K34:K34)+SUM('Panthers Den14 - Install'!K34:K34)+SUM('South Club - Install'!K34:K34)+SUM('S.E Corridor16 - Install'!K34:K34)+SUM('N.E Corridor17 - Install'!K34:K34)+SUM('Panthers Den18 - Install'!K34:K34)+SUM('Panthers Den19 - Install'!K34:K34)+SUM('Panthers Den20 - Install'!K34:K34)+SUM('Elev Lobby21 - Install'!K34:K34)+SUM('Elev Lobby22 - Install'!K34:K34)+SUM('Elev Lobby23 - Install'!K34:K34)+SUM('North Club24 - Install'!K34:K34)+SUM('South Club25 - Install'!K34:K34) -> 614186.76 | E9: =IFERROR(D9-C9,0) -> 92128.01 | F9: 0.15
B10: Engineering & Permits | C10: =SUM('Team Room - Install'!I52:I52)+SUM('Incident Command - Install'!I52:I52)+SUM('Def. Unit - Install'!I52:I52)+SUM('North Corridor - Install'!I52:I52)+SUM('South Corridor - Install'!I52:I52)+SUM('S.E Corridor - Install'!I52:I52)+SUM('East Corridor - Install'!I52:I52)+SUM('N.E Corridor - Install'!I52:I52)+SUM('Elev Lobby - Install'!I52:I52)+SUM('North Club - Install'!I52:I52)+SUM('Panthers Den - Install'!I52:I52)+SUM('Panthers Den12 - Install'!I52:I52)+SUM('Panthers Den13 - Install'!I52:I52)+SUM('Panthers Den14 - Install'!I52:I52)+SUM('South Club - Install'!I52:I52)+SUM('S.E Corridor16 - Install'!I52:I52)+SUM('N.E Corridor17 - Install'!I52:I52)+SUM('Panthers Den18 - Install'!I52:I52)+SUM('Panthers Den19 - Install'!I52:I52)+SUM('Panthers Den20 - Install'!I52:I52)+SUM('Elev Lobby21 - Install'!I52:I52)+SUM('Elev Lobby22 - Install'!I52:I52)+SUM('Elev Lobby23 - Install'!I52:I52)+SUM('North Club24 - Install'!I52:I52)+SUM('South Club25 - Install'!I52:I52) -> 117647 | D10: =SUM('Team Room - Install'!K52:K52)+SUM('Incident Command - Install'!K52:K52)+SUM('Def. Unit - Install'!K52:K52)+SUM('North Corridor - Install'!K52:K52)+SUM('South Corridor - Install'!K52:K52)+SUM('S.E Corridor - Install'!K52:K52)+SUM('East Corridor - Install'!K52:K52)+SUM('N.E Corridor - Install'!K52:K52)+SUM('Elev Lobby - Install'!K52:K52)+SUM('North Club - Install'!K52:K52)+SUM('Panthers Den - Install'!K52:K52)+SUM('Panthers Den12 - Install'!K52:K52)+SUM('Panthers Den13 - Install'!K52:K52)+SUM('Panthers Den14 - Install'!K52:K52)+SUM('South Club - Install'!K52:K52)+SUM('S.E Corridor16 - Install'!K52:K52)+SUM('N.E Corridor17 - Install'!K52:K52)+SUM('Panthers Den18 - Install'!K52:K52)+SUM('Panthers Den19 - Install'!K52:K52)+SUM('Panthers Den20 - Install'!K52:K52)+SUM('Elev Lobby21 - Install'!K52:K52)+SUM('Elev Lobby22 - Install'!K52:K52)+SUM('Elev Lobby23 - Install'!K52:K52)+SUM('North Club24 - Install'!K52:K52)+SUM('South Club25 - Install'!K52:K52) -> 138408.24 | E10: =IFERROR(D10-C10,0) -> 20761.24 | F10: 0.15
B11: CMS (Content Management System) | C11: =SUM(CMS!F26:F26) -> 0 | D11: =SUM(CMS!H26:H26) -> 0 | E11: =IFERROR(D11-C11,0) -> 0 | F11: 0.15
B12: Scoring System | C12: =SUM(Scoring!F27:F27) -> 0 | D12: =SUM(Scoring!H27:H27) -> 0 | E12: =IFERROR(D12-C12,0) -> 0 | F12: 0.15
B13: Venue Services | C13: =SUM('Venue Services'!B17:B17) -> 0 | D13: =SUM('Venue Services'!C17:C17) -> 0 | E13: =IFERROR(D13-C13,0) -> 0 | F13: 0.15
B14: Game Clock | C14: =SUM('Additional Items'!F5:F5) -> 0 | D14: =SUM('Additional Items'!H5:H5) -> 0 | E14: =IFERROR(D14-C14,0) -> 0 | F14: 0.15
B15: Pitch Clocks | C15: =SUM('Additional Items'!F6:F6) -> 0 | D15: =SUM('Additional Items'!H6:H6) -> 0 | E15: =IFERROR(D15-C15,0) -> 0 | F15: 0.15
B16: OES / MIS / Timing | C16: =SUM('Additional Items'!F7:F7) -> 0 | D16: =SUM('Additional Items'!H7:H7) -> 0 | E16: =IFERROR(D16-C16,0) -> 0 | F16: 0.15
B17: DMX / Misc Equipment | C17: =SUM('Additional Items'!F8:F8) -> 0 | D17: =SUM('Additional Items'!H8:H8) -> 0 | E17: =IFERROR(D17-C17,0) -> 0 | F17: 0.15
B19: SUBTOTAL | C19: =SUM(C5:C17) -> 3218418.2 | D19: =SUM(D5:D17) -> 3706135.2 | E19: =IFERROR(D19-C19,0) -> 487717 | F19: =IFERROR(1-C19/D19,0) -> 0.13 | G19: =IFERROR(C19/6742.33,0) -> 477.35
B20: TAX | C20: 0 | D20: 0 | E20: 0 | F20: 0
B21: BOND | C21: 0 | D21: 0 | E21: 0 | F21: 0
B22: GRAND TOTAL | C22: =C19+C20+C21 -> 3218418.2 | D22: =D19+D20+D21 -> 3706135.2 | E22: =IFERROR(D22-C22,0) -> 487717 | F22: =IFERROR(1-C22/D22,0) -> 0.13 | G22: =IFERROR(C22/6742.33,0) -> 477.35

Sheet LED Cost Sheet
A1: Bank of America Stadium Modernization — LED Cost Sheet
U2: LED Margin Override → | V2: 0.15
A3: Display | B3: RFP H (ft) | C3: RFP W (ft) | D3: RFP NITs | E3: Vendor | F3: Product | G3: Pitch | H3: H (ft) | I3: W (ft) | J3: H (px) | K3: W (px) | L3: Qty | M3: Total SqFt | N3: Product NITs | O3: Service | P3: $/SqFt | Q3: Display Cost | R3: Processor | S3: Shipping | T3: Total Cost | U3: Margin % | V3: Selling Price | W3: ANC Margin | X3: Weight (lbs) | Y3: Total Power (W) | Z3: BTU/hr
A4: Team Room — Team Room | B4: 8 | C4: 14 | D4: 8000 | E4: Yaham | F4: Yaham Corona C2.5-MIP Indoor | G4: 3.9mm | H4: 8 | I4: 14 | J4: 625 | K4: 1094 | L4: 1 | M4: =H4*I4*L4 -> 112 | N4: 7500 | O4: Front | P4: 244.16 | Q4: 27345.53 | R4: =SUM('Bundle Equipment'!E10:E10) -> 517.2 | S4: 1120 | T4: 28982.73 | U4: =V$2 -> 0.135464 | V4: 77048.19 | W4: 10437.23 | X4: 523 | Y4: 4177 | Z4: =Y4*3.412 -> 14252
A5: Incident Command — Incident Command | B5: 5.3333 | C5: 22.6667 | D5: 8000 | E5: Yaham | F5: Yaham Corona C2.5-MIP Indoor | G5: 3.9mm | H5: 5.3333 | I5: 22.6667 | J5: 417 | K5: 1771 | L5: 1 | M5: =H5*I5*L5 -> 120.89 | N5: 7500 | O5: Front | P5: 244.16 | Q5: 29516.08 | R5: =SUM('Bundle Equipment'!E15:E15) -> 522.53 | S5: 1208.9 | T5: 31247.51 | U5: =V$2 -> 0.135023 | V5: 80719.82 | W5: 10899.07 | X5: 564 | Y5: 4509 | Z5: =Y5*3.412 -> 15385
A6: Def. Unit — Def. Unit | B6: 8 | C6: 14 | D6: 8000 | E6: Yaham | F6: Yaham Corona C2.5-MIP Indoor | G6: 3.9mm | H6: 8 | I6: 14 | J6: 625 | K6: 1094 | L6: 1 | M6: =H6*I6*L6 -> 112 | N6: 7500 | O6: Front | P6: 244.16 | Q6: 27345.53 | R6: =SUM('Bundle Equipment'!E20:E20) -> 517.2 | S6: 1120 | T6: 28982.73 | U6: =V$2 -> 0.135464 | V6: 77048.19 | W6: 10437.23 | X6: 523 | Y6: 4177 | Z6: =Y6*3.412 -> 14252
A7: North Corridor — North Corridor | B7: 11 | C7: 100 | D7: 8000 | E7: Yaham | F7: Yaham Corona C2.5-MIP Indoor | G7: 3.9mm | H7: 11 | I7: 100 | J7: 860 | K7: 7815 | L7: 1 | M7: =H7*I7*L7 -> 1100 | N7: 7500 | O7: Front | P7: 244.16 | Q7: 268572.15 | R7: =SUM('Bundle Equipment'!E26:E26) -> 21060 | S7: 11000 | T7: 300632.15 | U7: =V$2 -> 0.128434 | V7: 510065.17 | W7: 65509.78 | X7: 5135 | Y7: 41028 | Z7: =Y7*3.412 -> 139988
A8: South Corridor — South Corridor | B8: 11 | C8: 85 | D8: 8000 | E8: Yaham | F8: Yaham Corona C2.5-MIP Indoor | G8: 3.9mm | H8: 11 | I8: 85 | J8: 860 | K8: 6643 | L8: 1 | M8: =H8*I8*L8 -> 935 | N8: 7500 | O8: Front | P8: 244.16 | Q8: 228286.33 | R8: =SUM('Bundle Equipment'!E32:E32) -> 20961 | S8: 9350 | T8: 258597.33 | U8: =V$2 -> 0.128831 | V8: 441677.13 | W8: 56901.57 | X8: 4364 | Y8: 34874 | Z8: =Y8*3.412 -> 118990
A9: S.E Corridor — S.E Corridor | B9: 10 | C9: 34 | D9: 8000 | E9: Yaham | F9: Yaham Corona C2.5-MIP Indoor | G9: 3.9mm | H9: 10 | I9: 34 | J9: 782 | K9: 2657 | L9: 2 | M9: =H9*I9*L9 -> 680 | N9: 7500 | O9: Front | P9: 244.16 | Q9: 166026.42 | R9: =SUM('Bundle Equipment'!E38:E38) -> 12858 | S9: 6800 | T9: 185684.42 | U9: =V$2 -> 0.12918 | V9: 326614.88 | W9: 42192.23 | X9: 3174 | Y9: 25363 | Z9: =Y9*3.412 -> 86539
A10: East Corridor — East Corridor | B10: 10 | C10: 36 | D10: 8000 | E10: Yaham | F10: Yaham Corona C2.5-MIP Indoor | G10: 3.9mm | H10: 10 | I10: 36 | J10: 782 | K10: 2814 | L10: 1 | M10: =H10*I10*L10 -> 360 | N10: 7500 | O10: Front | P10: 244.16 | Q10: 87896.34 | R10: =SUM('Bundle Equipment'!E44:E44) -> 12666 | S10: 3600 | T10: 104162.34 | U10: =V$2 -> 0.131443 | V10: 193994.8 | W10: 25499.22 | X10: 1680 | Y10: 13427 | Z10: =Y10*3.412 -> 45813
A11: N.E Corridor — N.E Corridor | B11: 10 | C11: 34 | D11: 8000 | E11: Yaham | F11: Yaham Corona C2.5-MIP Indoor | G11: 3.9mm | H11: 10 | I11: 34 | J11: 782 | K11: 2657 | L11: 2 | M11: =H11*I11*L11 -> 680 | N11: 7500 | O11: Front | P11: 244.16 | Q11: 166026.42 | R11: =SUM('Bundle Equipment'!E50:E50) -> 12858 | S11: 6800 | T11: 185684.42 | U11: =V$2 -> 0.12918 | V11: 326614.88 | W11: 42192.23 | X11: 3174 | Y11: 25363 | Z11: =Y11*3.412 -> 86539
A12: Elev Lobby — Elev Lobby | B12: 4 | C12: 6 | D12: 8000 | E12: Yaham | F12: Yaham Corona C2.5-MIP Indoor | G12: 3.9mm | H12: 4 | I12: 6 | J12: 313 | K12: 469 | L12: 4 | M12: =H12*I12*L12 -> 96 | N12: 7500 | O12: Front | P12: 244.16 | Q12: 23439.02 | R12: =SUM('Bundle Equipment'!E55:E55) -> 507.6 | S12: 960 | T12: 24906.62 | U12: =V$2 -> 0.136376 | V12: 70464.54 | W12: 9609.69 | X12: 448 | Y12: 3581 | Z12: =Y12*3.412 -> 12218
A13: North Club — North Club | B13: 10 | C13: 16 | D13: 8000 | E13: Yaham | F13: Yaham Corona C2.5-MIP Indoor | G13: 3.9mm | H13: 10 | I13: 16 | J13: 782 | K13: 1250 | L13: 2 | M13: =H13*I13*L13 -> 320 | N13: 7500 | O13: Front | P13: 244.16 | Q13: 78130.08 | R13: =SUM('Bundle Equipment'!E61:E61) -> 12642 | S13: 3200 | T13: 93972.08 | U13: =V$2 -> 0.131963 | V13: 177412.13 | W13: 23411.82 | X13: 1494 | Y13: 11935 | Z13: =Y13*3.412 -> 40722
A14: Panthers Den — Panthers Den | B14: 22 | C14: 3 | D14: 8000 | E14: Yaham | F14: Yaham Corona C2.5-MIP Indoor | G14: 3.9mm | H14: 22 | I14: 3 | J14: 1719 | K14: 234 | L14: 3 | M14: =H14*I14*L14 -> 198 | N14: 7500 | O14: Front | P14: 244.16 | Q14: 48342.99 | R14: =SUM('Bundle Equipment'!E66:E66) -> 568.8 | S14: 1980 | T14: 50891.79 | U14: =V$2 -> 0.132416 | V14: 112600.03 | W14: 14910.01 | X14: 924 | Y14: 7385 | Z14: =Y14*3.412 -> 25198
A15: Panthers Den — Panthers Den | B15: 19 | C15: 3.1667 | D15: 8000 | E15: LG | F15: LG GSQA 3.9mm Indoor | G15: 3.9mm | H15: 19 | I15: 3.1667 | J15: 1485 | K15: 247 | L15: 1 | M15: =H15*I15*L15 -> 60.17 | N15: 7500 | O15: Front | P15: 244.16 | Q15: 14690.9 | R15: =SUM('Bundle Equipment'!E71:E71) -> 486.1 | S15: 601.7 | T15: 15778.7 | U15: =V$2 -> 0.139165 | V15: 55535.56 | W15: 7728.63 | X15: 254 | Y15: 2730 | Z15: =Y15*3.412 -> 9315
A16: Panthers Den — Panthers Den | B16: 22 | C16: 3 | D16: 8000 | E16: LG | F16: LG GSQA 3.9mm Indoor | G16: 3.9mm | H16: 22 | I16: 3 | J16: 1719 | K16: 234 | L16: 1 | M16: =H16*I16*L16 -> 66 | N16: 7500 | O16: Front | P16: 244.16 | Q16: 16114.33 | R16: =SUM('Bundle Equipment'!E76:E76) -> 489.6 | S16: 660 | T16: 17263.93 | U16: =V$2 -> 0.138612 | V16: 57955.49 | W16: 8033.33 | X16: 278 | Y16: 2994 | Z16: =Y16*3.412 -> 10216
A17: Panthers Den — Panthers Den | B17: 19 | C17: 3.1667 | D17: 8000 | E17: LG | F17: LG GSQA 3.9mm Indoor | G17: 3.9mm | H17: 19 | I17: 3.1667 | J17: 1485 | K17: 247 | L17: 1 | M17: =H17*I17*L17 -> 60.17 | N17: 7500 | O17: Front | P17: 244.16 | Q17: 14690.9 | R17: =SUM('Bundle Equipment'!E81:E81) -> 486.1 | S17: 601.7 | T17: 15778.7 | U17: =V$2 -> 0.139165 | V17: 55535.56 | W17: 7728.63 | X17: 254 | Y17: 2730 | Z17: =Y17*3.412 -> 9315
A18: South Club — South Club | B18: 10 | C18: 16 | D18: 8000 | E18: Yaham | F18: Yaham Corona C2.5-MIP Indoor | G18: 3.9mm | H18: 10 | I18: 16 | J18: 782 | K18: 1250 | L18: 2 | M18: =H18*I18*L18 -> 320 | N18: 7500 | O18: Front | P18: 244.16 | Q18: 78130.08 | R18: =SUM('Bundle Equipment'!E87:E87) -> 12642 | S18: 3200 | T18: 93972.08 | U18: =V$2 -> 0.131963 | V18: 177412.13 | W18: 23411.82 | X18: 1494 | Y18: 11935 | Z18: =Y18*3.412 -> 40722
A19: S.E Corridor — S.E Corridor | B19: 10 | C19: 34 | D19: 8000 | E19: LG | F19: LG GSQA 3.9mm Indoor | G19: 3.9mm | H19: 10 | I19: 34 | J19: 782 | K19: 2657 | L19: 1 | M19: =H19*I19*L19 -> 340 | N19: 7500 | O19: Front | P19: 244.16 | Q19: 83013.21 | R19: =SUM('Bundle Equipment'!E93:E93) -> 12654 | S19: 3400 | T19: 99067.21 | U19: =V$2 -> 0.131689 | V19: 185682.88 | W19: 24452.43 | X19: 1434 | Y19: 15424 | Z19: =Y19*3.412 -> 52627
A20: N.E Corridor — N.E Corridor | B20: 10 | C20: 34 | D20: 8000 | E20: LG | F20: LG GSQA 3.9mm Indoor | G20: 3.9mm | H20: 10 | I20: 34 | J20: 782 | K20: 2657 | L20: 1 | M20: =H20*I20*L20 -> 340 | N20: 7500 | O20: Front | P20: 244.16 | Q20: 83013.21 | R20: =SUM('Bundle Equipment'!E99:E99) -> 12654 | S20: 3400 | T20: 99067.21 | U20: =V$2 -> 0.131689 | V20: 185682.88 | W20: 24452.43 | X20: 1434 | Y20: 15424 | Z20: =Y20*3.412 -> 52627
A21: Panthers Den — Panthers Den | B21: 22 | C21: 3 | D21: 8000 | E21: LG | F21: LG GSQA 3.9mm Indoor | G21: 3.9mm | H21: 22 | I21: 3 | J21: 1719 | K21: 234 | L21: 1 | M21: =H21*I21*L21 -> 66 | N21: 7500 | O21: Front | P21: 244.16 | Q21: 16114.33 | R21: =SUM('Bundle Equipment'!E104:E104) -> 489.6 | S21: 660 | T21: 17263.93 | U21: =V$2 -> 0.138612 | V21: 57955.49 | W21: 8033.33 | X21: 278 | Y21: 2994 | Z21: =Y21*3.412 -> 10216
A22: Panthers Den — Panthers Den | B22: 8 | C22: 29 | D22: 8000 | E22: LG | F22: LG GSQA 3.9mm Indoor | G22: 3.9mm | H22: 8 | I22: 29 | J22: 625 | K22: 2266 | L22: 1 | M22: =H22*I22*L22 -> 232 | N22: 7500 | O22: Front | P22: 244.16 | Q22: 56644.31 | R22: =SUM('Bundle Equipment'!E109:E109) -> 589.2 | S22: 2320 | T22: 59553.51 | U22: =V$2 -> 0.131697 | V22: 126754.99 | W22: 16693.25 | X22: 979 | Y22: 10525 | Z22: =Y22*3.412 -> 35911
A23: Panthers Den — Panthers Den | B23: 4.0833 | C23: 37.25 | D23: 8000 | E23: LG | F23: LG GSQA 3.9mm Indoor | G23: 3.9mm | H23: 4.0833 | I23: 37.25 | J23: 319 | K23: 2911 | L23: 1 | M23: =H23*I23*L23 -> 152.1 | N23: 7500 | O23: Front | P23: 244.16 | Q23: 37136.2 | R23: =SUM('Bundle Equipment'!E114:E114) -> 541.26 | S23: 1521 | T23: 39198.46 | U23: =V$2 -> 0.13376 | V23: 93659.65 | W23: 12527.95 | X23: 642 | Y23: 6900 | Z23: =Y23*3.412 -> 23543
A24: Elev Lobby — Elev Lobby | B24: 4 | C24: 6 | D24: 8000 | E24: LG | F24: LG GSQA 3.9mm Indoor | G24: 3.9mm | H24: 4 | I24: 6 | J24: 313 | K24: 469 | L24: 1 | M24: =H24*I24*L24 -> 24 | N24: 7500 | O24: Front | P24: 244.16 | Q24: 5859.76 | R24: =SUM('Bundle Equipment'!E119:E119) -> 464.4 | S24: 500 | T24: 6824.16 | U24: =V$2 -> 0.137682 | V24: 40591.05 | W24: 5588.66 | X24: 101 | Y24: 1089 | Z24: =Y24*3.412 -> 3716
A25: Elev Lobby — Elev Lobby | B25: 4 | C25: 6 | D25: 8000 | E25: LG | F25: LG GSQA 3.9mm Indoor | G25: 3.9mm | H25: 4 | I25: 6 | J25: 313 | K25: 469 | L25: 1 | M25: =H25*I25*L25 -> 24 | N25: 7500 | O25: Front | P25: 244.16 | Q25: 5859.76 | R25: =SUM('Bundle Equipment'!E124:E124) -> 464.4 | S25: 500 | T25: 6824.16 | U25: =V$2 -> 0.137682 | V25: 40591.05 | W25: 5588.66 | X25: 101 | Y25: 1089 | Z25: =Y25*3.412 -> 3716
A26: Elev Lobby — Elev Lobby | B26: 4 | C26: 6 | D26: 8000 | E26: LG | F26: LG GSQA 3.9mm Indoor | G26: 3.9mm | H26: 4 | I26: 6 | J26: 313 | K26: 469 | L26: 1 | M26: =H26*I26*L26 -> 24 | N26: 7500 | O26: Front | P26: 244.16 | Q26: 5859.76 | R26: =SUM('Bundle Equipment'!E129:E129) -> 464.4 | S26: 500 | T26: 6824.16 | U26: =V$2 -> 0.137682 | V26: 40591.05 | W26: 5588.66 | X26: 101 | Y26: 1089 | Z26: =Y26*3.412 -> 3716
A27: North Club — North Club | B27: 10 | C27: 16 | D27: 8000 | E27: LG | F27: LG GSQA 3.9mm Indoor | G27: 3.9mm | H27: 10 | I27: 16 | J27: 782 | K27: 1250 | L27: 1 | M27: =H27*I27*L27 -> 160 | N27: 7500 | O27: Front | P27: 244.16 | Q27: 39065.04 | R27: =SUM('Bundle Equipment'!E134:E134) -> 546 | S27: 1600 | T27: 41211.04 | U27: =V$2 -> 0.133499 | V27: 96963.84 | W27: 12944.57 | X27: 675 | Y27: 7258 | Z27: =Y27*3.412 -> 24764
A28: South Club — South Club | B28: 10 | C28: 16 | D28: 8000 | E28: LG | F28: LG GSQA 3.9mm Indoor | G28: 3.9mm | H28: 10 | I28: 16 | J28: 782 | K28: 1250 | L28: 1 | M28: =H28*I28*L28 -> 160 | N28: 7500 | O28: Front | P28: 244.16 | Q28: 39065.04 | R28: =SUM('Bundle Equipment'!E139:E139) -> 546 | S28: 1600 | T28: 41211.04 | U28: =V$2 -> 0.133499 | V28: 96963.84 | W28: 12944.57 | X28: 675 | Y28: 7258 | Z28: =Y28*3.412 -> 24764
A30: TOTAL (25 displays) | M30: =M4+M5+M6+M7+M8+M9+M10+M11+M12+M13+M14+M15+M16+M17+M18+M19+M20+M21+M22+M23+M24+M25+M26+M27+M28 -> 6742.33 | Q30: =Q4+Q5+Q6+Q7+Q8+Q9+Q10+Q11+Q12+Q13+Q14+Q15+Q16+Q17+Q18+Q19+Q20+Q21+Q22+Q23+Q24+Q25+Q26+Q27+Q28 -> 1646183.7 | R30: =R4+R5+R6+R7+R8+R9+R10+R11+R12+R13+R14+R15+R16+R17+R18+R19+R20+R21+R22+R23+R24+R25+R26+R27+R28 -> 139195.39 | S30: =S4+S5+S6+S7+S8+S9+S10+S11+S12+S13+S14+S15+S16+S17+S18+S19+S20+S21+S22+S23+S24+S25+S26+S27+S28 -> 68203.3 | T30: =T4+T5+T6+T7+T8+T9+T10+T11+T12+T13+T14+T15+T16+T17+T18+T19+T20+T21+T22+T23+T24+T25+T26+T27+T28 -> 1853582.4 | U30: =IFERROR(1-T30/V30,0) -> 0.15 | V30: =V4+V5+V6+V7+V8+V9+V10+V11+V12+V13+V14+V15+V16+V17+V18+V19+V20+V21+V22+V23+V24+V25+V26+V27+V28 -> 2180685.2 | W30: =W4+W5+W6+W7+W8+W9+W10+W11+W12+W13+W14+W15+W16+W17+W18+W19+W20+W21+W22+W23+W24+W25+W26+W27+W28 -> 327102.8 | X30: =X4+X5+X6+X7+X8+X9+X10+X11+X12+X13+X14+X15+X16+X17+X18+X19+X20+X21+X22+X23+X24+X25+X26+X27+X28 -> 36675 | Y30: =Y4+Y5+Y6+Y7+Y8+Y9+Y10+Y11+Y12+Y13+Y14+Y15+Y16+Y17+Y18+Y19+Y20+Y21+Y22+Y23+Y24+Y25+Y26+Y27+Y28 -> 693005 | Z30: =Z4+Z5+Z6+Z7+Z8+Z9+Z10+Z11+Z12+Z13+Z14+Z15+Z16+Z17+Z18+Z19+Z20+Z21+Z22+Z23+Z24+Z25+Z26+Z27+Z28 -> 2364533

Sheet Tech Specs (Installers)
A1: Bank of America Stadium Modernization — LED Technical Specifications (No Pricing)
A2: Technical specifications only — no pricing data. Safe for installer/subcontractor distribution.
A4: Display Name | B4: Qty | C4: Pixel Pitch | D4: Height (ft) | E4: Width (ft) | F4: Pixels H | G4: Pixels W | H4: Sq Ft | I4: Brightness (nits) | J4: Service | K4: Environment | L4: Weight (lbs) | M4: Total Power (W) | N4: Fiber Strands | O4: BTU/hr
A5: ='LED Cost Sheet'!A4 -> Team Room — Team Room | B5: ='LED Cost Sheet'!I4 -> 1 | C5: ='LED Cost Sheet'!D4 -> 3.9mm | D5: ='LED Cost Sheet'!E4 -> 8 | E5: ='LED Cost Sheet'!F4 -> 14 | F5: ='LED Cost Sheet'!G4 -> 625 | G5: ='LED Cost Sheet'!H4 -> 1094 | H5: =D5*E5*B5 -> 112 | I5: ='LED Cost Sheet'!K4 -> 8000 | J5: ='LED Cost Sheet'!L4 -> Front | K5: indoor | L5: ='LED Cost Sheet'!U4 -> 523 | M5: ='LED Cost Sheet'!V4 -> 4177 | N5: =IFERROR((F5*G5*B5)/400000,0) -> 1.71 | O5: ='LED Cost Sheet'!W4 -> 14252
A6: ='LED Cost Sheet'!A5 -> Incident Command — Incident Command | B6: ='LED Cost Sheet'!I5 -> 1 | C6: ='LED Cost Sheet'!D5 -> 3.9mm | D6: ='LED Cost Sheet'!E5 -> 5.3333 | E6: ='LED Cost Sheet'!F5 -> 22.6667 | F6: ='LED Cost Sheet'!G5 -> 417 | G6: ='LED Cost Sheet'!H5 -> 1771 | H6: =D6*E6*B6 -> 120.89 | I6: ='LED Cost Sheet'!K5 -> 8000 | J6: ='LED Cost Sheet'!L5 -> Front | K6: indoor | L6: ='LED Cost Sheet'!U5 -> 564 | M6: ='LED Cost Sheet'!V5 -> 4509 | N6: =IFERROR((F6*G6*B6)/400000,0) -> 1.85 | O6: ='LED Cost Sheet'!W5 -> 15385
A7: ='LED Cost Sheet'!A6 -> Def. Unit — Def. Unit | B7: ='LED Cost Sheet'!I6 -> 1 | C7: ='LED Cost Sheet'!D6 -> 3.9mm | D7: ='LED Cost Sheet'!E6 -> 8 | E7: ='LED Cost Sheet'!F6 -> 14 | F7: ='LED Cost Sheet'!G6 -> 625 | G7: ='LED Cost Sheet'!H6 -> 1094 | H7: =D7*E7*B7 -> 112 | I7: ='LED Cost Sheet'!K6 -> 8000 | J7: ='LED Cost Sheet'!L6 -> Front | K7: indoor | L7: ='LED Cost Sheet'!U6 -> 523 | M7: ='LED Cost Sheet'!V6 -> 4177 | N7: =IFERROR((F7*G7*B7)/400000,0) -> 1.71 | O7: ='LED Cost Sheet'!W6 -> 14252
A8: ='LED Cost Sheet'!A7 -> North Corridor — North Corridor | B8: ='LED Cost Sheet'!I7 -> 1 | C8: ='LED Cost Sheet'!D7 -> 3.9mm | D8: ='LED Cost Sheet'!E7 -> 11 | E8: ='LED Cost Sheet'!F7 -> 100 | F8: ='LED Cost Sheet'!G7 -> 860 | G8: ='LED Cost Sheet'!H7 -> 7815 | H8: =D8*E8*B8 -> 1100 | I8: ='LED Cost Sheet'!K7 -> 8000 | J8: ='LED Cost Sheet'!L7 -> Front | K8: indoor | L8: ='LED Cost Sheet'!U7 -> 5135 | M8: ='LED Cost Sheet'!V7 -> 41028 | N8: =IFERROR((F8*G8*B8)/400000,0) -> 16.8 | O8: ='LED Cost Sheet'!W7 -> 139988
A9: ='LED Cost Sheet'!A8 -> South Corridor — South Corridor | B9: ='LED Cost Sheet'!I8 -> 1 | C9: ='LED Cost Sheet'!D8 -> 3.9mm | D9: ='LED Cost Sheet'!E8 -> 11 | E9: ='LED Cost Sheet'!F8 -> 85 | F9: ='LED Cost Sheet'!G8 -> 860 | G9: ='LED Cost Sheet'!H8 -> 6643 | H9: =D9*E9*B9 -> 935 | I9: ='LED Cost Sheet'!K8 -> 8000 | J9: ='LED Cost Sheet'!L8 -> Front | K9: indoor | L9: ='LED Cost Sheet'!U8 -> 4364 | M9: ='LED Cost Sheet'!V8 -> 34874 | N9: =IFERROR((F9*G9*B9)/400000,0) -> 14.28 | O9: ='LED Cost Sheet'!W8 -> 118990
A10: ='LED Cost Sheet'!A9 -> S.E Corridor — S.E Corridor | B10: ='LED Cost Sheet'!I9 -> 2 | C10: ='LED Cost Sheet'!D9 -> 3.9mm | D10: ='LED Cost Sheet'!E9 -> 10 | E10: ='LED Cost Sheet'!F9 -> 34 | F10: ='LED Cost Sheet'!G9 -> 782 | G10: ='LED Cost Sheet'!H9 -> 2657 | H10: =D10*E10*B10 -> 680 | I10: ='LED Cost Sheet'!K9 -> 8000 | J10: ='LED Cost Sheet'!L9 -> Front | K10: indoor | L10: ='LED Cost Sheet'!U9 -> 3174 | M10: ='LED Cost Sheet'!V9 -> 25363 | N10: =IFERROR((F10*G10*B10)/400000,0) -> 10.39 | O10: ='LED Cost Sheet'!W9 -> 86539
A11: ='LED Cost Sheet'!A10 -> East Corridor — East Corridor | B11: ='LED Cost Sheet'!I10 -> 1 | C11: ='LED Cost Sheet'!D10 -> 3.9mm | D11: ='LED Cost Sheet'!E10 -> 10 | E11: ='LED Cost Sheet'!F10 -> 36 | F11: ='LED Cost Sheet'!G10 -> 782 | G11: ='LED Cost Sheet'!H10 -> 2814 | H11: =D11*E11*B11 -> 360 | I11: ='LED Cost Sheet'!K10 -> 8000 | J11: ='LED Cost Sheet'!L10 -> Front | K11: indoor | L11: ='LED Cost Sheet'!U10 -> 1680 | M11: ='LED Cost Sheet'!V10 -> 13427 | N11: =IFERROR((F11*G11*B11)/400000,0) -> 5.5 | O11: ='LED Cost Sheet'!W10 -> 45813
A12: ='LED Cost Sheet'!A11 -> N.E Corridor — N.E Corridor | B12: ='LED Cost Sheet'!I11 -> 2 | C12: ='LED Cost Sheet'!D11 -> 3.9mm | D12: ='LED Cost Sheet'!E11 -> 10 | E12: ='LED Cost Sheet'!F11 -> 34 | F12: ='LED Cost Sheet'!G11 -> 782 | G12: ='LED Cost Sheet'!H11 -> 2657 | H12: =D12*E12*B12 -> 680 | I12: ='LED Cost Sheet'!K11 -> 8000 | J12: ='LED Cost Sheet'!L11 -> Front | K12: indoor | L12: ='LED Cost Sheet'!U11 -> 3174 | M12: ='LED Cost Sheet'!V11 -> 25363 | N12: =IFERROR((F12*G12*B12)/400000,0) -> 10.39 | O12: ='LED Cost Sheet'!W11 -> 86539
A13: ='LED Cost Sheet'!A12 -> Elev Lobby — Elev Lobby | B13: ='LED Cost Sheet'!I12 -> 4 | C13: ='LED Cost Sheet'!D12 -> 3.9mm | D13: ='LED Cost Sheet'!E12 -> 4 | E13: ='LED Cost Sheet'!F12 -> 6 | F13: ='LED Cost Sheet'!G12 -> 313 | G13: ='LED Cost Sheet'!H12 -> 469 | H13: =D13*E13*B13 -> 96 | I13: ='LED Cost Sheet'!K12 -> 8000 | J13: ='LED Cost Sheet'!L12 -> Front | K13: indoor | L13: ='LED Cost Sheet'!U12 -> 448 | M13: ='LED Cost Sheet'!V12 -> 3581 | N13: =IFERROR((F13*G13*B13)/400000,0) -> 1.47 | O13: ='LED Cost Sheet'!W12 -> 12218
A14: ='LED Cost Sheet'!A13 -> North Club — North Club | B14: ='LED Cost Sheet'!I13 -> 2 | C14: ='LED Cost Sheet'!D13 -> 3.9mm | D14: ='LED Cost Sheet'!E13 -> 10 | E14: ='LED Cost Sheet'!F13 -> 16 | F14: ='LED Cost Sheet'!G13 -> 782 | G14: ='LED Cost Sheet'!H13 -> 1250 | H14: =D14*E14*B14 -> 320 | I14: ='LED Cost Sheet'!K13 -> 8000 | J14: ='LED Cost Sheet'!L13 -> Front | K14: indoor | L14: ='LED Cost Sheet'!U13 -> 1494 | M14: ='LED Cost Sheet'!V13 -> 11935 | N14: =IFERROR((F14*G14*B14)/400000,0) -> 4.89 | O14: ='LED Cost Sheet'!W13 -> 40722
A15: ='LED Cost Sheet'!A14 -> Panthers Den — Panthers Den | B15: ='LED Cost Sheet'!I14 -> 3 | C15: ='LED Cost Sheet'!D14 -> 3.9mm | D15: ='LED Cost Sheet'!E14 -> 22 | E15: ='LED Cost Sheet'!F14 -> 3 | F15: ='LED Cost Sheet'!G14 -> 1719 | G15: ='LED Cost Sheet'!H14 -> 234 | H15: =D15*E15*B15 -> 198 | I15: ='LED Cost Sheet'!K14 -> 8000 | J15: ='LED Cost Sheet'!L14 -> Front | K15: indoor | L15: ='LED Cost Sheet'!U14 -> 924 | M15: ='LED Cost Sheet'!V14 -> 7385 | N15: =IFERROR((F15*G15*B15)/400000,0) -> 3.02 | O15: ='LED Cost Sheet'!W14 -> 25198
A16: ='LED Cost Sheet'!A15 -> Panthers Den — Panthers Den | B16: ='LED Cost Sheet'!I15 -> 1 | C16: ='LED Cost Sheet'!D15 -> 3.9mm | D16: ='LED Cost Sheet'!E15 -> 19 | E16: ='LED Cost Sheet'!F15 -> 3.1667 | F16: ='LED Cost Sheet'!G15 -> 1485 | G16: ='LED Cost Sheet'!H15 -> 247 | H16: =D16*E16*B16 -> 60.17 | I16: ='LED Cost Sheet'!K15 -> 8000 | J16: ='LED Cost Sheet'!L15 -> Front | K16: indoor | L16: ='LED Cost Sheet'!U15 -> 254 | M16: ='LED Cost Sheet'!V15 -> 2730 | N16: =IFERROR((F16*G16*B16)/400000,0) -> 0.92 | O16: ='LED Cost Sheet'!W15 -> 9315
... A29: ='LED Cost Sheet'!A28 -> South Club — South Club | B29: ='LED Cost Sheet'!I28 -> 1 | C29: ='LED Cost Sheet'!D28 -> 3.9mm | D29: ='LED Cost Sheet'!E28 -> 10 | E29: ='LED Cost Sheet'!F28 -> 16 | F29: ='LED Cost Sheet'!G28 -> 782 | G29: ='LED Cost Sheet'!H28 -> 1250 | H29: =D29*E29*B29 -> 160 | I29: ='LED Cost Sheet'!K28 -> 8000 | J29: ='LED Cost Sheet'!L28 -> Front | K29: indoor | L29: ='LED Cost Sheet'!U28 -> 675 | M29: ='LED Cost Sheet'!V28 -> 7258 | N29: =IFERROR((F29*G29*B29)/400000,0) -> 2.44 | O29: ='LED Cost Sheet'!W28 -> 24764

Sheet Team Room - Install
A3: Project Name: Bank of America Stadium Modernization
A4: 2026-03-31
A5: Revised By: ANC Proposal Engine
C7: Linked Margin Assignment
C8: Install Margin | D8: 0.15
C9: Electrical Margin | D9: 0.15
C10: ANC Margin | D10: 0.15
C11: Engineering and Permits | D11: 0.15
B15: Team Room
B16: Height | C16: Width | D16: Total Sq. Ft | E16: QTY
B17: 8 | C17: 14 | D17: 112 | E17: 1
B19: Structural Materials: | C19: Subcontractor 1 | D19: Subcontractor 2 | E19: Subcontractor 3 | F19: Selected | G19: Additional Contingency | I19: Total Cost | J19: Install Margin | K19: Selling Price
B20: FABRICATE PRIMARY STEEL | C20: 0 | D20: 0 | E20: 0 | F20: 0 | G20: 0 | I20: =SUM(C20:G20) -> 0 | J20: =$D$8 -> 0.15 | K20: =I20/(1-J20) -> 0
B21: SUPPLY AND INSTALL PRIMARY PLYWOOD | C21: 0 | D21: 0 | E21: 0 | F21: 0 | G21: 0 | I21: =SUM(C21:G21) -> 0 | J21: =$D$8 -> 0.15 | K21: =I21/(1-J21) -> 0
B22: FABRICATE SECONDARY STEEL SUBSTRUCTURE | C22: 1290 | D22: 0 | E22: 0 | F22: 0 | G22: 0 | I22: =SUM(C22:G22) -> 1290 | J22: =$D$8 -> 0.15 | K22: =I22/(1-J22) -> 1517.65
B23: FABRICATE CLADDING AND TRIM | C23: 0 | D23: 0 | E23: 0 | F23: 0 | G23: 0 | I23: =SUM(C23:G23) -> 0 | J23: =$D$8 -> 0.15 | K23: =I23/(1-J23) -> 0
B24: OTHER SCOPE ITEM | C24: 0 | D24: 0 | E24: 0 | F24: 0 | G24: 0 | I24: =SUM(C24:G24) -> 0 | J24: =$D$8 -> 0.15 | K24: =I24/(1-J24) -> 0
B25: OTHER SCOPE ITEM | C25: 0 | D25: 0 | E25: 0 | F25: 0 | G25: 0 | I25: =SUM(C25:G25) -> 0 | J25: =$D$8 -> 0.15 | K25: =I25/(1-J25) -> 0
B26: SUBTOTAL | I26: =SUM(I20:I25) -> 1290 | K26: =SUM(K20:K25) -> 1517.65
B28: Structural Labor and LED Installation | C28: Subcontractor 1 | D28: Subcontractor 2 | E28: Subcontractor 3 | F28: Selected | G28: Additional Contingency | I28: Total Cost | J28: Install Margin | K28: Selling Price
B29: REMOVAL AND DISPOSAL | C29: 0 | D29: 0 | E29: 0 | F29: 0 | G29: 0 | I29: =SUM(C29:G29) -> 0 | J29: =$D$8 -> 0.15 | K29: =I29/(1-J29) -> 0
B30: INSTALL SECONDARY STEEL SUBSTRUCTURE | C30: 0 | D30: 0 | E30: 0 | F30: 0 | G30: 0 | I30: =SUM(C30:G30) -> 0 | J30: =$D$8 -> 0.15 | K30: =I30/(1-J30) -> 0
B31: INSTALL LED DISPLAYS | C31: 5375 | D31: 0 | E31: 0 | F31: 0 | G31: 0 | I31: =SUM(C31:G31) -> 5375 | J31: =$D$8 -> 0.15 | K31: =I31/(1-J31) -> 6323.53
B32: INSTALL CLADDING AND TRIM | C32: 0 | D32: 0 | E32: 0 | F32: 0 | G32: 0 | I32: =SUM(C32:G32) -> 0 | J32: =$D$8 -> 0.15 | K32: =I32/(1-J32) -> 0
B33: HEAVY EQUIPMENT | C33: 0 | D33: 0 | E33: 0 | F33: 0 | G33: 0 | I33: =SUM(C33:G33) -> 0 | J33: =$D$8 -> 0.15 | K33: =I33/(1-J33) -> 0
B34: PM/GENERAL CONDITIONS/TRAVEL | C34: 20882.35 | D34: 0 | E34: 0 | F34: 0 | G34: 0 | I34: =SUM(C34:G34) -> 20882.35 | J34: =$D$8 -> 0.15 | K34: =I34/(1-J34) -> 24567.47
B35: SUBTOTAL | I35: =SUM(I29:I34) -> 26257.35 | K35: =SUM(K29:K34) -> 30891
B37: Electrical and Data - Materials and Subcontracting | C37: Subcontractor 1 | D37: Subcontractor 2 | E37: Subcontractor 3 | F37: Selected | G37: Additional Contingency | I37: Total Cost | J37: Install Margin | K37: Selling Price
B38: ELECTRICAL MATERIALS | C38: 5375 | D38: 0 | E38: 0 | F38: 0 | G38: 0 | I38: =SUM(C38:G38) -> 5375 | J38: =$D$9 -> 0.15 | K38: =I38/(1-J38) -> 6323.53
B39: DATA MATERIALS | C39: 0 | D39: 0 | E39: 0 | F39: 0 | G39: 0 | I39: =SUM(C39:G39) -> 0 | J39: =$D$9 -> 0.15 | K39: =I39/(1-J39) -> 0
B40: ELECTRICAL LABOR | C40: 0 | D40: 0 | E40: 0 | F40: 0 | G40: 0 | I40: =SUM(C40:G40) -> 0 | J40: =$D$9 -> 0.15 | K40: =I40/(1-J40) -> 0
B41: DATA LABOR | C41: 0 | D41: 0 | E41: 0 | F41: 0 | G41: 0 | I41: =SUM(C41:G41) -> 0 | J41: =$D$9 -> 0.15 | K41: =I41/(1-J41) -> 0
B42: SUB PANEL | C42: 0 | D42: 0 | E42: 0 | F42: 0 | G42: 0 | I42: =SUM(C42:G42) -> 0 | J42: =$D$9 -> 0.15 | K42: =I42/(1-J42) -> 0
B43: MISC | C43: 0 | D43: 0 | E43: 0 | F43: 0 | G43: 0 | I43: =SUM(C43:G43) -> 0 | J43: =$D$9 -> 0.15 | K43: =I43/(1-J43) -> 0
B44: SUBTOTAL | I44: =SUM(I38:I43) -> 5375 | K44: =SUM(K38:K43) -> 6323.53
B46: Submittals, Engineering, and Permits | C46: Subcontractor 1 | D46: Subcontractor 2 | E46: Subcontractor 3 | F46: Selected | G46: Additional Contingency | I46: Total Cost | J46: Install Margin | K46: Selling Price
B47: STRUCTURAL ENGINEERING | C47: 4705.88 | D47: 0 | E47: 0 | F47: 0 | G47: 0 | I47: =SUM(C47:G47) -> 4705.88 | J47: =$D$11 -> 0.15 | K47: =I47/(1-J47) -> 5536.33
B48: STRUCTURAL CERTIFICATION | C48: 0 | D48: 0 | E48: 0 | F48: 0 | G48: 0 | I48: =SUM(C48:G48) -> 0 | J48: =$D$11 -> 0.15 | K48: =I48/(1-J48) -> 0
B49: ELECTRICAL ENGINEERING | C49: 0 | D49: 0 | E49: 0 | F49: 0 | G49: 0 | I49: =SUM(C49:G49) -> 0 | J49: =$D$11 -> 0.15 | K49: =I49/(1-J49) -> 0
B50: ELECTRICAL CERTIFICATION | C50: 0 | D50: 0 | E50: 0 | F50: 0 | G50: 0 | I50: =SUM(C50:G50) -> 0 | J50: =$D$11 -> 0.15 | K50: =I50/(1-J50) -> 0
...

Sheet Incident Command - Install
A3: Project Name: Bank of America Stadium Modernization
A4: 2026-03-31
A5: Revised By: ANC Proposal Engine
C7: Linked Margin Assignment
C8: Install Margin | D8: 0.15
C9: Electrical Margin | D9: 0.15
C10: ANC Margin | D10: 0.15
C11: Engineering and Permits | D11: 0.15
B15: Incident Command
B16: Height | C16: Width | D16: Total Sq. Ft | E16: QTY
B17: 5.3333 | C17: 22.6667 | D17: 120.89 | E17: 1
B19: Structural Materials: | C19: Subcontractor 1 | D19: Subcontractor 2 | E19: Subcontractor 3 | F19: Selected | G19: Additional Contingency | I19: Total Cost | J19: Install Margin | K19: Selling Price
B20: FABRICATE PRIMARY STEEL | C20: 0 | D20: 0 | E20: 0 | F20: 0 | G20: 0 | I20: =SUM(C20:G20) -> 0 | J20: =$D$8 -> 0.15 | K20: =I20/(1-J20) -> 0
B21: SUPPLY AND INSTALL PRIMARY PLYWOOD | C21: 0 | D21: 0 | E21: 0 | F21: 0 | G21: 0 | I21: =SUM(C21:G21) -> 0 | J21: =$D$8 -> 0.15 | K21: =I21/(1-J21) -> 0
B22: FABRICATE SECONDARY STEEL SUBSTRUCTURE | C22: 1391.25 | D22: 0 | E22: 0 | F22: 0 | G22: 0 | I22: =SUM(C22:G22) -> 1391.25 | J22: =$D$8 -> 0.15 | K22: =I22/(1-J22) -> 1636.76
B23: FABRICATE CLADDING AND TRIM | C23: 0 | D23: 0 | E23: 0 | F23: 0 | G23: 0 | I23: =SUM(C23:G23) -> 0 | J23: =$D$8 -> 0.15 | K23: =I23/(1-J23) -> 0
B24: OTHER SCOPE ITEM | C24: 0 | D24: 0 | E24: 0 | F24: 0 | G24: 0 | I24: =SUM(C24:G24) -> 0 | J24: =$D$8 -> 0.15 | K24: =I24/(1-J24) -> 0
B25: OTHER SCOPE ITEM | C25: 0 | D25: 0 | E25: 0 | F25: 0 | G25: 0 | I25: =SUM(C25:G25) -> 0 | J25: =$D$8 -> 0.15 | K25: =I25/(1-J25) -> 0
B26: SUBTOTAL | I26: =SUM(I20:I25) -> 1391.25 | K26: =SUM(K20:K25) -> 1636.76
B28: Structural Labor and LED Installation | C28: Subcontractor 1 | D28: Subcontractor 2 | E28: Subcontractor 3 | F28: Selected | G28: Additional Contingency | I28: Total Cost | J28: Install Margin | K28: Selling Price
B29: REMOVAL AND DISPOSAL | C29: 0 | D29: 0 | E29: 0 | F29: 0 | G29: 0 | I29: =SUM(C29:G29) -> 0 | J29: =$D$8 -> 0.15 | K29: =I29/(1-J29) -> 0
B30: INSTALL SECONDARY STEEL SUBSTRUCTURE | C30: 0 | D30: 0 | E30: 0 | F30: 0 | G30: 0 | I30: =SUM(C30:G30) -> 0 | J30: =$D$8 -> 0.15 | K30: =I30/(1-J30) -> 0
B31: INSTALL LED DISPLAYS | C31: 5796.88 | D31: 0 | E31: 0 | F31: 0 | G31: 0 | I31: =SUM(C31:G31) -> 5796.88 | J31: =$D$8 -> 0.15 | K31: =I31/(1-J31) -> 6819.86
B32: INSTALL CLADDING AND TRIM | C32: 0 | D32: 0 | E32: 0 | F32: 0 | G32: 0 | I32: =SUM(C32:G32) -> 0 | J32: =$D$8 -> 0.15 | K32: =I32/(1-J32) -> 0
B33: HEAVY EQUIPMENT | C33: 0 | D33: 0 | E33: 0 | F33: 0 | G33: 0 | I33: =SUM(C33:G33) -> 0 | J33: =$D$8 -> 0.15 | K33: =I33/(1-J33) -> 0
B34: PM/GENERAL CONDITIONS/TRAVEL | C34: 20882.35 | D34: 0 | E34: 0 | F34: 0 | G34: 0 | I34: =SUM(C34:G34) -> 20882.35 | J34: =$D$8 -> 0.15 | K34: =I34/(1-J34) -> 24567.47
B35: SUBTOTAL | I35: =SUM(I29:I34) -> 26679.23 | K35: =SUM(K29:K34) -> 31387.33
B37: Electrical and Data - Materials and Subcontracting | C37: Subcontractor 1 | D37: Subcontractor 2 | E37: Subcontractor 3 | F37: Selected | G37: Additional Contingency | I37: Total Cost | J37: Install Margin | K37: Selling Price
B38: ELECTRICAL MATERIALS | C38: 5796.88 | D38: 0 | E38: 0 | F38: 0 | G38: 0 | I38: =SUM(C38:G38) -> 5796.88 | J38: =$D$9 -> 0.15 | K38: =I38/(1-J38) -> 6819.86
B39: DATA MATERIALS | C39: 0 | D39: 0 | E39: 0 | F39: 0 | G39: 0 | I39: =SUM(C39:G39) -> 0 | J39: =$D$9 -> 0.15 | K39: =I39/(1-J39) -> 0
B40: ELECTRICAL LABOR | C40: 0 | D40: 0 | E40: 0 | F40: 0 | G40: 0 | I40: =SUM(C40:G40) -> 0 | J40: =$D$9 -> 0.15 | K40: =I40/(1-J40) -> 0
B41: DATA LABOR | C41: 0 | D41: 0 | E41: 0 | F41: 0 | G41: 0 | I41: =SUM(C41:G41) -> 0 | J41: =$D$9 -> 0.15 | K41: =I41/(1-J41) -> 0
B42: SUB PANEL | C42: 0 | D42: 0 | E42: 0 | F42: 0 | G42: 0 | I42: =SUM(C42:G42) -> 0 | J42: =$D$9 -> 0.15 | K42: =I42/(1-J42) -> 0
B43: MISC | C43: 0 | D43: 0 | E43: 0 | F43: 0 | G43: 0 | I43: =SUM(C43:G43) -> 0 | J43: =$D$9 -> 0.15 | K43: =I43/(1-J43) -> 0
B44: SUBTOTAL | I44: =SUM(I38:I43) -> 5796.88 | K44: =SUM(K38:K43) -> 6819.86
B46: Submittals, Engineering, and Permits | C46: Subcontractor 1 | D46: Subcontractor 2 | E46: Subcontractor 3 | F46: Selected | G46: Additional Contingency | I46: Total Cost | J46: Install Margin | K46: Selling Price
B47: STRUCTURAL ENGINEERING | C47: 4705.88 | D47: 0 | E47: 0 | F47: 0 | G47: 0 | I47: =SUM(C47:G47) -> 4705.88 | J47: =$D$11 -> 0.15 | K47: =I47/(1-J47) -> 5536.33
B48: STRUCTURAL CERTIFICATION | C48: 0 | D48: 0 | E48: 0 | F48: 0 | G48: 0 | I48: =SUM(C48:G48) -> 0 | J48: =$D$11 -> 0.15 | K48: =I48/(1-J48) -> 0
B49: ELECTRICAL ENGINEERING | C49: 0 | D49: 0 | E49: 0 | F49: 0 | G49: 0 | I49: =SUM(C49:G49) -> 0 | J49: =$D$11 -> 0.15 | K49: =I49/(1-J49) -> 0
B50: ELECTRICAL CERTIFICATION | C50: 0 | D50: 0 | E50: 0 | F50: 0 | G50: 0 | I50: =SUM(C50:G50) -> 0 | J50: =$D$11 -> 0.15 | K50: =I50/(1-J50) -> 0
...

Sheet Def. Unit - Install
A3: Project Name: Bank of America Stadium Modernization
A4: 2026-03-31
A5: Revised By: ANC Proposal Engine
C7: Linked Margin Assignment
C8: Install Margin | D8: 0.15
C9: Electrical Margin | D9: 0.15
C10: ANC Margin | D10: 0.15
C11: Engineering and Permits | D11: 0.15
B15: Def. Unit
B16: Height | C16: Width | D16: Total Sq. Ft | E16: QTY
B17: 8 | C17: 14 | D17: 112 | E17: 1
B19: Structural Materials: | C19: Subcontractor 1 | D19: Subcontractor 2 | E19: Subcontractor 3 | F19: Selected | G19: Additional Contingency | I19: Total Cost | J19: Install Margin | K19: Selling Price
B20: FABRICATE PRIMARY STEEL | C20: 0 | D20: 0 | E20: 0 | F20: 0 | G20: 0 | I20: =SUM(C20:G20) -> 0 | J20: =$D$8 -> 0.15 | K20: =I20/(1-J20) -> 0
B21: SUPPLY AND INSTALL PRIMARY PLYWOOD | C21: 0 | D21: 0 | E21: 0 | F21: 0 | G21: 0 | I21: =SUM(C21:G21) -> 0 | J21: =$D$8 -> 0.15 | K21: =I21/(1-J21) -> 0
B22: FABRICATE SECONDARY STEEL SUBSTRUCTURE | C22: 1290 | D22: 0 | E22: 0 | F22: 0 | G22: 0 | I22: =SUM(C22:G22) -> 1290 | J22: =$D$8 -> 0.15 | K22: =I22/(1-J22) -> 1517.65
B23: FABRICATE CLADDING AND TRIM | C23: 0 | D23: 0 | E23: 0 | F23: 0 | G23: 0 | I23: =SUM(C23:G23) -> 0 | J23: =$D$8 -> 0.15 | K23: =I23/(1-J23) -> 0
B24: OTHER SCOPE ITEM | C24: 0 | D24: 0 | E24: 0 | F24: 0 | G24: 0 | I24: =SUM(C24:G24) -> 0 | J24: =$D$8 -> 0.15 | K24: =I24/(1-J24) -> 0
B25: OTHER SCOPE ITEM | C25: 0 | D25: 0 | E25: 0 | F25: 0 | G25: 0 | I25: =SUM(C25:G25) -> 0 | J25: =$D$8 -> 0.15 | K25: =I25/(1-J25) -> 0
B26: SUBTOTAL | I26: =SUM(I20:I25) -> 1290 | K26: =SUM(K20:K25) -> 1517.65
B28: Structural Labor and LED Installation | C28: Subcontractor 1 | D28: Subcontractor 2 | E28: Subcontractor 3 | F28: Selected | G28: Additional Contingency | I28: Total Cost | J28: Install Margin | K28: Selling Price
B29: REMOVAL AND DISPOSAL | C29: 0 | D29: 0 | E29: 0 | F29: 0 | G29: 0 | I29: =SUM(C29:G29) -> 0 | J29: =$D$8 -> 0.15 | K29: =I29/(1-J29) -> 0
B30: INSTALL SECONDARY STEEL SUBSTRUCTURE | C30: 0 | D30: 0 | E30: 0 | F30: 0 | G30: 0 | I30: =SUM(C30:G30) -> 0 | J30: =$D$8 -> 0.15 | K30: =I30/(1-J30) -> 0
B31: INSTALL LED DISPLAYS | C31: 5375 | D31: 0 | E31: 0 | F31: 0 | G31: 0 | I31: =SUM(C31:G31) -> 5375 | J31: =$D$8 -> 0.15 | K31: =I31/(1-J31) -> 6323.53
B32: INSTALL CLADDING AND TRIM | C32: 0 | D32: 0 | E32: 0 | F32: 0 | G32: 0 | I32: =SUM(C32:G32) -> 0 | J32: =$D$8 -> 0.15 | K32: =I32/(1-J32) -> 0
B33: HEAVY EQUIPMENT | C33: 0 | D33: 0 | E33: 0 | F33: 0 | G33: 0 | I33: =SUM(C33:G33) -> 0 | J33: =$D$8 -> 0.15 | K33: =I33/(1-J33) -> 0
B34: PM/GENERAL CONDITIONS/TRAVEL | C34: 20882.35 | D34: 0 | E34: 0 | F34: 0 | G34: 0 | I34: =SUM(C34:G34) -> 20882.35 | J34: =$D$8 -> 0.15 | K34: =I34/(1-J34) -> 24567.47
B35: SUBTOTAL | I35: =SUM(I29:I34) -> 26257.35 | K35: =SUM(K29:K34) -> 30891
B37: Electrical and Data - Materials and Subcontracting | C37: Subcontractor 1 | D37: Subcontractor 2 | E37: Subcontractor 3 | F37: Selected | G37: Additional Contingency | I37: Total Cost | J37: Install Margin | K37: Selling Price
B38: ELECTRICAL MATERIALS | C38: 5375 | D38: 0 | E38: 0 | F38: 0 | G38: 0 | I38: =SUM(C38:G38) -> 5375 | J38: =$D$9 -> 0.15 | K38: =I38/(1-J38) -> 6323.53
B39: DATA MATERIALS | C39: 0 | D39: 0 | E39: 0 | F39: 0 | G39: 0 | I39: =SUM(C39:G39) -> 0 | J39: =$D$9 -> 0.15 | K39: =I39/(1-J39) -> 0
B40: ELECTRICAL LABOR | C40: 0 | D40: 0 | E40: 0 | F40: 0 | G40: 0 | I40: =SUM(C40:G40) -> 0 | J40: =$D$9 -> 0.15 | K40: =I40/(1-J40) -> 0
B41: DATA LABOR | C41: 0 | D41: 0 | E41: 0 | F41: 0 | G41: 0 | I41: =SUM(C41:G41) -> 0 | J41: =$D$9 -> 0.15 | K41: =I41/(1-J41) -> 0
B42: SUB PANEL | C42: 0 | D42: 0 | E42: 0 | F42: 0 | G42: 0 | I42: =SUM(C42:G42) -> 0 | J42: =$D$9 -> 0.15 | K42: =I42/(1-J42) -> 0
B43: MISC | C43: 0 | D43: 0 | E43: 0 | F43: 0 | G43: 0 | I43: =SUM(C43:G43) -> 0 | J43: =$D$9 -> 0.15 | K43: =I43/(1-J43) -> 0
B44: SUBTOTAL | I44: =SUM(I38:I43) -> 5375 | K44: =SUM(K38:K43) -> 6323.53
B46: Submittals, Engineering, and Permits | C46: Subcontractor 1 | D46: Subcontractor 2 | E46: Subcontractor 3 | F46: Selected | G46: Additional Contingency | I46: Total Cost | J46: Install Margin | K46: Selling Price
B47: STRUCTURAL ENGINEERING | C47: 4705.88 | D47: 0 | E47: 0 | F47: 0 | G47: 0 | I47: =SUM(C47:G47) -> 4705.88 | J47: =$D$11 -> 0.15 | K47: =I47/(1-J47) -> 5536.33
B48: STRUCTURAL CERTIFICATION | C48: 0 | D48: 0 | E48: 0 | F48: 0 | G48: 0 | I48: =SUM(C48:G48) -> 0 | J48: =$D$11 -> 0.15 | K48: =I48/(1-J48) -> 0
B49: ELECTRICAL ENGINEERING | C49: 0 | D49: 0 | E49: 0 | F49: 0 | G49: 0 | I49: =SUM(C49:G49) -> 0 | J49: =$D$11 -> 0.15 | K49: =I49/(1-J49) -> 0
B50: ELECTRICAL CERTIFICATION | C50: 0 | D50: 0 | E50: 0 | F50: 0 | G50: 0 | I50: =SUM(C50:G50) -> 0 | J50: =$D$11 -> 0.15 | K50: =I50/(1-J50) -> 0
...

Sheet North Corridor - Install
A3: Project Name: Bank of America Stadium Modernization
A4: 2026-03-31
A5: Revised By: ANC Proposal Engine
C7: Linked Margin Assignment
C8: Install Margin | D8: 0.15
C9: Electrical Margin | D9: 0.15
C10: ANC Margin | D10: 0.15
C11: Engineering and Permits | D11: 0.15
B15: North Corridor
B16: Height | C16: Width | D16: Total Sq. Ft | E16: QTY
B17: 11 | C17: 100 | D17: 1100 | E17: 1
B19: Structural Materials: | C19: Subcontractor 1 | D19: Subcontractor 2 | E19: Subcontractor 3 | F19: Selected | G19: Additional Contingency | I19: Total Cost | J19: Install Margin | K19: Selling Price
B20: FABRICATE PRIMARY STEEL | C20: 0 | D20: 0 | E20: 0 | F20: 0 | G20: 0 | I20: =SUM(C20:G20) -> 0 | J20: =$D$8 -> 0.15 | K20: =I20/(1-J20) -> 0
B21: SUPPLY AND INSTALL PRIMARY PLYWOOD | C21: 0 | D21: 0 | E21: 0 | F21: 0 | G21: 0 | I21: =SUM(C21:G21) -> 0 | J21: =$D$8 -> 0.15 | K21: =I21/(1-J21) -> 0
B22: FABRICATE SECONDARY STEEL SUBSTRUCTURE | C22: 12678.75 | D22: 0 | E22: 0 | F22: 0 | G22: 0 | I22: =SUM(C22:G22) -> 12678.75 | J22: =$D$8 -> 0.15 | K22: =I22/(1-J22) -> 14916.18
B23: FABRICATE CLADDING AND TRIM | C23: 0 | D23: 0 | E23: 0 | F23: 0 | G23: 0 | I23: =SUM(C23:G23) -> 0 | J23: =$D$8 -> 0.15 | K23: =I23/(1-J23) -> 0
B24: OTHER SCOPE ITEM | C24: 0 | D24: 0 | E24: 0 | F24: 0 | G24: 0 | I24: =SUM(C24:G24) -> 0 | J24: =$D$8 -> 0.15 | K24: =I24/(1-J24) -> 0
B25: OTHER SCOPE ITEM | C25: 0 | D25: 0 | E25: 0 | F25: 0 | G25: 0 | I25: =SUM(C25:G25) -> 0 | J25: =$D$8 -> 0.15 | K25: =I25/(1-J25) -> 0
B26: SUBTOTAL | I26: =SUM(I20:I25) -> 12678.75 | K26: =SUM(K20:K25) -> 14916.18
B28: Structural Labor and LED Installation | C28: Subcontractor 1 | D28: Subcontractor 2 | E28: Subcontractor 3 | F28: Selected | G28: Additional Contingency | I28: Total Cost | J28: Install Margin | K28: Selling Price
B29: REMOVAL AND DISPOSAL | C29: 0 | D29: 0 | E29: 0 | F29: 0 | G29: 0 | I29: =SUM(C29:G29) -> 0 | J29: =$D$8 -> 0.15 | K29: =I29/(1-J29) -> 0
B30: INSTALL SECONDARY STEEL SUBSTRUCTURE | C30: 0 | D30: 0 | E30: 0 | F30: 0 | G30: 0 | I30: =SUM(C30:G30) -> 0 | J30: =$D$8 -> 0.15 | K30: =I30/(1-J30) -> 0
B31: INSTALL LED DISPLAYS | C31: 52828.13 | D31: 0 | E31: 0 | F31: 0 | G31: 0 | I31: =SUM(C31:G31) -> 52828.13 | J31: =$D$8 -> 0.15 | K31: =I31/(1-J31) -> 62150.74
B32: INSTALL CLADDING AND TRIM | C32: 0 | D32: 0 | E32: 0 | F32: 0 | G32: 0 | I32: =SUM(C32:G32) -> 0 | J32: =$D$8 -> 0.15 | K32: =I32/(1-J32) -> 0
B33: HEAVY EQUIPMENT | C33: 0 | D33: 0 | E33: 0 | F33: 0 | G33: 0 | I33: =SUM(C33:G33) -> 0 | J33: =$D$8 -> 0.15 | K33: =I33/(1-J33) -> 0
B34: PM/GENERAL CONDITIONS/TRAVEL | C34: 20882.35 | D34: 0 | E34: 0 | F34: 0 | G34: 0 | I34: =SUM(C34:G34) -> 20882.35 | J34: =$D$8 -> 0.15 | K34: =I34/(1-J34) -> 24567.47
B35: SUBTOTAL | I35: =SUM(I29:I34) -> 73710.48 | K35: =SUM(K29:K34) -> 86718.21
B37: Electrical and Data - Materials and Subcontracting | C37: Subcontractor 1 | D37: Subcontractor 2 | E37: Subcontractor 3 | F37: Selected | G37: Additional Contingency | I37: Total Cost | J37: Install Margin | K37: Selling Price
B38: ELECTRICAL MATERIALS | C38: 52828.13 | D38: 0 | E38: 0 | F38: 0 | G38: 0 | I38: =SUM(C38:G38) -> 52828.13 | J38: =$D$9 -> 0.15 | K38: =I38/(1-J38) -> 62150.74
B39: DATA MATERIALS | C39: 0 | D39: 0 | E39: 0 | F39: 0 | G39: 0 | I39: =SUM(C39:G39) -> 0 | J39: =$D$9 -> 0.15 | K39: =I39/(1-J39) -> 0
B40: ELECTRICAL LABOR | C40: 0 | D40: 0 | E40: 0 | F40: 0 | G40: 0 | I40: =SUM(C40:G40) -> 0 | J40: =$D$9 -> 0.15 | K40: =I40/(1-J40) -> 0
B41: DATA LABOR | C41: 0 | D41: 0 | E41: 0 | F41: 0 | G41: 0 | I41: =SUM(C41:G41) -> 0 | J41: =$D$9 -> 0.15 | K41: =I41/(1-J41) -> 0
B42: SUB PANEL | C42: 0 | D42: 0 | E42: 0 | F42: 0 | G42: 0 | I42: =SUM(C42:G42) -> 0 | J42: =$D$9 -> 0.15 | K42: =I42/(1-J42) -> 0
B43: MISC | C43: 0 | D43: 0 | E43: 0 | F43: 0 | G43: 0 | I43: =SUM(C43:G43) -> 0 | J43: =$D$9 -> 0.15 | K43: =I43/(1-J43) -> 0
B44: SUBTOTAL | I44: =SUM(I38:I43) -> 52828.13 | K44: =SUM(K38:K43) -> 62150.74
B46: Submittals, Engineering, and Permits | C46: Subcontractor 1 | D46: Subcontractor 2 | E46: Subcontractor 3 | F46: Selected | G46: Additional Contingency | I46: Total Cost | J46: Install Margin | K46: Selling Price
B47: STRUCTURAL ENGINEERING | C47: 4705.88 | D47: 0 | E47: 0 | F47: 0 | G47: 0 | I47: =SUM(C47:G47) -> 4705.88 | J47: =$D$11 -> 0.15 | K47: =I47/(1-J47) -> 5536.33
B48: STRUCTURAL CERTIFICATION | C48: 0 | D48: 0 | E48: 0 | F48: 0 | G48: 0 | I48: =SUM(C48:G48) -> 0 | J48: =$D$11 -> 0.15 | K48: =I48/(1-J48) -> 0
B49: ELECTRICAL ENGINEERING | C49: 0 | D49: 0 | E49: 0 | F49: 0 | G49: 0 | I49: =SUM(C49:G49) -> 0 | J49: =$D$11 -> 0.15 | K49: =I49/(1-J49) -> 0
B50: ELECTRICAL CERTIFICATION | C50: 0 | D50: 0 | E50: 0 | F50: 0 | G50: 0 | I50: =SUM(C50:G50) -> 0 | J50: =$D$11 -> 0.15 | K50: =I50/(1-J50) -> 0
...

Sheet South Corridor - Install
A3: Project Name: Bank of America Stadium Modernization
A4: 2026-03-31
A5: Revised By: ANC Proposal Engine
C7: Linked Margin Assignment
C8: Install Margin | D8: 0.15
C9: Electrical Margin | D9: 0.15
C10: ANC Margin | D10: 0.15
C11: Engineering and Permits | D11: 0.15
B15: South Corridor
B16: Height | C16: Width | D16: Total Sq. Ft | E16: QTY
B17: 11 | C17: 85 | D17: 935 | E17: 1
