Workbook

Sheet Project Overview
A1: Large Format LED — Project Overview
A2: Client | 2026-04-01 | ANC Proposal Engine
B4: PROJECT INFORMATION
B5: Client | C5: Client
B6: Project Name | C6: Large Format LED
B7: Location | C7: Large Format LED
B8: Date Created | C8: 2026-04-01
B9: Currency | C9: USD
B10: Environment | C10: Indoor
B11: Union Labor | C11: No
B12: Bond Required | C12: No
B13: Number of Displays | C13: =SUM('LED Cost Sheet'!I4:I50) -> 47
B15: FINANCIAL PARAMETERS
B16: LED Hardware Margin | C16: 0.15
B17: Install / Services Margin | C17: 0.15
B18: Engineering Margin | C18: 0.15
B19: Equipment Margin | C19: 0.15
B20: CMS Margin | C20: 0.15
B21: Bond Rate | C21: N/A
B22: Tax Rate | C22: Per zone (editable on MA)
B23: Tariff Rate | C23: Per zone (editable on MA)
B25: SUMMARY TOTALS
B26: Total Cost | C26: ='Margin Analysis'!C626 -> 15093962
B27: Total Selling Price | C27: ='Margin Analysis'!D626 -> 17365514
B28: Project Margin $ | C28: ='Margin Analysis'!E626 -> 2271551.9
B29: Project Margin % | C29: ='Margin Analysis'!F626 -> 0.13
B30: DOCUMENT TOTAL | C30: ='Margin Analysis'!D626 -> 17365514

Sheet Margin Analysis
A1: Large Format LED — Margin Analysis
A2: Client | 2026-04-01 | ANC Proposal Engine
B4: Zone / Category | C4: Cost | D4: Selling Price | E4: Margin $ | F4: Margin %
B5: FIELD RIBBON NORTH — FIELD RIBBON NORTH | D5: Selling Price
B6: LED Hardware | C6: ='LED Cost Sheet'!T4 -> 279185.75 | D6: ='LED Cost Sheet'!V4 -> 328453.82 | E6: =IFERROR(D6-C6,0) -> 49268.07 | F6: 0.15
B7: Structural Materials | C7: ='FIELD RIBBON NORTH - Install'!I26 -> 17173.33 | D7: =IFERROR(C7/(1-F7),0) -> 20203.92 | E7: =IFERROR(D7-C7,0) -> 3030.59 | F7: 0.15
B8: Structural Labor & LED Installation | C8: ='FIELD RIBBON NORTH - Install'!I35-'FIELD RIBBON NORTH - Install'!I34 -> 46836.36 | D8: =IFERROR(C8/(1-F8),0) -> 55101.6 | E8: =IFERROR(D8-C8,0) -> 8265.24 | F8: 0.15
B9: Electrical & Data | C9: ='FIELD RIBBON NORTH - Install'!I44 -> 39030.3 | D9: =IFERROR(C9/(1-F9),0) -> 45918 | E9: =IFERROR(D9-C9,0) -> 6887.7 | F9: 0.15
B10: PM / General Conditions / Travel | C10: ='FIELD RIBBON NORTH - Install'!I34 -> 20882.35 | D10: =IFERROR(C10/(1-F10),0) -> 24567.47 | E10: =IFERROR(D10-C10,0) -> 3685.12 | F10: 0.15
B11: Engineering & Permits | C11: ='FIELD RIBBON NORTH - Install'!I52 -> 4705.88 | D11: =IFERROR(C11/(1-F11),0) -> 5536.33 | E11: =IFERROR(D11-C11,0) -> 830.45 | F11: 0.15
B12: SUBTOTAL | C12: =SUM(C6:C11) -> 407813.97 | D12: =SUM(D6:D11) -> 468487.02 | E12: =IFERROR(D12-C12,0) -> 60673.05 | F12: =IFERROR(1-C12/D12,0) -> 0.129508
B13: TAX | C13: 0 | D13: 0 | E13: 0 | G13: 0
B14: BOND | C14: 0 | D14: 0 | E14: 0 | G14: 0
B15: TARIFF | C15: 0 | D15: 0 | E15: 0 | G15: 0
B16: GRAND TOTAL | C16: =C12+C13+C14+C15 -> 407813.97 | D16: =D12+D13+D14+D15 -> 468487.02 | E16: =IFERROR(D16-C16,0) -> 60673.05 | F16: =IFERROR(1-C16/D16,0) -> 0.1295085
B18: FIELD RIBBON EAST — FIELD RIBBON EAST | D18: Selling Price
B19: LED Hardware | C19: ='LED Cost Sheet'!T5 -> 175128.6 | D19: ='LED Cost Sheet'!V5 -> 206033.65 | E19: =IFERROR(D19-C19,0) -> 30905.05 | F19: 0.15
B20: Structural Materials | C20: ='FIELD RIBBON EAST - Install'!I26 -> 10733.33 | D20: =IFERROR(C20/(1-F20),0) -> 12627.45 | E20: =IFERROR(D20-C20,0) -> 1894.12 | F20: 0.15
B21: Structural Labor & LED Installation | C21: ='FIELD RIBBON EAST - Install'!I35-'FIELD RIBBON EAST - Install'!I34 -> 29272.73 | D21: =IFERROR(C21/(1-F21),0) -> 34438.51 | E21: =IFERROR(D21-C21,0) -> 5165.78 | F21: 0.15
B22: Electrical & Data | C22: ='FIELD RIBBON EAST - Install'!I44 -> 24393.94 | D22: =IFERROR(C22/(1-F22),0) -> 28698.75 | E22: =IFERROR(D22-C22,0) -> 4304.81 | F22: 0.15
B23: PM / General Conditions / Travel | C23: ='FIELD RIBBON EAST - Install'!I34 -> 20882.35 | D23: =IFERROR(C23/(1-F23),0) -> 24567.47 | E23: =IFERROR(D23-C23,0) -> 3685.12 | F23: 0.15
B24: Engineering & Permits | C24: ='FIELD RIBBON EAST - Install'!I52 -> 4705.88 | D24: =IFERROR(C24/(1-F24),0) -> 5536.33 | E24: =IFERROR(D24-C24,0) -> 830.45 | F24: 0.15
B25: SUBTOTAL | C25: =SUM(C19:C24) -> 265116.83 | D25: =SUM(D19:D24) -> 304843.33 | E25: =IFERROR(D25-C25,0) -> 39726.5 | F25: =IFERROR(1-C25/D25,0) -> 0.130318
B26: TAX | C26: 0 | D26: 0 | E26: 0 | G26: 0
B27: BOND | C27: 0 | D27: 0 | E27: 0 | G27: 0
B28: TARIFF | C28: 0 | D28: 0 | E28: 0 | G28: 0
B29: GRAND TOTAL | C29: =C25+C26+C27+C28 -> 265116.83 | D29: =D25+D26+D27+D28 -> 304843.33 | E29: =IFERROR(D29-C29,0) -> 39726.5 | F29: =IFERROR(1-C29/D29,0) -> 0.13031776
B31: TEAM ROOM — TEAM ROOM | D31: Selling Price
B32: LED Hardware | C32: ='LED Cost Sheet'!T6 -> 30350.01 | D32: ='LED Cost Sheet'!V6 -> 35705.89 | E32: =IFERROR(D32-C32,0) -> 5355.88 | F32: 0.15
B33: Structural Materials | C33: ='TEAM ROOM - Install'!I26 -> 1290 | D33: =IFERROR(C33/(1-F33),0) -> 1517.65 | E33: =IFERROR(D33-C33,0) -> 227.65 | F33: 0.15
B34: Structural Labor & LED Installation | C34: ='TEAM ROOM - Install'!I35-'TEAM ROOM - Install'!I34 -> 5375 | D34: =IFERROR(C34/(1-F34),0) -> 6323.53 | E34: =IFERROR(D34-C34,0) -> 948.53 | F34: 0.15
B35: Electrical & Data | C35: ='TEAM ROOM - Install'!I44 -> 5375 | D35: =IFERROR(C35/(1-F35),0) -> 6323.53 | E35: =IFERROR(D35-C35,0) -> 948.53 | F35: 0.15
B36: PM / General Conditions / Travel | C36: ='TEAM ROOM - Install'!I34 -> 20882.35 | D36: =IFERROR(C36/(1-F36),0) -> 24567.47 | E36: =IFERROR(D36-C36,0) -> 3685.12 | F36: 0.15
B37: Engineering & Permits | C37: ='TEAM ROOM - Install'!I52 -> 4705.88 | D37: =IFERROR(C37/(1-F37),0) -> 5536.33 | E37: =IFERROR(D37-C37,0) -> 830.45 | F37: 0.15
B38: SUBTOTAL | C38: =SUM(C32:C37) -> 67978.24 | D38: =SUM(D32:D37) -> 78656.76 | E38: =IFERROR(D38-C38,0) -> 10678.52 | F38: =IFERROR(1-C38/D38,0) -> 0.135761
B39: TAX | C39: 0 | D39: 0 | E39: 0 | G39: 0
B40: BOND | C40: 0 | D40: 0 | E40: 0 | G40: 0
B41: TARIFF | C41: 0 | D41: 0 | E41: 0 | G41: 0
B42: GRAND TOTAL | C42: =C38+C39+C40+C41 -> 67978.24 | D42: =D38+D39+D40+D41 -> 78656.76 | E42: =IFERROR(D42-C42,0) -> 10678.52 | F42: =IFERROR(1-C42/D42,0) -> 0.13576099
B44: FIELD RIBBON WEST — FIELD RIBBON WEST | D44: Selling Price
...

Sheet Budget Summary
A1: Large Format LED — Budget Summary
A2: Client | 2026-04-01 | By Category
B4: Category | C4: Cost | D4: Selling Price | E4: Margin $ | F4: Margin % | G4: Price / SqFt
B5: LED Hardware (all displays) | C5: =SUM('LED Cost Sheet'!Q4:Q50) -> 6135419.9 | D5: =SUM('LED Cost Sheet'!S4:S50) -> 7218141 | E5: =IFERROR(D5-C5,0) -> 1082721.1 | F5: 0.15 | G5: =IFERROR(C5/33186.380000000005,0) -> 184.88
B6: Structural Materials | C6: =SUM('FIELD RIBBON NORTH - Install'!I26:I26)+SUM('FIELD RIBBON EAST - Install'!I26:I26)+SUM('TEAM ROOM - Install'!I26:I26)+SUM('FIELD RIBBON WEST - Install'!I26:I26)+SUM('INCIDENT COMMAND - Install'!I26:I26)+SUM('DEF UNIT - Install'!I26:I26)+SUM('NORTH CORRIDOR - Install'!I26:I26)+SUM('SOUTH CORRIDOR - Install'!I26:I26)+SUM('S.E. CORRIDOR (CEILING) - Insta'!I26:I26)+SUM('S.E. CORRIDOR (CEILING10 - Inst'!I26:I26)+SUM('EAST CORRIDOR (CEILING) - Insta'!I26:I26)+SUM('N.E. CORRIDOR (CEILING) - Insta'!I26:I26)+SUM('N.E. CORRIDOR (CEILING13 - Inst'!I26:I26)+SUM('LARGE ADMIN ROOM - Install'!I26:I26)+SUM('ELEV LOBBY - Install'!I26:I26)+SUM('NORTH CLUB - Install'!I26:I26)+SUM('PANTHERS DEN - Install'!I26:I26)+SUM('PANTHERS DEN18 - Install'!I26:I26)+SUM('PANTHERS DEN19 - Install'!I26:I26)+SUM('PANTHERS DEN20 - Install'!I26:I26)+SUM('PANTHERS DEN21 - Install'!I26:I26)+SUM('PANTHERS DEN22 - Install'!I26:I26)+SUM('PANTHERS DEN23 - Install'!I26:I26)+SUM('SOUTH CLUB - Install'!I26:I26)+SUM('ELEV LOBBY25 - Install'!I26:I26)+SUM('SOUTH CLUB26 - Install'!I26:I26)+SUM('ELEV LOBBY27 - Install'!I26:I26)+SUM('ELEV LOBBY28 - Install'!I26:I26)+SUM('NORTH CLUB29 - Install'!I26:I26)+SUM('RIBBON NW - Install'!I26:I26)+SUM('RIBBON NW31 - Install'!I26:I26)+SUM('RIBBON NW32 - Install'!I26:I26)+SUM('RIBBON NW33 - Install'!I26:I26)+SUM('RIBBON SW - Install'!I26:I26)+SUM('RIBBON SW35 - Install'!I26:I26)+SUM('RIBBON SW36 - Install'!I26:I26)+SUM('SCOREBOARD EAST - Install'!I26:I26)+SUM('SCOREBOARD WEST - Install'!I26:I26)+SUM('EAST ENTRY A - Install'!I26:I26)+SUM('EAST ENTRY B - Install'!I26:I26)+SUM('EAST ENTRY C - Install'!I26:I26)+SUM('EAST ENTRY D - Install'!I26:I26)+SUM('NORTH EAST EXTERIOR NE - Instal'!I26:I26)+SUM('NORTH ENTRY C - Install'!I26:I26)+SUM('NORTH ENTRY C45 - Install'!I26:I26)+SUM('NORTH ENTRY C46 - Install'!I26:I26)+SUM('SOUTH EAST EXTERIOR SE - Instal'!I26:I26) -> 798964.87 | D6: =SUM('FIELD RIBBON NORTH - Install'!K26:K26)+SUM('FIELD RIBBON EAST - Install'!K26:K26)+SUM('TEAM ROOM - Install'!K26:K26)+SUM('FIELD RIBBON WEST - Install'!K26:K26)+SUM('INCIDENT COMMAND - Install'!K26:K26)+SUM('DEF UNIT - Install'!K26:K26)+SUM('NORTH CORRIDOR - Install'!K26:K26)+SUM('SOUTH CORRIDOR - Install'!K26:K26)+SUM('S.E. CORRIDOR (CEILING) - Insta'!K26:K26)+SUM('S.E. CORRIDOR (CEILING10 - Inst'!K26:K26)+SUM('EAST CORRIDOR (CEILING) - Insta'!K26:K26)+SUM('N.E. CORRIDOR (CEILING) - Insta'!K26:K26)+SUM('N.E. CORRIDOR (CEILING13 - Inst'!K26:K26)+SUM('LARGE ADMIN ROOM - Install'!K26:K26)+SUM('ELEV LOBBY - Install'!K26:K26)+SUM('NORTH CLUB - Install'!K26:K26)+SUM('PANTHERS DEN - Install'!K26:K26)+SUM('PANTHERS DEN18 - Install'!K26:K26)+SUM('PANTHERS DEN19 - Install'!K26:K26)+SUM('PANTHERS DEN20 - Install'!K26:K26)+SUM('PANTHERS DEN21 - Install'!K26:K26)+SUM('PANTHERS DEN22 - Install'!K26:K26)+SUM('PANTHERS DEN23 - Install'!K26:K26)+SUM('SOUTH CLUB - Install'!K26:K26)+SUM('ELEV LOBBY25 - Install'!K26:K26)+SUM('SOUTH CLUB26 - Install'!K26:K26)+SUM('ELEV LOBBY27 - Install'!K26:K26)+SUM('ELEV LOBBY28 - Install'!K26:K26)+SUM('NORTH CLUB29 - Install'!K26:K26)+SUM('RIBBON NW - Install'!K26:K26)+SUM('RIBBON NW31 - Install'!K26:K26)+SUM('RIBBON NW32 - Install'!K26:K26)+SUM('RIBBON NW33 - Install'!K26:K26)+SUM('RIBBON SW - Install'!K26:K26)+SUM('RIBBON SW35 - Install'!K26:K26)+SUM('RIBBON SW36 - Install'!K26:K26)+SUM('SCOREBOARD EAST - Install'!K26:K26)+SUM('SCOREBOARD WEST - Install'!K26:K26)+SUM('EAST ENTRY A - Install'!K26:K26)+SUM('EAST ENTRY B - Install'!K26:K26)+SUM('EAST ENTRY C - Install'!K26:K26)+SUM('EAST ENTRY D - Install'!K26:K26)+SUM('NORTH EAST EXTERIOR NE - Instal'!K26:K26)+SUM('NORTH ENTRY C - Install'!K26:K26)+SUM('NORTH ENTRY C45 - Install'!K26:K26)+SUM('NORTH ENTRY C46 - Install'!K26:K26)+SUM('SOUTH EAST EXTERIOR SE - Instal'!K26:K26) -> 939958.67 | E6: =IFERROR(D6-C6,0) -> 140993.8 | F6: 0.15 | G6: =IFERROR(C6/33186.380000000005,0) -> 24.08
B7: Structural Labor & LED Installation | C7: =(SUM('FIELD RIBBON NORTH - Install'!I35:I35)-SUM('FIELD RIBBON NORTH - Install'!I34:I34))+(SUM('FIELD RIBBON EAST - Install'!I35:I35)-SUM('FIELD RIBBON EAST - Install'!I34:I34))+(SUM('TEAM ROOM - Install'!I35:I35)-SUM('TEAM ROOM - Install'!I34:I34))+(SUM('FIELD RIBBON WEST - Install'!I35:I35)-SUM('FIELD RIBBON WEST - Install'!I34:I34))+(SUM('INCIDENT COMMAND - Install'!I35:I35)-SUM('INCIDENT COMMAND - Install'!I34:I34))+(SUM('DEF UNIT - Install'!I35:I35)-SUM('DEF UNIT - Install'!I34:I34))+(SUM('NORTH CORRIDOR - Install'!I35:I35)-SUM('NORTH CORRIDOR - Install'!I34:I34))+(SUM('SOUTH CORRIDOR - Install'!I35:I35)-SUM('SOUTH CORRIDOR - Install'!I34:I34))+(SUM('S.E. CORRIDOR (CEILING) - Insta'!I35:I35)-SUM('S.E. CORRIDOR (CEILING) - Insta'!I34:I34))+(SUM('S.E. CORRIDOR (CEILING10 - Inst'!I35:I35)-SUM('S.E. CORRIDOR (CEILING10 - Inst'!I34:I34))+(SUM('EAST CORRIDOR (CEILING) - Insta'!I35:I35)-SUM('EAST CORRIDOR (CEILING) - Insta'!I34:I34))+(SUM('N.E. CORRIDOR (CEILING) - Insta'!I35:I35)-SUM('N.E. CORRIDOR (CEILING) - Insta'!I34:I34))+(SUM('N.E. CORRIDOR (CEILING13 - Inst'!I35:I35)-SUM('N.E. CORRIDOR (CEILING13 - Inst'!I34:I34))+(SUM('LARGE ADMIN ROOM - Install'!I35:I35)-SUM('LARGE ADMIN ROOM - Install'!I34:I34))+(SUM('ELEV LOBBY - Install'!I35:I35)-SUM('ELEV LOBBY - Install'!I34:I34))+(SUM('NORTH CLUB - Install'!I35:I35)-SUM('NORTH CLUB - Install'!I34:I34))+(SUM('PANTHERS DEN - Install'!I35:I35)-SUM('PANTHERS DEN - Install'!I34:I34))+(SUM('PANTHERS DEN18 - Install'!I35:I35)-SUM('PANTHERS DEN18 - Install'!I34:I34))+(SUM('PANTHERS DEN19 - Install'!I35:I35)-SUM('PANTHERS DEN19 - Install'!I34:I34))+(SUM('PANTHERS DEN20 - Install'!I35:I35)-SUM('PANTHERS DEN20 - Install'!I34:I34))+(SUM('PANTHERS DEN21 - Install'!I35:I35)-SUM('PANTHERS DEN21 - Install'!I34:I34))+(SUM('PANTHERS DEN22 - Install'!I35:I35)-SUM('PANTHERS DEN22 - Install'!I34:I34))+(SUM('PANTHERS DEN23 - Install'!I35:I35)-SUM('PANTHERS DEN23 - Install'!I34:I34))+(SUM('SOUTH CLUB - Install'!I35:I35)-SUM('SOUTH CLUB - Install'!I34:I34))+(SUM('ELEV LOBBY25 - Install'!I35:I35)-SUM('ELEV LOBBY25 - Install'!I34:I34))+(SUM('SOUTH CLUB26 - Install'!I35:I35)-SUM('SOUTH CLUB26 - Install'!I34:I34))+(SUM('ELEV LOBBY27 - Install'!I35:I35)-SUM('ELEV LOBBY27 - Install'!I34:I34))+(SUM('ELEV LOBBY28 - Install'!I35:I35)-SUM('ELEV LOBBY28 - Install'!I34:I34))+(SUM('NORTH CLUB29 - Install'!I35:I35)-SUM('NORTH CLUB29 - Install'!I34:I34))+(SUM('RIBBON NW - Install'!I35:I35)-SUM('RIBBON NW - Install'!I34:I34))+(SUM('RIBBON NW31 - Install'!I35:I35)-SUM('RIBBON NW31 - Install'!I34:I34))+(SUM('RIBBON NW32 - Install'!I35:I35)-SUM('RIBBON NW32 - Install'!I34:I34))+(SUM('RIBBON NW33 - Install'!I35:I35)-SUM('RIBBON NW33 - Install'!I34:I34))+(SUM('RIBBON SW - Install'!I35:I35)-SUM('RIBBON SW - Install'!I34:I34))+(SUM('RIBBON SW35 - Install'!I35:I35)-SUM('RIBBON SW35 - Install'!I34:I34))+(SUM('RIBBON SW36 - Install'!I35:I35)-SUM('RIBBON SW36 - Install'!I34:I34))+(SUM('SCOREBOARD EAST - Install'!I35:I35)-SUM('SCOREBOARD EAST - Install'!I34:I34))+(SUM('SCOREBOARD WEST - Install'!I35:I35)-SUM('SCOREBOARD WEST - Install'!I34:I34))+(SUM('EAST ENTRY A - Install'!I35:I35)-SUM('EAST ENTRY A - Install'!I34:I34))+(SUM('EAST ENTRY B - Install'!I35:I35)-SUM('EAST ENTRY B - Install'!I34:I34))+(SUM('EAST ENTRY C - Install'!I35:I35)-SUM('EAST ENTRY C - Install'!I34:I34))+(SUM('EAST ENTRY D - Install'!I35:I35)-SUM('EAST ENTRY D - Install'!I34:I34))+(SUM('NORTH EAST EXTERIOR NE - Instal'!I35:I35)-SUM('NORTH EAST EXTERIOR NE - Instal'!I34:I34))+(SUM('NORTH ENTRY C - Install'!I35:I35)-SUM('NORTH ENTRY C - Install'!I34:I34))+(SUM('NORTH ENTRY C45 - Install'!I35:I35)-SUM('NORTH ENTRY C45 - Install'!I34:I34))+(SUM('NORTH ENTRY C46 - Install'!I35:I35)-SUM('NORTH ENTRY C46 - Install'!I34:I34))+(SUM('SOUTH EAST EXTERIOR SE - Instal'!I35:I35)-SUM('SOUTH EAST EXTERIOR SE - Instal'!I34:I34)) -> 5001136.4 | D7: =(SUM('FIELD RIBBON NORTH - Install'!K35:K35)-SUM('FIELD RIBBON NORTH - Install'!K34:K34))+(SUM('FIELD RIBBON EAST - Install'!K35:K35)-SUM('FIELD RIBBON EAST - Install'!K34:K34))+(SUM('TEAM ROOM - Install'!K35:K35)-SUM('TEAM ROOM - Install'!K34:K34))+(SUM('FIELD RIBBON WEST - Install'!K35:K35)-SUM('FIELD RIBBON WEST - Install'!K34:K34))+(SUM('INCIDENT COMMAND - Install'!K35:K35)-SUM('INCIDENT COMMAND - Install'!K34:K34))+(SUM('DEF UNIT - Install'!K35:K35)-SUM('DEF UNIT - Install'!K34:K34))+(SUM('NORTH CORRIDOR - Install'!K35:K35)-SUM('NORTH CORRIDOR - Install'!K34:K34))+(SUM('SOUTH CORRIDOR - Install'!K35:K35)-SUM('SOUTH CORRIDOR - Install'!K34:K34))+(SUM('S.E. CORRIDOR (CEILING) - Insta'!K35:K35)-SUM('S.E. CORRIDOR (CEILING) - Insta'!K34:K34))+(SUM('S.E. CORRIDOR (CEILING10 - Inst'!K35:K35)-SUM('S.E. CORRIDOR (CEILING10 - Inst'!K34:K34))+(SUM('EAST CORRIDOR (CEILING) - Insta'!K35:K35)-SUM('EAST CORRIDOR (CEILING) - Insta'!K34:K34))+(SUM('N.E. CORRIDOR (CEILING) - Insta'!K35:K35)-SUM('N.E. CORRIDOR (CEILING) - Insta'!K34:K34))+(SUM('N.E. CORRIDOR (CEILING13 - Inst'!K35:K35)-SUM('N.E. CORRIDOR (CEILING13 - Inst'!K34:K34))+(SUM('LARGE ADMIN ROOM - Install'!K35:K35)-SUM('LARGE ADMIN ROOM - Install'!K34:K34))+(SUM('ELEV LOBBY - Install'!K35:K35)-SUM('ELEV LOBBY - Install'!K34:K34))+(SUM('NORTH CLUB - Install'!K35:K35)-SUM('NORTH CLUB - Install'!K34:K34))+(SUM('PANTHERS DEN - Install'!K35:K35)-SUM('PANTHERS DEN - Install'!K34:K34))+(SUM('PANTHERS DEN18 - Install'!K35:K35)-SUM('PANTHERS DEN18 - Install'!K34:K34))+(SUM('PANTHERS DEN19 - Install'!K35:K35)-SUM('PANTHERS DEN19 - Install'!K34:K34))+(SUM('PANTHERS DEN20 - Install'!K35:K35)-SUM('PANTHERS DEN20 - Install'!K34:K34))+(SUM('PANTHERS DEN21 - Install'!K35:K35)-SUM('PANTHERS DEN21 - Install'!K34:K34))+(SUM('PANTHERS DEN22 - Install'!K35:K35)-SUM('PANTHERS DEN22 - Install'!K34:K34))+(SUM('PANTHERS DEN23 - Install'!K35:K35)-SUM('PANTHERS DEN23 - Install'!K34:K34))+(SUM('SOUTH CLUB - Install'!K35:K35)-SUM('SOUTH CLUB - Install'!K34:K34))+(SUM('ELEV LOBBY25 - Install'!K35:K35)-SUM('ELEV LOBBY25 - Install'!K34:K34))+(SUM('SOUTH CLUB26 - Install'!K35:K35)-SUM('SOUTH CLUB26 - Install'!K34:K34))+(SUM('ELEV LOBBY27 - Install'!K35:K35)-SUM('ELEV LOBBY27 - Install'!K34:K34))+(SUM('ELEV LOBBY28 - Install'!K35:K35)-SUM('ELEV LOBBY28 - Install'!K34:K34))+(SUM('NORTH CLUB29 - Install'!K35:K35)-SUM('NORTH CLUB29 - Install'!K34:K34))+(SUM('RIBBON NW - Install'!K35:K35)-SUM('RIBBON NW - Install'!K34:K34))+(SUM('RIBBON NW31 - Install'!K35:K35)-SUM('RIBBON NW31 - Install'!K34:K34))+(SUM('RIBBON NW32 - Install'!K35:K35)-SUM('RIBBON NW32 - Install'!K34:K34))+(SUM('RIBBON NW33 - Install'!K35:K35)-SUM('RIBBON NW33 - Install'!K34:K34))+(SUM('RIBBON SW - Install'!K35:K35)-SUM('RIBBON SW - Install'!K34:K34))+(SUM('RIBBON SW35 - Install'!K35:K35)-SUM('RIBBON SW35 - Install'!K34:K34))+(SUM('RIBBON SW36 - Install'!K35:K35)-SUM('RIBBON SW36 - Install'!K34:K34))+(SUM('SCOREBOARD EAST - Install'!K35:K35)-SUM('SCOREBOARD EAST - Install'!K34:K34))+(SUM('SCOREBOARD WEST - Install'!K35:K35)-SUM('SCOREBOARD WEST - Install'!K34:K34))+(SUM('EAST ENTRY A - Install'!K35:K35)-SUM('EAST ENTRY A - Install'!K34:K34))+(SUM('EAST ENTRY B - Install'!K35:K35)-SUM('EAST ENTRY B - Install'!K34:K34))+(SUM('EAST ENTRY C - Install'!K35:K35)-SUM('EAST ENTRY C - Install'!K34:K34))+(SUM('EAST ENTRY D - Install'!K35:K35)-SUM('EAST ENTRY D - Install'!K34:K34))+(SUM('NORTH EAST EXTERIOR NE - Instal'!K35:K35)-SUM('NORTH EAST EXTERIOR NE - Instal'!K34:K34))+(SUM('NORTH ENTRY C - Install'!K35:K35)-SUM('NORTH ENTRY C - Install'!K34:K34))+(SUM('NORTH ENTRY C45 - Install'!K35:K35)-SUM('NORTH ENTRY C45 - Install'!K34:K34))+(SUM('NORTH ENTRY C46 - Install'!K35:K35)-SUM('NORTH ENTRY C46 - Install'!K34:K34))+(SUM('SOUTH EAST EXTERIOR SE - Instal'!K35:K35)-SUM('SOUTH EAST EXTERIOR SE - Instal'!K34:K34)) -> 5883689.9 | E7: =IFERROR(D7-C7,0) -> 882553.48 | F7: 0.15 | G7: =IFERROR(C7/33186.380000000005,0) -> 150.7
B8: Electrical & Data | C8: =SUM('FIELD RIBBON NORTH - Install'!I44:I44)+SUM('FIELD RIBBON EAST - Install'!I44:I44)+SUM('TEAM ROOM - Install'!I44:I44)+SUM('FIELD RIBBON WEST - Install'!I44:I44)+SUM('INCIDENT COMMAND - Install'!I44:I44)+SUM('DEF UNIT - Install'!I44:I44)+SUM('NORTH CORRIDOR - Install'!I44:I44)+SUM('SOUTH CORRIDOR - Install'!I44:I44)+SUM('S.E. CORRIDOR (CEILING) - Insta'!I44:I44)+SUM('S.E. CORRIDOR (CEILING10 - Inst'!I44:I44)+SUM('EAST CORRIDOR (CEILING) - Insta'!I44:I44)+SUM('N.E. CORRIDOR (CEILING) - Insta'!I44:I44)+SUM('N.E. CORRIDOR (CEILING13 - Inst'!I44:I44)+SUM('LARGE ADMIN ROOM - Install'!I44:I44)+SUM('ELEV LOBBY - Install'!I44:I44)+SUM('NORTH CLUB - Install'!I44:I44)+SUM('PANTHERS DEN - Install'!I44:I44)+SUM('PANTHERS DEN18 - Install'!I44:I44)+SUM('PANTHERS DEN19 - Install'!I44:I44)+SUM('PANTHERS DEN20 - Install'!I44:I44)+SUM('PANTHERS DEN21 - Install'!I44:I44)+SUM('PANTHERS DEN22 - Install'!I44:I44)+SUM('PANTHERS DEN23 - Install'!I44:I44)+SUM('SOUTH CLUB - Install'!I44:I44)+SUM('ELEV LOBBY25 - Install'!I44:I44)+SUM('SOUTH CLUB26 - Install'!I44:I44)+SUM('ELEV LOBBY27 - Install'!I44:I44)+SUM('ELEV LOBBY28 - Install'!I44:I44)+SUM('NORTH CLUB29 - Install'!I44:I44)+SUM('RIBBON NW - Install'!I44:I44)+SUM('RIBBON NW31 - Install'!I44:I44)+SUM('RIBBON NW32 - Install'!I44:I44)+SUM('RIBBON NW33 - Install'!I44:I44)+SUM('RIBBON SW - Install'!I44:I44)+SUM('RIBBON SW35 - Install'!I44:I44)+SUM('RIBBON SW36 - Install'!I44:I44)+SUM('SCOREBOARD EAST - Install'!I44:I44)+SUM('SCOREBOARD WEST - Install'!I44:I44)+SUM('EAST ENTRY A - Install'!I44:I44)+SUM('EAST ENTRY B - Install'!I44:I44)+SUM('EAST ENTRY C - Install'!I44:I44)+SUM('EAST ENTRY D - Install'!I44:I44)+SUM('NORTH EAST EXTERIOR NE - Instal'!I44:I44)+SUM('NORTH ENTRY C - Install'!I44:I44)+SUM('NORTH ENTRY C45 - Install'!I44:I44)+SUM('NORTH ENTRY C46 - Install'!I44:I44)+SUM('SOUTH EAST EXTERIOR SE - Instal'!I44:I44) -> 1955793.8 | D8: =SUM('FIELD RIBBON NORTH - Install'!K44:K44)+SUM('FIELD RIBBON EAST - Install'!K44:K44)+SUM('TEAM ROOM - Install'!K44:K44)+SUM('FIELD RIBBON WEST - Install'!K44:K44)+SUM('INCIDENT COMMAND - Install'!K44:K44)+SUM('DEF UNIT - Install'!K44:K44)+SUM('NORTH CORRIDOR - Install'!K44:K44)+SUM('SOUTH CORRIDOR - Install'!K44:K44)+SUM('S.E. CORRIDOR (CEILING) - Insta'!K44:K44)+SUM('S.E. CORRIDOR (CEILING10 - Inst'!K44:K44)+SUM('EAST CORRIDOR (CEILING) - Insta'!K44:K44)+SUM('N.E. CORRIDOR (CEILING) - Insta'!K44:K44)+SUM('N.E. CORRIDOR (CEILING13 - Inst'!K44:K44)+SUM('LARGE ADMIN ROOM - Install'!K44:K44)+SUM('ELEV LOBBY - Install'!K44:K44)+SUM('NORTH CLUB - Install'!K44:K44)+SUM('PANTHERS DEN - Install'!K44:K44)+SUM('PANTHERS DEN18 - Install'!K44:K44)+SUM('PANTHERS DEN19 - Install'!K44:K44)+SUM('PANTHERS DEN20 - Install'!K44:K44)+SUM('PANTHERS DEN21 - Install'!K44:K44)+SUM('PANTHERS DEN22 - Install'!K44:K44)+SUM('PANTHERS DEN23 - Install'!K44:K44)+SUM('SOUTH CLUB - Install'!K44:K44)+SUM('ELEV LOBBY25 - Install'!K44:K44)+SUM('SOUTH CLUB26 - Install'!K44:K44)+SUM('ELEV LOBBY27 - Install'!K44:K44)+SUM('ELEV LOBBY28 - Install'!K44:K44)+SUM('NORTH CLUB29 - Install'!K44:K44)+SUM('RIBBON NW - Install'!K44:K44)+SUM('RIBBON NW31 - Install'!K44:K44)+SUM('RIBBON NW32 - Install'!K44:K44)+SUM('RIBBON NW33 - Install'!K44:K44)+SUM('RIBBON SW - Install'!K44:K44)+SUM('RIBBON SW35 - Install'!K44:K44)+SUM('RIBBON SW36 - Install'!K44:K44)+SUM('SCOREBOARD EAST - Install'!K44:K44)+SUM('SCOREBOARD WEST - Install'!K44:K44)+SUM('EAST ENTRY A - Install'!K44:K44)+SUM('EAST ENTRY B - Install'!K44:K44)+SUM('EAST ENTRY C - Install'!K44:K44)+SUM('EAST ENTRY D - Install'!K44:K44)+SUM('NORTH EAST EXTERIOR NE - Instal'!K44:K44)+SUM('NORTH ENTRY C - Install'!K44:K44)+SUM('NORTH ENTRY C45 - Install'!K44:K44)+SUM('NORTH ENTRY C46 - Install'!K44:K44)+SUM('SOUTH EAST EXTERIOR SE - Instal'!K44:K44) -> 2300933.9 | E8: =IFERROR(D8-C8,0) -> 345140.08 | F8: 0.15 | G8: =IFERROR(C8/33186.380000000005,0) -> 58.93
B9: PM / General Conditions / Travel | C9: =SUM('FIELD RIBBON NORTH - Install'!I34:I34)+SUM('FIELD RIBBON EAST - Install'!I34:I34)+SUM('TEAM ROOM - Install'!I34:I34)+SUM('FIELD RIBBON WEST - Install'!I34:I34)+SUM('INCIDENT COMMAND - Install'!I34:I34)+SUM('DEF UNIT - Install'!I34:I34)+SUM('NORTH CORRIDOR - Install'!I34:I34)+SUM('SOUTH CORRIDOR - Install'!I34:I34)+SUM('S.E. CORRIDOR (CEILING) - Insta'!I34:I34)+SUM('S.E. CORRIDOR (CEILING10 - Inst'!I34:I34)+SUM('EAST CORRIDOR (CEILING) - Insta'!I34:I34)+SUM('N.E. CORRIDOR (CEILING) - Insta'!I34:I34)+SUM('N.E. CORRIDOR (CEILING13 - Inst'!I34:I34)+SUM('LARGE ADMIN ROOM - Install'!I34:I34)+SUM('ELEV LOBBY - Install'!I34:I34)+SUM('NORTH CLUB - Install'!I34:I34)+SUM('PANTHERS DEN - Install'!I34:I34)+SUM('PANTHERS DEN18 - Install'!I34:I34)+SUM('PANTHERS DEN19 - Install'!I34:I34)+SUM('PANTHERS DEN20 - Install'!I34:I34)+SUM('PANTHERS DEN21 - Install'!I34:I34)+SUM('PANTHERS DEN22 - Install'!I34:I34)+SUM('PANTHERS DEN23 - Install'!I34:I34)+SUM('SOUTH CLUB - Install'!I34:I34)+SUM('ELEV LOBBY25 - Install'!I34:I34)+SUM('SOUTH CLUB26 - Install'!I34:I34)+SUM('ELEV LOBBY27 - Install'!I34:I34)+SUM('ELEV LOBBY28 - Install'!I34:I34)+SUM('NORTH CLUB29 - Install'!I34:I34)+SUM('RIBBON NW - Install'!I34:I34)+SUM('RIBBON NW31 - Install'!I34:I34)+SUM('RIBBON NW32 - Install'!I34:I34)+SUM('RIBBON NW33 - Install'!I34:I34)+SUM('RIBBON SW - Install'!I34:I34)+SUM('RIBBON SW35 - Install'!I34:I34)+SUM('RIBBON SW36 - Install'!I34:I34)+SUM('SCOREBOARD EAST - Install'!I34:I34)+SUM('SCOREBOARD WEST - Install'!I34:I34)+SUM('EAST ENTRY A - Install'!I34:I34)+SUM('EAST ENTRY B - Install'!I34:I34)+SUM('EAST ENTRY C - Install'!I34:I34)+SUM('EAST ENTRY D - Install'!I34:I34)+SUM('NORTH EAST EXTERIOR NE - Instal'!I34:I34)+SUM('NORTH ENTRY C - Install'!I34:I34)+SUM('NORTH ENTRY C45 - Install'!I34:I34)+SUM('NORTH ENTRY C46 - Install'!I34:I34)+SUM('SOUTH EAST EXTERIOR SE - Instal'!I34:I34) -> 981470.45 | D9: =SUM('FIELD RIBBON NORTH - Install'!K34:K34)+SUM('FIELD RIBBON EAST - Install'!K34:K34)+SUM('TEAM ROOM - Install'!K34:K34)+SUM('FIELD RIBBON WEST - Install'!K34:K34)+SUM('INCIDENT COMMAND - Install'!K34:K34)+SUM('DEF UNIT - Install'!K34:K34)+SUM('NORTH CORRIDOR - Install'!K34:K34)+SUM('SOUTH CORRIDOR - Install'!K34:K34)+SUM('S.E. CORRIDOR (CEILING) - Insta'!K34:K34)+SUM('S.E. CORRIDOR (CEILING10 - Inst'!K34:K34)+SUM('EAST CORRIDOR (CEILING) - Insta'!K34:K34)+SUM('N.E. CORRIDOR (CEILING) - Insta'!K34:K34)+SUM('N.E. CORRIDOR (CEILING13 - Inst'!K34:K34)+SUM('LARGE ADMIN ROOM - Install'!K34:K34)+SUM('ELEV LOBBY - Install'!K34:K34)+SUM('NORTH CLUB - Install'!K34:K34)+SUM('PANTHERS DEN - Install'!K34:K34)+SUM('PANTHERS DEN18 - Install'!K34:K34)+SUM('PANTHERS DEN19 - Install'!K34:K34)+SUM('PANTHERS DEN20 - Install'!K34:K34)+SUM('PANTHERS DEN21 - Install'!K34:K34)+SUM('PANTHERS DEN22 - Install'!K34:K34)+SUM('PANTHERS DEN23 - Install'!K34:K34)+SUM('SOUTH CLUB - Install'!K34:K34)+SUM('ELEV LOBBY25 - Install'!K34:K34)+SUM('SOUTH CLUB26 - Install'!K34:K34)+SUM('ELEV LOBBY27 - Install'!K34:K34)+SUM('ELEV LOBBY28 - Install'!K34:K34)+SUM('NORTH CLUB29 - Install'!K34:K34)+SUM('RIBBON NW - Install'!K34:K34)+SUM('RIBBON NW31 - Install'!K34:K34)+SUM('RIBBON NW32 - Install'!K34:K34)+SUM('RIBBON NW33 - Install'!K34:K34)+SUM('RIBBON SW - Install'!K34:K34)+SUM('RIBBON SW35 - Install'!K34:K34)+SUM('RIBBON SW36 - Install'!K34:K34)+SUM('SCOREBOARD EAST - Install'!K34:K34)+SUM('SCOREBOARD WEST - Install'!K34:K34)+SUM('EAST ENTRY A - Install'!K34:K34)+SUM('EAST ENTRY B - Install'!K34:K34)+SUM('EAST ENTRY C - Install'!K34:K34)+SUM('EAST ENTRY D - Install'!K34:K34)+SUM('NORTH EAST EXTERIOR NE - Instal'!K34:K34)+SUM('NORTH ENTRY C - Install'!K34:K34)+SUM('NORTH ENTRY C45 - Install'!K34:K34)+SUM('NORTH ENTRY C46 - Install'!K34:K34)+SUM('SOUTH EAST EXTERIOR SE - Instal'!K34:K34) -> 1154671.1 | E9: =IFERROR(D9-C9,0) -> 173200.67 | F9: 0.15
B10: Engineering & Permits | C10: =SUM('FIELD RIBBON NORTH - Install'!I52:I52)+SUM('FIELD RIBBON EAST - Install'!I52:I52)+SUM('TEAM ROOM - Install'!I52:I52)+SUM('FIELD RIBBON WEST - Install'!I52:I52)+SUM('INCIDENT COMMAND - Install'!I52:I52)+SUM('DEF UNIT - Install'!I52:I52)+SUM('NORTH CORRIDOR - Install'!I52:I52)+SUM('SOUTH CORRIDOR - Install'!I52:I52)+SUM('S.E. CORRIDOR (CEILING) - Insta'!I52:I52)+SUM('S.E. CORRIDOR (CEILING10 - Inst'!I52:I52)+SUM('EAST CORRIDOR (CEILING) - Insta'!I52:I52)+SUM('N.E. CORRIDOR (CEILING) - Insta'!I52:I52)+SUM('N.E. CORRIDOR (CEILING13 - Inst'!I52:I52)+SUM('LARGE ADMIN ROOM - Install'!I52:I52)+SUM('ELEV LOBBY - Install'!I52:I52)+SUM('NORTH CLUB - Install'!I52:I52)+SUM('PANTHERS DEN - Install'!I52:I52)+SUM('PANTHERS DEN18 - Install'!I52:I52)+SUM('PANTHERS DEN19 - Install'!I52:I52)+SUM('PANTHERS DEN20 - Install'!I52:I52)+SUM('PANTHERS DEN21 - Install'!I52:I52)+SUM('PANTHERS DEN22 - Install'!I52:I52)+SUM('PANTHERS DEN23 - Install'!I52:I52)+SUM('SOUTH CLUB - Install'!I52:I52)+SUM('ELEV LOBBY25 - Install'!I52:I52)+SUM('SOUTH CLUB26 - Install'!I52:I52)+SUM('ELEV LOBBY27 - Install'!I52:I52)+SUM('ELEV LOBBY28 - Install'!I52:I52)+SUM('NORTH CLUB29 - Install'!I52:I52)+SUM('RIBBON NW - Install'!I52:I52)+SUM('RIBBON NW31 - Install'!I52:I52)+SUM('RIBBON NW32 - Install'!I52:I52)+SUM('RIBBON NW33 - Install'!I52:I52)+SUM('RIBBON SW - Install'!I52:I52)+SUM('RIBBON SW35 - Install'!I52:I52)+SUM('RIBBON SW36 - Install'!I52:I52)+SUM('SCOREBOARD EAST - Install'!I52:I52)+SUM('SCOREBOARD WEST - Install'!I52:I52)+SUM('EAST ENTRY A - Install'!I52:I52)+SUM('EAST ENTRY B - Install'!I52:I52)+SUM('EAST ENTRY C - Install'!I52:I52)+SUM('EAST ENTRY D - Install'!I52:I52)+SUM('NORTH EAST EXTERIOR NE - Instal'!I52:I52)+SUM('NORTH ENTRY C - Install'!I52:I52)+SUM('NORTH ENTRY C45 - Install'!I52:I52)+SUM('NORTH ENTRY C46 - Install'!I52:I52)+SUM('SOUTH EAST EXTERIOR SE - Instal'!I52:I52) -> 221176.36 | D10: =SUM('FIELD RIBBON NORTH - Install'!K52:K52)+SUM('FIELD RIBBON EAST - Install'!K52:K52)+SUM('TEAM ROOM - Install'!K52:K52)+SUM('FIELD RIBBON WEST - Install'!K52:K52)+SUM('INCIDENT COMMAND - Install'!K52:K52)+SUM('DEF UNIT - Install'!K52:K52)+SUM('NORTH CORRIDOR - Install'!K52:K52)+SUM('SOUTH CORRIDOR - Install'!K52:K52)+SUM('S.E. CORRIDOR (CEILING) - Insta'!K52:K52)+SUM('S.E. CORRIDOR (CEILING10 - Inst'!K52:K52)+SUM('EAST CORRIDOR (CEILING) - Insta'!K52:K52)+SUM('N.E. CORRIDOR (CEILING) - Insta'!K52:K52)+SUM('N.E. CORRIDOR (CEILING13 - Inst'!K52:K52)+SUM('LARGE ADMIN ROOM - Install'!K52:K52)+SUM('ELEV LOBBY - Install'!K52:K52)+SUM('NORTH CLUB - Install'!K52:K52)+SUM('PANTHERS DEN - Install'!K52:K52)+SUM('PANTHERS DEN18 - Install'!K52:K52)+SUM('PANTHERS DEN19 - Install'!K52:K52)+SUM('PANTHERS DEN20 - Install'!K52:K52)+SUM('PANTHERS DEN21 - Install'!K52:K52)+SUM('PANTHERS DEN22 - Install'!K52:K52)+SUM('PANTHERS DEN23 - Install'!K52:K52)+SUM('SOUTH CLUB - Install'!K52:K52)+SUM('ELEV LOBBY25 - Install'!K52:K52)+SUM('SOUTH CLUB26 - Install'!K52:K52)+SUM('ELEV LOBBY27 - Install'!K52:K52)+SUM('ELEV LOBBY28 - Install'!K52:K52)+SUM('NORTH CLUB29 - Install'!K52:K52)+SUM('RIBBON NW - Install'!K52:K52)+SUM('RIBBON NW31 - Install'!K52:K52)+SUM('RIBBON NW32 - Install'!K52:K52)+SUM('RIBBON NW33 - Install'!K52:K52)+SUM('RIBBON SW - Install'!K52:K52)+SUM('RIBBON SW35 - Install'!K52:K52)+SUM('RIBBON SW36 - Install'!K52:K52)+SUM('SCOREBOARD EAST - Install'!K52:K52)+SUM('SCOREBOARD WEST - Install'!K52:K52)+SUM('EAST ENTRY A - Install'!K52:K52)+SUM('EAST ENTRY B - Install'!K52:K52)+SUM('EAST ENTRY C - Install'!K52:K52)+SUM('EAST ENTRY D - Install'!K52:K52)+SUM('NORTH EAST EXTERIOR NE - Instal'!K52:K52)+SUM('NORTH ENTRY C - Install'!K52:K52)+SUM('NORTH ENTRY C45 - Install'!K52:K52)+SUM('NORTH ENTRY C46 - Install'!K52:K52)+SUM('SOUTH EAST EXTERIOR SE - Instal'!K52:K52) -> 260207.48 | E10: =IFERROR(D10-C10,0) -> 39031.12 | F10: 0.15
B11: CMS (Content Management System) | C11: =SUM(CMS!F26:F26) -> 0 | D11: =SUM(CMS!H26:H26) -> 0 | E11: =IFERROR(D11-C11,0) -> 0 | F11: 0.15
B12: Scoring System | C12: =SUM(Scoring!F27:F27) -> 0 | D12: =SUM(Scoring!H27:H27) -> 0 | E12: =IFERROR(D12-C12,0) -> 0 | F12: 0.15
B13: Venue Services | C13: =SUM('Venue Services'!B17:B17) -> 0 | D13: =SUM('Venue Services'!C17:C17) -> 0 | E13: =IFERROR(D13-C13,0) -> 0 | F13: 0.15
B14: Game Clock | C14: =SUM('Additional Items'!F5:F5) -> 0 | D14: =SUM('Additional Items'!H5:H5) -> 0 | E14: =IFERROR(D14-C14,0) -> 0 | F14: 0.15
B15: Pitch Clocks | C15: =SUM('Additional Items'!F6:F6) -> 0 | D15: =SUM('Additional Items'!H6:H6) -> 0 | E15: =IFERROR(D15-C15,0) -> 0 | F15: 0.15
B16: OES / MIS / Timing | C16: =SUM('Additional Items'!F7:F7) -> 0 | D16: =SUM('Additional Items'!H7:H7) -> 0 | E16: =IFERROR(D16-C16,0) -> 0 | F16: 0.15
B17: DMX / Misc Equipment | C17: =SUM('Additional Items'!F8:F8) -> 0 | D17: =SUM('Additional Items'!H8:H8) -> 0 | E17: =IFERROR(D17-C17,0) -> 0 | F17: 0.15
B19: SUBTOTAL | C19: =SUM(C5:C17) -> 15093962 | D19: =SUM(D5:D17) -> 17365514 | E19: =IFERROR(D19-C19,0) -> 2271551.9 | F19: =IFERROR(1-C19/D19,0) -> 0.13 | G19: =IFERROR(C19/33186.380000000005,0) -> 454.82
B20: TAX | C20: 0 | D20: 0 | E20: 0 | F20: 0
B21: BOND | C21: 0 | D21: 0 | E21: 0 | F21: 0
B22: GRAND TOTAL | C22: =C19+C20+C21 -> 15093962 | D22: =D19+D20+D21 -> 17365514 | E22: =IFERROR(D22-C22,0) -> 2271551.9 | F22: =IFERROR(1-C22/D22,0) -> 0.13 | G22: =IFERROR(C22/33186.380000000005,0) -> 454.82

Sheet LED Cost Sheet
A1: Large Format LED — LED Cost Sheet
U2: LED Margin Override → | V2: 0.15
A3: Display | B3: RFP H (ft) | C3: RFP W (ft) | D3: RFP NITs | E3: Vendor | F3: Product | G3: Pitch | H3: H (ft) | I3: W (ft) | J3: H (px) | K3: W (px) | L3: Qty | M3: Total SqFt | N3: Product NITs | O3: Service | P3: $/SqFt | Q3: Display Cost | R3: Processor | S3: Shipping | T3: Total Cost | U3: Margin % | V3: Selling Price | W3: ANC Margin | X3: Weight (lbs) | Y3: Total Power (W) | Z3: BTU/hr
A4: FIELD RIBBON NORTH — FIELD RIBBON NORTH | B4: 3 | C4: 320 | D4: 8000 | E4: =IFERROR(VLOOKUP(F4,'_Products'!$A$1:$G$23,2,FALSE),"") -> Nationstar | F4: 2.5mm Indoor (Nationstar MIP) | G4: =IFERROR(VLOOKUP(F4,'_Products'!$A$1:$G$23,3,FALSE),0) -> 2.5 | H4: 3 | I4: 320 | J4: =IFERROR(ROUND(H4*304.8/G4,0),0) -> 366 | K4: =IFERROR(ROUND(I4*304.8/G4,0),0) -> 39014 | L4: 1 | M4: =H4*I4*L4 -> 960 | N4: =IFERROR(VLOOKUP(F4,'_Products'!$A$1:$G$23,5,FALSE),0) -> 2000 | O4: Front | P4: 256.36 | Q4: =P4*M4 -> 246109.75 | R4: =SUM('Bundle Equipment'!E12:E12) -> 23476 | S4: =MAX(M4*10,500) -> 9600 | T4: =Q4+R4+S4 -> 279185.75 | U4: =V$2 -> 0.15 | V4: =IFERROR(T4/(1-U4),0) -> 328453.82 | W4: =V4-T4 -> 49268.07 | X4: =IFERROR(ROUND(M4*0.092903*VLOOKUP(F4,'_Products'!$A$1:$G$23,6,FALSE),0),0) -> 4691 | Y4: =IFERROR(ROUND(M4*0.092903*VLOOKUP(F4,'_Products'!$A$1:$G$23,7,FALSE),0),0) -> 34836 | Z4: =Y4*3.412 -> 118860
A5: FIELD RIBBON EAST — FIELD RIBBON EAST | B5: 3 | C5: 200 | D5: 8000 | E5: =IFERROR(VLOOKUP(F5,'_Products'!$A$1:$G$23,2,FALSE),"") -> Nationstar | F5: 2.5mm Indoor (Nationstar MIP) | G5: =IFERROR(VLOOKUP(F5,'_Products'!$A$1:$G$23,3,FALSE),0) -> 2.5 | H5: 3 | I5: 200 | J5: =IFERROR(ROUND(H5*304.8/G5,0),0) -> 366 | K5: =IFERROR(ROUND(I5*304.8/G5,0),0) -> 24384 | L5: 1 | M5: =H5*I5*L5 -> 600 | N5: =IFERROR(VLOOKUP(F5,'_Products'!$A$1:$G$23,5,FALSE),0) -> 2000 | O5: Front | P5: 256.36 | Q5: =P5*M5 -> 153818.6 | R5: =SUM('Bundle Equipment'!E19:E19) -> 15310 | S5: =MAX(M5*10,500) -> 6000 | T5: =Q5+R5+S5 -> 175128.6 | U5: =V$2 -> 0.15 | V5: =IFERROR(T5/(1-U5),0) -> 206033.65 | W5: =V5-T5 -> 30905.05 | X5: =IFERROR(ROUND(M5*0.092903*VLOOKUP(F5,'_Products'!$A$1:$G$23,6,FALSE),0),0) -> 2932 | Y5: =IFERROR(ROUND(M5*0.092903*VLOOKUP(F5,'_Products'!$A$1:$G$23,7,FALSE),0),0) -> 21773 | Z5: =Y5*3.412 -> 74289
A6: TEAM ROOM — TEAM ROOM | B6: 8 | C6: 14 | D6: 4000 | E6: =IFERROR(VLOOKUP(F6,'_Products'!$A$1:$G$23,2,FALSE),"") -> Nationstar | F6: 2.5mm Indoor (Nationstar MIP) | G6: =IFERROR(VLOOKUP(F6,'_Products'!$A$1:$G$23,3,FALSE),0) -> 2.5 | H6: 8 | I6: 14 | J6: =IFERROR(ROUND(H6*304.8/G6,0),0) -> 975 | K6: =IFERROR(ROUND(I6*304.8/G6,0),0) -> 1707 | L6: 1 | M6: =H6*I6*L6 -> 112 | N6: =IFERROR(VLOOKUP(F6,'_Products'!$A$1:$G$23,5,FALSE),0) -> 2000 | O6: Front | P6: 256.36 | Q6: =P6*M6 -> 28712.81 | R6: =SUM('Bundle Equipment'!E24:E24) -> 517.2 | S6: =MAX(M6*10,500) -> 1120 | T6: =Q6+R6+S6 -> 30350.01 | U6: =V$2 -> 0.15 | V6: =IFERROR(T6/(1-U6),0) -> 35705.89 | W6: =V6-T6 -> 5355.88 | X6: =IFERROR(ROUND(M6*0.092903*VLOOKUP(F6,'_Products'!$A$1:$G$23,6,FALSE),0),0) -> 547 | Y6: =IFERROR(ROUND(M6*0.092903*VLOOKUP(F6,'_Products'!$A$1:$G$23,7,FALSE),0),0) -> 4064 | Z6: =Y6*3.412 -> 13866
A7: FIELD RIBBON WEST — FIELD RIBBON WEST | B7: 3 | C7: 200 | D7: 8000 | E7: =IFERROR(VLOOKUP(F7,'_Products'!$A$1:$G$23,2,FALSE),"") -> Nationstar | F7: 2.5mm Indoor (Nationstar MIP) | G7: =IFERROR(VLOOKUP(F7,'_Products'!$A$1:$G$23,3,FALSE),0) -> 2.5 | H7: 3 | I7: 200 | J7: =IFERROR(ROUND(H7*304.8/G7,0),0) -> 366 | K7: =IFERROR(ROUND(I7*304.8/G7,0),0) -> 24384 | L7: 1 | M7: =H7*I7*L7 -> 600 | N7: =IFERROR(VLOOKUP(F7,'_Products'!$A$1:$G$23,5,FALSE),0) -> 2000 | O7: Front | P7: 256.36 | Q7: =P7*M7 -> 153818.6 | R7: =SUM('Bundle Equipment'!E31:E31) -> 15310 | S7: =MAX(M7*10,500) -> 6000 | T7: =Q7+R7+S7 -> 175128.6 | U7: =V$2 -> 0.15 | V7: =IFERROR(T7/(1-U7),0) -> 206033.65 | W7: =V7-T7 -> 30905.05 | X7: =IFERROR(ROUND(M7*0.092903*VLOOKUP(F7,'_Products'!$A$1:$G$23,6,FALSE),0),0) -> 2932 | Y7: =IFERROR(ROUND(M7*0.092903*VLOOKUP(F7,'_Products'!$A$1:$G$23,7,FALSE),0),0) -> 21773 | Z7: =Y7*3.412 -> 74289
A8: INCIDENT COMMAND — INCIDENT COMMANT | B8: 5.33 | C8: 21 | D8: 4000 | E8: =IFERROR(VLOOKUP(F8,'_Products'!$A$1:$G$23,2,FALSE),"") -> Nationstar | F8: 2.5mm Indoor (Nationstar MIP) | G8: =IFERROR(VLOOKUP(F8,'_Products'!$A$1:$G$23,3,FALSE),0) -> 2.5 | H8: 5.33 | I8: 21 | J8: =IFERROR(ROUND(H8*304.8/G8,0),0) -> 650 | K8: =IFERROR(ROUND(I8*304.8/G8,0),0) -> 2560 | L8: 1 | M8: =H8*I8*L8 -> 111.93 | N8: =IFERROR(VLOOKUP(F8,'_Products'!$A$1:$G$23,5,FALSE),0) -> 2000 | O8: Front | P8: 256.36 | Q8: =P8*M8 -> 28694.85 | R8: =SUM('Bundle Equipment'!E36:E36) -> 517.16 | S8: =MAX(M8*10,500) -> 1119.3 | T8: =Q8+R8+S8 -> 30331.31 | U8: =V$2 -> 0.15 | V8: =IFERROR(T8/(1-U8),0) -> 35683.89 | W8: =V8-T8 -> 5352.58 | X8: =IFERROR(ROUND(M8*0.092903*VLOOKUP(F8,'_Products'!$A$1:$G$23,6,FALSE),0),0) -> 547 | Y8: =IFERROR(ROUND(M8*0.092903*VLOOKUP(F8,'_Products'!$A$1:$G$23,7,FALSE),0),0) -> 4062 | Z8: =Y8*3.412 -> 13860
A9: DEF UNIT — DEF UNIT | B9: 6 | C9: 11 | D9: 4000 | E9: =IFERROR(VLOOKUP(F9,'_Products'!$A$1:$G$23,2,FALSE),"") -> Nationstar | F9: 2.5mm Indoor (Nationstar MIP) | G9: =IFERROR(VLOOKUP(F9,'_Products'!$A$1:$G$23,3,FALSE),0) -> 2.5 | H9: 6 | I9: 11 | J9: =IFERROR(ROUND(H9*304.8/G9,0),0) -> 732 | K9: =IFERROR(ROUND(I9*304.8/G9,0),0) -> 1341 | L9: 1 | M9: =H9*I9*L9 -> 66 | N9: =IFERROR(VLOOKUP(F9,'_Products'!$A$1:$G$23,5,FALSE),0) -> 2000 | O9: Front | P9: 256.36 | Q9: =P9*M9 -> 16920.05 | R9: =SUM('Bundle Equipment'!E41:E41) -> 489.6 | S9: =MAX(M9*10,500) -> 660 | T9: =Q9+R9+S9 -> 18069.65 | U9: =V$2 -> 0.15 | V9: =IFERROR(T9/(1-U9),0) -> 21258.41 | W9: =V9-T9 -> 3188.76 | X9: =IFERROR(ROUND(M9*0.092903*VLOOKUP(F9,'_Products'!$A$1:$G$23,6,FALSE),0),0) -> 323 | Y9: =IFERROR(ROUND(M9*0.092903*VLOOKUP(F9,'_Products'!$A$1:$G$23,7,FALSE),0),0) -> 2395 | Z9: =Y9*3.412 -> 8172
A10: NORTH CORRIDOR — NORTH CORRIDOR | B10: 11 | C10: 100 | D10: 4000 | E10: =IFERROR(VLOOKUP(F10,'_Products'!$A$1:$G$23,2,FALSE),"") -> Nationstar | F10: 2.5mm Indoor (Nationstar MIP) | G10: =IFERROR(VLOOKUP(F10,'_Products'!$A$1:$G$23,3,FALSE),0) -> 2.5 | H10: 11 | I10: 100 | J10: =IFERROR(ROUND(H10*304.8/G10,0),0) -> 1341 | K10: =IFERROR(ROUND(I10*304.8/G10,0),0) -> 12192 | L10: 1 | M10: =H10*I10*L10 -> 1100 | N10: =IFERROR(VLOOKUP(F10,'_Products'!$A$1:$G$23,5,FALSE),0) -> 2000 | O10: Front | P10: 256.36 | Q10: =P10*M10 -> 282000.76 | R10: =SUM('Bundle Equipment'!E47:E47) -> 21060 | S10: =MAX(M10*10,500) -> 11000 | T10: =Q10+R10+S10 -> 314060.76 | U10: =V$2 -> 0.15 | V10: =IFERROR(T10/(1-U10),0) -> 369483.25 | W10: =V10-T10 -> 55422.49 | X10: =IFERROR(ROUND(M10*0.092903*VLOOKUP(F10,'_Products'!$A$1:$G$23,6,FALSE),0),0) -> 5375 | Y10: =IFERROR(ROUND(M10*0.092903*VLOOKUP(F10,'_Products'!$A$1:$G$23,7,FALSE),0),0) -> 39917 | Z10: =Y10*3.412 -> 136197
A11: SOUTH CORRIDOR — SOUTH CORRIDOR | B11: 11 | C11: 85 | D11: 4000 | E11: =IFERROR(VLOOKUP(F11,'_Products'!$A$1:$G$23,2,FALSE),"") -> Nationstar | F11: 2.5mm Indoor (Nationstar MIP) | G11: =IFERROR(VLOOKUP(F11,'_Products'!$A$1:$G$23,3,FALSE),0) -> 2.5 | H11: 11 | I11: 85 | J11: =IFERROR(ROUND(H11*304.8/G11,0),0) -> 1341 | K11: =IFERROR(ROUND(I11*304.8/G11,0),0) -> 10363 | L11: 1 | M11: =H11*I11*L11 -> 935 | N11: =IFERROR(VLOOKUP(F11,'_Products'!$A$1:$G$23,5,FALSE),0) -> 2000 | O11: Front | P11: 256.36 | Q11: =P11*M11 -> 239700.65 | R11: =SUM('Bundle Equipment'!E53:E53) -> 20961 | S11: =MAX(M11*10,500) -> 9350 | T11: =Q11+R11+S11 -> 270011.65 | U11: =V$2 -> 0.15 | V11: =IFERROR(T11/(1-U11),0) -> 317660.76 | W11: =V11-T11 -> 47649.11 | X11: =IFERROR(ROUND(M11*0.092903*VLOOKUP(F11,'_Products'!$A$1:$G$23,6,FALSE),0),0) -> 4569 | Y11: =IFERROR(ROUND(M11*0.092903*VLOOKUP(F11,'_Products'!$A$1:$G$23,7,FALSE),0),0) -> 33929 | Z11: =Y11*3.412 -> 115766
A12: S.E. CORRIDOR (CEILING) — S.E. CORRIDOR (CEILING) | B12: 10 | C12: 34 | D12: 4000 | E12: =IFERROR(VLOOKUP(F12,'_Products'!$A$1:$G$23,2,FALSE),"") -> Nationstar | F12: 2.5mm Indoor (Nationstar MIP) | G12: =IFERROR(VLOOKUP(F12,'_Products'!$A$1:$G$23,3,FALSE),0) -> 2.5 | H12: 10 | I12: 34 | J12: =IFERROR(ROUND(H12*304.8/G12,0),0) -> 1219 | K12: =IFERROR(ROUND(I12*304.8/G12,0),0) -> 4145 | L12: 1 | M12: =H12*I12*L12 -> 340 | N12: =IFERROR(VLOOKUP(F12,'_Products'!$A$1:$G$23,5,FALSE),0) -> 2000 | O12: Front | P12: 256.36 | Q12: =P12*M12 -> 87163.87 | R12: =SUM('Bundle Equipment'!E59:E59) -> 12654 | S12: =MAX(M12*10,500) -> 3400 | T12: =Q12+R12+S12 -> 103217.87 | U12: =V$2 -> 0.15 | V12: =IFERROR(T12/(1-U12),0) -> 121432.79 | W12: =V12-T12 -> 18214.92 | X12: =IFERROR(ROUND(M12*0.092903*VLOOKUP(F12,'_Products'!$A$1:$G$23,6,FALSE),0),0) -> 1661 | Y12: =IFERROR(ROUND(M12*0.092903*VLOOKUP(F12,'_Products'!$A$1:$G$23,7,FALSE),0),0) -> 12338 | Z12: =Y12*3.412 -> 42097
A13: S.E. CORRIDOR (CEILING) — S.E. CORRIDOR (CEILING) | B13: 10 | C13: 34 | D13: 4000 | E13: =IFERROR(VLOOKUP(F13,'_Products'!$A$1:$G$23,2,FALSE),"") -> LG/Yaham | F13: Mesh P10 FM1921 3.9mm Indoor | G13: =IFERROR(VLOOKUP(F13,'_Products'!$A$1:$G$23,3,FALSE),0) -> 3.9 | H13: 10 | I13: 34 | J13: =IFERROR(ROUND(H13*304.8/G13,0),0) -> 782 | K13: =IFERROR(ROUND(I13*304.8/G13,0),0) -> 2657 | L13: 1 | M13: =H13*I13*L13 -> 340 | N13: =IFERROR(VLOOKUP(F13,'_Products'!$A$1:$G$23,5,FALSE),0) -> 6000 | O13: Front | P13: 256.36 | Q13: =P13*M13 -> 87163.87 | R13: =SUM('Bundle Equipment'!E65:E65) -> 12654 | S13: =MAX(M13*10,500) -> 3400 | T13: =Q13+R13+S13 -> 103217.87 | U13: =V$2 -> 0.15 | V13: =IFERROR(T13/(1-U13),0) -> 121432.79 | W13: =V13-T13 -> 18214.92 | X13: =IFERROR(ROUND(M13*0.092903*VLOOKUP(F13,'_Products'!$A$1:$G$23,6,FALSE),0),0) -> 1045 | Y13: =IFERROR(ROUND(M13*0.092903*VLOOKUP(F13,'_Products'!$A$1:$G$23,7,FALSE),0),0) -> 18952 | Z13: =Y13*3.412 -> 64664
A14: EAST CORRIDOR (CEILING) — EAST CORRIDOR (CEILING) | B14: 10 | C14: 36 | D14: 4000 | E14: =IFERROR(VLOOKUP(F14,'_Products'!$A$1:$G$23,2,FALSE),"") -> Nationstar | F14: 2.5mm Indoor (Nationstar MIP) | G14: =IFERROR(VLOOKUP(F14,'_Products'!$A$1:$G$23,3,FALSE),0) -> 2.5 | H14: 10 | I14: 36 | J14: =IFERROR(ROUND(H14*304.8/G14,0),0) -> 1219 | K14: =IFERROR(ROUND(I14*304.8/G14,0),0) -> 4389 | L14: 1 | M14: =H14*I14*L14 -> 360 | N14: =IFERROR(VLOOKUP(F14,'_Products'!$A$1:$G$23,5,FALSE),0) -> 2000 | O14: Front | P14: 256.36 | Q14: =P14*M14 -> 92291.16 | R14: =SUM('Bundle Equipment'!E71:E71) -> 12666 | S14: =MAX(M14*10,500) -> 3600 | T14: =Q14+R14+S14 -> 108557.16 | U14: =V$2 -> 0.15 | V14: =IFERROR(T14/(1-U14),0) -> 127714.31 | W14: =V14-T14 -> 19157.15 | X14: =IFERROR(ROUND(M14*0.092903*VLOOKUP(F14,'_Products'!$A$1:$G$23,6,FALSE),0),0) -> 1759 | Y14: =IFERROR(ROUND(M14*0.092903*VLOOKUP(F14,'_Products'!$A$1:$G$23,7,FALSE),0),0) -> 13064 | Z14: =Y14*3.412 -> 44574
A15: N.E. CORRIDOR (CEILING) — N.E. CORRIDOR (CEILING) | B15: 10 | C15: 34 | D15: 4000 | E15: =IFERROR(VLOOKUP(F15,'_Products'!$A$1:$G$23,2,FALSE),"") -> Nationstar | F15: 2.5mm Indoor (Nationstar MIP) | G15: =IFERROR(VLOOKUP(F15,'_Products'!$A$1:$G$23,3,FALSE),0) -> 2.5 | H15: 10 | I15: 34 | J15: =IFERROR(ROUND(H15*304.8/G15,0),0) -> 1219 | K15: =IFERROR(ROUND(I15*304.8/G15,0),0) -> 4145 | L15: 1 | M15: =H15*I15*L15 -> 340 | N15: =IFERROR(VLOOKUP(F15,'_Products'!$A$1:$G$23,5,FALSE),0) -> 2000 | O15: Front | P15: 256.36 | Q15: =P15*M15 -> 87163.87 | R15: =SUM('Bundle Equipment'!E77:E77) -> 12654 | S15: =MAX(M15*10,500) -> 3400 | T15: =Q15+R15+S15 -> 103217.87 | U15: =V$2 -> 0.15 | V15: =IFERROR(T15/(1-U15),0) -> 121432.79 | W15: =V15-T15 -> 18214.92 | X15: =IFERROR(ROUND(M15*0.092903*VLOOKUP(F15,'_Products'!$A$1:$G$23,6,FALSE),0),0) -> 1661 | Y15: =IFERROR(ROUND(M15*0.092903*VLOOKUP(F15,'_Products'!$A$1:$G$23,7,FALSE),0),0) -> 12338 | Z15: =Y15*3.412 -> 42097
A16: N.E. CORRIDOR (CEILING) — N.E. CORRIDOR (CEILING) | B16: 10 | C16: 34 | D16: 4000 | E16: =IFERROR(VLOOKUP(F16,'_Products'!$A$1:$G$23,2,FALSE),"") -> LG/Yaham | F16: Mesh P10 FM1921 3.9mm Indoor | G16: =IFERROR(VLOOKUP(F16,'_Products'!$A$1:$G$23,3,FALSE),0) -> 3.9 | H16: 10 | I16: 34 | J16: =IFERROR(ROUND(H16*304.8/G16,0),0) -> 782 | K16: =IFERROR(ROUND(I16*304.8/G16,0),0) -> 2657 | L16: 1 | M16: =H16*I16*L16 -> 340 | N16: =IFERROR(VLOOKUP(F16,'_Products'!$A$1:$G$23,5,FALSE),0) -> 6000 | O16: Front | P16: 256.36 | Q16: =P16*M16 -> 87163.87 | R16: =SUM('Bundle Equipment'!E83:E83) -> 12654 | S16: =MAX(M16*10,500) -> 3400 | T16: =Q16+R16+S16 -> 103217.87 | U16: =V$2 -> 0.15 | V16: =IFERROR(T16/(1-U16),0) -> 121432.79 | W16: =V16-T16 -> 18214.92 | X16: =IFERROR(ROUND(M16*0.092903*VLOOKUP(F16,'_Products'!$A$1:$G$23,6,FALSE),0),0) -> 1045 | Y16: =IFERROR(ROUND(M16*0.092903*VLOOKUP(F16,'_Products'!$A$1:$G$23,7,FALSE),0),0) -> 18952 | Z16: =Y16*3.412 -> 64664
A17: LARGE ADMIN ROOM — LARGE ADMIN ROOM | B17: 8 | C17: 28 | D17: 4000 | E17: =IFERROR(VLOOKUP(F17,'_Products'!$A$1:$G$23,2,FALSE),"") -> Nationstar | F17: 2.5mm Indoor (Nationstar MIP) | G17: =IFERROR(VLOOKUP(F17,'_Products'!$A$1:$G$23,3,FALSE),0) -> 2.5 | H17: 8 | I17: 28 | J17: =IFERROR(ROUND(H17*304.8/G17,0),0) -> 975 | K17: =IFERROR(ROUND(I17*304.8/G17,0),0) -> 3414 | L17: 1 | M17: =H17*I17*L17 -> 224 | N17: =IFERROR(VLOOKUP(F17,'_Products'!$A$1:$G$23,5,FALSE),0) -> 2000 | O17: Front | P17: 256.36 | Q17: =P17*M17 -> 57425.61 | R17: =SUM('Bundle Equipment'!E88:E88) -> 584.4 | S17: =MAX(M17*10,500) -> 2240 | T17: =Q17+R17+S17 -> 60250.01 | U17: =V$2 -> 0.15 | V17: =IFERROR(T17/(1-U17),0) -> 70882.36 | W17: =V17-T17 -> 10632.35 | X17: =IFERROR(ROUND(M17*0.092903*VLOOKUP(F17,'_Products'!$A$1:$G$23,6,FALSE),0),0) -> 1095 | Y17: =IFERROR(ROUND(M17*0.092903*VLOOKUP(F17,'_Products'!$A$1:$G$23,7,FALSE),0),0) -> 8128 | Z17: =Y17*3.412 -> 27733
A18: ELEV LOBBY — ELEV LOBBY | B18: 4 | C18: 6 | D18: 4000 | E18: =IFERROR(VLOOKUP(F18,'_Products'!$A$1:$G$23,2,FALSE),"") -> Nationstar | F18: 2.5mm Indoor (Nationstar MIP) | G18: =IFERROR(VLOOKUP(F18,'_Products'!$A$1:$G$23,3,FALSE),0) -> 2.5 | H18: 4 | I18: 6 | J18: =IFERROR(ROUND(H18*304.8/G18,0),0) -> 488 | K18: =IFERROR(ROUND(I18*304.8/G18,0),0) -> 732 | L18: 1 | M18: =H18*I18*L18 -> 24 | N18: =IFERROR(VLOOKUP(F18,'_Products'!$A$1:$G$23,5,FALSE),0) -> 2000 | O18: Front | P18: 256.36 | Q18: =P18*M18 -> 6152.75 | R18: =SUM('Bundle Equipment'!E93:E93) -> 464.4 | S18: =MAX(M18*10,500) -> 500 | T18: =Q18+R18+S18 -> 7117.15 | U18: =V$2 -> 0.15 | V18: =IFERROR(T18/(1-U18),0) -> 8373.12 | W18: =V18-T18 -> 1255.97 | X18: =IFERROR(ROUND(M18*0.092903*VLOOKUP(F18,'_Products'!$A$1:$G$23,6,FALSE),0),0) -> 117 | Y18: =IFERROR(ROUND(M18*0.092903*VLOOKUP(F18,'_Products'!$A$1:$G$23,7,FALSE),0),0) -> 871 | Z18: =Y18*3.412 -> 2972
A19: NORTH CLUB — NORTH CLUB | B19: 9 | C19: 16 | D19: 4000 | E19: =IFERROR(VLOOKUP(F19,'_Products'!$A$1:$G$23,2,FALSE),"") -> Nationstar | F19: 2.5mm Indoor (Nationstar MIP) | G19: =IFERROR(VLOOKUP(F19,'_Products'!$A$1:$G$23,3,FALSE),0) -> 2.5 | H19: 9 | I19: 16 | J19: =IFERROR(ROUND(H19*304.8/G19,0),0) -> 1097 | K19: =IFERROR(ROUND(I19*304.8/G19,0),0) -> 1951 | L19: 1 | M19: =H19*I19*L19 -> 144 | N19: =IFERROR(VLOOKUP(F19,'_Products'!$A$1:$G$23,5,FALSE),0) -> 2000 | O19: Front | P19: 256.36 | Q19: =P19*M19 -> 36916.47 | R19: =SUM('Bundle Equipment'!E98:E98) -> 536.4 | S19: =MAX(M19*10,500) -> 1440 | T19: =Q19+R19+S19 -> 38892.87 | U19: =V$2 -> 0.15 | V19: =IFERROR(T19/(1-U19),0) -> 45756.32 | W19: =V19-T19 -> 6863.45 | X19: =IFERROR(ROUND(M19*0.092903*VLOOKUP(F19,'_Products'!$A$1:$G$23,6,FALSE),0),0) -> 704 | Y19: =IFERROR(ROUND(M19*0.092903*VLOOKUP(F19,'_Products'!$A$1:$G$23,7,FALSE),0),0) -> 5225 | Z19: =Y19*3.412 -> 17828
A20: PANTHERS DEN — PANTHERS DEN | B20: 22 | C20: 3 | D20: 4000 | E20: =IFERROR(VLOOKUP(F20,'_Products'!$A$1:$G$23,2,FALSE),"") -> Nationstar | F20: 2.5mm Indoor (Nationstar MIP) | G20: =IFERROR(VLOOKUP(F20,'_Products'!$A$1:$G$23,3,FALSE),0) -> 2.5 | H20: 22 | I20: 3 | J20: =IFERROR(ROUND(H20*304.8/G20,0),0) -> 2682 | K20: =IFERROR(ROUND(I20*304.8/G20,0),0) -> 366 | L20: 1 | M20: =H20*I20*L20 -> 66 | N20: =IFERROR(VLOOKUP(F20,'_Products'!$A$1:$G$23,5,FALSE),0) -> 2000 | O20: Front | P20: 256.36 | Q20: =P20*M20 -> 16920.05 | R20: =SUM('Bundle Equipment'!E103:E103) -> 489.6 | S20: =MAX(M20*10,500) -> 660 | T20: =Q20+R20+S20 -> 18069.65 | U20: =V$2 -> 0.15 | V20: =IFERROR(T20/(1-U20),0) -> 21258.41 | W20: =V20-T20 -> 3188.76 | X20: =IFERROR(ROUND(M20*0.092903*VLOOKUP(F20,'_Products'!$A$1:$G$23,6,FALSE),0),0) -> 323 | Y20: =IFERROR(ROUND(M20*0.092903*VLOOKUP(F20,'_Products'!$A$1:$G$23,7,FALSE),0),0) -> 2395 | Z20: =Y20*3.412 -> 8172
A21: PANTHERS DEN — PANTHERS DEN | B21: 19 | C21: 3 | D21: 4000 | E21: =IFERROR(VLOOKUP(F21,'_Products'!$A$1:$G$23,2,FALSE),"") -> LG/Yaham | F21: Mesh P10 FM1921 3.9mm Indoor | G21: =IFERROR(VLOOKUP(F21,'_Products'!$A$1:$G$23,3,FALSE),0) -> 3.9 | H21: 19 | I21: 3 | J21: =IFERROR(ROUND(H21*304.8/G21,0),0) -> 1485 | K21: =IFERROR(ROUND(I21*304.8/G21,0),0) -> 234 | L21: 1 | M21: =H21*I21*L21 -> 57 | N21: =IFERROR(VLOOKUP(F21,'_Products'!$A$1:$G$23,5,FALSE),0) -> 6000 | O21: Front | P21: 256.36 | Q21: =P21*M21 -> 14612.77 | R21: =SUM('Bundle Equipment'!E108:E108) -> 484.2 | S21: =MAX(M21*10,500) -> 570 | T21: =Q21+R21+S21 -> 15666.97 | U21: =V$2 -> 0.15 | V21: =IFERROR(T21/(1-U21),0) -> 18431.73 | W21: =V21-T21 -> 2764.76 | X21: =IFERROR(ROUND(M21*0.092903*VLOOKUP(F21,'_Products'!$A$1:$G$23,6,FALSE),0),0) -> 175 | Y21: =IFERROR(ROUND(M21*0.092903*VLOOKUP(F21,'_Products'!$A$1:$G$23,7,FALSE),0),0) -> 3177 | Z21: =Y21*3.412 -> 10840
A22: PANTHERS DEN — PANTHERS DEN | B22: 22 | C22: 3.17 | D22: 4000 | E22: =IFERROR(VLOOKUP(F22,'_Products'!$A$1:$G$23,2,FALSE),"") -> LG/Yaham | F22: Mesh P10 FM1921 3.9mm Indoor | G22: =IFERROR(VLOOKUP(F22,'_Products'!$A$1:$G$23,3,FALSE),0) -> 3.9 | H22: 22 | I22: 3.17 | J22: =IFERROR(ROUND(H22*304.8/G22,0),0) -> 1719 | K22: =IFERROR(ROUND(I22*304.8/G22,0),0) -> 248 | L22: 1 | M22: =H22*I22*L22 -> 69.74 | N22: =IFERROR(VLOOKUP(F22,'_Products'!$A$1:$G$23,5,FALSE),0) -> 6000 | O22: Front | P22: 256.36 | Q22: =P22*M22 -> 17878.84 | R22: =SUM('Bundle Equipment'!E113:E113) -> 491.84 | S22: =MAX(M22*10,500) -> 697.4 | T22: =Q22+R22+S22 -> 19068.08 | U22: =V$2 -> 0.15 | V22: =IFERROR(T22/(1-U22),0) -> 22433.04 | W22: =V22-T22 -> 3364.96 | X22: =IFERROR(ROUND(M22*0.092903*VLOOKUP(F22,'_Products'!$A$1:$G$23,6,FALSE),0),0) -> 214 | Y22: =IFERROR(ROUND(M22*0.092903*VLOOKUP(F22,'_Products'!$A$1:$G$23,7,FALSE),0),0) -> 3887 | Z22: =Y22*3.412 -> 13262
A23: PANTHERS DEN — PANTHERS DEN | B23: 22 | C23: 3 | D23: 4000 | E23: =IFERROR(VLOOKUP(F23,'_Products'!$A$1:$G$23,2,FALSE),"") -> LG/Yaham | F23: Mesh P10 FM1921 3.9mm Indoor | G23: =IFERROR(VLOOKUP(F23,'_Products'!$A$1:$G$23,3,FALSE),0) -> 3.9 | H23: 22 | I23: 3 | J23: =IFERROR(ROUND(H23*304.8/G23,0),0) -> 1719 | K23: =IFERROR(ROUND(I23*304.8/G23,0),0) -> 234 | L23: 1 | M23: =H23*I23*L23 -> 66 | N23: =IFERROR(VLOOKUP(F23,'_Products'!$A$1:$G$23,5,FALSE),0) -> 6000 | O23: Front | P23: 256.36 | Q23: =P23*M23 -> 16920.05 | R23: =SUM('Bundle Equipment'!E118:E118) -> 489.6 | S23: =MAX(M23*10,500) -> 660 | T23: =Q23+R23+S23 -> 18069.65 | U23: =V$2 -> 0.15 | V23: =IFERROR(T23/(1-U23),0) -> 21258.41 | W23: =V23-T23 -> 3188.76 | X23: =IFERROR(ROUND(M23*0.092903*VLOOKUP(F23,'_Products'!$A$1:$G$23,6,FALSE),0),0) -> 203 | Y23: =IFERROR(ROUND(M23*0.092903*VLOOKUP(F23,'_Products'!$A$1:$G$23,7,FALSE),0),0) -> 3679 | Z23: =Y23*3.412 -> 12553
A24: PANTHERS DEN — PANTHERS DEN | B24: 22 | C24: 3 | D24: 4000 | E24: =IFERROR(VLOOKUP(F24,'_Products'!$A$1:$G$23,2,FALSE),"") -> LG/Yaham | F24: Mesh P10 FM1921 3.9mm Indoor | G24: =IFERROR(VLOOKUP(F24,'_Products'!$A$1:$G$23,3,FALSE),0) -> 3.9 | H24: 22 | I24: 3 | J24: =IFERROR(ROUND(H24*304.8/G24,0),0) -> 1719 | K24: =IFERROR(ROUND(I24*304.8/G24,0),0) -> 234 | L24: 1 | M24: =H24*I24*L24 -> 66 | N24: =IFERROR(VLOOKUP(F24,'_Products'!$A$1:$G$23,5,FALSE),0) -> 6000 | O24: Front | P24: 256.36 | Q24: =P24*M24 -> 16920.05 | R24: =SUM('Bundle Equipment'!E123:E123) -> 489.6 | S24: =MAX(M24*10,500) -> 660 | T24: =Q24+R24+S24 -> 18069.65 | U24: =V$2 -> 0.15 | V24: =IFERROR(T24/(1-U24),0) -> 21258.41 | W24: =V24-T24 -> 3188.76 | X24: =IFERROR(ROUND(M24*0.092903*VLOOKUP(F24,'_Products'!$A$1:$G$23,6,FALSE),0),0) -> 203 | Y24: =IFERROR(ROUND(M24*0.092903*VLOOKUP(F24,'_Products'!$A$1:$G$23,7,FALSE),0),0) -> 3679 | Z24: =Y24*3.412 -> 12553
A25: PANTHERS DEN — PANTHERS DEN | B25: 8 | C25: 29 | D25: 4000 | E25: =IFERROR(VLOOKUP(F25,'_Products'!$A$1:$G$23,2,FALSE),"") -> LG/Yaham | F25: Mesh P10 FM1921 3.9mm Indoor | G25: =IFERROR(VLOOKUP(F25,'_Products'!$A$1:$G$23,3,FALSE),0) -> 3.9 | H25: 8 | I25: 29 | J25: =IFERROR(ROUND(H25*304.8/G25,0),0) -> 625 | K25: =IFERROR(ROUND(I25*304.8/G25,0),0) -> 2266 | L25: 1 | M25: =H25*I25*L25 -> 232 | N25: =IFERROR(VLOOKUP(F25,'_Products'!$A$1:$G$23,5,FALSE),0) -> 6000 | O25: Front | P25: 256.36 | Q25: =P25*M25 -> 59476.53 | R25: =SUM('Bundle Equipment'!E128:E128) -> 589.2 | S25: =MAX(M25*10,500) -> 2320 | T25: =Q25+R25+S25 -> 62385.73 | U25: =V$2 -> 0.15 | V25: =IFERROR(T25/(1-U25),0) -> 73394.98 | W25: =V25-T25 -> 11009.25 | X25: =IFERROR(ROUND(M25*0.092903*VLOOKUP(F25,'_Products'!$A$1:$G$23,6,FALSE),0),0) -> 713 | Y25: =IFERROR(ROUND(M25*0.092903*VLOOKUP(F25,'_Products'!$A$1:$G$23,7,FALSE),0),0) -> 12932 | Z25: =Y25*3.412 -> 44124
A26: PANTHERS DEN — PANTHERS DEN | B26: 4.08 | C26: 37.25 | D26: 4000 | E26: =IFERROR(VLOOKUP(F26,'_Products'!$A$1:$G$23,2,FALSE),"") -> LG/Yaham | F26: Mesh P10 FM1921 3.9mm Indoor | G26: =IFERROR(VLOOKUP(F26,'_Products'!$A$1:$G$23,3,FALSE),0) -> 3.9 | H26: 4.08 | I26: 37.25 | J26: =IFERROR(ROUND(H26*304.8/G26,0),0) -> 319 | K26: =IFERROR(ROUND(I26*304.8/G26,0),0) -> 2911 | L26: 1 | M26: =H26*I26*L26 -> 151.98 | N26: =IFERROR(VLOOKUP(F26,'_Products'!$A$1:$G$23,5,FALSE),0) -> 6000 | O26: Front | P26: 256.36 | Q26: =P26*M26 -> 38962.26 | R26: =SUM('Bundle Equipment'!E133:E133) -> 541.19 | S26: =MAX(M26*10,500) -> 1519.8 | T26: =Q26+R26+S26 -> 41023.25 | U26: =V$2 -> 0.15 | V26: =IFERROR(T26/(1-U26),0) -> 48262.65 | W26: =V26-T26 -> 7239.4 | X26: =IFERROR(ROUND(M26*0.092903*VLOOKUP(F26,'_Products'!$A$1:$G$23,6,FALSE),0),0) -> 467 | Y26: =IFERROR(ROUND(M26*0.092903*VLOOKUP(F26,'_Products'!$A$1:$G$23,7,FALSE),0),0) -> 8472 | Z26: =Y26*3.412 -> 28906
A27: SOUTH CLUB — SOUTH CLUB | B27: 9 | C27: 37.25 | D27: 4000 | E27: =IFERROR(VLOOKUP(F27,'_Products'!$A$1:$G$23,2,FALSE),"") -> Nationstar | F27: 2.5mm Indoor (Nationstar MIP) | G27: =IFERROR(VLOOKUP(F27,'_Products'!$A$1:$G$23,3,FALSE),0) -> 2.5 | H27: 9 | I27: 37.25 | J27: =IFERROR(ROUND(H27*304.8/G27,0),0) -> 1097 | K27: =IFERROR(ROUND(I27*304.8/G27,0),0) -> 4542 | L27: 1 | M27: =H27*I27*L27 -> 335.25 | N27: =IFERROR(VLOOKUP(F27,'_Products'!$A$1:$G$23,5,FALSE),0) -> 2000 | O27: Front | P27: 256.36 | Q27: =P27*M27 -> 85946.13 | R27: =SUM('Bundle Equipment'!E139:E139) -> 12651.15 | S27: =MAX(M27*10,500) -> 3352.5 | T27: =Q27+R27+S27 -> 101949.78 | U27: =V$2 -> 0.15 | V27: =IFERROR(T27/(1-U27),0) -> 119940.92 | W27: =V27-T27 -> 17991.14 | X27: =IFERROR(ROUND(M27*0.092903*VLOOKUP(F27,'_Products'!$A$1:$G$23,6,FALSE),0),0) -> 1638 | Y27: =IFERROR(ROUND(M27*0.092903*VLOOKUP(F27,'_Products'!$A$1:$G$23,7,FALSE),0),0) -> 12166 | Z27: =Y27*3.412 -> 41510
A28: ELEV LOBBY — ELEV LOBBY | B28: 4 | C28: 6 | D28: 4000 | E28: =IFERROR(VLOOKUP(F28,'_Products'!$A$1:$G$23,2,FALSE),"") -> LG/Yaham | F28: Mesh P10 FM1921 3.9mm Indoor | G28: =IFERROR(VLOOKUP(F28,'_Products'!$A$1:$G$23,3,FALSE),0) -> 3.9 | H28: 4 | I28: 6 | J28: =IFERROR(ROUND(H28*304.8/G28,0),0) -> 313 | K28: =IFERROR(ROUND(I28*304.8/G28,0),0) -> 469 | L28: 1 | M28: =H28*I28*L28 -> 24 | N28: =IFERROR(VLOOKUP(F28,'_Products'!$A$1:$G$23,5,FALSE),0) -> 6000 | O28: Front | P28: 256.36 | Q28: =P28*M28 -> 6152.75 | R28: =SUM('Bundle Equipment'!E144:E144) -> 464.4 | S28: =MAX(M28*10,500) -> 500 | T28: =Q28+R28+S28 -> 7117.15 | U28: =V$2 -> 0.15 | V28: =IFERROR(T28/(1-U28),0) -> 8373.12 | W28: =V28-T28 -> 1255.97 | X28: =IFERROR(ROUND(M28*0.092903*VLOOKUP(F28,'_Products'!$A$1:$G$23,6,FALSE),0),0) -> 74 | Y28: =IFERROR(ROUND(M28*0.092903*VLOOKUP(F28,'_Products'!$A$1:$G$23,7,FALSE),0),0) -> 1338 | Z28: =Y28*3.412 -> 4565
A29: SOUTH CLUB — SOUTH CLUB | B29: 9 | C29: 16 | D29: 4000 | E29: =IFERROR(VLOOKUP(F29,'_Products'!$A$1:$G$23,2,FALSE),"") -> LG/Yaham | F29: Mesh P10 FM1921 3.9mm Indoor | G29: =IFERROR(VLOOKUP(F29,'_Products'!$A$1:$G$23,3,FALSE),0) -> 3.9 | H29: 9 | I29: 16 | J29: =IFERROR(ROUND(H29*304.8/G29,0),0) -> 703 | K29: =IFERROR(ROUND(I29*304.8/G29,0),0) -> 1250 | L29: 1 | M29: =H29*I29*L29 -> 144 | N29: =IFERROR(VLOOKUP(F29,'_Products'!$A$1:$G$23,5,FALSE),0) -> 6000 | O29: Front | P29: 256.36 | Q29: =P29*M29 -> 36916.47 | R29: =SUM('Bundle Equipment'!E149:E149) -> 536.4 | S29: =MAX(M29*10,500) -> 1440 | T29: =Q29+R29+S29 -> 38892.87 | U29: =V$2 -> 0.15 | V29: =IFERROR(T29/(1-U29),0) -> 45756.32 | W29: =V29-T29 -> 6863.45 | X29: =IFERROR(ROUND(M29*0.092903*VLOOKUP(F29,'_Products'!$A$1:$G$23,6,FALSE),0),0) -> 442 | Y29: =IFERROR(ROUND(M29*0.092903*VLOOKUP(F29,'_Products'!$A$1:$G$23,7,FALSE),0),0) -> 8027 | Z29: =Y29*3.412 -> 27388
A30: ELEV LOBBY — ELEV LOBBY | B30: 4 | C30: 6 | D30: 4000 | E30: =IFERROR(VLOOKUP(F30,'_Products'!$A$1:$G$23,2,FALSE),"") -> LG/Yaham | F30: Mesh P10 FM1921 3.9mm Indoor | G30: =IFERROR(VLOOKUP(F30,'_Products'!$A$1:$G$23,3,FALSE),0) -> 3.9 | H30: 4 | I30: 6 | J30: =IFERROR(ROUND(H30*304.8/G30,0),0) -> 313 | K30: =IFERROR(ROUND(I30*304.8/G30,0),0) -> 469 | L30: 1 | M30: =H30*I30*L30 -> 24 | N30: =IFERROR(VLOOKUP(F30,'_Products'!$A$1:$G$23,5,FALSE),0) -> 6000 | O30: Front | P30: 256.36 | Q30: =P30*M30 -> 6152.75 | R30: =SUM('Bundle Equipment'!E154:E154) -> 464.4 | S30: =MAX(M30*10,500) -> 500 | T30: =Q30+R30+S30 -> 7117.15 | U30: =V$2 -> 0.15 | V30: =IFERROR(T30/(1-U30),0) -> 8373.12 | W30: =V30-T30 -> 1255.97 | X30: =IFERROR(ROUND(M30*0.092903*VLOOKUP(F30,'_Products'!$A$1:$G$23,6,FALSE),0),0) -> 74 | Y30: =IFERROR(ROUND(M30*0.092903*VLOOKUP(F30,'_Products'!$A$1:$G$23,7,FALSE),0),0) -> 1338 | Z30: =Y30*3.412 -> 4565
A31: ELEV LOBBY — ELEV LOBBY | B31: 4 | C31: 6 | D31: 4000 | E31: =IFERROR(VLOOKUP(F31,'_Products'!$A$1:$G$23,2,FALSE),"") -> LG/Yaham | F31: Mesh P10 FM1921 3.9mm Indoor | G31: =IFERROR(VLOOKUP(F31,'_Products'!$A$1:$G$23,3,FALSE),0) -> 3.9 | H31: 4 | I31: 6 | J31: =IFERROR(ROUND(H31*304.8/G31,0),0) -> 313 | K31: =IFERROR(ROUND(I31*304.8/G31,0),0) -> 469 | L31: 1 | M31: =H31*I31*L31 -> 24 | N31: =IFERROR(VLOOKUP(F31,'_Products'!$A$1:$G$23,5,FALSE),0) -> 6000 | O31: Front | P31: 256.36 | Q31: =P31*M31 -> 6152.75 | R31: =SUM('Bundle Equipment'!E159:E159) -> 464.4 | S31: =MAX(M31*10,500) -> 500 | T31: =Q31+R31+S31 -> 7117.15 | U31: =V$2 -> 0.15 | V31: =IFERROR(T31/(1-U31),0) -> 8373.12 | W31: =V31-T31 -> 1255.97 | X31: =IFERROR(ROUND(M31*0.092903*VLOOKUP(F31,'_Products'!$A$1:$G$23,6,FALSE),0),0) -> 74 | Y31: =IFERROR(ROUND(M31*0.092903*VLOOKUP(F31,'_Products'!$A$1:$G$23,7,FALSE),0),0) -> 1338 | Z31: =Y31*3.412 -> 4565
A32: NORTH CLUB — NORTH CLUB | B32: 9 | C32: 16 | D32: 4000 | E32: =IFERROR(VLOOKUP(F32,'_Products'!$A$1:$G$23,2,FALSE),"") -> LG/Yaham | F32: Mesh P10 FM1921 3.9mm Indoor | G32: =IFERROR(VLOOKUP(F32,'_Products'!$A$1:$G$23,3,FALSE),0) -> 3.9 | H32: 9 | I32: 16 | J32: =IFERROR(ROUND(H32*304.8/G32,0),0) -> 703 | K32: =IFERROR(ROUND(I32*304.8/G32,0),0) -> 1250 | L32: 1 | M32: =H32*I32*L32 -> 144 | N32: =IFERROR(VLOOKUP(F32,'_Products'!$A$1:$G$23,5,FALSE),0) -> 6000 | O32: Front | P32: 256.36 | Q32: =P32*M32 -> 36916.47 | R32: =SUM('Bundle Equipment'!E164:E164) -> 536.4 | S32: =MAX(M32*10,500) -> 1440 | T32: =Q32+R32+S32 -> 38892.87 | U32: =V$2 -> 0.15 | V32: =IFERROR(T32/(1-U32),0) -> 45756.32 | W32: =V32-T32 -> 6863.45 | X32: =IFERROR(ROUND(M32*0.092903*VLOOKUP(F32,'_Products'!$A$1:$G$23,6,FALSE),0),0) -> 442 | Y32: =IFERROR(ROUND(M32*0.092903*VLOOKUP(F32,'_Products'!$A$1:$G$23,7,FALSE),0),0) -> 8027 | Z32: =Y32*3.412 -> 27388
