Workbook

Sheet Project Overview
A1: WTC Digital Signage Upgrade — Project Overview
A2: Westfield | 2026-04-01 | ANC Proposal Engine
B4: PROJECT INFORMATION
B5: Client | C5: Westfield
B6: Project Name | C6: WTC Digital Signage Upgrade
B7: Location | C7: New York, NY
B8: Date Created | C8: 2026-04-01
B9: Currency | C9: USD
B10: Environment | C10: Indoor
B11: Union Labor | C11: No
B12: Bond Required | C12: No
B13: Number of Displays | C13: =SUM('LED Cost Sheet'!I4:I14) -> 22
B15: FINANCIAL PARAMETERS
B16: LED Hardware Margin | C16: 15%
B17: Install / Services Margin | C17: 15%
B18: Engineering Margin | C18: 15%
B19: Equipment Margin | C19: 15%
B20: CMS Margin | C20: 15%
B21: Bond Rate | C21: N/A
B22: Tax Rate | C22: Per zone (editable on MA)
B23: Tariff Rate | C23: Per zone (editable on MA)
B25: SUMMARY TOTALS
B26: Total Cost | C26: ='Margin Analysis'!C158 -> 3435750.1
B27: Total Selling Price | C27: ='Margin Analysis'!D158 -> 3967550.8
B28: Project Margin $ | C28: ='Margin Analysis'!E158 -> 531800.62
B29: Project Margin % | C29: ='Margin Analysis'!F158 -> 0.13
B30: DOCUMENT TOTAL | C30: ='Margin Analysis'!D158 -> 3967550.8

Sheet Margin Analysis
A1: WTC Digital Signage Upgrade — Margin Analysis
A2: Westfield | 2026-04-01 | ANC Proposal Engine
B4: Zone / Category | C4: Cost | D4: Selling Price | E4: Margin $ | F4: Margin %
B5: Underpass 3 — Underpass 1-4, WTC | D5: Selling Price
B6: LED Hardware | C6: ='LED Cost Sheet'!T4 -> 68046.11 | D6: ='LED Cost Sheet'!V4 -> 80054.25 | E6: =IFERROR(D6-C6,0) -> 12008.14 | F6: 0.15
B7: Structural Materials | C7: ='Underpass 3 - Install'!I26 -> 4102.5 | D7: =IFERROR(C7/(1-F7),0) -> 4826.47 | E7: =IFERROR(D7-C7,0) -> 723.97 | F7: 0.15
B8: Structural Labor & LED Installation | C8: ='Underpass 3 - Install'!I35-'Underpass 3 - Install'!I34 -> 17093.75 | D8: =IFERROR(C8/(1-F8),0) -> 20110.29 | E8: =IFERROR(D8-C8,0) -> 3016.54 | F8: 0.15
B9: Electrical & Data | C9: ='Underpass 3 - Install'!I44 -> 17093.75 | D9: =IFERROR(C9/(1-F9),0) -> 20110.29 | E9: =IFERROR(D9-C9,0) -> 3016.54 | F9: 0.15
B10: PM / General Conditions / Travel | C10: ='Underpass 3 - Install'!I34 -> 20882.35 | D10: =IFERROR(C10/(1-F10),0) -> 24567.47 | E10: =IFERROR(D10-C10,0) -> 3685.12 | F10: 0.15
B11: Engineering & Permits | C11: ='Underpass 3 - Install'!I52 -> 4705.88 | D11: =IFERROR(C11/(1-F11),0) -> 5536.33 | E11: =IFERROR(D11-C11,0) -> 830.45 | F11: 0.15
B12: SUBTOTAL | C12: =SUM(C6:C11) -> 131924.34 | D12: =SUM(D6:D11) -> 152572.17 | E12: =IFERROR(D12-C12,0) -> 20647.83 | F12: =IFERROR(1-C12/D12,0) -> 0.135332
B13: TAX | C13: 0 | D13: 0 | E13: 0 | G13: 0
B14: BOND | C14: 0 | D14: 0 | E14: 0 | G14: 0
B15: TARIFF | C15: 0 | D15: 0 | E15: 0 | G15: 0
B16: GRAND TOTAL | C16: =C12+C13+C14+C15 -> 131924.34 | D16: =D12+D13+D14+D15 -> 152572.17 | E16: =IFERROR(D16-C16,0) -> 20647.83 | F16: =IFERROR(1-C16/D16,0) -> 0.13533156
B18: Underpass 4 — Underpass 1-4, WTC | D18: Selling Price
B19: LED Hardware | C19: ='LED Cost Sheet'!T5 -> 134265.3 | D19: ='LED Cost Sheet'!V5 -> 157959.18 | E19: =IFERROR(D19-C19,0) -> 23693.88 | F19: 0.15
B20: Structural Materials | C20: ='Underpass 4 - Install'!I26 -> 6907.5 | D20: =IFERROR(C20/(1-F20),0) -> 8126.47 | E20: =IFERROR(D20-C20,0) -> 1218.97 | F20: 0.15
B21: Structural Labor & LED Installation | C21: ='Underpass 4 - Install'!I35-'Underpass 4 - Install'!I34 -> 28781.25 | D21: =IFERROR(C21/(1-F21),0) -> 33860.29 | E21: =IFERROR(D21-C21,0) -> 5079.04 | F21: 0.15
B22: Electrical & Data | C22: ='Underpass 4 - Install'!I44 -> 28781.25 | D22: =IFERROR(C22/(1-F22),0) -> 33860.29 | E22: =IFERROR(D22-C22,0) -> 5079.04 | F22: 0.15
B23: PM / General Conditions / Travel | C23: ='Underpass 4 - Install'!I34 -> 20882.35 | D23: =IFERROR(C23/(1-F23),0) -> 24567.47 | E23: =IFERROR(D23-C23,0) -> 3685.12 | F23: 0.15
B24: Engineering & Permits | C24: ='Underpass 4 - Install'!I52 -> 4705.88 | D24: =IFERROR(C24/(1-F24),0) -> 5536.33 | E24: =IFERROR(D24-C24,0) -> 830.45 | F24: 0.15
B25: SUBTOTAL | C25: =SUM(C19:C24) -> 224323.53 | D25: =SUM(D19:D24) -> 259474.86 | E25: =IFERROR(D25-C25,0) -> 35151.33 | F25: =IFERROR(1-C25/D25,0) -> 0.135471
B26: TAX | C26: 0 | D26: 0 | E26: 0 | G26: 0
B27: BOND | C27: 0 | D27: 0 | E27: 0 | G27: 0
B28: TARIFF | C28: 0 | D28: 0 | E28: 0 | G28: 0
B29: GRAND TOTAL | C29: =C25+C26+C27+C28 -> 224323.53 | D29: =D25+D26+D27+D28 -> 259474.86 | E29: =IFERROR(D29-C29,0) -> 35151.33 | F29: =IFERROR(1-C29/D29,0) -> 0.13547104
B31: Concourse — Concourse, WTC | D31: Selling Price
B32: LED Hardware | C32: ='LED Cost Sheet'!T6 -> 845677.52 | D32: ='LED Cost Sheet'!V6 -> 994914.73 | E32: =IFERROR(D32-C32,0) -> 149237.21 | F32: 0.15
B33: Structural Materials | C33: ='Concourse - Install'!I26 -> 48536.25 | D33: =IFERROR(C33/(1-F33),0) -> 57101.47 | E33: =IFERROR(D33-C33,0) -> 8565.22 | F33: 0.15
B34: Structural Labor & LED Installation | C34: ='Concourse - Install'!I35-'Concourse - Install'!I34 -> 202234.38 | D34: =IFERROR(C34/(1-F34),0) -> 237922.8 | E34: =IFERROR(D34-C34,0) -> 35688.42 | F34: 0.15
B35: Electrical & Data | C35: ='Concourse - Install'!I44 -> 202234.38 | D35: =IFERROR(C35/(1-F35),0) -> 237922.8 | E35: =IFERROR(D35-C35,0) -> 35688.42 | F35: 0.15
B36: PM / General Conditions / Travel | C36: ='Concourse - Install'!I34 -> 20882.35 | D36: =IFERROR(C36/(1-F36),0) -> 24567.47 | E36: =IFERROR(D36-C36,0) -> 3685.12 | F36: 0.15
B37: Engineering & Permits | C37: ='Concourse - Install'!I52 -> 4705.88 | D37: =IFERROR(C37/(1-F37),0) -> 5536.33 | E37: =IFERROR(D37-C37,0) -> 830.45 | F37: 0.15
B38: SUBTOTAL | C38: =SUM(C32:C37) -> 1324270.8 | D38: =SUM(D32:D37) -> 1526801.7 | E38: =IFERROR(D38-C38,0) -> 202530.95 | F38: =IFERROR(1-C38/D38,0) -> 0.13265
B39: TAX | C39: 0 | D39: 0 | E39: 0 | G39: 0
B40: BOND | C40: 0 | D40: 0 | E40: 0 | G40: 0
B41: TARIFF | C41: 0 | D41: 0 | E41: 0 | G41: 0
B42: GRAND TOTAL | C42: =C38+C39+C40+C41 -> 1324270.8 | D42: =D38+D39+D40+D41 -> 1526801.7 | E42: =IFERROR(D42-C42,0) -> 202530.95 | F42: =IFERROR(1-C42/D42,0) -> 0.13265046
B44: T4-B1 (6-9) — T4-B1, WTC | D44: Selling Price
...

Sheet Budget Summary
A1: WTC Digital Signage Upgrade — Budget Summary
A2: Westfield | 2026-04-01 | By Category
B4: Category | C4: Cost | D4: Selling Price | E4: Margin $ | F4: Margin % | G4: Price / SqFt
B5: LED Hardware (all displays) | C5: =SUM('LED Cost Sheet'!Q4:Q14) -> 2071099.6 | D5: =SUM('LED Cost Sheet'!S4:S14) -> 2436587.7 | E5: =IFERROR(D5-C5,0) -> 365488.16 | F5: 0.15 | G5: =IFERROR(C5/6333.2,0) -> 327.02
B6: Structural Materials | C6: =SUM('Underpass 3 - Install'!I26:I26)+SUM('Underpass 4 - Install'!I26:I26)+SUM('Concourse - Install'!I26:I26)+SUM('T4-B1 (6-9) - Install'!I26:I26)+SUM('T4-B2 (10-18) - Install'!I26:I26)+SUM('T4 Lobby Elevator - Install'!I26:I26)+SUM('T2-B1M Screen 20 - Install'!I26:I26)+SUM('T2-B1M Screen 21 - Install'!I26:I26)+SUM('T2-B1M Screen 22 - Install'!I26:I26)+SUM('New Path Hall Option 1 - Instal'!I26:I26)+SUM('New Path Hall Option 2 - Instal'!I26:I26) -> 116055 | D6: =SUM('Underpass 3 - Install'!K26:K26)+SUM('Underpass 4 - Install'!K26:K26)+SUM('Concourse - Install'!K26:K26)+SUM('T4-B1 (6-9) - Install'!K26:K26)+SUM('T4-B2 (10-18) - Install'!K26:K26)+SUM('T4 Lobby Elevator - Install'!K26:K26)+SUM('T2-B1M Screen 20 - Install'!K26:K26)+SUM('T2-B1M Screen 21 - Install'!K26:K26)+SUM('T2-B1M Screen 22 - Install'!K26:K26)+SUM('New Path Hall Option 1 - Instal'!K26:K26)+SUM('New Path Hall Option 2 - Instal'!K26:K26) -> 136535.29 | E6: =IFERROR(D6-C6,0) -> 20480.29 | F6: 0.15 | G6: =IFERROR(C6/6333.2,0) -> 18.32
B7: Structural Labor & LED Installation | C7: =(SUM('Underpass 3 - Install'!I35:I35)-SUM('Underpass 3 - Install'!I34:I34))+(SUM('Underpass 4 - Install'!I35:I35)-SUM('Underpass 4 - Install'!I34:I34))+(SUM('Concourse - Install'!I35:I35)-SUM('Concourse - Install'!I34:I34))+(SUM('T4-B1 (6-9) - Install'!I35:I35)-SUM('T4-B1 (6-9) - Install'!I34:I34))+(SUM('T4-B2 (10-18) - Install'!I35:I35)-SUM('T4-B2 (10-18) - Install'!I34:I34))+(SUM('T4 Lobby Elevator - Install'!I35:I35)-SUM('T4 Lobby Elevator - Install'!I34:I34))+(SUM('T2-B1M Screen 20 - Install'!I35:I35)-SUM('T2-B1M Screen 20 - Install'!I34:I34))+(SUM('T2-B1M Screen 21 - Install'!I35:I35)-SUM('T2-B1M Screen 21 - Install'!I34:I34))+(SUM('T2-B1M Screen 22 - Install'!I35:I35)-SUM('T2-B1M Screen 22 - Install'!I34:I34))+(SUM('New Path Hall Option 1 - Instal'!I35:I35)-SUM('New Path Hall Option 1 - Instal'!I34:I34))+(SUM('New Path Hall Option 2 - Instal'!I35:I35)-SUM('New Path Hall Option 2 - Instal'!I34:I34)) -> 483562.52 | D7: =(SUM('Underpass 3 - Install'!K35:K35)-SUM('Underpass 3 - Install'!K34:K34))+(SUM('Underpass 4 - Install'!K35:K35)-SUM('Underpass 4 - Install'!K34:K34))+(SUM('Concourse - Install'!K35:K35)-SUM('Concourse - Install'!K34:K34))+(SUM('T4-B1 (6-9) - Install'!K35:K35)-SUM('T4-B1 (6-9) - Install'!K34:K34))+(SUM('T4-B2 (10-18) - Install'!K35:K35)-SUM('T4-B2 (10-18) - Install'!K34:K34))+(SUM('T4 Lobby Elevator - Install'!K35:K35)-SUM('T4 Lobby Elevator - Install'!K34:K34))+(SUM('T2-B1M Screen 20 - Install'!K35:K35)-SUM('T2-B1M Screen 20 - Install'!K34:K34))+(SUM('T2-B1M Screen 21 - Install'!K35:K35)-SUM('T2-B1M Screen 21 - Install'!K34:K34))+(SUM('T2-B1M Screen 22 - Install'!K35:K35)-SUM('T2-B1M Screen 22 - Install'!K34:K34))+(SUM('New Path Hall Option 1 - Instal'!K35:K35)-SUM('New Path Hall Option 1 - Instal'!K34:K34))+(SUM('New Path Hall Option 2 - Instal'!K35:K35)-SUM('New Path Hall Option 2 - Instal'!K34:K34)) -> 568897.08 | E7: =IFERROR(D7-C7,0) -> 85334.56 | F7: 0.15 | G7: =IFERROR(C7/6333.2,0) -> 76.35
B8: Electrical & Data | C8: =SUM('Underpass 3 - Install'!I44:I44)+SUM('Underpass 4 - Install'!I44:I44)+SUM('Concourse - Install'!I44:I44)+SUM('T4-B1 (6-9) - Install'!I44:I44)+SUM('T4-B2 (10-18) - Install'!I44:I44)+SUM('T4 Lobby Elevator - Install'!I44:I44)+SUM('T2-B1M Screen 20 - Install'!I44:I44)+SUM('T2-B1M Screen 21 - Install'!I44:I44)+SUM('T2-B1M Screen 22 - Install'!I44:I44)+SUM('New Path Hall Option 1 - Instal'!I44:I44)+SUM('New Path Hall Option 2 - Instal'!I44:I44) -> 483562.52 | D8: =SUM('Underpass 3 - Install'!K44:K44)+SUM('Underpass 4 - Install'!K44:K44)+SUM('Concourse - Install'!K44:K44)+SUM('T4-B1 (6-9) - Install'!K44:K44)+SUM('T4-B2 (10-18) - Install'!K44:K44)+SUM('T4 Lobby Elevator - Install'!K44:K44)+SUM('T2-B1M Screen 20 - Install'!K44:K44)+SUM('T2-B1M Screen 21 - Install'!K44:K44)+SUM('T2-B1M Screen 22 - Install'!K44:K44)+SUM('New Path Hall Option 1 - Instal'!K44:K44)+SUM('New Path Hall Option 2 - Instal'!K44:K44) -> 568897.08 | E8: =IFERROR(D8-C8,0) -> 85334.56 | F8: 0.15 | G8: =IFERROR(C8/6333.2,0) -> 76.35
B9: PM / General Conditions / Travel | C9: =SUM('Underpass 3 - Install'!I34:I34)+SUM('Underpass 4 - Install'!I34:I34)+SUM('Concourse - Install'!I34:I34)+SUM('T4-B1 (6-9) - Install'!I34:I34)+SUM('T4-B2 (10-18) - Install'!I34:I34)+SUM('T4 Lobby Elevator - Install'!I34:I34)+SUM('T2-B1M Screen 20 - Install'!I34:I34)+SUM('T2-B1M Screen 21 - Install'!I34:I34)+SUM('T2-B1M Screen 22 - Install'!I34:I34)+SUM('New Path Hall Option 1 - Instal'!I34:I34)+SUM('New Path Hall Option 2 - Instal'!I34:I34) -> 229705.85 | D9: =SUM('Underpass 3 - Install'!K34:K34)+SUM('Underpass 4 - Install'!K34:K34)+SUM('Concourse - Install'!K34:K34)+SUM('T4-B1 (6-9) - Install'!K34:K34)+SUM('T4-B2 (10-18) - Install'!K34:K34)+SUM('T4 Lobby Elevator - Install'!K34:K34)+SUM('T2-B1M Screen 20 - Install'!K34:K34)+SUM('T2-B1M Screen 21 - Install'!K34:K34)+SUM('T2-B1M Screen 22 - Install'!K34:K34)+SUM('New Path Hall Option 1 - Instal'!K34:K34)+SUM('New Path Hall Option 2 - Instal'!K34:K34) -> 270242.18 | E9: =IFERROR(D9-C9,0) -> 40536.33 | F9: 0.15
B10: Engineering & Permits | C10: =SUM('Underpass 3 - Install'!I52:I52)+SUM('Underpass 4 - Install'!I52:I52)+SUM('Concourse - Install'!I52:I52)+SUM('T4-B1 (6-9) - Install'!I52:I52)+SUM('T4-B2 (10-18) - Install'!I52:I52)+SUM('T4 Lobby Elevator - Install'!I52:I52)+SUM('T2-B1M Screen 20 - Install'!I52:I52)+SUM('T2-B1M Screen 21 - Install'!I52:I52)+SUM('T2-B1M Screen 22 - Install'!I52:I52)+SUM('New Path Hall Option 1 - Instal'!I52:I52)+SUM('New Path Hall Option 2 - Instal'!I52:I52) -> 51764.68 | D10: =SUM('Underpass 3 - Install'!K52:K52)+SUM('Underpass 4 - Install'!K52:K52)+SUM('Concourse - Install'!K52:K52)+SUM('T4-B1 (6-9) - Install'!K52:K52)+SUM('T4-B2 (10-18) - Install'!K52:K52)+SUM('T4 Lobby Elevator - Install'!K52:K52)+SUM('T2-B1M Screen 20 - Install'!K52:K52)+SUM('T2-B1M Screen 21 - Install'!K52:K52)+SUM('T2-B1M Screen 22 - Install'!K52:K52)+SUM('New Path Hall Option 1 - Instal'!K52:K52)+SUM('New Path Hall Option 2 - Instal'!K52:K52) -> 60899.62 | E10: =IFERROR(D10-C10,0) -> 9134.94 | F10: 0.15
B11: CMS (Content Management System) | C11: =SUM(CMS!F26:F26) -> 0 | D11: =SUM(CMS!H26:H26) -> 0 | E11: =IFERROR(D11-C11,0) -> 0 | F11: 0.15
B12: Scoring System | C12: =SUM(Scoring!F27:F27) -> 0 | D12: =SUM(Scoring!H27:H27) -> 0 | E12: =IFERROR(D12-C12,0) -> 0 | F12: 0.15
B13: Venue Services | C13: =SUM('Venue Services'!B17:B17) -> 0 | D13: =SUM('Venue Services'!C17:C17) -> 0 | E13: =IFERROR(D13-C13,0) -> 0 | F13: 0.15
B14: Game Clock | C14: =SUM('Additional Items'!F5:F5) -> 0 | D14: =SUM('Additional Items'!H5:H5) -> 0 | E14: =IFERROR(D14-C14,0) -> 0 | F14: 0.15
B15: Pitch Clocks | C15: =SUM('Additional Items'!F6:F6) -> 0 | D15: =SUM('Additional Items'!H6:H6) -> 0 | E15: =IFERROR(D15-C15,0) -> 0 | F15: 0.15
B16: OES / MIS / Timing | C16: =SUM('Additional Items'!F7:F7) -> 0 | D16: =SUM('Additional Items'!H7:H7) -> 0 | E16: =IFERROR(D16-C16,0) -> 0 | F16: 0.15
B17: DMX / Misc Equipment | C17: =SUM('Additional Items'!F8:F8) -> 0 | D17: =SUM('Additional Items'!H8:H8) -> 0 | E17: =IFERROR(D17-C17,0) -> 0 | F17: 0.15
B19: SUBTOTAL | C19: =SUM(C5:C17) -> 3435750.1 | D19: =SUM(D5:D17) -> 3967550.8 | E19: =IFERROR(D19-C19,0) -> 531800.62 | F19: =IFERROR(1-C19/D19,0) -> 0.13 | G19: =IFERROR(C19/6333.2,0) -> 542.5
B20: TAX | C20: 0 | D20: 0 | E20: 0 | F20: 0
B21: BOND | C21: 0 | D21: 0 | E21: 0 | F21: 0
B22: GRAND TOTAL | C22: =C19+C20+C21 -> 3435750.1 | D22: =D19+D20+D21 -> 3967550.8 | E22: =IFERROR(D22-C22,0) -> 531800.62 | F22: =IFERROR(1-C22/D22,0) -> 0.13 | G22: =IFERROR(C22/6333.2,0) -> 542.5

Sheet LED Cost Sheet
A1: WTC Digital Signage Upgrade — LED Cost Sheet
U2: LED Margin Override → | V2: 0.15
A3: Display | B3: RFP H (ft) | C3: RFP W (ft) | D3: RFP NITs | E3: Vendor | F3: Product | G3: Pitch | H3: H (ft) | I3: W (ft) | J3: H (px) | K3: W (px) | L3: Qty | M3: Total SqFt | N3: Product NITs | O3: Service | P3: $/SqFt | Q3: Display Cost | R3: Processor | S3: Shipping | T3: Total Cost | U3: Margin % | V3: Selling Price | W3: ANC Margin | X3: Weight (lbs) | Y3: Total Power (W) | Z3: BTU/hr
A4: Underpass 3 — Underpass 1-4, WTC | B4: 7.48 | C4: 29.92 | E4: =IFERROR(VLOOKUP(F4,'_Products'!$A$1:$G$23,2,FALSE),"") -> LG/Yaham | F4: C2.5-MIP 2.5mm Indoor (Alt) | G4: =IFERROR(VLOOKUP(F4,'_Products'!$A$1:$G$23,3,FALSE),0) -> 2.5 | H4: 7.48 | I4: 29.92 | J4: =IFERROR(ROUND(H4*304.8/G4,0),0) -> 912 | K4: =IFERROR(ROUND(I4*304.8/G4,0),0) -> 3648 | L4: 1 | M4: =H4*I4*L4 -> 223.8 | N4: =IFERROR(VLOOKUP(F4,'_Products'!$A$1:$G$23,5,FALSE),0) -> 2000 | O4: front | P4: =IFERROR(VLOOKUP(F4,'_Products'!$A$1:$G$23,4,FALSE),0) -> 291.44 | Q4: =P4*M4 -> 65223.83 | R4: =SUM('Bundle Equipment'!E10:E10) -> 584.28 | S4: =MAX(M4*10,500) -> 2238 | T4: =Q4+R4+S4 -> 68046.11 | U4: =V$2 -> 0.15 | V4: =IFERROR(T4/(1-U4),0) -> 80054.25 | W4: =V4-T4 -> 12008.14 | X4: =IFERROR(ROUND(M4*0.092903*VLOOKUP(F4,'_Products'!$A$1:$G$23,6,FALSE),0),0) -> 1094 | Y4: =IFERROR(ROUND(M4*0.092903*VLOOKUP(F4,'_Products'!$A$1:$G$23,7,FALSE),0),0) -> 8121 | Z4: =Y4*3.412 -> 27709
A5: Underpass 4 — Underpass 1-4, WTC | B5: 12.6 | C5: 29.92 | E5: =IFERROR(VLOOKUP(F5,'_Products'!$A$1:$G$23,2,FALSE),"") -> LG/Yaham | F5: C2.5-MIP 2.5mm Indoor (Alt) | G5: =IFERROR(VLOOKUP(F5,'_Products'!$A$1:$G$23,3,FALSE),0) -> 2.5 | H5: 12.6 | I5: 29.92 | J5: =IFERROR(ROUND(H5*304.8/G5,0),0) -> 1536 | K5: =IFERROR(ROUND(I5*304.8/G5,0),0) -> 3648 | L5: 1 | M5: =H5*I5*L5 -> 376.99 | N5: =IFERROR(VLOOKUP(F5,'_Products'!$A$1:$G$23,5,FALSE),0) -> 2000 | O5: front | P5: =IFERROR(VLOOKUP(F5,'_Products'!$A$1:$G$23,4,FALSE),0) -> 291.44 | Q5: =P5*M5 -> 109869.21 | R5: =SUM('Bundle Equipment'!E16:E16) -> 20626.19 | S5: =MAX(M5*10,500) -> 3769.9 | T5: =Q5+R5+S5 -> 134265.3 | U5: =V$2 -> 0.15 | V5: =IFERROR(T5/(1-U5),0) -> 157959.18 | W5: =V5-T5 -> 23693.88 | X5: =IFERROR(ROUND(M5*0.092903*VLOOKUP(F5,'_Products'!$A$1:$G$23,6,FALSE),0),0) -> 1842 | Y5: =IFERROR(ROUND(M5*0.092903*VLOOKUP(F5,'_Products'!$A$1:$G$23,7,FALSE),0),0) -> 13680 | Z5: =Y5*3.412 -> 46676
A6: Concourse — Concourse, WTC | B6: 9.45 | C6: 280.31 | E6: =IFERROR(VLOOKUP(F6,'_Products'!$A$1:$G$23,2,FALSE),"") -> LG/Yaham | F6: C2.5-MIP 2.5mm Indoor (Alt) | G6: =IFERROR(VLOOKUP(F6,'_Products'!$A$1:$G$23,3,FALSE),0) -> 2.5 | H6: 9.45 | I6: 280.31 | J6: =IFERROR(ROUND(H6*304.8/G6,0),0) -> 1152 | K6: =IFERROR(ROUND(I6*304.8/G6,0),0) -> 34175 | L6: 1 | M6: =H6*I6*L6 -> 2648.93 | N6: =IFERROR(VLOOKUP(F6,'_Products'!$A$1:$G$23,5,FALSE),0) -> 2000 | O6: front | P6: =IFERROR(VLOOKUP(F6,'_Products'!$A$1:$G$23,4,FALSE),0) -> 291.44 | Q6: =P6*M6 -> 771998.86 | R6: =SUM('Bundle Equipment'!E22:E22) -> 47189.36 | S6: =MAX(M6*10,500) -> 26489.3 | T6: =Q6+R6+S6 -> 845677.52 | U6: =V$2 -> 0.15 | V6: =IFERROR(T6/(1-U6),0) -> 994914.73 | W6: =V6-T6 -> 149237.21 | X6: =IFERROR(ROUND(M6*0.092903*VLOOKUP(F6,'_Products'!$A$1:$G$23,6,FALSE),0),0) -> 12945 | Y6: =IFERROR(ROUND(M6*0.092903*VLOOKUP(F6,'_Products'!$A$1:$G$23,7,FALSE),0),0) -> 96124 | Z6: =Y6*3.412 -> 327975
A7: T4-B1 (6-9) — T4-B1, WTC | B7: 7.87 | C7: 8.66 | E7: =IFERROR(VLOOKUP(F7,'_Products'!$A$1:$G$23,2,FALSE),"") -> LG/Yaham | F7: C2.5-MIP 2.5mm Indoor (Alt) | G7: =IFERROR(VLOOKUP(F7,'_Products'!$A$1:$G$23,3,FALSE),0) -> 2.5 | H7: 7.87 | I7: 8.66 | J7: =IFERROR(ROUND(H7*304.8/G7,0),0) -> 960 | K7: =IFERROR(ROUND(I7*304.8/G7,0),0) -> 1056 | L7: 4 | M7: =H7*I7*L7 -> 272.62 | N7: =IFERROR(VLOOKUP(F7,'_Products'!$A$1:$G$23,5,FALSE),0) -> 2000 | O7: front | P7: =IFERROR(VLOOKUP(F7,'_Products'!$A$1:$G$23,4,FALSE),0) -> 291.42 | Q7: =P7*M7 -> 79446 | R7: =SUM('Bundle Equipment'!E27:E27) -> 613.57 | S7: =MAX(M7*10,500) -> 2726.2 | T7: =Q7+R7+S7 -> 82785.77 | U7: =V$2 -> 0.15 | V7: =IFERROR(T7/(1-U7),0) -> 97395.02 | W7: =V7-T7 -> 14609.25 | X7: =IFERROR(ROUND(M7*0.092903*VLOOKUP(F7,'_Products'!$A$1:$G$23,6,FALSE),0),0) -> 1332 | Y7: =IFERROR(ROUND(M7*0.092903*VLOOKUP(F7,'_Products'!$A$1:$G$23,7,FALSE),0),0) -> 9893 | Z7: =Y7*3.412 -> 33755
A8: T4-B2 (10-18) — T4-B2, WTC | B8: 7.87 | C8: 8.66 | E8: =IFERROR(VLOOKUP(F8,'_Products'!$A$1:$G$23,2,FALSE),"") -> LG/Yaham | F8: C2.5-MIP 2.5mm Indoor (Alt) | G8: =IFERROR(VLOOKUP(F8,'_Products'!$A$1:$G$23,3,FALSE),0) -> 2.5 | H8: 7.87 | I8: 8.66 | J8: =IFERROR(ROUND(H8*304.8/G8,0),0) -> 960 | K8: =IFERROR(ROUND(I8*304.8/G8,0),0) -> 1056 | L8: 9 | M8: =H8*I8*L8 -> 613.39 | N8: =IFERROR(VLOOKUP(F8,'_Products'!$A$1:$G$23,5,FALSE),0) -> 2000 | O8: front | P8: =IFERROR(VLOOKUP(F8,'_Products'!$A$1:$G$23,4,FALSE),0) -> 291.42 | Q8: =P8*M8 -> 178753.5 | R8: =SUM('Bundle Equipment'!E33:E33) -> 20768.03 | S8: =MAX(M8*10,500) -> 6133.9 | T8: =Q8+R8+S8 -> 205655.43 | U8: =V$2 -> 0.15 | V8: =IFERROR(T8/(1-U8),0) -> 241947.56 | W8: =V8-T8 -> 36292.13 | X8: =IFERROR(ROUND(M8*0.092903*VLOOKUP(F8,'_Products'!$A$1:$G$23,6,FALSE),0),0) -> 2997 | Y8: =IFERROR(ROUND(M8*0.092903*VLOOKUP(F8,'_Products'!$A$1:$G$23,7,FALSE),0),0) -> 22259 | Z8: =Y8*3.412 -> 75948
A9: T4 Lobby Elevator — T4 Lobby Elevator, WTC | B9: 71.6 | C9: 5.5 | E9: =IFERROR(VLOOKUP(F9,'_Products'!$A$1:$G$23,2,FALSE),"") -> LG/Yaham | F9: C2.5-MIP 2.5mm Indoor (Alt) | G9: =IFERROR(VLOOKUP(F9,'_Products'!$A$1:$G$23,3,FALSE),0) -> 2.5 | H9: 71.6 | I9: 5.5 | J9: =IFERROR(ROUND(H9*304.8/G9,0),0) -> 8729 | K9: =IFERROR(ROUND(I9*304.8/G9,0),0) -> 671 | L9: 1 | M9: =H9*I9*L9 -> 393.8 | N9: =IFERROR(VLOOKUP(F9,'_Products'!$A$1:$G$23,5,FALSE),0) -> 2000 | O9: front | P9: =IFERROR(VLOOKUP(F9,'_Products'!$A$1:$G$23,4,FALSE),0) -> 291.44 | Q9: =P9*M9 -> 114768.29 | R9: =SUM('Bundle Equipment'!E39:E39) -> 20636.28 | S9: =MAX(M9*10,500) -> 3938 | T9: =Q9+R9+S9 -> 139342.57 | U9: =V$2 -> 0.15 | V9: =IFERROR(T9/(1-U9),0) -> 163932.44 | W9: =V9-T9 -> 24589.87 | X9: =IFERROR(ROUND(M9*0.092903*VLOOKUP(F9,'_Products'!$A$1:$G$23,6,FALSE),0),0) -> 1924 | Y9: =IFERROR(ROUND(M9*0.092903*VLOOKUP(F9,'_Products'!$A$1:$G$23,7,FALSE),0),0) -> 14290 | Z9: =Y9*3.412 -> 48757
A10: T2-B1M Screen 20 — T2-B1M, WTC | B10: 7.91 | C10: 16.5 | E10: =IFERROR(VLOOKUP(F10,'_Products'!$A$1:$G$23,2,FALSE),"") -> LG/Yaham | F10: C2.5-MIP 2.5mm Indoor (Alt) | G10: =IFERROR(VLOOKUP(F10,'_Products'!$A$1:$G$23,3,FALSE),0) -> 2.5 | H10: 7.91 | I10: 16.5 | J10: =IFERROR(ROUND(H10*304.8/G10,0),0) -> 964 | K10: =IFERROR(ROUND(I10*304.8/G10,0),0) -> 2012 | L10: 1 | M10: =H10*I10*L10 -> 130.52 | N10: =IFERROR(VLOOKUP(F10,'_Products'!$A$1:$G$23,5,FALSE),0) -> 2000 | O10: front | P10: =IFERROR(VLOOKUP(F10,'_Products'!$A$1:$G$23,4,FALSE),0) -> 291.44 | Q10: =P10*M10 -> 38038.49 | R10: =SUM('Bundle Equipment'!E44:E44) -> 528.31 | S10: =MAX(M10*10,500) -> 1305.2 | T10: =Q10+R10+S10 -> 39872 | U10: =V$2 -> 0.15 | V10: =IFERROR(T10/(1-U10),0) -> 46908.24 | W10: =V10-T10 -> 7036.24 | X10: =IFERROR(ROUND(M10*0.092903*VLOOKUP(F10,'_Products'!$A$1:$G$23,6,FALSE),0),0) -> 638 | Y10: =IFERROR(ROUND(M10*0.092903*VLOOKUP(F10,'_Products'!$A$1:$G$23,7,FALSE),0),0) -> 4736 | Z10: =Y10*3.412 -> 16159
A11: T2-B1M Screen 21 — T2-B1M, WTC | B11: 7.91 | C11: 11.83 | E11: =IFERROR(VLOOKUP(F11,'_Products'!$A$1:$G$23,2,FALSE),"") -> LG/Yaham | F11: C2.5-MIP 2.5mm Indoor (Alt) | G11: =IFERROR(VLOOKUP(F11,'_Products'!$A$1:$G$23,3,FALSE),0) -> 2.5 | H11: 7.91 | I11: 11.83 | J11: =IFERROR(ROUND(H11*304.8/G11,0),0) -> 964 | K11: =IFERROR(ROUND(I11*304.8/G11,0),0) -> 1442 | L11: 1 | M11: =H11*I11*L11 -> 93.58 | N11: =IFERROR(VLOOKUP(F11,'_Products'!$A$1:$G$23,5,FALSE),0) -> 2000 | O11: front | P11: =IFERROR(VLOOKUP(F11,'_Products'!$A$1:$G$23,4,FALSE),0) -> 291.44 | Q11: =P11*M11 -> 27272.76 | R11: =SUM('Bundle Equipment'!E49:E49) -> 506.15 | S11: =MAX(M11*10,500) -> 935.8 | T11: =Q11+R11+S11 -> 28714.71 | U11: =V$2 -> 0.15 | V11: =IFERROR(T11/(1-U11),0) -> 33782.01 | W11: =V11-T11 -> 5067.3 | X11: =IFERROR(ROUND(M11*0.092903*VLOOKUP(F11,'_Products'!$A$1:$G$23,6,FALSE),0),0) -> 457 | Y11: =IFERROR(ROUND(M11*0.092903*VLOOKUP(F11,'_Products'!$A$1:$G$23,7,FALSE),0),0) -> 3396 | Z11: =Y11*3.412 -> 11587
A12: T2-B1M Screen 22 — T2-B1M, WTC | B12: 7.91 | C12: 7.91 | E12: =IFERROR(VLOOKUP(F12,'_Products'!$A$1:$G$23,2,FALSE),"") -> LG/Yaham | F12: C2.5-MIP 2.5mm Indoor (Alt) | G12: =IFERROR(VLOOKUP(F12,'_Products'!$A$1:$G$23,3,FALSE),0) -> 2.5 | H12: 7.91 | I12: 7.91 | J12: =IFERROR(ROUND(H12*304.8/G12,0),0) -> 964 | K12: =IFERROR(ROUND(I12*304.8/G12,0),0) -> 964 | L12: 1 | M12: =H12*I12*L12 -> 62.57 | N12: =IFERROR(VLOOKUP(F12,'_Products'!$A$1:$G$23,5,FALSE),0) -> 2000 | O12: front | P12: =IFERROR(VLOOKUP(F12,'_Products'!$A$1:$G$23,4,FALSE),0) -> 291.44 | Q12: =P12*M12 -> 18235.28 | R12: =SUM('Bundle Equipment'!E54:E54) -> 487.54 | S12: =MAX(M12*10,500) -> 625.7 | T12: =Q12+R12+S12 -> 19348.52 | U12: =V$2 -> 0.15 | V12: =IFERROR(T12/(1-U12),0) -> 22762.96 | W12: =V12-T12 -> 3414.44 | X12: =IFERROR(ROUND(M12*0.092903*VLOOKUP(F12,'_Products'!$A$1:$G$23,6,FALSE),0),0) -> 306 | Y12: =IFERROR(ROUND(M12*0.092903*VLOOKUP(F12,'_Products'!$A$1:$G$23,7,FALSE),0),0) -> 2271 | Z12: =Y12*3.412 -> 7749
A13: New Path Hall Option 1 — New Path Hall, WTC | B13: 48 | C13: 14 | E13: =IFERROR(VLOOKUP(F13,'_Products'!$A$1:$G$23,2,FALSE),"") -> LG/Yaham | F13: C2.5-MIP 2.5mm Indoor (Alt) | G13: =IFERROR(VLOOKUP(F13,'_Products'!$A$1:$G$23,3,FALSE),0) -> 2.5 | H13: 48 | I13: 14 | J13: =IFERROR(ROUND(H13*304.8/G13,0),0) -> 5852 | K13: =IFERROR(ROUND(I13*304.8/G13,0),0) -> 1707 | L13: 1 | M13: =H13*I13*L13 -> 672 | N13: =IFERROR(VLOOKUP(F13,'_Products'!$A$1:$G$23,5,FALSE),0) -> 2000 | O13: front | P13: =IFERROR(VLOOKUP(F13,'_Products'!$A$1:$G$23,4,FALSE),0) -> 291.44 | Q13: =P13*M13 -> 195846.34 | R13: =SUM('Bundle Equipment'!E60:E60) -> 20803.2 | S13: =MAX(M13*10,500) -> 6720 | T13: =Q13+R13+S13 -> 223369.54 | U13: =V$2 -> 0.15 | V13: =IFERROR(T13/(1-U13),0) -> 262787.69 | W13: =V13-T13 -> 39418.15 | X13: =IFERROR(ROUND(M13*0.092903*VLOOKUP(F13,'_Products'!$A$1:$G$23,6,FALSE),0),0) -> 3284 | Y13: =IFERROR(ROUND(M13*0.092903*VLOOKUP(F13,'_Products'!$A$1:$G$23,7,FALSE),0),0) -> 24385 | Z13: =Y13*3.412 -> 83202
A14: New Path Hall Option 2 — New Path Hall, WTC | B14: 65 | C14: 13 | E14: =IFERROR(VLOOKUP(F14,'_Products'!$A$1:$G$23,2,FALSE),"") -> LG/Yaham | F14: C2.5-MIP 2.5mm Indoor (Alt) | G14: =IFERROR(VLOOKUP(F14,'_Products'!$A$1:$G$23,3,FALSE),0) -> 2.5 | H14: 65 | I14: 13 | J14: =IFERROR(ROUND(H14*304.8/G14,0),0) -> 7925 | K14: =IFERROR(ROUND(I14*304.8/G14,0),0) -> 1585 | L14: 1 | M14: =H14*I14*L14 -> 845 | N14: =IFERROR(VLOOKUP(F14,'_Products'!$A$1:$G$23,5,FALSE),0) -> 2000 | O14: front | P14: =IFERROR(VLOOKUP(F14,'_Products'!$A$1:$G$23,4,FALSE),0) -> 291.44 | Q14: =P14*M14 -> 246265.11 | R14: =SUM('Bundle Equipment'!E66:E66) -> 29307 | S14: =MAX(M14*10,500) -> 8450 | T14: =Q14+R14+S14 -> 284022.11 | U14: =V$2 -> 0.15 | V14: =IFERROR(T14/(1-U14),0) -> 334143.66 | W14: =V14-T14 -> 50121.55 | X14: =IFERROR(ROUND(M14*0.092903*VLOOKUP(F14,'_Products'!$A$1:$G$23,6,FALSE),0),0) -> 4129 | Y14: =IFERROR(ROUND(M14*0.092903*VLOOKUP(F14,'_Products'!$A$1:$G$23,7,FALSE),0),0) -> 30663 | Z14: =Y14*3.412 -> 104622
A16: TOTAL (11 displays) | M16: =SUM(M4:M14) -> 6333.2 | Q16: =SUM(Q4:Q14) -> 1845717.7 | R16: =SUM(R4:R14) -> 162049.91 | S16: =SUM(S4:S14) -> 63332 | T16: =SUM(T4:T14) -> 2071099.6 | U16: =IFERROR(1-T16/V16,0) -> 0.15 | V16: =SUM(V4:V14) -> 2436587.7 | W16: =SUM(W4:W14) -> 365488.16 | X16: =SUM(X4:X14) -> 86745 | Y16: =SUM(Y4:Y14) -> 786800 | Z16: =SUM(Z4:Z14) -> 2684562

Sheet Tech Specs (Installers)
A1: WTC Digital Signage Upgrade — LED Technical Specifications (No Pricing)
A2: Technical specifications only — no pricing data. Safe for installer/subcontractor distribution.
A4: Display Name | B4: Qty | C4: Pixel Pitch | D4: Height (ft) | E4: Width (ft) | F4: Pixels H | G4: Pixels W | H4: Sq Ft | I4: Brightness (nits) | J4: Service | K4: Environment | L4: Weight (lbs) | M4: Total Power (W) | N4: Fiber Strands | O4: BTU/hr
A5: ='LED Cost Sheet'!A4 -> Underpass 3 — Underpass 1-4, WTC | B5: ='LED Cost Sheet'!I4 -> 1 | C5: ='LED Cost Sheet'!D4 -> 2.5mm | D5: ='LED Cost Sheet'!E4 -> 7.48 | E5: ='LED Cost Sheet'!F4 -> 29.92 | F5: ='LED Cost Sheet'!G4 -> 912 | G5: ='LED Cost Sheet'!H4 -> 3648 | H5: =D5*E5*B5 -> 223.8 | I5: ='LED Cost Sheet'!K4 | J5: ='LED Cost Sheet'!L4 -> front | K5: indoor | L5: ='LED Cost Sheet'!U4 -> 1094 | M5: ='LED Cost Sheet'!V4 -> 8121 | N5: =IFERROR((F5*G5*B5)/400000,0) -> 8.32 | O5: ='LED Cost Sheet'!W4 -> 27709
A6: ='LED Cost Sheet'!A5 -> Underpass 4 — Underpass 1-4, WTC | B6: ='LED Cost Sheet'!I5 -> 1 | C6: ='LED Cost Sheet'!D5 -> 2.5mm | D6: ='LED Cost Sheet'!E5 -> 12.6 | E6: ='LED Cost Sheet'!F5 -> 29.92 | F6: ='LED Cost Sheet'!G5 -> 1536 | G6: ='LED Cost Sheet'!H5 -> 3648 | H6: =D6*E6*B6 -> 376.99 | I6: ='LED Cost Sheet'!K5 | J6: ='LED Cost Sheet'!L5 -> front | K6: indoor | L6: ='LED Cost Sheet'!U5 -> 1842 | M6: ='LED Cost Sheet'!V5 -> 13680 | N6: =IFERROR((F6*G6*B6)/400000,0) -> 14.01 | O6: ='LED Cost Sheet'!W5 -> 46676
A7: ='LED Cost Sheet'!A6 -> Concourse — Concourse, WTC | B7: ='LED Cost Sheet'!I6 -> 1 | C7: ='LED Cost Sheet'!D6 -> 2.5mm | D7: ='LED Cost Sheet'!E6 -> 9.45 | E7: ='LED Cost Sheet'!F6 -> 280.31 | F7: ='LED Cost Sheet'!G6 -> 1152 | G7: ='LED Cost Sheet'!H6 -> 34175 | H7: =D7*E7*B7 -> 2648.93 | I7: ='LED Cost Sheet'!K6 | J7: ='LED Cost Sheet'!L6 -> front | K7: indoor | L7: ='LED Cost Sheet'!U6 -> 12945 | M7: ='LED Cost Sheet'!V6 -> 96124 | N7: =IFERROR((F7*G7*B7)/400000,0) -> 98.42 | O7: ='LED Cost Sheet'!W6 -> 327975
A8: ='LED Cost Sheet'!A7 -> T4-B1 (6-9) — T4-B1, WTC | B8: ='LED Cost Sheet'!I7 -> 4 | C8: ='LED Cost Sheet'!D7 -> 2.5mm | D8: ='LED Cost Sheet'!E7 -> 7.87 | E8: ='LED Cost Sheet'!F7 -> 8.66 | F8: ='LED Cost Sheet'!G7 -> 960 | G8: ='LED Cost Sheet'!H7 -> 1056 | H8: =D8*E8*B8 -> 272.62 | I8: ='LED Cost Sheet'!K7 | J8: ='LED Cost Sheet'!L7 -> front | K8: indoor | L8: ='LED Cost Sheet'!U7 -> 1332 | M8: ='LED Cost Sheet'!V7 -> 9893 | N8: =IFERROR((F8*G8*B8)/400000,0) -> 10.14 | O8: ='LED Cost Sheet'!W7 -> 33755
A9: ='LED Cost Sheet'!A8 -> T4-B2 (10-18) — T4-B2, WTC | B9: ='LED Cost Sheet'!I8 -> 9 | C9: ='LED Cost Sheet'!D8 -> 2.5mm | D9: ='LED Cost Sheet'!E8 -> 7.87 | E9: ='LED Cost Sheet'!F8 -> 8.66 | F9: ='LED Cost Sheet'!G8 -> 960 | G9: ='LED Cost Sheet'!H8 -> 1056 | H9: =D9*E9*B9 -> 613.39 | I9: ='LED Cost Sheet'!K8 | J9: ='LED Cost Sheet'!L8 -> front | K9: indoor | L9: ='LED Cost Sheet'!U8 -> 2997 | M9: ='LED Cost Sheet'!V8 -> 22259 | N9: =IFERROR((F9*G9*B9)/400000,0) -> 22.81 | O9: ='LED Cost Sheet'!W8 -> 75948
A10: ='LED Cost Sheet'!A9 -> T4 Lobby Elevator — T4 Lobby Elevator, WTC | B10: ='LED Cost Sheet'!I9 -> 1 | C10: ='LED Cost Sheet'!D9 -> 2.5mm | D10: ='LED Cost Sheet'!E9 -> 71.6 | E10: ='LED Cost Sheet'!F9 -> 5.5 | F10: ='LED Cost Sheet'!G9 -> 8729 | G10: ='LED Cost Sheet'!H9 -> 671 | H10: =D10*E10*B10 -> 393.8 | I10: ='LED Cost Sheet'!K9 | J10: ='LED Cost Sheet'!L9 -> front | K10: indoor | L10: ='LED Cost Sheet'!U9 -> 1924 | M10: ='LED Cost Sheet'!V9 -> 14290 | N10: =IFERROR((F10*G10*B10)/400000,0) -> 14.64 | O10: ='LED Cost Sheet'!W9 -> 48757
A11: ='LED Cost Sheet'!A10 -> T2-B1M Screen 20 — T2-B1M, WTC | B11: ='LED Cost Sheet'!I10 -> 1 | C11: ='LED Cost Sheet'!D10 -> 2.5mm | D11: ='LED Cost Sheet'!E10 -> 7.91 | E11: ='LED Cost Sheet'!F10 -> 16.5 | F11: ='LED Cost Sheet'!G10 -> 964 | G11: ='LED Cost Sheet'!H10 -> 2012 | H11: =D11*E11*B11 -> 130.52 | I11: ='LED Cost Sheet'!K10 | J11: ='LED Cost Sheet'!L10 -> front | K11: indoor | L11: ='LED Cost Sheet'!U10 -> 638 | M11: ='LED Cost Sheet'!V10 -> 4736 | N11: =IFERROR((F11*G11*B11)/400000,0) -> 4.85 | O11: ='LED Cost Sheet'!W10 -> 16159
A12: ='LED Cost Sheet'!A11 -> T2-B1M Screen 21 — T2-B1M, WTC | B12: ='LED Cost Sheet'!I11 -> 1 | C12: ='LED Cost Sheet'!D11 -> 2.5mm | D12: ='LED Cost Sheet'!E11 -> 7.91 | E12: ='LED Cost Sheet'!F11 -> 11.83 | F12: ='LED Cost Sheet'!G11 -> 964 | G12: ='LED Cost Sheet'!H11 -> 1442 | H12: =D12*E12*B12 -> 93.58 | I12: ='LED Cost Sheet'!K11 | J12: ='LED Cost Sheet'!L11 -> front | K12: indoor | L12: ='LED Cost Sheet'!U11 -> 457 | M12: ='LED Cost Sheet'!V11 -> 3396 | N12: =IFERROR((F12*G12*B12)/400000,0) -> 3.48 | O12: ='LED Cost Sheet'!W11 -> 11587
A13: ='LED Cost Sheet'!A12 -> T2-B1M Screen 22 — T2-B1M, WTC | B13: ='LED Cost Sheet'!I12 -> 1 | C13: ='LED Cost Sheet'!D12 -> 2.5mm | D13: ='LED Cost Sheet'!E12 -> 7.91 | E13: ='LED Cost Sheet'!F12 -> 7.91 | F13: ='LED Cost Sheet'!G12 -> 964 | G13: ='LED Cost Sheet'!H12 -> 964 | H13: =D13*E13*B13 -> 62.57 | I13: ='LED Cost Sheet'!K12 | J13: ='LED Cost Sheet'!L12 -> front | K13: indoor | L13: ='LED Cost Sheet'!U12 -> 306 | M13: ='LED Cost Sheet'!V12 -> 2271 | N13: =IFERROR((F13*G13*B13)/400000,0) -> 2.32 | O13: ='LED Cost Sheet'!W12 -> 7749
A14: ='LED Cost Sheet'!A13 -> New Path Hall Option 1 — New Path Hall, WTC | B14: ='LED Cost Sheet'!I13 -> 1 | C14: ='LED Cost Sheet'!D13 -> 2.5mm | D14: ='LED Cost Sheet'!E13 -> 48 | E14: ='LED Cost Sheet'!F13 -> 14 | F14: ='LED Cost Sheet'!G13 -> 5852 | G14: ='LED Cost Sheet'!H13 -> 1707 | H14: =D14*E14*B14 -> 672 | I14: ='LED Cost Sheet'!K13 | J14: ='LED Cost Sheet'!L13 -> front | K14: indoor | L14: ='LED Cost Sheet'!U13 -> 3284 | M14: ='LED Cost Sheet'!V13 -> 24385 | N14: =IFERROR((F14*G14*B14)/400000,0) -> 24.97 | O14: ='LED Cost Sheet'!W13 -> 83202
A15: ='LED Cost Sheet'!A14 -> New Path Hall Option 2 — New Path Hall, WTC | B15: ='LED Cost Sheet'!I14 -> 1 | C15: ='LED Cost Sheet'!D14 -> 2.5mm | D15: ='LED Cost Sheet'!E14 -> 65 | E15: ='LED Cost Sheet'!F14 -> 13 | F15: ='LED Cost Sheet'!G14 -> 7925 | G15: ='LED Cost Sheet'!H14 -> 1585 | H15: =D15*E15*B15 -> 845 | I15: ='LED Cost Sheet'!K14 | J15: ='LED Cost Sheet'!L14 -> front | K15: indoor | L15: ='LED Cost Sheet'!U14 -> 4129 | M15: ='LED Cost Sheet'!V14 -> 30663 | N15: =IFERROR((F15*G15*B15)/400000,0) -> 31.4 | O15: ='LED Cost Sheet'!W14 -> 104622

Sheet Underpass 3 - Install
A3: Project Name: WTC Digital Signage Upgrade
A4: 2026-04-01
A5: Revised By: ANC Proposal Engine
C7: Linked Margin Assignment
C8: Install Margin | D8: 0.15
C9: Electrical Margin | D9: 0.15
C10: ANC Margin | D10: 0.15
C11: Engineering and Permits | D11: 0.15
B15: Underpass 3
B16: Height | C16: Width | D16: Total Sq. Ft | E16: QTY
B17: 7.48 | C17: 29.92 | D17: 223.8 | E17: 1
B19: Structural Materials: | C19: Subcontractor 1 | D19: Subcontractor 2 | E19: Subcontractor 3 | F19: Selected | G19: Additional Contingency | I19: Total Cost | J19: Install Margin | K19: Selling Price
B20: FABRICATE PRIMARY STEEL | C20: 0 | D20: 0 | E20: 0 | F20: 0 | G20: 0 | I20: =SUM(C20:G20) -> 0 | J20: =$D$8 -> 0.15 | K20: =I20/(1-J20) -> 0
B21: SUPPLY AND INSTALL PRIMARY PLYWOOD | C21: 0 | D21: 0 | E21: 0 | F21: 0 | G21: 0 | I21: =SUM(C21:G21) -> 0 | J21: =$D$8 -> 0.15 | K21: =I21/(1-J21) -> 0
B22: FABRICATE SECONDARY STEEL SUBSTRUCTURE | C22: 4102.5 | D22: 0 | E22: 0 | F22: 0 | G22: 0 | I22: =SUM(C22:G22) -> 4102.5 | J22: =$D$8 -> 0.15 | K22: =I22/(1-J22) -> 4826.47
B23: FABRICATE CLADDING AND TRIM | C23: 0 | D23: 0 | E23: 0 | F23: 0 | G23: 0 | I23: =SUM(C23:G23) -> 0 | J23: =$D$8 -> 0.15 | K23: =I23/(1-J23) -> 0
B24: OTHER SCOPE ITEM | C24: 0 | D24: 0 | E24: 0 | F24: 0 | G24: 0 | I24: =SUM(C24:G24) -> 0 | J24: =$D$8 -> 0.15 | K24: =I24/(1-J24) -> 0
B25: OTHER SCOPE ITEM | C25: 0 | D25: 0 | E25: 0 | F25: 0 | G25: 0 | I25: =SUM(C25:G25) -> 0 | J25: =$D$8 -> 0.15 | K25: =I25/(1-J25) -> 0
B26: SUBTOTAL | I26: =SUM(I20:I25) -> 4102.5 | K26: =SUM(K20:K25) -> 4826.47
B28: Structural Labor and LED Installation | C28: Subcontractor 1 | D28: Subcontractor 2 | E28: Subcontractor 3 | F28: Selected | G28: Additional Contingency | I28: Total Cost | J28: Install Margin | K28: Selling Price
B29: REMOVAL AND DISPOSAL | C29: 0 | D29: 0 | E29: 0 | F29: 0 | G29: 0 | I29: =SUM(C29:G29) -> 0 | J29: =$D$8 -> 0.15 | K29: =I29/(1-J29) -> 0
B30: INSTALL SECONDARY STEEL SUBSTRUCTURE | C30: 0 | D30: 0 | E30: 0 | F30: 0 | G30: 0 | I30: =SUM(C30:G30) -> 0 | J30: =$D$8 -> 0.15 | K30: =I30/(1-J30) -> 0
B31: INSTALL LED DISPLAYS | C31: 17093.75 | D31: 0 | E31: 0 | F31: 0 | G31: 0 | I31: =SUM(C31:G31) -> 17093.75 | J31: =$D$8 -> 0.15 | K31: =I31/(1-J31) -> 20110.29
B32: INSTALL CLADDING AND TRIM | C32: 0 | D32: 0 | E32: 0 | F32: 0 | G32: 0 | I32: =SUM(C32:G32) -> 0 | J32: =$D$8 -> 0.15 | K32: =I32/(1-J32) -> 0
B33: HEAVY EQUIPMENT | C33: 0 | D33: 0 | E33: 0 | F33: 0 | G33: 0 | I33: =SUM(C33:G33) -> 0 | J33: =$D$8 -> 0.15 | K33: =I33/(1-J33) -> 0
B34: PM/GENERAL CONDITIONS/TRAVEL | C34: 20882.35 | D34: 0 | E34: 0 | F34: 0 | G34: 0 | I34: =SUM(C34:G34) -> 20882.35 | J34: =$D$8 -> 0.15 | K34: =I34/(1-J34) -> 24567.47
B35: SUBTOTAL | I35: =SUM(I29:I34) -> 37976.1 | K35: =SUM(K29:K34) -> 44677.76
B37: Electrical and Data - Materials and Subcontracting | C37: Subcontractor 1 | D37: Subcontractor 2 | E37: Subcontractor 3 | F37: Selected | G37: Additional Contingency | I37: Total Cost | J37: Install Margin | K37: Selling Price
B38: ELECTRICAL MATERIALS | C38: 17093.75 | D38: 0 | E38: 0 | F38: 0 | G38: 0 | I38: =SUM(C38:G38) -> 17093.75 | J38: =$D$9 -> 0.15 | K38: =I38/(1-J38) -> 20110.29
B39: DATA MATERIALS | C39: 0 | D39: 0 | E39: 0 | F39: 0 | G39: 0 | I39: =SUM(C39:G39) -> 0 | J39: =$D$9 -> 0.15 | K39: =I39/(1-J39) -> 0
B40: ELECTRICAL LABOR | C40: 0 | D40: 0 | E40: 0 | F40: 0 | G40: 0 | I40: =SUM(C40:G40) -> 0 | J40: =$D$9 -> 0.15 | K40: =I40/(1-J40) -> 0
B41: DATA LABOR | C41: 0 | D41: 0 | E41: 0 | F41: 0 | G41: 0 | I41: =SUM(C41:G41) -> 0 | J41: =$D$9 -> 0.15 | K41: =I41/(1-J41) -> 0
B42: SUB PANEL | C42: 0 | D42: 0 | E42: 0 | F42: 0 | G42: 0 | I42: =SUM(C42:G42) -> 0 | J42: =$D$9 -> 0.15 | K42: =I42/(1-J42) -> 0
B43: MISC | C43: 0 | D43: 0 | E43: 0 | F43: 0 | G43: 0 | I43: =SUM(C43:G43) -> 0 | J43: =$D$9 -> 0.15 | K43: =I43/(1-J43) -> 0
B44: SUBTOTAL | I44: =SUM(I38:I43) -> 17093.75 | K44: =SUM(K38:K43) -> 20110.29
B46: Submittals, Engineering, and Permits | C46: Subcontractor 1 | D46: Subcontractor 2 | E46: Subcontractor 3 | F46: Selected | G46: Additional Contingency | I46: Total Cost | J46: Install Margin | K46: Selling Price
B47: STRUCTURAL ENGINEERING | C47: 4705.88 | D47: 0 | E47: 0 | F47: 0 | G47: 0 | I47: =SUM(C47:G47) -> 4705.88 | J47: =$D$11 -> 0.15 | K47: =I47/(1-J47) -> 5536.33
B48: STRUCTURAL CERTIFICATION | C48: 0 | D48: 0 | E48: 0 | F48: 0 | G48: 0 | I48: =SUM(C48:G48) -> 0 | J48: =$D$11 -> 0.15 | K48: =I48/(1-J48) -> 0
B49: ELECTRICAL ENGINEERING | C49: 0 | D49: 0 | E49: 0 | F49: 0 | G49: 0 | I49: =SUM(C49:G49) -> 0 | J49: =$D$11 -> 0.15 | K49: =I49/(1-J49) -> 0
B50: ELECTRICAL CERTIFICATION | C50: 0 | D50: 0 | E50: 0 | F50: 0 | G50: 0 | I50: =SUM(C50:G50) -> 0 | J50: =$D$11 -> 0.15 | K50: =I50/(1-J50) -> 0
...

Sheet Underpass 4 - Install
A3: Project Name: WTC Digital Signage Upgrade
A4: 2026-04-01
A5: Revised By: ANC Proposal Engine
C7: Linked Margin Assignment
C8: Install Margin | D8: 0.15
C9: Electrical Margin | D9: 0.15
C10: ANC Margin | D10: 0.15
C11: Engineering and Permits | D11: 0.15
B15: Underpass 4
B16: Height | C16: Width | D16: Total Sq. Ft | E16: QTY
B17: 12.6 | C17: 29.92 | D17: 376.99 | E17: 1
B19: Structural Materials: | C19: Subcontractor 1 | D19: Subcontractor 2 | E19: Subcontractor 3 | F19: Selected | G19: Additional Contingency | I19: Total Cost | J19: Install Margin | K19: Selling Price
B20: FABRICATE PRIMARY STEEL | C20: 0 | D20: 0 | E20: 0 | F20: 0 | G20: 0 | I20: =SUM(C20:G20) -> 0 | J20: =$D$8 -> 0.15 | K20: =I20/(1-J20) -> 0
B21: SUPPLY AND INSTALL PRIMARY PLYWOOD | C21: 0 | D21: 0 | E21: 0 | F21: 0 | G21: 0 | I21: =SUM(C21:G21) -> 0 | J21: =$D$8 -> 0.15 | K21: =I21/(1-J21) -> 0
B22: FABRICATE SECONDARY STEEL SUBSTRUCTURE | C22: 6907.5 | D22: 0 | E22: 0 | F22: 0 | G22: 0 | I22: =SUM(C22:G22) -> 6907.5 | J22: =$D$8 -> 0.15 | K22: =I22/(1-J22) -> 8126.47
B23: FABRICATE CLADDING AND TRIM | C23: 0 | D23: 0 | E23: 0 | F23: 0 | G23: 0 | I23: =SUM(C23:G23) -> 0 | J23: =$D$8 -> 0.15 | K23: =I23/(1-J23) -> 0
B24: OTHER SCOPE ITEM | C24: 0 | D24: 0 | E24: 0 | F24: 0 | G24: 0 | I24: =SUM(C24:G24) -> 0 | J24: =$D$8 -> 0.15 | K24: =I24/(1-J24) -> 0
B25: OTHER SCOPE ITEM | C25: 0 | D25: 0 | E25: 0 | F25: 0 | G25: 0 | I25: =SUM(C25:G25) -> 0 | J25: =$D$8 -> 0.15 | K25: =I25/(1-J25) -> 0
B26: SUBTOTAL | I26: =SUM(I20:I25) -> 6907.5 | K26: =SUM(K20:K25) -> 8126.47
B28: Structural Labor and LED Installation | C28: Subcontractor 1 | D28: Subcontractor 2 | E28: Subcontractor 3 | F28: Selected | G28: Additional Contingency | I28: Total Cost | J28: Install Margin | K28: Selling Price
B29: REMOVAL AND DISPOSAL | C29: 0 | D29: 0 | E29: 0 | F29: 0 | G29: 0 | I29: =SUM(C29:G29) -> 0 | J29: =$D$8 -> 0.15 | K29: =I29/(1-J29) -> 0
B30: INSTALL SECONDARY STEEL SUBSTRUCTURE | C30: 0 | D30: 0 | E30: 0 | F30: 0 | G30: 0 | I30: =SUM(C30:G30) -> 0 | J30: =$D$8 -> 0.15 | K30: =I30/(1-J30) -> 0
B31: INSTALL LED DISPLAYS | C31: 28781.25 | D31: 0 | E31: 0 | F31: 0 | G31: 0 | I31: =SUM(C31:G31) -> 28781.25 | J31: =$D$8 -> 0.15 | K31: =I31/(1-J31) -> 33860.29
B32: INSTALL CLADDING AND TRIM | C32: 0 | D32: 0 | E32: 0 | F32: 0 | G32: 0 | I32: =SUM(C32:G32) -> 0 | J32: =$D$8 -> 0.15 | K32: =I32/(1-J32) -> 0
B33: HEAVY EQUIPMENT | C33: 0 | D33: 0 | E33: 0 | F33: 0 | G33: 0 | I33: =SUM(C33:G33) -> 0 | J33: =$D$8 -> 0.15 | K33: =I33/(1-J33) -> 0
B34: PM/GENERAL CONDITIONS/TRAVEL | C34: 20882.35 | D34: 0 | E34: 0 | F34: 0 | G34: 0 | I34: =SUM(C34:G34) -> 20882.35 | J34: =$D$8 -> 0.15 | K34: =I34/(1-J34) -> 24567.47
B35: SUBTOTAL | I35: =SUM(I29:I34) -> 49663.6 | K35: =SUM(K29:K34) -> 58427.76
B37: Electrical and Data - Materials and Subcontracting | C37: Subcontractor 1 | D37: Subcontractor 2 | E37: Subcontractor 3 | F37: Selected | G37: Additional Contingency | I37: Total Cost | J37: Install Margin | K37: Selling Price
B38: ELECTRICAL MATERIALS | C38: 28781.25 | D38: 0 | E38: 0 | F38: 0 | G38: 0 | I38: =SUM(C38:G38) -> 28781.25 | J38: =$D$9 -> 0.15 | K38: =I38/(1-J38) -> 33860.29
B39: DATA MATERIALS | C39: 0 | D39: 0 | E39: 0 | F39: 0 | G39: 0 | I39: =SUM(C39:G39) -> 0 | J39: =$D$9 -> 0.15 | K39: =I39/(1-J39) -> 0
B40: ELECTRICAL LABOR | C40: 0 | D40: 0 | E40: 0 | F40: 0 | G40: 0 | I40: =SUM(C40:G40) -> 0 | J40: =$D$9 -> 0.15 | K40: =I40/(1-J40) -> 0
B41: DATA LABOR | C41: 0 | D41: 0 | E41: 0 | F41: 0 | G41: 0 | I41: =SUM(C41:G41) -> 0 | J41: =$D$9 -> 0.15 | K41: =I41/(1-J41) -> 0
B42: SUB PANEL | C42: 0 | D42: 0 | E42: 0 | F42: 0 | G42: 0 | I42: =SUM(C42:G42) -> 0 | J42: =$D$9 -> 0.15 | K42: =I42/(1-J42) -> 0
B43: MISC | C43: 0 | D43: 0 | E43: 0 | F43: 0 | G43: 0 | I43: =SUM(C43:G43) -> 0 | J43: =$D$9 -> 0.15 | K43: =I43/(1-J43) -> 0
B44: SUBTOTAL | I44: =SUM(I38:I43) -> 28781.25 | K44: =SUM(K38:K43) -> 33860.29
B46: Submittals, Engineering, and Permits | C46: Subcontractor 1 | D46: Subcontractor 2 | E46: Subcontractor 3 | F46: Selected | G46: Additional Contingency | I46: Total Cost | J46: Install Margin | K46: Selling Price
B47: STRUCTURAL ENGINEERING | C47: 4705.88 | D47: 0 | E47: 0 | F47: 0 | G47: 0 | I47: =SUM(C47:G47) -> 4705.88 | J47: =$D$11 -> 0.15 | K47: =I47/(1-J47) -> 5536.33
B48: STRUCTURAL CERTIFICATION | C48: 0 | D48: 0 | E48: 0 | F48: 0 | G48: 0 | I48: =SUM(C48:G48) -> 0 | J48: =$D$11 -> 0.15 | K48: =I48/(1-J48) -> 0
B49: ELECTRICAL ENGINEERING | C49: 0 | D49: 0 | E49: 0 | F49: 0 | G49: 0 | I49: =SUM(C49:G49) -> 0 | J49: =$D$11 -> 0.15 | K49: =I49/(1-J49) -> 0
B50: ELECTRICAL CERTIFICATION | C50: 0 | D50: 0 | E50: 0 | F50: 0 | G50: 0 | I50: =SUM(C50:G50) -> 0 | J50: =$D$11 -> 0.15 | K50: =I50/(1-J50) -> 0
...

Sheet Concourse - Install
A3: Project Name: WTC Digital Signage Upgrade
A4: 2026-04-01
A5: Revised By: ANC Proposal Engine
C7: Linked Margin Assignment
C8: Install Margin | D8: 0.15
C9: Electrical Margin | D9: 0.15
C10: ANC Margin | D10: 0.15
C11: Engineering and Permits | D11: 0.15
B15: Concourse
B16: Height | C16: Width | D16: Total Sq. Ft | E16: QTY
B17: 9.45 | C17: 280.31 | D17: 2648.93 | E17: 1
B19: Structural Materials: | C19: Subcontractor 1 | D19: Subcontractor 2 | E19: Subcontractor 3 | F19: Selected | G19: Additional Contingency | I19: Total Cost | J19: Install Margin | K19: Selling Price
B20: FABRICATE PRIMARY STEEL | C20: 0 | D20: 0 | E20: 0 | F20: 0 | G20: 0 | I20: =SUM(C20:G20) -> 0 | J20: =$D$8 -> 0.15 | K20: =I20/(1-J20) -> 0
B21: SUPPLY AND INSTALL PRIMARY PLYWOOD | C21: 0 | D21: 0 | E21: 0 | F21: 0 | G21: 0 | I21: =SUM(C21:G21) -> 0 | J21: =$D$8 -> 0.15 | K21: =I21/(1-J21) -> 0
B22: FABRICATE SECONDARY STEEL SUBSTRUCTURE | C22: 48536.25 | D22: 0 | E22: 0 | F22: 0 | G22: 0 | I22: =SUM(C22:G22) -> 48536.25 | J22: =$D$8 -> 0.15 | K22: =I22/(1-J22) -> 57101.47
B23: FABRICATE CLADDING AND TRIM | C23: 0 | D23: 0 | E23: 0 | F23: 0 | G23: 0 | I23: =SUM(C23:G23) -> 0 | J23: =$D$8 -> 0.15 | K23: =I23/(1-J23) -> 0
B24: OTHER SCOPE ITEM | C24: 0 | D24: 0 | E24: 0 | F24: 0 | G24: 0 | I24: =SUM(C24:G24) -> 0 | J24: =$D$8 -> 0.15 | K24: =I24/(1-J24) -> 0
B25: OTHER SCOPE ITEM | C25: 0 | D25: 0 | E25: 0 | F25: 0 | G25: 0 | I25: =SUM(C25:G25) -> 0 | J25: =$D$8 -> 0.15 | K25: =I25/(1-J25) -> 0
B26: SUBTOTAL | I26: =SUM(I20:I25) -> 48536.25 | K26: =SUM(K20:K25) -> 57101.47
B28: Structural Labor and LED Installation | C28: Subcontractor 1 | D28: Subcontractor 2 | E28: Subcontractor 3 | F28: Selected | G28: Additional Contingency | I28: Total Cost | J28: Install Margin | K28: Selling Price
B29: REMOVAL AND DISPOSAL | C29: 0 | D29: 0 | E29: 0 | F29: 0 | G29: 0 | I29: =SUM(C29:G29) -> 0 | J29: =$D$8 -> 0.15 | K29: =I29/(1-J29) -> 0
B30: INSTALL SECONDARY STEEL SUBSTRUCTURE | C30: 0 | D30: 0 | E30: 0 | F30: 0 | G30: 0 | I30: =SUM(C30:G30) -> 0 | J30: =$D$8 -> 0.15 | K30: =I30/(1-J30) -> 0
B31: INSTALL LED DISPLAYS | C31: 202234.38 | D31: 0 | E31: 0 | F31: 0 | G31: 0 | I31: =SUM(C31:G31) -> 202234.38 | J31: =$D$8 -> 0.15 | K31: =I31/(1-J31) -> 237922.8
B32: INSTALL CLADDING AND TRIM | C32: 0 | D32: 0 | E32: 0 | F32: 0 | G32: 0 | I32: =SUM(C32:G32) -> 0 | J32: =$D$8 -> 0.15 | K32: =I32/(1-J32) -> 0
B33: HEAVY EQUIPMENT | C33: 0 | D33: 0 | E33: 0 | F33: 0 | G33: 0 | I33: =SUM(C33:G33) -> 0 | J33: =$D$8 -> 0.15 | K33: =I33/(1-J33) -> 0
B34: PM/GENERAL CONDITIONS/TRAVEL | C34: 20882.35 | D34: 0 | E34: 0 | F34: 0 | G34: 0 | I34: =SUM(C34:G34) -> 20882.35 | J34: =$D$8 -> 0.15 | K34: =I34/(1-J34) -> 24567.47
B35: SUBTOTAL | I35: =SUM(I29:I34) -> 223116.73 | K35: =SUM(K29:K34) -> 262490.27
B37: Electrical and Data - Materials and Subcontracting | C37: Subcontractor 1 | D37: Subcontractor 2 | E37: Subcontractor 3 | F37: Selected | G37: Additional Contingency | I37: Total Cost | J37: Install Margin | K37: Selling Price
B38: ELECTRICAL MATERIALS | C38: 202234.38 | D38: 0 | E38: 0 | F38: 0 | G38: 0 | I38: =SUM(C38:G38) -> 202234.38 | J38: =$D$9 -> 0.15 | K38: =I38/(1-J38) -> 237922.8
B39: DATA MATERIALS | C39: 0 | D39: 0 | E39: 0 | F39: 0 | G39: 0 | I39: =SUM(C39:G39) -> 0 | J39: =$D$9 -> 0.15 | K39: =I39/(1-J39) -> 0
B40: ELECTRICAL LABOR | C40: 0 | D40: 0 | E40: 0 | F40: 0 | G40: 0 | I40: =SUM(C40:G40) -> 0 | J40: =$D$9 -> 0.15 | K40: =I40/(1-J40) -> 0
B41: DATA LABOR | C41: 0 | D41: 0 | E41: 0 | F41: 0 | G41: 0 | I41: =SUM(C41:G41) -> 0 | J41: =$D$9 -> 0.15 | K41: =I41/(1-J41) -> 0
B42: SUB PANEL | C42: 0 | D42: 0 | E42: 0 | F42: 0 | G42: 0 | I42: =SUM(C42:G42) -> 0 | J42: =$D$9 -> 0.15 | K42: =I42/(1-J42) -> 0
B43: MISC | C43: 0 | D43: 0 | E43: 0 | F43: 0 | G43: 0 | I43: =SUM(C43:G43) -> 0 | J43: =$D$9 -> 0.15 | K43: =I43/(1-J43) -> 0
B44: SUBTOTAL | I44: =SUM(I38:I43) -> 202234.38 | K44: =SUM(K38:K43) -> 237922.8
B46: Submittals, Engineering, and Permits | C46: Subcontractor 1 | D46: Subcontractor 2 | E46: Subcontractor 3 | F46: Selected | G46: Additional Contingency | I46: Total Cost | J46: Install Margin | K46: Selling Price
B47: STRUCTURAL ENGINEERING | C47: 4705.88 | D47: 0 | E47: 0 | F47: 0 | G47: 0 | I47: =SUM(C47:G47) -> 4705.88 | J47: =$D$11 -> 0.15 | K47: =I47/(1-J47) -> 5536.33
B48: STRUCTURAL CERTIFICATION | C48: 0 | D48: 0 | E48: 0 | F48: 0 | G48: 0 | I48: =SUM(C48:G48) -> 0 | J48: =$D$11 -> 0.15 | K48: =I48/(1-J48) -> 0
B49: ELECTRICAL ENGINEERING | C49: 0 | D49: 0 | E49: 0 | F49: 0 | G49: 0 | I49: =SUM(C49:G49) -> 0 | J49: =$D$11 -> 0.15 | K49: =I49/(1-J49) -> 0
B50: ELECTRICAL CERTIFICATION | C50: 0 | D50: 0 | E50: 0 | F50: 0 | G50: 0 | I50: =SUM(C50:G50) -> 0 | J50: =$D$11 -> 0.15 | K50: =I50/(1-J50) -> 0
...

Sheet T4-B1 (6-9) - Install
A3: Project Name: WTC Digital Signage Upgrade
A4: 2026-04-01
A5: Revised By: ANC Proposal Engine
C7: Linked Margin Assignment
C8: Install Margin | D8: 0.15
C9: Electrical Margin | D9: 0.15
C10: ANC Margin | D10: 0.15
C11: Engineering and Permits | D11: 0.15
B15: T4-B1 (6-9)
B16: Height | C16: Width | D16: Total Sq. Ft | E16: QTY
B17: 7.87 | C17: 8.66 | D17: 272.62 | E17: 4
B19: Structural Materials: | C19: Subcontractor 1 | D19: Subcontractor 2 | E19: Subcontractor 3 | F19: Selected | G19: Additional Contingency | I19: Total Cost | J19: Install Margin | K19: Selling Price
B20: FABRICATE PRIMARY STEEL | C20: 0 | D20: 0 | E20: 0 | F20: 0 | G20: 0 | I20: =SUM(C20:G20) -> 0 | J20: =$D$8 -> 0.15 | K20: =I20/(1-J20) -> 0
B21: SUPPLY AND INSTALL PRIMARY PLYWOOD | C21: 0 | D21: 0 | E21: 0 | F21: 0 | G21: 0 | I21: =SUM(C21:G21) -> 0 | J21: =$D$8 -> 0.15 | K21: =I21/(1-J21) -> 0
B22: FABRICATE SECONDARY STEEL SUBSTRUCTURE | C22: 4995 | D22: 0 | E22: 0 | F22: 0 | G22: 0 | I22: =SUM(C22:G22) -> 4995 | J22: =$D$8 -> 0.15 | K22: =I22/(1-J22) -> 5876.47
B23: FABRICATE CLADDING AND TRIM | C23: 0 | D23: 0 | E23: 0 | F23: 0 | G23: 0 | I23: =SUM(C23:G23) -> 0 | J23: =$D$8 -> 0.15 | K23: =I23/(1-J23) -> 0
B24: OTHER SCOPE ITEM | C24: 0 | D24: 0 | E24: 0 | F24: 0 | G24: 0 | I24: =SUM(C24:G24) -> 0 | J24: =$D$8 -> 0.15 | K24: =I24/(1-J24) -> 0
B25: OTHER SCOPE ITEM | C25: 0 | D25: 0 | E25: 0 | F25: 0 | G25: 0 | I25: =SUM(C25:G25) -> 0 | J25: =$D$8 -> 0.15 | K25: =I25/(1-J25) -> 0
B26: SUBTOTAL | I26: =SUM(I20:I25) -> 4995 | K26: =SUM(K20:K25) -> 5876.47
B28: Structural Labor and LED Installation | C28: Subcontractor 1 | D28: Subcontractor 2 | E28: Subcontractor 3 | F28: Selected | G28: Additional Contingency | I28: Total Cost | J28: Install Margin | K28: Selling Price
B29: REMOVAL AND DISPOSAL | C29: 0 | D29: 0 | E29: 0 | F29: 0 | G29: 0 | I29: =SUM(C29:G29) -> 0 | J29: =$D$8 -> 0.15 | K29: =I29/(1-J29) -> 0
B30: INSTALL SECONDARY STEEL SUBSTRUCTURE | C30: 0 | D30: 0 | E30: 0 | F30: 0 | G30: 0 | I30: =SUM(C30:G30) -> 0 | J30: =$D$8 -> 0.15 | K30: =I30/(1-J30) -> 0
B31: INSTALL LED DISPLAYS | C31: 20812.5 | D31: 0 | E31: 0 | F31: 0 | G31: 0 | I31: =SUM(C31:G31) -> 20812.5 | J31: =$D$8 -> 0.15 | K31: =I31/(1-J31) -> 24485.29
B32: INSTALL CLADDING AND TRIM | C32: 0 | D32: 0 | E32: 0 | F32: 0 | G32: 0 | I32: =SUM(C32:G32) -> 0 | J32: =$D$8 -> 0.15 | K32: =I32/(1-J32) -> 0
B33: HEAVY EQUIPMENT | C33: 0 | D33: 0 | E33: 0 | F33: 0 | G33: 0 | I33: =SUM(C33:G33) -> 0 | J33: =$D$8 -> 0.15 | K33: =I33/(1-J33) -> 0
B34: PM/GENERAL CONDITIONS/TRAVEL | C34: 20882.35 | D34: 0 | E34: 0 | F34: 0 | G34: 0 | I34: =SUM(C34:G34) -> 20882.35 | J34: =$D$8 -> 0.15 | K34: =I34/(1-J34) -> 24567.47
B35: SUBTOTAL | I35: =SUM(I29:I34) -> 41694.85 | K35: =SUM(K29:K34) -> 49052.76
B37: Electrical and Data - Materials and Subcontracting | C37: Subcontractor 1 | D37: Subcontractor 2 | E37: Subcontractor 3 | F37: Selected | G37: Additional Contingency | I37: Total Cost | J37: Install Margin | K37: Selling Price
B38: ELECTRICAL MATERIALS | C38: 20812.5 | D38: 0 | E38: 0 | F38: 0 | G38: 0 | I38: =SUM(C38:G38) -> 20812.5 | J38: =$D$9 -> 0.15 | K38: =I38/(1-J38) -> 24485.29
B39: DATA MATERIALS | C39: 0 | D39: 0 | E39: 0 | F39: 0 | G39: 0 | I39: =SUM(C39:G39) -> 0 | J39: =$D$9 -> 0.15 | K39: =I39/(1-J39) -> 0
B40: ELECTRICAL LABOR | C40: 0 | D40: 0 | E40: 0 | F40: 0 | G40: 0 | I40: =SUM(C40:G40) -> 0 | J40: =$D$9 -> 0.15 | K40: =I40/(1-J40) -> 0
B41: DATA LABOR | C41: 0 | D41: 0 | E41: 0 | F41: 0 | G41: 0 | I41: =SUM(C41:G41) -> 0 | J41: =$D$9 -> 0.15 | K41: =I41/(1-J41) -> 0
B42: SUB PANEL | C42: 0 | D42: 0 | E42: 0 | F42: 0 | G42: 0 | I42: =SUM(C42:G42) -> 0 | J42: =$D$9 -> 0.15 | K42: =I42/(1-J42) -> 0
B43: MISC | C43: 0 | D43: 0 | E43: 0 | F43: 0 | G43: 0 | I43: =SUM(C43:G43) -> 0 | J43: =$D$9 -> 0.15 | K43: =I43/(1-J43) -> 0
B44: SUBTOTAL | I44: =SUM(I38:I43) -> 20812.5 | K44: =SUM(K38:K43) -> 24485.29
B46: Submittals, Engineering, and Permits | C46: Subcontractor 1 | D46: Subcontractor 2 | E46: Subcontractor 3 | F46: Selected | G46: Additional Contingency | I46: Total Cost | J46: Install Margin | K46: Selling Price
B47: STRUCTURAL ENGINEERING | C47: 4705.88 | D47: 0 | E47: 0 | F47: 0 | G47: 0 | I47: =SUM(C47:G47) -> 4705.88 | J47: =$D$11 -> 0.15 | K47: =I47/(1-J47) -> 5536.33
B48: STRUCTURAL CERTIFICATION | C48: 0 | D48: 0 | E48: 0 | F48: 0 | G48: 0 | I48: =SUM(C48:G48) -> 0 | J48: =$D$11 -> 0.15 | K48: =I48/(1-J48) -> 0
B49: ELECTRICAL ENGINEERING | C49: 0 | D49: 0 | E49: 0 | F49: 0 | G49: 0 | I49: =SUM(C49:G49) -> 0 | J49: =$D$11 -> 0.15 | K49: =I49/(1-J49) -> 0
B50: ELECTRICAL CERTIFICATION | C50: 0 | D50: 0 | E50: 0 | F50: 0 | G50: 0 | I50: =SUM(C50:G50) -> 0 | J50: =$D$11 -> 0.15 | K50: =I50/(1-J50) -> 0
...

Sheet T4-B2 (10-18) - Install
A3: Project Name: WTC Digital Signage Upgrade
A4: 2026-04-01
A5: Revised By: ANC Proposal Engine
C7: Linked Margin Assignment
C8: Install Margin | D8: 0.15
C9: Electrical Margin | D9: 0.15
C10: ANC Margin | D10: 0.15
C11: Engineering and Permits | D11: 0.15
B15: T4-B2 (10-18)
B16: Height | C16: Width | D16: Total Sq. Ft | E16: QTY
B17: 7.87 | C17: 8.66 | D17: 613.39 | E17: 9
B19: Structural Materials: | C19: Subcontractor 1 | D19: Subcontractor 2 | E19: Subcontractor 3 | F19: Selected | G19: Additional Contingency | I19: Total Cost | J19: Install Margin | K19: Selling Price
B20: FABRICATE PRIMARY STEEL | C20: 0 | D20: 0 | E20: 0 | F20: 0 | G20: 0 | I20: =SUM(C20:G20) -> 0 | J20: =$D$8 -> 0.15 | K20: =I20/(1-J20) -> 0
B21: SUPPLY AND INSTALL PRIMARY PLYWOOD | C21: 0 | D21: 0 | E21: 0 | F21: 0 | G21: 0 | I21: =SUM(C21:G21) -> 0 | J21: =$D$8 -> 0.15 | K21: =I21/(1-J21) -> 0
B22: FABRICATE SECONDARY STEEL SUBSTRUCTURE | C22: 11238.75 | D22: 0 | E22: 0 | F22: 0 | G22: 0 | I22: =SUM(C22:G22) -> 11238.75 | J22: =$D$8 -> 0.15 | K22: =I22/(1-J22) -> 13222.06
B23: FABRICATE CLADDING AND TRIM | C23: 0 | D23: 0 | E23: 0 | F23: 0 | G23: 0 | I23: =SUM(C23:G23) -> 0 | J23: =$D$8 -> 0.15 | K23: =I23/(1-J23) -> 0
B24: OTHER SCOPE ITEM | C24: 0 | D24: 0 | E24: 0 | F24: 0 | G24: 0 | I24: =SUM(C24:G24) -> 0 | J24: =$D$8 -> 0.15 | K24: =I24/(1-J24) -> 0
B25: OTHER SCOPE ITEM | C25: 0 | D25: 0 | E25: 0 | F25: 0 | G25: 0 | I25: =SUM(C25:G25) -> 0 | J25: =$D$8 -> 0.15 | K25: =I25/(1-J25) -> 0
B26: SUBTOTAL | I26: =SUM(I20:I25) -> 11238.75 | K26: =SUM(K20:K25) -> 13222.06
B28: Structural Labor and LED Installation | C28: Subcontractor 1 | D28: Subcontractor 2 | E28: Subcontractor 3 | F28: Selected | G28: Additional Contingency | I28: Total Cost | J28: Install Margin | K28: Selling Price
B29: REMOVAL AND DISPOSAL | C29: 0 | D29: 0 | E29: 0 | F29: 0 | G29: 0 | I29: =SUM(C29:G29) -> 0 | J29: =$D$8 -> 0.15 | K29: =I29/(1-J29) -> 0
B30: INSTALL SECONDARY STEEL SUBSTRUCTURE | C30: 0 | D30: 0 | E30: 0 | F30: 0 | G30: 0 | I30: =SUM(C30:G30) -> 0 | J30: =$D$8 -> 0.15 | K30: =I30/(1-J30) -> 0
B31: INSTALL LED DISPLAYS | C31: 46828.13 | D31: 0 | E31: 0 | F31: 0 | G31: 0 | I31: =SUM(C31:G31) -> 46828.13 | J31: =$D$8 -> 0.15 | K31: =I31/(1-J31) -> 55091.92
B32: INSTALL CLADDING AND TRIM | C32: 0 | D32: 0 | E32: 0 | F32: 0 | G32: 0 | I32: =SUM(C32:G32) -> 0 | J32: =$D$8 -> 0.15 | K32: =I32/(1-J32) -> 0
B33: HEAVY EQUIPMENT | C33: 0 | D33: 0 | E33: 0 | F33: 0 | G33: 0 | I33: =SUM(C33:G33) -> 0 | J33: =$D$8 -> 0.15 | K33: =I33/(1-J33) -> 0
B34: PM/GENERAL CONDITIONS/TRAVEL | C34: 20882.35 | D34: 0 | E34: 0 | F34: 0 | G34: 0 | I34: =SUM(C34:G34) -> 20882.35 | J34: =$D$8 -> 0.15 | K34: =I34/(1-J34) -> 24567.47
B35: SUBTOTAL | I35: =SUM(I29:I34) -> 67710.48 | K35: =SUM(K29:K34) -> 79659.39
B37: Electrical and Data - Materials and Subcontracting | C37: Subcontractor 1 | D37: Subcontractor 2 | E37: Subcontractor 3 | F37: Selected | G37: Additional Contingency | I37: Total Cost | J37: Install Margin | K37: Selling Price
B38: ELECTRICAL MATERIALS | C38: 46828.13 | D38: 0 | E38: 0 | F38: 0 | G38: 0 | I38: =SUM(C38:G38) -> 46828.13 | J38: =$D$9 -> 0.15 | K38: =I38/(1-J38) -> 55091.92
B39: DATA MATERIALS | C39: 0 | D39: 0 | E39: 0 | F39: 0 | G39: 0 | I39: =SUM(C39:G39) -> 0 | J39: =$D$9 -> 0.15 | K39: =I39/(1-J39) -> 0
B40: ELECTRICAL LABOR | C40: 0 | D40: 0 | E40: 0 | F40: 0 | G40: 0 | I40: =SUM(C40:G40) -> 0 | J40: =$D$9 -> 0.15 | K40: =I40/(1-J40) -> 0
B41: DATA LABOR | C41: 0 | D41: 0 | E41: 0 | F41: 0 | G41: 0 | I41: =SUM(C41:G41) -> 0 | J41: =$D$9 -> 0.15 | K41: =I41/(1-J41) -> 0
B42: SUB PANEL | C42: 0 | D42: 0 | E42: 0 | F42: 0 | G42: 0 | I42: =SUM(C42:G42) -> 0 | J42: =$D$9 -> 0.15 | K42: =I42/(1-J42) -> 0
B43: MISC | C43: 0 | D43: 0 | E43: 0 | F43: 0 | G43: 0 | I43: =SUM(C43:G43) -> 0 | J43: =$D$9 -> 0.15 | K43: =I43/(1-J43) -> 0
B44: SUBTOTAL | I44: =SUM(I38:I43) -> 46828.13 | K44: =SUM(K38:K43) -> 55091.92
B46: Submittals, Engineering, and Permits | C46: Subcontractor 1 | D46: Subcontractor 2 | E46: Subcontractor 3 | F46: Selected | G46: Additional Contingency | I46: Total Cost | J46: Install Margin | K46: Selling Price
B47: STRUCTURAL ENGINEERING | C47: 4705.88 | D47: 0 | E47: 0 | F47: 0 | G47: 0 | I47: =SUM(C47:G47) -> 4705.88 | J47: =$D$11 -> 0.15 | K47: =I47/(1-J47) -> 5536.33
B48: STRUCTURAL CERTIFICATION | C48: 0 | D48: 0 | E48: 0 | F48: 0 | G48: 0 | I48: =SUM(C48:G48) -> 0 | J48: =$D$11 -> 0.15 | K48: =I48/(1-J48) -> 0
B49: ELECTRICAL ENGINEERING | C49: 0 | D49: 0 | E49: 0 | F49: 0 | G49: 0 | I49: =SUM(C49:G49) -> 0 | J49: =$D$11 -> 0.15 | K49: =I49/(1-J49) -> 0
B50: ELECTRICAL CERTIFICATION | C50: 0 | D50: 0 | E50: 0 | F50: 0 | G50: 0 | I50: =SUM(C50:G50) -> 0 | J50: =$D$11 -> 0.15 | K50: =I50/(1-J50) -> 0
...

Sheet T4 Lobby Elevator - Install
A3: Project Name: WTC Digital Signage Upgrade
A4: 2026-04-01
A5: Revised By: ANC Proposal Engine
C7: Linked Margin Assignment
C8: Install Margin | D8: 0.15
C9: Electrical Margin | D9: 0.15
C10: ANC Margin | D10: 0.15
C11: Engineering and Permits | D11: 0.15
B15: T4 Lobby Elevator
B16: Height | C16: Width | D16: Total Sq. Ft | E16: QTY
B17: 71.6 | C17: 5.5 | D17: 393.8 | E17: 1
B19: Structural Materials: | C19: Subcontractor 1 | D19: Subcontractor 2 | E19: Subcontractor 3 | F19: Selected | G19: Additional Contingency | I19: Total Cost | J19: Install Margin | K19: Selling Price
B20: FABRICATE PRIMARY STEEL | C20: 0 | D20: 0 | E20: 0 | F20: 0 | G20: 0 | I20: =SUM(C20:G20) -> 0 | J20: =$D$8 -> 0.15 | K20: =I20/(1-J20) -> 0
B21: SUPPLY AND INSTALL PRIMARY PLYWOOD | C21: 0 | D21: 0 | E21: 0 | F21: 0 | G21: 0 | I21: =SUM(C21:G21) -> 0 | J21: =$D$8 -> 0.15 | K21: =I21/(1-J21) -> 0
B22: FABRICATE SECONDARY STEEL SUBSTRUCTURE | C22: 7222.5 | D22: 0 | E22: 0 | F22: 0 | G22: 0 | I22: =SUM(C22:G22) -> 7222.5 | J22: =$D$8 -> 0.15 | K22: =I22/(1-J22) -> 8497.06
B23: FABRICATE CLADDING AND TRIM | C23: 0 | D23: 0 | E23: 0 | F23: 0 | G23: 0 | I23: =SUM(C23:G23) -> 0 | J23: =$D$8 -> 0.15 | K23: =I23/(1-J23) -> 0
B24: OTHER SCOPE ITEM | C24: 0 | D24: 0 | E24: 0 | F24: 0 | G24: 0 | I24: =SUM(C24:G24) -> 0 | J24: =$D$8 -> 0.15 | K24: =I24/(1-J24) -> 0
B25: OTHER SCOPE ITEM | C25: 0 | D25: 0 | E25: 0 | F25: 0 | G25: 0 | I25: =SUM(C25:G25) -> 0 | J25: =$D$8 -> 0.15 | K25: =I25/(1-J25) -> 0
B26: SUBTOTAL | I26: =SUM(I20:I25) -> 7222.5 | K26: =SUM(K20:K25) -> 8497.06
B28: Structural Labor and LED Installation | C28: Subcontractor 1 | D28: Subcontractor 2 | E28: Subcontractor 3 | F28: Selected | G28: Additional Contingency | I28: Total Cost | J28: Install Margin | K28: Selling Price
B29: REMOVAL AND DISPOSAL | C29: 0 | D29: 0 | E29: 0 | F29: 0 | G29: 0 | I29: =SUM(C29:G29) -> 0 | J29: =$D$8 -> 0.15 | K29: =I29/(1-J29) -> 0
B30: INSTALL SECONDARY STEEL SUBSTRUCTURE | C30: 0 | D30: 0 | E30: 0 | F30: 0 | G30: 0 | I30: =SUM(C30:G30) -> 0 | J30: =$D$8 -> 0.15 | K30: =I30/(1-J30) -> 0
B31: INSTALL LED DISPLAYS | C31: 30093.75 | D31: 0 | E31: 0 | F31: 0 | G31: 0 | I31: =SUM(C31:G31) -> 30093.75 | J31: =$D$8 -> 0.15 | K31: =I31/(1-J31) -> 35404.41
B32: INSTALL CLADDING AND TRIM | C32: 0 | D32: 0 | E32: 0 | F32: 0 | G32: 0 | I32: =SUM(C32:G32) -> 0 | J32: =$D$8 -> 0.15 | K32: =I32/(1-J32) -> 0
B33: HEAVY EQUIPMENT | C33: 0 | D33: 0 | E33: 0 | F33: 0 | G33: 0 | I33: =SUM(C33:G33) -> 0 | J33: =$D$8 -> 0.15 | K33: =I33/(1-J33) -> 0
B34: PM/GENERAL CONDITIONS/TRAVEL | C34: 20882.35 | D34: 0 | E34: 0 | F34: 0 | G34: 0 | I34: =SUM(C34:G34) -> 20882.35 | J34: =$D$8 -> 0.15 | K34: =I34/(1-J34) -> 24567.47
B35: SUBTOTAL | I35: =SUM(I29:I34) -> 50976.1 | K35: =SUM(K29:K34) -> 59971.88
B37: Electrical and Data - Materials and Subcontracting | C37: Subcontractor 1 | D37: Subcontractor 2 | E37: Subcontractor 3 | F37: Selected | G37: Additional Contingency | I37: Total Cost | J37: Install Margin | K37: Selling Price
B38: ELECTRICAL MATERIALS | C38: 30093.75 | D38: 0 | E38: 0 | F38: 0 | G38: 0 | I38: =SUM(C38:G38) -> 30093.75 | J38: =$D$9 -> 0.15 | K38: =I38/(1-J38) -> 35404.41
B39: DATA MATERIALS | C39: 0 | D39: 0 | E39: 0 | F39: 0 | G39: 0 | I39: =SUM(C39:G39) -> 0 | J39: =$D$9 -> 0.15 | K39: =I39/(1-J39) -> 0
B40: ELECTRICAL LABOR | C40: 0 | D40: 0 | E40: 0 | F40: 0 | G40: 0 | I40: =SUM(C40:G40) -> 0 | J40: =$D$9 -> 0.15 | K40: =I40/(1-J40) -> 0
B41: DATA LABOR | C41: 0 | D41: 0 | E41: 0 | F41: 0 | G41: 0 | I41: =SUM(C41:G41) -> 0 | J41: =$D$9 -> 0.15 | K41: =I41/(1-J41) -> 0
B42: SUB PANEL | C42: 0 | D42: 0 | E42: 0 | F42: 0 | G42: 0 | I42: =SUM(C42:G42) -> 0 | J42: =$D$9 -> 0.15 | K42: =I42/(1-J42) -> 0
