Workbook

Sheet Project Overview
A1: Test Project — Project Overview
A2: Test Client | 2026-04-01 | ANC Proposal Engine
B4: PROJECT INFORMATION
B5: Client | C5: Test Client
B6: Project Name | C6: Test Project
B7: Location | C7: —
B8: Date Created | C8: 2026-04-01
B9: Currency | C9: USD
B10: Environment | C10: Indoor
B11: Union Labor | C11: No
B12: Bond Required | C12: No
B13: Number of Displays | C13: =SUM('LED Cost Sheet'!I4:I4) -> 1
B15: FINANCIAL PARAMETERS
B16: LED Hardware Margin | C16: 15%
B17: Install / Services Margin | C17: 15%
B18: Engineering Margin | C18: 15%
B19: Equipment Margin | C19: 15%
B20: CMS Margin | C20: 15%
B21: Bond Rate | C21: N/A
B22: Tax Rate | C22: Per zone (editable on MA)
B23: Tariff Rate | C23: Per zone (editable on MA)
B25: SUMMARY TOTALS
B26: Total Cost | C26: ='Margin Analysis'!C28 -> 136987.93
B27: Total Selling Price | C27: ='Margin Analysis'!D28 -> 164808.47
B28: Project Margin $ | C28: ='Margin Analysis'!E28 -> 27820.54
B29: Project Margin % | C29: ='Margin Analysis'!F28 -> 0.17
B30: DOCUMENT TOTAL | C30: ='Margin Analysis'!D28 -> 164808.47

Sheet Margin Analysis
A1: Test Project — Margin Analysis
A2: Test Client | 2026-04-01 | ANC Proposal Engine
B4: Zone / Category | C4: Cost | D4: Selling Price | E4: Margin $ | F4: Margin %
B5: Marquee — wall | D5: Selling Price
B6: LED Hardware | C6: ='LED Cost Sheet'!T4 -> 55399.7 | D6: ='LED Cost Sheet'!V4 -> 65176.12 | E6: =IFERROR(D6-C6,0) -> 9776.42 | F6: 0.15
B7: Structural Materials | C7: ='Marquee - Install'!I26 -> 6000 | D7: =IFERROR(C7/(1-F7),0) -> 7500 | E7: =IFERROR(D7-C7,0) -> 1500 | F7: 0.2
B8: Structural Labor & LED Installation | C8: ='Marquee - Install'!I35-'Marquee - Install'!I34 -> 25000 | D8: =IFERROR(C8/(1-F8),0) -> 31250 | E8: =IFERROR(D8-C8,0) -> 6250 | F8: 0.2
B9: Electrical & Data | C9: ='Marquee - Install'!I44 -> 25000 | D9: =IFERROR(C9/(1-F9),0) -> 31250 | E9: =IFERROR(D9-C9,0) -> 6250 | F9: 0.2
B10: PM / General Conditions / Travel | C10: ='Marquee - Install'!I34 -> 20882.35 | D10: =IFERROR(C10/(1-F10),0) -> 26102.94 | E10: =IFERROR(D10-C10,0) -> 5220.59 | F10: 0.2
B11: Engineering & Permits | C11: ='Marquee - Install'!I52 -> 4705.88 | D11: =IFERROR(C11/(1-F11),0) -> 5882.35 | E11: =IFERROR(D11-C11,0) -> 1176.47 | F11: 0.2
B12: SUBTOTAL | C12: =SUM(C6:C11) -> 136987.93 | D12: =SUM(D6:D11) -> 164808.47 | E12: =IFERROR(D12-C12,0) -> 27820.54 | F12: =IFERROR(1-C12/D12,0) -> 0.168805
B13: TAX | C13: 0 | D13: 0 | E13: 0 | G13: 0
B14: BOND | C14: 0 | D14: 0 | E14: 0 | G14: 0
B15: TARIFF | C15: 0 | D15: 0 | E15: 0 | G15: 0
B16: GRAND TOTAL | C16: =C12+C13+C14+C15 -> 136987.93 | D16: =D12+D13+D14+D15 -> 164808.47 | E16: =IFERROR(D16-C16,0) -> 27820.54 | F16: =IFERROR(1-C16/D16,0) -> 0.16880528
B19: ADDITIONAL COST CENTERS
B20: CMS (Content Management System) | C20: =SUM(CMS!F26:F26) -> 0 | D20: =SUM(CMS!H26:H26) -> 0 | E20: =SUM(CMS!I26:I26) -> 0 | F20: 0.15
B21: Scoring System | C21: =SUM(Scoring!F27:F27) -> 0 | D21: =SUM(Scoring!H27:H27) -> 0 | E21: =SUM(Scoring!I27:I27) -> 0 | F21: 0.15
B22: Venue Services | C22: =SUM('Venue Services'!B17:B17) -> 0 | D22: =SUM('Venue Services'!C17:C17) -> 0 | E22: =SUM('Venue Services'!D17:D17) -> 0 | F22: 0.15
B23: Game Clock | C23: =SUM('Additional Items'!F5:F5) -> 0 | D23: =SUM('Additional Items'!H5:H5) -> 0 | E23: =SUM('Additional Items'!I5:I5) -> 0 | F23: =SUM('Additional Items'!G5:G5) -> 0.15
B24: Pitch Clocks | C24: =SUM('Additional Items'!F6:F6) -> 0 | D24: =SUM('Additional Items'!H6:H6) -> 0 | E24: =SUM('Additional Items'!I6:I6) -> 0 | F24: =SUM('Additional Items'!G6:G6) -> 0.15
B25: OES / MIS / Timing | C25: =SUM('Additional Items'!F7:F7) -> 0 | D25: =SUM('Additional Items'!H7:H7) -> 0 | E25: =SUM('Additional Items'!I7:I7) -> 0 | F25: =SUM('Additional Items'!G7:G7) -> 0.15
B26: DMX / Misc Equipment | C26: =SUM('Additional Items'!F8:F8) -> 0 | D26: =SUM('Additional Items'!H8:H8) -> 0 | E26: =SUM('Additional Items'!I8:I8) -> 0 | F26: =SUM('Additional Items'!G8:G8) -> 0.15
B28: BASE BID GRAND TOTAL | C28: =SUM(C16,C20,C21,C22,C23,C24,C25,C26) -> 136987.93 | D28: =SUM(D16,D20,D21,D22,D23,D24,D25,D26) -> 164808.47 | E28: =IFERROR(D28-C28,0) -> 27820.54 | F28: =IFERROR(1-C28/D28,0) -> 0.17

Sheet Budget Summary
A1: Test Project — Budget Summary
A2: Test Client | 2026-04-01 | By Category
B4: Category | C4: Cost | D4: Selling Price | E4: Margin $ | F4: Margin % | G4: Price / SqFt
B5: LED Hardware (all displays) | C5: =SUM('LED Cost Sheet'!Q4:Q4) -> 55399.7 | D5: =SUM('LED Cost Sheet'!S4:S4) -> 65176.12 | E5: =IFERROR(D5-C5,0) -> 9776.42 | F5: 0.15 | G5: =IFERROR(C5/200,0) -> 277
B6: Structural Materials | C6: =SUM('Marquee - Install'!I26:I26) -> 6000 | D6: =SUM('Marquee - Install'!K26:K26) -> 7500 | E6: =IFERROR(D6-C6,0) -> 1500 | F6: 0.2 | G6: =IFERROR(C6/200,0) -> 30
B7: Structural Labor & LED Installation | C7: =(SUM('Marquee - Install'!I35:I35)-SUM('Marquee - Install'!I34:I34)) -> 25000 | D7: =(SUM('Marquee - Install'!K35:K35)-SUM('Marquee - Install'!K34:K34)) -> 31250 | E7: =IFERROR(D7-C7,0) -> 6250 | F7: 0.2 | G7: =IFERROR(C7/200,0) -> 125
B8: Electrical & Data | C8: =SUM('Marquee - Install'!I44:I44) -> 25000 | D8: =SUM('Marquee - Install'!K44:K44) -> 31250 | E8: =IFERROR(D8-C8,0) -> 6250 | F8: 0.2 | G8: =IFERROR(C8/200,0) -> 125
B9: PM / General Conditions / Travel | C9: =SUM('Marquee - Install'!I34:I34) -> 20882.35 | D9: =SUM('Marquee - Install'!K34:K34) -> 26102.94 | E9: =IFERROR(D9-C9,0) -> 5220.59 | F9: 0.2
B10: Engineering & Permits | C10: =SUM('Marquee - Install'!I52:I52) -> 4705.88 | D10: =SUM('Marquee - Install'!K52:K52) -> 5882.35 | E10: =IFERROR(D10-C10,0) -> 1176.47 | F10: 0.2
B11: CMS (Content Management System) | C11: =SUM(CMS!F26:F26) -> 0 | D11: =SUM(CMS!H26:H26) -> 0 | E11: =IFERROR(D11-C11,0) -> 0 | F11: 0.15
B12: Scoring System | C12: =SUM(Scoring!F27:F27) -> 0 | D12: =SUM(Scoring!H27:H27) -> 0 | E12: =IFERROR(D12-C12,0) -> 0 | F12: 0.15
B13: Venue Services | C13: =SUM('Venue Services'!B17:B17) -> 0 | D13: =SUM('Venue Services'!C17:C17) -> 0 | E13: =IFERROR(D13-C13,0) -> 0 | F13: 0.15
B14: Game Clock | C14: =SUM('Additional Items'!F5:F5) -> 0 | D14: =SUM('Additional Items'!H5:H5) -> 0 | E14: =IFERROR(D14-C14,0) -> 0 | F14: 0.15
B15: Pitch Clocks | C15: =SUM('Additional Items'!F6:F6) -> 0 | D15: =SUM('Additional Items'!H6:H6) -> 0 | E15: =IFERROR(D15-C15,0) -> 0 | F15: 0.15
B16: OES / MIS / Timing | C16: =SUM('Additional Items'!F7:F7) -> 0 | D16: =SUM('Additional Items'!H7:H7) -> 0 | E16: =IFERROR(D16-C16,0) -> 0 | F16: 0.15
B17: DMX / Misc Equipment | C17: =SUM('Additional Items'!F8:F8) -> 0 | D17: =SUM('Additional Items'!H8:H8) -> 0 | E17: =IFERROR(D17-C17,0) -> 0 | F17: 0.15
B19: SUBTOTAL | C19: =SUM(C5:C17) -> 136987.93 | D19: =SUM(D5:D17) -> 164808.47 | E19: =IFERROR(D19-C19,0) -> 27820.54 | F19: =IFERROR(1-C19/D19,0) -> 0.17 | G19: =IFERROR(C19/200,0) -> 684.94
B20: TAX | C20: 0 | D20: 0 | E20: 0 | F20: 0
B21: BOND | C21: 0 | D21: 0 | E21: 0 | F21: 0
B22: GRAND TOTAL | C22: =C19+C20+C21 -> 136987.93 | D22: =D19+D20+D21 -> 164808.47 | E22: =IFERROR(D22-C22,0) -> 27820.54 | F22: =IFERROR(1-C22/D22,0) -> 0.17 | G22: =IFERROR(C22/200,0) -> 684.94

Sheet LED Cost Sheet
A1: Test Project — LED Cost Sheet
U2: LED Margin Override → | V2: 0.15
A3: Display | B3: RFP H (ft) | C3: RFP W (ft) | D3: RFP NITs | E3: Vendor | F3: Product | G3: Pitch | H3: H (ft) | I3: W (ft) | J3: H (px) | K3: W (px) | L3: Qty | M3: Total SqFt | N3: Product NITs | O3: Service | P3: $/SqFt | Q3: Display Cost | R3: Processor | S3: Shipping | T3: Total Cost | U3: Margin % | V3: Selling Price | W3: ANC Margin | X3: Weight (lbs) | Y3: Total Power (W) | Z3: BTU/hr
A4: Marquee — wall | B4: 10 | C4: 20 | E4: LG/Yaham | F4: — | G4: 2.5mm | H4: 10 | I4: 20 | J4: 1219 | K4: 2438 | L4: 1 | M4: =H4*I4*L4 -> 200 | O4: front | P4: 264.15 | Q4: 52829.7 | R4: =SUM('Bundle Equipment'!E10:E10) -> 570 | S4: 2000 | T4: =Q4+R4+S4 -> 55399.7 | U4: =V$2 -> 0.168805 | V4: =IFERROR(T4/(1-U4),0) -> 164808.47 | W4: =V4-T4 -> 27820.54 | X4: 977 | Y4: 7258 | Z4: =Y4*3.412 -> 24764
A6: TOTAL (1 displays) | M6: =SUM(M4:M4) -> 200 | Q6: =SUM(Q4:Q4) -> 52829.7 | R6: =SUM(R4:R4) -> 570 | S6: =SUM(S4:S4) -> 2000 | T6: =SUM(T4:T4) -> 55399.7 | U6: =IFERROR(1-T6/V6,0) -> 0.15 | V6: =SUM(V4:V4) -> 65176.12 | W6: =SUM(W4:W4) -> 9776.42 | X6: =SUM(X4:X4) -> 0 | Y6: =SUM(Y4:Y4) -> 0 | Z6: =SUM(Z4:Z4) -> 0

Sheet Tech Specs (Installers)
A1: Test Project — LED Technical Specifications (No Pricing)
A2: Technical specifications only — no pricing data. Safe for installer/subcontractor distribution.
A4: Display Name | B4: Qty | C4: Pixel Pitch | D4: Height (ft) | E4: Width (ft) | F4: Pixels H | G4: Pixels W | H4: Sq Ft | I4: Brightness (nits) | J4: Service | K4: Environment | L4: Weight (lbs) | M4: Total Power (W) | N4: Fiber Strands | O4: BTU/hr
A5: ='LED Cost Sheet'!A4 -> Marquee — wall | B5: ='LED Cost Sheet'!I4 -> 1 | C5: ='LED Cost Sheet'!D4 -> 2.5mm | D5: ='LED Cost Sheet'!E4 -> 10 | E5: ='LED Cost Sheet'!F4 -> 20 | F5: ='LED Cost Sheet'!G4 -> 1219 | G5: ='LED Cost Sheet'!H4 -> 2438 | H5: =D5*E5*B5 -> 200 | I5: ='LED Cost Sheet'!K4 | J5: ='LED Cost Sheet'!L4 -> front | K5: indoor | L5: ='LED Cost Sheet'!U4 -> 977 | M5: ='LED Cost Sheet'!V4 -> 7258 | N5: =IFERROR((F5*G5*B5)/400000,0) -> 7.43 | O5: ='LED Cost Sheet'!W4 -> 24764

Sheet Marquee - Install
A3: Project Name: Test Project
A4: 2026-04-01
A5: Revised By: ANC Proposal Engine
C7: Linked Margin Assignment
C8: Install Margin | D8: 0.2
C9: Electrical Margin | D9: 0.2
C10: ANC Margin | D10: 0.2
C11: Engineering and Permits | D11: 0.2
B15: Marquee
B16: Height | C16: Width | D16: Total Sq. Ft | E16: QTY
B17: 10 | C17: 20 | D17: 200 | E17: 1
B19: Structural Materials: | C19: Subcontractor 1 | D19: Subcontractor 2 | E19: Subcontractor 3 | F19: Selected | G19: Additional Contingency | I19: Total Cost | J19: Install Margin | K19: Selling Price
B20: FABRICATE PRIMARY STEEL | C20: 0 | D20: 0 | E20: 0 | F20: 0 | G20: 0 | I20: =SUM(C20:G20) -> 0 | J20: =$D$8 -> 0.2 | K20: =I20/(1-J20) -> 0
B21: SUPPLY AND INSTALL PRIMARY PLYWOOD | C21: 0 | D21: 0 | E21: 0 | F21: 0 | G21: 0 | I21: =SUM(C21:G21) -> 0 | J21: =$D$8 -> 0.2 | K21: =I21/(1-J21) -> 0
B22: FABRICATE SECONDARY STEEL SUBSTRUCTURE | C22: 6000 | D22: 0 | E22: 0 | F22: 0 | G22: 0 | I22: =SUM(C22:G22) -> 6000 | J22: =$D$8 -> 0.2 | K22: =I22/(1-J22) -> 7500
B23: FABRICATE CLADDING AND TRIM | C23: 0 | D23: 0 | E23: 0 | F23: 0 | G23: 0 | I23: =SUM(C23:G23) -> 0 | J23: =$D$8 -> 0.2 | K23: =I23/(1-J23) -> 0
B24: OTHER SCOPE ITEM | C24: 0 | D24: 0 | E24: 0 | F24: 0 | G24: 0 | I24: =SUM(C24:G24) -> 0 | J24: =$D$8 -> 0.2 | K24: =I24/(1-J24) -> 0
B25: OTHER SCOPE ITEM | C25: 0 | D25: 0 | E25: 0 | F25: 0 | G25: 0 | I25: =SUM(C25:G25) -> 0 | J25: =$D$8 -> 0.2 | K25: =I25/(1-J25) -> 0
B26: SUBTOTAL | I26: =SUM(I20:I25) -> 6000 | K26: =SUM(K20:K25) -> 7500
B28: Structural Labor and LED Installation | C28: Subcontractor 1 | D28: Subcontractor 2 | E28: Subcontractor 3 | F28: Selected | G28: Additional Contingency | I28: Total Cost | J28: Install Margin | K28: Selling Price
B29: REMOVAL AND DISPOSAL | C29: 0 | D29: 0 | E29: 0 | F29: 0 | G29: 0 | I29: =SUM(C29:G29) -> 0 | J29: =$D$8 -> 0.2 | K29: =I29/(1-J29) -> 0
B30: INSTALL SECONDARY STEEL SUBSTRUCTURE | C30: 0 | D30: 0 | E30: 0 | F30: 0 | G30: 0 | I30: =SUM(C30:G30) -> 0 | J30: =$D$8 -> 0.2 | K30: =I30/(1-J30) -> 0
B31: INSTALL LED DISPLAYS | C31: 25000 | D31: 0 | E31: 0 | F31: 0 | G31: 0 | I31: =SUM(C31:G31) -> 25000 | J31: =$D$8 -> 0.2 | K31: =I31/(1-J31) -> 31250
B32: INSTALL CLADDING AND TRIM | C32: 0 | D32: 0 | E32: 0 | F32: 0 | G32: 0 | I32: =SUM(C32:G32) -> 0 | J32: =$D$8 -> 0.2 | K32: =I32/(1-J32) -> 0
B33: HEAVY EQUIPMENT | C33: 0 | D33: 0 | E33: 0 | F33: 0 | G33: 0 | I33: =SUM(C33:G33) -> 0 | J33: =$D$8 -> 0.2 | K33: =I33/(1-J33) -> 0
B34: PM/GENERAL CONDITIONS/TRAVEL | C34: 20882.35 | D34: 0 | E34: 0 | F34: 0 | G34: 0 | I34: =SUM(C34:G34) -> 20882.35 | J34: =$D$8 -> 0.2 | K34: =I34/(1-J34) -> 26102.94
B35: SUBTOTAL | I35: =SUM(I29:I34) -> 45882.35 | K35: =SUM(K29:K34) -> 57352.94
B37: Electrical and Data - Materials and Subcontracting | C37: Subcontractor 1 | D37: Subcontractor 2 | E37: Subcontractor 3 | F37: Selected | G37: Additional Contingency | I37: Total Cost | J37: Install Margin | K37: Selling Price
B38: ELECTRICAL MATERIALS | C38: 25000 | D38: 0 | E38: 0 | F38: 0 | G38: 0 | I38: =SUM(C38:G38) -> 25000 | J38: =$D$9 -> 0.2 | K38: =I38/(1-J38) -> 31250
B39: DATA MATERIALS | C39: 0 | D39: 0 | E39: 0 | F39: 0 | G39: 0 | I39: =SUM(C39:G39) -> 0 | J39: =$D$9 -> 0.2 | K39: =I39/(1-J39) -> 0
B40: ELECTRICAL LABOR | C40: 0 | D40: 0 | E40: 0 | F40: 0 | G40: 0 | I40: =SUM(C40:G40) -> 0 | J40: =$D$9 -> 0.2 | K40: =I40/(1-J40) -> 0
B41: DATA LABOR | C41: 0 | D41: 0 | E41: 0 | F41: 0 | G41: 0 | I41: =SUM(C41:G41) -> 0 | J41: =$D$9 -> 0.2 | K41: =I41/(1-J41) -> 0
B42: SUB PANEL | C42: 0 | D42: 0 | E42: 0 | F42: 0 | G42: 0 | I42: =SUM(C42:G42) -> 0 | J42: =$D$9 -> 0.2 | K42: =I42/(1-J42) -> 0
B43: MISC | C43: 0 | D43: 0 | E43: 0 | F43: 0 | G43: 0 | I43: =SUM(C43:G43) -> 0 | J43: =$D$9 -> 0.2 | K43: =I43/(1-J43) -> 0
B44: SUBTOTAL | I44: =SUM(I38:I43) -> 25000 | K44: =SUM(K38:K43) -> 31250
B46: Submittals, Engineering, and Permits | C46: Subcontractor 1 | D46: Subcontractor 2 | E46: Subcontractor 3 | F46: Selected | G46: Additional Contingency | I46: Total Cost | J46: Install Margin | K46: Selling Price
B47: STRUCTURAL ENGINEERING | C47: 4705.88 | D47: 0 | E47: 0 | F47: 0 | G47: 0 | I47: =SUM(C47:G47) -> 4705.88 | J47: =$D$11 -> 0.2 | K47: =I47/(1-J47) -> 5882.35
B48: STRUCTURAL CERTIFICATION | C48: 0 | D48: 0 | E48: 0 | F48: 0 | G48: 0 | I48: =SUM(C48:G48) -> 0 | J48: =$D$11 -> 0.2 | K48: =I48/(1-J48) -> 0
B49: ELECTRICAL ENGINEERING | C49: 0 | D49: 0 | E49: 0 | F49: 0 | G49: 0 | I49: =SUM(C49:G49) -> 0 | J49: =$D$11 -> 0.2 | K49: =I49/(1-J49) -> 0
B50: ELECTRICAL CERTIFICATION | C50: 0 | D50: 0 | E50: 0 | F50: 0 | G50: 0 | I50: =SUM(C50:G50) -> 0 | J50: =$D$11 -> 0.2 | K50: =I50/(1-J50) -> 0
...

Sheet Processor Count
A1: Test Project — Processor Count
B4: Display | C4: Width (px) | D4: Height (px) | E4: Ports | F4: Ports (80%) | G4: 8-bit Video | H4: 8-bit (80%) | I4: 10/12/HDR bit
B5: 660 Pro | C5: 1920 | D5: 1080 | E5: 8 | G5: 650000 | H5: 455000 | I5: 320000
B6: MCTRL4K | C6: 3840 | D6: 2160 | E6: 16 | G6: 650000 | H6: 455000 | I6: 320000
B7: H9 Enhanced | C7: 7680 | D7: 4320 | E7: 20 | G7: 1200000 | H7: 960000 | I7: 650000
B10: DISPLAY PROCESSOR REQUIREMENTS
B11: Display | C11: Width (px) | D11: Height (px) | E11: Qty | F11: Total Pixels | G11: Ports Needed | H11: Processor Type | I11: Processors Needed
B12: ='LED Cost Sheet'!A4 -> Marquee | C12: ='LED Cost Sheet'!H4 -> 2438 | D12: ='LED Cost Sheet'!G4 -> 1219 | E12: ='LED Cost Sheet'!I4 -> 1 | F12: =C12*D12*E12 -> 2971922 | G12: =IFERROR(CEILING(F12/650000,1),0) -> 5 | H12: =IF(G12>8,"MCTRL4K","660 Pro") -> 660 Pro | I12: =IFERROR(CEILING(G12/IF(G12>8,16,8),1),0) -> 1
B13: TOTAL | F13: =SUM(F12:F12) -> 2971922 | G13: =SUM(G12:G12) -> 5 | I13: =SUM(I12:I12) -> 1

Sheet Bundle Equipment
A1: Test Project — Processor & Equipment Breakdown
A2: Editable — adjust component costs per display zone. Totals roll into Margin Analysis.
A6: Category | B6: Component | C6: Cost | D6: Qty | E6: Total Cost | F6: Margin | G6: Selling Price | H6: Margin $
A7: Marquee — wall
A8: EQUIPMENT | B8: Sending Card | C8: 450 | D8: 1 | E8: =C8*D8 -> 450 | F8: 0.15 | G8: =IFERROR(E8/(1-F8),0) -> 529.41 | H8: =IFERROR(G8-E8,0) -> 79.41
A9: EQUIPMENT | B9: Signal Cable Kit | C9: 120 | D9: 1 | E9: =C9*D9 -> 120 | F9: 0.15 | G9: =IFERROR(E9/(1-F9),0) -> 141.18 | H9: =IFERROR(G9-E9,0) -> 21.18
B10: Zone Subtotal | E10: =SUM(E8:E9) -> 570 | G10: =SUM(G8:G9) -> 670.59 | H10: =IFERROR(G10-E10,0) -> 100.59
A12: EQUIPMENT GRAND TOTAL | E12: =E10 -> 570 | G12: =G10 -> 670.59 | H12: =IFERROR(G12-E12,0) -> 100.59

Sheet ANC Travel
A1: Test Project — ANC Travel
B4: Travel - Installation | C4: Cost | D4: Quantity | E4: Total Cost
B5: Hotel | C5: 300 | D5: 0 | E5: 0
B6: Airfare | C6: 1000 | D6: 0 | E6: 0
B7: Car | C7: 125 | D7: 0 | E7: 0
B8: Per Diem | C8: 100 | D8: 0 | E8: 0
B9: Bundled | C9: 10000 | D9: 0 | E9: 0 | G9: Account for freelancer
B10: Total | E10: 0
B11: TOTAL | C11: USD: | E11: 0
B13: Travel - Commissioning | C13: Cost | D13: Quantity | E13: Total Cost
B14: Hotel | C14: 300 | D14: 0 | E14: 0
B15: Airfare | C15: 1000 | D15: 0 | E15: 0
B16: Car | C16: 125 | D16: 0 | E16: 0
B17: Per Diem | C17: 100 | D17: 0 | E17: 0
B18: Bundled | C18: 10000 | D18: 0 | E18: 0 | G18: Account for freelancer
B19: Total | E19: 0
B20: TOTAL | C20: USD: | E20: 0
B22: Game Support | C22: Cost | D22: Quantity | E22: Total Cost
B23: Hotel | C23: 300 | D23: 0 | E23: 0
B24: Airfare | C24: 1000 | D24: 0 | E24: 0
B25: Car | C25: 125 | D25: 0 | E25: 0
B26: Per Diem | C26: 100 | D26: 0 | E26: 0
B27: Bundled | C27: 10000 | D27: 0 | E27: 0 | G27: Account for freelancer
B28: Game Day Support | C28: 1500 | D28: 0 | E28: 0
B29: Total | E29: 0
B30: TOTAL | C30: USD: | E30: 0

Sheet CMS
A1: Test Project — Content Management System
B4: CMS Platform
B5: All costs require project-specific pricing — update items below based on RFP requirements
B6: Category | C6: Item | D6: Cost | E6: Quantity | F6: Total Cost | G6: Margin | H6: Selling Price | I6: Margin $
B7: PRIMARY | C7: DESIGN & CONTROL SOFTWARE | D7: 0 | E7: 0 | F7: =D7*E7 -> 0 | G7: 0.1 | H7: =IFERROR(F7/(1-G7),0) -> 0 | I7: =IFERROR(H7-F7,0) -> 0
B8: PRIMARY | C8: GRAPHICS PLAYBACK ENGINE | D8: 0 | E8: 0 | F8: =D8*E8 -> 0 | G8: 0.1 | H8: =IFERROR(F8/(1-G8),0) -> 0 | I8: =IFERROR(H8-F8,0) -> 0
B9: PRIMARY | C9: IMAGE PROCESSING | D9: 0 | E9: 0 | F9: =D9*E9 -> 0 | G9: 0.1 | H9: =IFERROR(F9/(1-G9),0) -> 0 | I9: =IFERROR(H9-F9,0) -> 0
B10: PRIMARY | C10: DEDICATED LED ROUTER / SWITCH | D10: 0 | E10: 0 | F10: =D10*E10 -> 0 | G10: 0.1 | H10: =IFERROR(F10/(1-G10),0) -> 0 | I10: =IFERROR(H10-F10,0) -> 0
B11: REDUNDANT | C11: DESIGN & CONTROL SOFTWARE | D11: 0 | E11: 0 | F11: =D11*E11 -> 0 | G11: 0.1 | H11: =IFERROR(F11/(1-G11),0) -> 0 | I11: =IFERROR(H11-F11,0) -> 0
B12: REDUNDANT | C12: GRAPHICS PLAYBACK ENGINE | D12: 0 | E12: 0 | F12: =D12*E12 -> 0 | G12: 0.1 | H12: =IFERROR(F12/(1-G12),0) -> 0 | I12: =IFERROR(H12-F12,0) -> 0
B13: REDUNDANT | C13: IMAGE PROCESSING | D13: 0 | E13: 0 | F13: =D13*E13 -> 0 | G13: 0.1 | H13: =IFERROR(F13/(1-G13),0) -> 0 | I13: =IFERROR(H13-F13,0) -> 0
B14: STANDARD SERVICES | C14: COMMISSIONING | D14: 0 | E14: 0 | F14: =D14*E14 -> 0 | G14: 0.1 | H14: =IFERROR(F14/(1-G14),0) -> 0 | I14: =IFERROR(H14-F14,0) -> 0
B15: STANDARD SERVICES | C15: EVENT SUPPORT | D15: 0 | E15: 0 | F15: =D15*E15 -> 0 | G15: 0.1 | H15: =IFERROR(F15/(1-G15),0) -> 0 | I15: =IFERROR(H15-F15,0) -> 0
B16: STANDARD SERVICES | C16: PROJECT MANAGEMENT | D16: 0 | E16: 0 | F16: =D16*E16 -> 0 | G16: 0.1 | H16: =IFERROR(F16/(1-G16),0) -> 0 | I16: =IFERROR(H16-F16,0) -> 0
C17: Integration Hardware | D17: 0 | E17: 0 | F17: =D17*E17 -> 0 | G17: 0.1 | H17: =IFERROR(F17/(1-G17),0) -> 0 | I17: =IFERROR(H17-F17,0) -> 0
C18: Integration Labor | D18: 0 | E18: 0 | F18: =D18*E18 -> 0 | G18: 0.1 | H18: =IFERROR(F18/(1-G18),0) -> 0 | I18: =IFERROR(H18-F18,0) -> 0
C19: Shipping | D19: 0 | E19: 0 | F19: =D19*E19 -> 0 | G19: 0.1 | H19: =IFERROR(F19/(1-G19),0) -> 0 | I19: =IFERROR(H19-F19,0) -> 0
C20: Travel | D20: 0 | E20: 0 | F20: =D20*E20 -> 0 | G20: 0.1 | H20: =IFERROR(F20/(1-G20),0) -> 0 | I20: =IFERROR(H20-F20,0) -> 0
C22: CMS TOTAL | F22: =SUM(F7:F20) -> 0 | H22: =SUM(H7:H20) -> 0 | I22: =IFERROR(H22-F22,0) -> 0
B24: TAX | F24: 0
B25: BOND | F25: 0
B26: SUB TOTAL | C26: USD: | F26: =F22+F24+F25 -> 0 | H26: =H22 -> 0 | I26: =IFERROR(H26-F26,0) -> 0

Sheet Scoring
A1: Test Project — Scoring System
B4: Scoring Platform
B5: All costs require project-specific pricing — update items below based on RFP requirements
B6: Category | C6: Item | D6: Cost | E6: Quantity | F6: Total Cost | G6: Margin | H6: Selling Price | I6: Margin $
B7: HARDWARE | C7: SCORING CONTROLLER / SERVER | D7: 0 | E7: 0 | F7: =D7*E7 -> 0 | G7: 0.1 | H7: =IFERROR(F7/(1-G7),0) -> 0 | I7: =IFERROR(H7-F7,0) -> 0
B8: HARDWARE | C8: OPERATOR WORKSTATION(S) | D8: 0 | E8: 0 | F8: =D8*E8 -> 0 | G8: 0.1 | H8: =IFERROR(F8/(1-G8),0) -> 0 | I8: =IFERROR(H8-F8,0) -> 0
B9: HARDWARE | C9: SCOREBOARD INPUT DEVICES | D9: 0 | E9: 0 | F9: =D9*E9 -> 0 | G9: 0.1 | H9: =IFERROR(F9/(1-G9),0) -> 0 | I9: =IFERROR(H9-F9,0) -> 0
B10: HARDWARE | C10: SHOT CLOCK / GAME CLOCK INTERFACE | D10: 0 | E10: 0 | F10: =D10*E10 -> 0 | G10: 0.1 | H10: =IFERROR(F10/(1-G10),0) -> 0 | I10: =IFERROR(H10-F10,0) -> 0
B11: HARDWARE | C11: STATISTICS INTERFACE | D11: 0 | E11: 0 | F11: =D11*E11 -> 0 | G11: 0.1 | H11: =IFERROR(F11/(1-G11),0) -> 0 | I11: =IFERROR(H11-F11,0) -> 0
B12: SOFTWARE | C12: SCORING SOFTWARE LICENSE | D12: 0 | E12: 0 | F12: =D12*E12 -> 0 | G12: 0.1 | H12: =IFERROR(F12/(1-G12),0) -> 0 | I12: =IFERROR(H12-F12,0) -> 0
B13: SOFTWARE | C13: GRAPHICS / ANIMATION PACKAGE | D13: 0 | E13: 0 | F13: =D13*E13 -> 0 | G13: 0.1 | H13: =IFERROR(F13/(1-G13),0) -> 0 | I13: =IFERROR(H13-F13,0) -> 0
B14: SOFTWARE | C14: STATISTICS INTEGRATION | D14: 0 | E14: 0 | F14: =D14*E14 -> 0 | G14: 0.1 | H14: =IFERROR(F14/(1-G14),0) -> 0 | I14: =IFERROR(H14-F14,0) -> 0
B15: SERVICES | C15: COMMISSIONING | D15: 0 | E15: 0 | F15: =D15*E15 -> 0 | G15: 0.1 | H15: =IFERROR(F15/(1-G15),0) -> 0 | I15: =IFERROR(H15-F15,0) -> 0
B16: SERVICES | C16: TRAINING | D16: 0 | E16: 0 | F16: =D16*E16 -> 0 | G16: 0.1 | H16: =IFERROR(F16/(1-G16),0) -> 0 | I16: =IFERROR(H16-F16,0) -> 0
B17: SERVICES | C17: PROJECT MANAGEMENT | D17: 0 | E17: 0 | F17: =D17*E17 -> 0 | G17: 0.1 | H17: =IFERROR(F17/(1-G17),0) -> 0 | I17: =IFERROR(H17-F17,0) -> 0
C18: Integration Hardware | D18: 0 | E18: 0 | F18: =D18*E18 -> 0 | G18: 0.1 | H18: =IFERROR(F18/(1-G18),0) -> 0 | I18: =IFERROR(H18-F18,0) -> 0
C19: Integration Labor | D19: 0 | E19: 0 | F19: =D19*E19 -> 0 | G19: 0.1 | H19: =IFERROR(F19/(1-G19),0) -> 0 | I19: =IFERROR(H19-F19,0) -> 0
C20: Shipping | D20: 0 | E20: 0 | F20: =D20*E20 -> 0 | G20: 0.1 | H20: =IFERROR(F20/(1-G20),0) -> 0 | I20: =IFERROR(H20-F20,0) -> 0
C21: Travel | D21: 0 | E21: 0 | F21: =D21*E21 -> 0 | G21: 0.1 | H21: =IFERROR(F21/(1-G21),0) -> 0 | I21: =IFERROR(H21-F21,0) -> 0
C23: SCORING TOTAL | F23: =SUM(F7:F21) -> 0 | H23: =SUM(H7:H21) -> 0 | I23: =IFERROR(H23-F23,0) -> 0
B25: TAX | F25: 0
B26: BOND | F26: 0
B27: SUB TOTAL | C27: USD: | F27: =F23+F25+F26 -> 0 | H27: =H23 -> 0 | I27: =IFERROR(H27-F27,0) -> 0

Sheet Venue Services
A1: Test Project — Venue Services
A2: Multi-year service contract calculator
A4: Contract Years | B4: 3 | C4: Editable service term
A5: Year 1 Cost | B5: 0 | C5: Base annual contract value
A6: Annual Escalation % | B6: 0.03 | C6: Applied to each renewal year
A7: Margin % | B7: 0.15 | C7: Target service-contract margin
A10: Year | B10: Cost | C10: Selling Price | D10: Margin $ | E10: Notes
A11: =IF($B$4>=1,"Year 1","") -> Year 1 | B11: =$B$5 -> 0 | C11: =IF(A11="",0,IFERROR(B11/(1-$B$7),0)) -> 0 | D11: =IF(A11="",0,IFERROR(C11-B11,0)) -> 0 | E11: Escalated annual term
A12: =IF($B$4>=2,"Year 2","") -> Year 2 | B12: =IF(A12="",0,B11*(1+$B$6)) -> 0 | C12: =IF(A12="",0,IFERROR(B12/(1-$B$7),0)) -> 0 | D12: =IF(A12="",0,IFERROR(C12-B12,0)) -> 0 | E12: Escalated annual term
A13: =IF($B$4>=3,"Year 3","") -> Year 3 | B13: =IF(A13="",0,B12*(1+$B$6)) -> 0 | C13: =IF(A13="",0,IFERROR(B13/(1-$B$7),0)) -> 0 | D13: =IF(A13="",0,IFERROR(C13-B13,0)) -> 0 | E13: Escalated annual term
A14: =IF($B$4>=4,"Year 4","") | B14: =IF(A14="",0,B13*(1+$B$6)) -> 0 | C14: =IF(A14="",0,IFERROR(B14/(1-$B$7),0)) -> 0 | D14: =IF(A14="",0,IFERROR(C14-B14,0)) -> 0
A15: =IF($B$4>=5,"Year 5","") | B15: =IF(A15="",0,B14*(1+$B$6)) -> 0 | C15: =IF(A15="",0,IFERROR(B15/(1-$B$7),0)) -> 0 | D15: =IF(A15="",0,IFERROR(C15-B15,0)) -> 0
A17: VENUE SERVICES TOTAL | B17: =SUM(B11:B15) -> 0 | C17: =SUM(C11:C15) -> 0 | D17: =IFERROR(C17-B17,0) -> 0

Sheet Additional Items
A1: Test Project — Additional Non-LED Items
B4: Category | C4: Item | D4: Cost | E4: Quantity | F4: Total Cost | G4: Margin | H4: Selling Price | I4: Margin $
B5: GAME CLOCK | C5: Six-Digit Game Clocks | D5: 0 | E5: 1 | F5: =D5*E5 -> 0 | G5: 0.15 | H5: =IFERROR(F5/(1-G5),0) -> 0 | I5: =IFERROR(H5-F5,0) -> 0
B6: PITCH CLOCK | C6: Pitch Clocks | D6: 0 | E6: 1 | F6: =D6*E6 -> 0 | G6: 0.15 | H6: =IFERROR(F6/(1-G6),0) -> 0 | I6: =IFERROR(H6-F6,0) -> 0
B7: OES / MIS | C7: OES / MIS / Timing | D7: 0 | E7: 1 | F7: =D7*E7 -> 0 | G7: 0.15 | H7: =IFERROR(F7/(1-G7),0) -> 0 | I7: =IFERROR(H7-F7,0) -> 0
B8: MISC | C8: DMX / Misc Equipment | D8: 0 | E8: 1 | F8: =D8*E8 -> 0 | G8: 0.15 | H8: =IFERROR(F8/(1-G8),0) -> 0 | I8: =IFERROR(H8-F8,0) -> 0
C10: ADDITIONAL ITEMS TOTAL | F10: =SUM(F5:F8) -> 0 | H10: =SUM(H5:H8) -> 0 | I10: =IFERROR(H10-F10,0) -> 0

Sheet Resp Matrix
B1: Project: Test Project
B2: Date: 4/1/2026
B4: Administrative | C4: ANC | D4: Purchaser
B5: Provide accurate architectural, structural engineering, and AV drawings. | D5: X
B6: Provide Payment and Performance Bond. | C6: NA
B7: All required zoning, building, street or sidewalk permits. | C7: NA
B8: Shipping of all equipment to site. | C8: X
B9: Receive, unload, and inspect all new equipment upon arrival. | C9: X
B10: Provide safe storage of video equipment and control room. | D10: X
B11: Unobstructed access to equipment and control room. | D11: X
B13: Engineering & Submittals | C13: ANC | D13: Purchaser
B14: Customer responsible to ensure existing structure supports new equipment. | D14: X
B15: Provide mechanical drawings, electrical drawings, and load calculations. | C15: X
B16: Engineering and certification for new equipment attachments. | C16: X
B17: Provide approval of all mechanical/electrical drawings. | D17: X
B18: Responsible to ensure structural integrity of existing conditions. | D18: X
B20: Physical Installation | C20: ANC | D20: Purchaser
B21: ANC assumes all base building structure is provided by others. | C21: Include Statement
B22: ANC has included removal and disposal of existing equipment. | D22: X
B23: ANC assumes reasonable access will be provided to the work area. | C23: Include Statement
B24: Fabricate, deliver, and install support structure. | C24: X
B25: Provide & Install LED components. | C25: X
B26: Provide all required Floor/Site Protection. | D26: X
B28: Electrical & Data Installation | C28: ANC | D28: Purchaser
B29: Submit electrical engineering drawings. | C29: X
B30: Provide primary power feed to each display location. | D30: X
B31: Provide secondary electrical panels and/or remote disconnects. | D31: X
B32: Furnish signal cables as specified by ANC. | C32: X
B33: Provide and install signal cable conduit. | D33: X
B34: Labor to pull signal cable. | C34: X
B35: Terminate signal cable at control system equipment. | C35: X
B36: Mount and install data patch panel. | C36: X
B37: Provide high speed internet connection to control room. | D37: X
B39: Control System | C39: ANC | D39: Purchaser
B40: ANC has provided display processors only. | C40: Include Statement
B41: Provide climate controlled control room. | D41: X
B42: Supply static IP address five (5) days prior to installation. | D42: X
B44: Training | C44: ANC | D44: Purchaser
B45: Provide appropriate on-site operation and maintenance training. | C45: X
B46: Provide sign off list for all training. | C46: X
...

Sheet P&L
A1: Test Project — P&L
A3: Project #: | D3: Net 30
B5: PROJECTS BUDGET | I5: CONTRACT BUDGET
B6: Revenue | C6: Budgeted Cost | D6: Margin | I6: Revenue | J6: Budgeted Cost
A7: Base Contract | B7: 164808.47 | C7: 136987.93 | D7: 27820.54 | H7: TOTAL BASE CONTRACT | I7: 164808.47 | J7: 136987.93
A8: TOTAL BASE CONTRACT | B8: 164808.47 | C8: 136987.93 | D8: 27820.54
A10: Change Orders
A11: Total Change Order(s) Amount | B11: 0 | C11: 0 | D11: 0
A13: Grand Total | B13: 164808.47 | C13: 136987.93 | D13: 27820.54
A16: Cost Category | B16: Revenue | C16: Budget | D16: Committed POs | E16: Budget Remaining
A17: LED | B17: 0 | C17: 50314 | D17: 0 | E17: 50314
A18: Install | B18: 0 | C18: 31000 | D18: 0 | E18: 31000
A19: Electrical | B19: 0 | C19: 25000 | D19: 0 | E19: 25000
A20: ANC Travel | B20: 0 | C20: 15000 | D20: 0 | E20: 15000
A21: Structural Engineering | B21: 0 | C21: 4705.88 | D21: 0 | E21: 4705.88
A22: Electrical Engineering | B22: 0 | C22: 0 | D22: 0 | E22: 0
A23: CMS | B23: 0 | C23: 0 | D23: 0 | E23: 0
A24: Parts/Labor | B24: 0 | C24: 0 | D24: 0 | E24: 0
A25: Tax | B25: 0 | C25: 0 | D25: 0 | E25: 0
A26: Bond | B26: 0 | C26: 0 | D26: 0 | E26: 0
A27: BASE CONTRACT TOTAL | C27: 136987.93 | D27: 0 | E27: 136987.93

Sheet Cash Flow
A1: Test Project — Cash Flow
D3: Payment Terms: Net 30
D4: Payment Phases | E4: Contract Signed | F4: Product Shipping | G4: Substantial Completion | H4: Sign Off
D5: Percentages | E5: 0.25 | F5: 0.25 | G5: 0.25 | H5: 0.25
B6: Contract Award Date | C6: TBD
B7: Scheduled Completion | C7: TBD
B9: Revenue | C9: Expenses | D9: Gross Profit | E9: Gross Profit % | F9: Budget Tracking (+/-)
B10: 164808.47 | C10: 136987.93 | D10: 27820.54 | E10: 0.16880528 | F10: 0
A12: Month | E12: Month 1 | F12: Month 2 | G12: Month 3 | H12: Month 4 | I12: Month 5 | J12: Month 6 | K12: Month 7 | L12: Month 8 | M12: Month 9 | N12: Month 10
A13: Revenue | C13: Amount | D13: Date Submitted
A14: 1 | C14: 0 | E14: 0 | F14: 0 | G14: 0 | H14: 0 | I14: 0 | J14: 0 | K14: 0 | L14: 0 | M14: 0 | N14: 0
A15: 2 | C15: 0 | E15: 0 | F15: 0 | G15: 0 | H15: 0 | I15: 0 | J15: 0 | K15: 0 | L15: 0 | M15: 0 | N15: 0
A16: 3 | C16: 0 | E16: 0 | F16: 0 | G16: 0 | H16: 0 | I16: 0 | J16: 0 | K16: 0 | L16: 0 | M16: 0 | N16: 0
A17: 4 | C17: 0 | E17: 0 | F17: 0 | G17: 0 | H17: 0 | I17: 0 | J17: 0 | K17: 0 | L17: 0 | M17: 0 | N17: 0
A18: 5 | C18: 0 | E18: 0 | F18: 0 | G18: 0 | H18: 0 | I18: 0 | J18: 0 | K18: 0 | L18: 0 | M18: 0 | N18: 0
A19: 6 | C19: 0 | E19: 0 | F19: 0 | G19: 0 | H19: 0 | I19: 0 | J19: 0 | K19: 0 | L19: 0 | M19: 0 | N19: 0
A20: 7 | C20: 0 | E20: 0 | F20: 0 | G20: 0 | H20: 0 | I20: 0 | J20: 0 | K20: 0 | L20: 0 | M20: 0 | N20: 0
A21: 8 | C21: 0 | E21: 0 | F21: 0 | G21: 0 | H21: 0 | I21: 0 | J21: 0 | K21: 0 | L21: 0 | M21: 0 | N21: 0
A22: 9 | C22: 0 | E22: 0 | F22: 0 | G22: 0 | H22: 0 | I22: 0 | J22: 0 | K22: 0 | L22: 0 | M22: 0 | N22: 0
A23: 10 | C23: 0 | E23: 0 | F23: 0 | G23: 0 | H23: 0 | I23: 0 | J23: 0 | K23: 0 | L23: 0 | M23: 0 | N23: 0
A24: Total Revenue | C24: 0

Sheet PO's
A1: Test Project — Purchase Orders
A3: PO Number | B3: Vendor | C3: Title / Description | D3: Original Contract Amount | E3: Category
D4: 0
D5: 0
D6: 0
D7: 0
D8: 0
D9: 0
D10: 0
D11: 0
D12: 0
D13: 0
D14: 0
D15: 0
... D33: 0

Sheet _Products
A1: 10mm Mesh P10 (Nitxeon)
A2: 2.5mm Indoor (Nationstar MIP)
A3: 4mm Indoor (Nitxeon)
A4: C1.2-MIP 1.2mm Indoor (Alt)
A5: C1.8-MIP 1.8mm Indoor/VisiBowl (Alt)
A6: LG LSCA015 1.5mm Indoor Fine Pitch
A7: LG LSCA039 3.91mm Indoor Ceiling
A8: LG LSCB025 2.5mm Indoor Wall
A9: LG LSGA039 3.9mm Indoor Wall
A10: Mesh P10 FM1921 3.9mm Indoor
A11: Yaham Aura A10 Perimeter
A12: Yaham Corona C10 Indoor
... A23: Yaham Radiance R8 Outdoor
