Workbook

Sheet Project Overview
A1: Large Format LED — Project Overview
A2: Client | 2026-04-01 | ANC Proposal Engine
B4: PROJECT INFORMATION
B5: Client | C5: Client
B6: Project Name | C6: Large Format LED
B7: Location | C7: Large Format LED
B8: Date Created | C8: 2026-04-01
B9: Currency | C9: USD
B10: Environment | C10: Indoor
B11: Union Labor | C11: No
B12: Bond Required | C12: No
B13: Number of Displays | C13: =SUM('LED Cost Sheet'!I4:I47) -> 44
B15: FINANCIAL PARAMETERS
B16: LED Hardware Margin | C16: 0.15
B17: Install / Services Margin | C17: 0.15
B18: Engineering Margin | C18: 0.15
B19: Equipment Margin | C19: 0.15
B20: CMS Margin | C20: 0.15
B21: Bond Rate | C21: N/A
B22: Tax Rate | C22: Per zone (editable on MA)
B23: Tariff Rate | C23: Per zone (editable on MA)
B25: SUMMARY TOTALS
B26: Total Cost | C26: ='Margin Analysis'!C587 -> 20352793
B27: Total Selling Price | C27: ='Margin Analysis'!D587 -> 23399111
B28: Project Margin $ | C28: ='Margin Analysis'!E587 -> 3046318.6
B29: Project Margin % | C29: ='Margin Analysis'!F587 -> 0.13
B30: DOCUMENT TOTAL | C30: ='Margin Analysis'!D587 -> 23399111

Sheet Margin Analysis
A1: Large Format LED — Margin Analysis
A2: Client | 2026-04-01 | ANC Proposal Engine
B4: Zone / Category | C4: Cost | D4: Selling Price | E4: Margin $ | F4: Margin %
B5: TEAM ROOM — TEAM ROOM | D5: Selling Price
B6: LED Hardware | C6: ='LED Cost Sheet'!T4 -> 23528.42 | D6: ='LED Cost Sheet'!V4 -> 27680.49 | E6: =IFERROR(D6-C6,0) -> 4152.07 | F6: 0.15
B7: Structural Materials | C7: ='TEAM ROOM - Install'!I26 -> 1222.5 | D7: =IFERROR(C7/(1-F7),0) -> 1438.24 | E7: =IFERROR(D7-C7,0) -> 215.74 | F7: 0.15
B8: Structural Labor & LED Installation | C8: ='TEAM ROOM - Install'!I35-'TEAM ROOM - Install'!I34 -> 5093.75 | D8: =IFERROR(C8/(1-F8),0) -> 5992.65 | E8: =IFERROR(D8-C8,0) -> 898.9 | F8: 0.15
B9: Electrical & Data | C9: ='TEAM ROOM - Install'!I44 -> 5093.75 | D9: =IFERROR(C9/(1-F9),0) -> 5992.65 | E9: =IFERROR(D9-C9,0) -> 898.9 | F9: 0.15
B10: PM / General Conditions / Travel | C10: ='TEAM ROOM - Install'!I34 -> 20882.35 | D10: =IFERROR(C10/(1-F10),0) -> 24567.47 | E10: =IFERROR(D10-C10,0) -> 3685.12 | F10: 0.15
B11: Engineering & Permits | C11: ='TEAM ROOM - Install'!I52 -> 4705.88 | D11: =IFERROR(C11/(1-F11),0) -> 5536.33 | E11: =IFERROR(D11-C11,0) -> 830.45 | F11: 0.15
B12: SUBTOTAL | C12: =SUM(C6:C11) -> 60526.65 | D12: =SUM(D6:D11) -> 69895.82 | E12: =IFERROR(D12-C12,0) -> 9369.17 | F12: =IFERROR(1-C12/D12,0) -> 0.134045
B13: TAX | C13: 0 | D13: 0 | E13: 0 | G13: 0
B14: BOND | C14: 0 | D14: 0 | E14: 0 | G14: 0
B15: TARIFF | C15: 0 | D15: 0 | E15: 0 | G15: 0
B16: GRAND TOTAL | C16: =C12+C13+C14+C15 -> 60526.65 | D16: =D12+D13+D14+D15 -> 69895.82 | E16: =IFERROR(D16-C16,0) -> 9369.17 | F16: =IFERROR(1-C16/D16,0) -> 0.13404478
B18: INCIDENT COMMANT — INCIDENT COMMANT | D18: Selling Price
B19: LED Hardware | C19: ='LED Cost Sheet'!T5 -> 25593.73 | D19: ='LED Cost Sheet'!V5 -> 30110.27 | E19: =IFERROR(D19-C19,0) -> 4516.54 | F19: 0.15
B20: Structural Materials | C20: ='INCIDENT COMMANT - Install'!I26 -> 1331.25 | D20: =IFERROR(C20/(1-F20),0) -> 1566.18 | E20: =IFERROR(D20-C20,0) -> 234.93 | F20: 0.15
B21: Structural Labor & LED Installation | C21: ='INCIDENT COMMANT - Install'!I35-'INCIDENT COMMANT - Install'!I34 -> 5546.88 | D21: =IFERROR(C21/(1-F21),0) -> 6525.74 | E21: =IFERROR(D21-C21,0) -> 978.86 | F21: 0.15
B22: Electrical & Data | C22: ='INCIDENT COMMANT - Install'!I44 -> 5546.88 | D22: =IFERROR(C22/(1-F22),0) -> 6525.74 | E22: =IFERROR(D22-C22,0) -> 978.86 | F22: 0.15
B23: PM / General Conditions / Travel | C23: ='INCIDENT COMMANT - Install'!I34 -> 20882.35 | D23: =IFERROR(C23/(1-F23),0) -> 24567.47 | E23: =IFERROR(D23-C23,0) -> 3685.12 | F23: 0.15
B24: Engineering & Permits | C24: ='INCIDENT COMMANT - Install'!I52 -> 4705.88 | D24: =IFERROR(C24/(1-F24),0) -> 5536.33 | E24: =IFERROR(D24-C24,0) -> 830.45 | F24: 0.15
B25: SUBTOTAL | C25: =SUM(C19:C24) -> 63606.97 | D25: =SUM(D19:D24) -> 73402.32 | E25: =IFERROR(D25-C25,0) -> 9795.35 | F25: =IFERROR(1-C25/D25,0) -> 0.133447
B26: TAX | C26: 0 | D26: 0 | E26: 0 | G26: 0
B27: BOND | C27: 0 | D27: 0 | E27: 0 | G27: 0
B28: TARIFF | C28: 0 | D28: 0 | E28: 0 | G28: 0
B29: GRAND TOTAL | C29: =C25+C26+C27+C28 -> 63606.97 | D29: =D25+D26+D27+D28 -> 73402.32 | E29: =IFERROR(D29-C29,0) -> 9795.35 | F29: =IFERROR(1-C29/D29,0) -> 0.13344742
B31: DEF UNIT — DEF UNIT | D31: Selling Price
B32: LED Hardware | C32: ='LED Cost Sheet'!T6 -> 14818.14 | D32: ='LED Cost Sheet'!V6 -> 17433.11 | E32: =IFERROR(D32-C32,0) -> 2614.97 | F32: 0.15
B33: Structural Materials | C33: ='DEF UNIT - Install'!I26 -> 761.25 | D33: =IFERROR(C33/(1-F33),0) -> 895.59 | E33: =IFERROR(D33-C33,0) -> 134.34 | F33: 0.15
B34: Structural Labor & LED Installation | C34: ='DEF UNIT - Install'!I35-'DEF UNIT - Install'!I34 -> 3171.88 | D34: =IFERROR(C34/(1-F34),0) -> 3731.62 | E34: =IFERROR(D34-C34,0) -> 559.74 | F34: 0.15
B35: Electrical & Data | C35: ='DEF UNIT - Install'!I44 -> 3171.88 | D35: =IFERROR(C35/(1-F35),0) -> 3731.62 | E35: =IFERROR(D35-C35,0) -> 559.74 | F35: 0.15
B36: PM / General Conditions / Travel | C36: ='DEF UNIT - Install'!I34 -> 20882.35 | D36: =IFERROR(C36/(1-F36),0) -> 24567.47 | E36: =IFERROR(D36-C36,0) -> 3685.12 | F36: 0.15
B37: Engineering & Permits | C37: ='DEF UNIT - Install'!I52 -> 4705.88 | D37: =IFERROR(C37/(1-F37),0) -> 5536.33 | E37: =IFERROR(D37-C37,0) -> 830.45 | F37: 0.15
B38: SUBTOTAL | C38: =SUM(C32:C37) -> 47511.38 | D38: =SUM(D32:D37) -> 55078.92 | E38: =IFERROR(D38-C38,0) -> 7567.54 | F38: =IFERROR(1-C38/D38,0) -> 0.137394
B39: TAX | C39: 0 | D39: 0 | E39: 0 | G39: 0
B40: BOND | C40: 0 | D40: 0 | E40: 0 | G40: 0
B41: TARIFF | C41: 0 | D41: 0 | E41: 0 | G41: 0
B42: GRAND TOTAL | C42: =C38+C39+C40+C41 -> 47511.38 | D42: =D38+D39+D40+D41 -> 55078.92 | E42: =IFERROR(D42-C42,0) -> 7567.54 | F42: =IFERROR(1-C42/D42,0) -> 0.13739449
B44: NORTH CORRIDOR — NORTH CORRIDOR | D44: Selling Price
...

Sheet Budget Summary
A1: Large Format LED — Budget Summary
A2: Client | 2026-04-01 | By Category
B4: Category | C4: Cost | D4: Selling Price | E4: Margin $ | F4: Margin % | G4: Price / SqFt
B5: LED Hardware (all displays) | C5: =SUM('LED Cost Sheet'!Q4:Q47) -> 7532605.6 | D5: =SUM('LED Cost Sheet'!S4:S47) -> 8861888.9 | E5: =IFERROR(D5-C5,0) -> 1329283.3 | F5: 0.15 | G5: =IFERROR(C5/46207.810000000005,0) -> 163.02
B6: Structural Materials | C6: =SUM('TEAM ROOM - Install'!I26:I26)+SUM('INCIDENT COMMANT - Install'!I26:I26)+SUM('DEF UNIT - Install'!I26:I26)+SUM('NORTH CORRIDOR - Install'!I26:I26)+SUM('SOUTH CORRIDOR - Install'!I26:I26)+SUM('S.E. CORRIDOR (CEILING) - Insta'!I26:I26)+SUM('S.E. CORRIDOR (CEILING7 - Insta'!I26:I26)+SUM('EAST CORRIDOR (CEILING) - Insta'!I26:I26)+SUM('N.E. CORRIDOR (CEILING) - Insta'!I26:I26)+SUM('N.E. CORRIDOR (CEILING10 - Inst'!I26:I26)+SUM('LARGE ADMIN ROOM - Install'!I26:I26)+SUM('ELEV LOBBY - Install'!I26:I26)+SUM('NORTH CLUB - Install'!I26:I26)+SUM('PANTHERS DEN - Install'!I26:I26)+SUM('PANTHERS DEN15 - Install'!I26:I26)+SUM('PANTHERS DEN16 - Install'!I26:I26)+SUM('PANTHERS DEN17 - Install'!I26:I26)+SUM('PANTHERS DEN18 - Install'!I26:I26)+SUM('PANTHERS DEN19 - Install'!I26:I26)+SUM('PANTHERS DEN20 - Install'!I26:I26)+SUM('SOUTH CLUB - Install'!I26:I26)+SUM('ELEV LOBBY22 - Install'!I26:I26)+SUM('SOUTH CLUB23 - Install'!I26:I26)+SUM('ELEV LOBBY24 - Install'!I26:I26)+SUM('ELEV LOBBY25 - Install'!I26:I26)+SUM('NORTH CLUB26 - Install'!I26:I26)+SUM('RIBBON NW - Install'!I26:I26)+SUM('RIBBON NW28 - Install'!I26:I26)+SUM('RIBBON NW29 - Install'!I26:I26)+SUM('RIBBON NW30 - Install'!I26:I26)+SUM('RIBBON SW - Install'!I26:I26)+SUM('RIBBON SW32 - Install'!I26:I26)+SUM('RIBBON SW33 - Install'!I26:I26)+SUM('SCOREBOARD EAST - Install'!I26:I26)+SUM('SCOREBOARD WEST - Install'!I26:I26)+SUM('EAST ENTRY A - Install'!I26:I26)+SUM('EAST ENTRY B - Install'!I26:I26)+SUM('EAST ENTRY C - Install'!I26:I26)+SUM('EAST ENTRY D - Install'!I26:I26)+SUM('NORTH EAST EXTERIOR NE - Instal'!I26:I26)+SUM('NORTH ENTRY C - Install'!I26:I26)+SUM('NORTH ENTRY C42 - Install'!I26:I26)+SUM('NORTH ENTRY C43 - Install'!I26:I26)+SUM('SOUTH EAST EXTERIOR SE - Instal'!I26:I26) -> 1187209 | D6: =SUM('TEAM ROOM - Install'!K26:K26)+SUM('INCIDENT COMMANT - Install'!K26:K26)+SUM('DEF UNIT - Install'!K26:K26)+SUM('NORTH CORRIDOR - Install'!K26:K26)+SUM('SOUTH CORRIDOR - Install'!K26:K26)+SUM('S.E. CORRIDOR (CEILING) - Insta'!K26:K26)+SUM('S.E. CORRIDOR (CEILING7 - Insta'!K26:K26)+SUM('EAST CORRIDOR (CEILING) - Insta'!K26:K26)+SUM('N.E. CORRIDOR (CEILING) - Insta'!K26:K26)+SUM('N.E. CORRIDOR (CEILING10 - Inst'!K26:K26)+SUM('LARGE ADMIN ROOM - Install'!K26:K26)+SUM('ELEV LOBBY - Install'!K26:K26)+SUM('NORTH CLUB - Install'!K26:K26)+SUM('PANTHERS DEN - Install'!K26:K26)+SUM('PANTHERS DEN15 - Install'!K26:K26)+SUM('PANTHERS DEN16 - Install'!K26:K26)+SUM('PANTHERS DEN17 - Install'!K26:K26)+SUM('PANTHERS DEN18 - Install'!K26:K26)+SUM('PANTHERS DEN19 - Install'!K26:K26)+SUM('PANTHERS DEN20 - Install'!K26:K26)+SUM('SOUTH CLUB - Install'!K26:K26)+SUM('ELEV LOBBY22 - Install'!K26:K26)+SUM('SOUTH CLUB23 - Install'!K26:K26)+SUM('ELEV LOBBY24 - Install'!K26:K26)+SUM('ELEV LOBBY25 - Install'!K26:K26)+SUM('NORTH CLUB26 - Install'!K26:K26)+SUM('RIBBON NW - Install'!K26:K26)+SUM('RIBBON NW28 - Install'!K26:K26)+SUM('RIBBON NW29 - Install'!K26:K26)+SUM('RIBBON NW30 - Install'!K26:K26)+SUM('RIBBON SW - Install'!K26:K26)+SUM('RIBBON SW32 - Install'!K26:K26)+SUM('RIBBON SW33 - Install'!K26:K26)+SUM('SCOREBOARD EAST - Install'!K26:K26)+SUM('SCOREBOARD WEST - Install'!K26:K26)+SUM('EAST ENTRY A - Install'!K26:K26)+SUM('EAST ENTRY B - Install'!K26:K26)+SUM('EAST ENTRY C - Install'!K26:K26)+SUM('EAST ENTRY D - Install'!K26:K26)+SUM('NORTH EAST EXTERIOR NE - Instal'!K26:K26)+SUM('NORTH ENTRY C - Install'!K26:K26)+SUM('NORTH ENTRY C42 - Install'!K26:K26)+SUM('NORTH ENTRY C43 - Install'!K26:K26)+SUM('SOUTH EAST EXTERIOR SE - Instal'!K26:K26) -> 1396716.5 | E6: =IFERROR(D6-C6,0) -> 209507.47 | F6: 0.15 | G6: =IFERROR(C6/46207.810000000005,0) -> 25.69
B7: Structural Labor & LED Installation | C7: =(SUM('TEAM ROOM - Install'!I35:I35)-SUM('TEAM ROOM - Install'!I34:I34))+(SUM('INCIDENT COMMANT - Install'!I35:I35)-SUM('INCIDENT COMMANT - Install'!I34:I34))+(SUM('DEF UNIT - Install'!I35:I35)-SUM('DEF UNIT - Install'!I34:I34))+(SUM('NORTH CORRIDOR - Install'!I35:I35)-SUM('NORTH CORRIDOR - Install'!I34:I34))+(SUM('SOUTH CORRIDOR - Install'!I35:I35)-SUM('SOUTH CORRIDOR - Install'!I34:I34))+(SUM('S.E. CORRIDOR (CEILING) - Insta'!I35:I35)-SUM('S.E. CORRIDOR (CEILING) - Insta'!I34:I34))+(SUM('S.E. CORRIDOR (CEILING7 - Insta'!I35:I35)-SUM('S.E. CORRIDOR (CEILING7 - Insta'!I34:I34))+(SUM('EAST CORRIDOR (CEILING) - Insta'!I35:I35)-SUM('EAST CORRIDOR (CEILING) - Insta'!I34:I34))+(SUM('N.E. CORRIDOR (CEILING) - Insta'!I35:I35)-SUM('N.E. CORRIDOR (CEILING) - Insta'!I34:I34))+(SUM('N.E. CORRIDOR (CEILING10 - Inst'!I35:I35)-SUM('N.E. CORRIDOR (CEILING10 - Inst'!I34:I34))+(SUM('LARGE ADMIN ROOM - Install'!I35:I35)-SUM('LARGE ADMIN ROOM - Install'!I34:I34))+(SUM('ELEV LOBBY - Install'!I35:I35)-SUM('ELEV LOBBY - Install'!I34:I34))+(SUM('NORTH CLUB - Install'!I35:I35)-SUM('NORTH CLUB - Install'!I34:I34))+(SUM('PANTHERS DEN - Install'!I35:I35)-SUM('PANTHERS DEN - Install'!I34:I34))+(SUM('PANTHERS DEN15 - Install'!I35:I35)-SUM('PANTHERS DEN15 - Install'!I34:I34))+(SUM('PANTHERS DEN16 - Install'!I35:I35)-SUM('PANTHERS DEN16 - Install'!I34:I34))+(SUM('PANTHERS DEN17 - Install'!I35:I35)-SUM('PANTHERS DEN17 - Install'!I34:I34))+(SUM('PANTHERS DEN18 - Install'!I35:I35)-SUM('PANTHERS DEN18 - Install'!I34:I34))+(SUM('PANTHERS DEN19 - Install'!I35:I35)-SUM('PANTHERS DEN19 - Install'!I34:I34))+(SUM('PANTHERS DEN20 - Install'!I35:I35)-SUM('PANTHERS DEN20 - Install'!I34:I34))+(SUM('SOUTH CLUB - Install'!I35:I35)-SUM('SOUTH CLUB - Install'!I34:I34))+(SUM('ELEV LOBBY22 - Install'!I35:I35)-SUM('ELEV LOBBY22 - Install'!I34:I34))+(SUM('SOUTH CLUB23 - Install'!I35:I35)-SUM('SOUTH CLUB23 - Install'!I34:I34))+(SUM('ELEV LOBBY24 - Install'!I35:I35)-SUM('ELEV LOBBY24 - Install'!I34:I34))+(SUM('ELEV LOBBY25 - Install'!I35:I35)-SUM('ELEV LOBBY25 - Install'!I34:I34))+(SUM('NORTH CLUB26 - Install'!I35:I35)-SUM('NORTH CLUB26 - Install'!I34:I34))+(SUM('RIBBON NW - Install'!I35:I35)-SUM('RIBBON NW - Install'!I34:I34))+(SUM('RIBBON NW28 - Install'!I35:I35)-SUM('RIBBON NW28 - Install'!I34:I34))+(SUM('RIBBON NW29 - Install'!I35:I35)-SUM('RIBBON NW29 - Install'!I34:I34))+(SUM('RIBBON NW30 - Install'!I35:I35)-SUM('RIBBON NW30 - Install'!I34:I34))+(SUM('RIBBON SW - Install'!I35:I35)-SUM('RIBBON SW - Install'!I34:I34))+(SUM('RIBBON SW32 - Install'!I35:I35)-SUM('RIBBON SW32 - Install'!I34:I34))+(SUM('RIBBON SW33 - Install'!I35:I35)-SUM('RIBBON SW33 - Install'!I34:I34))+(SUM('SCOREBOARD EAST - Install'!I35:I35)-SUM('SCOREBOARD EAST - Install'!I34:I34))+(SUM('SCOREBOARD WEST - Install'!I35:I35)-SUM('SCOREBOARD WEST - Install'!I34:I34))+(SUM('EAST ENTRY A - Install'!I35:I35)-SUM('EAST ENTRY A - Install'!I34:I34))+(SUM('EAST ENTRY B - Install'!I35:I35)-SUM('EAST ENTRY B - Install'!I34:I34))+(SUM('EAST ENTRY C - Install'!I35:I35)-SUM('EAST ENTRY C - Install'!I34:I34))+(SUM('EAST ENTRY D - Install'!I35:I35)-SUM('EAST ENTRY D - Install'!I34:I34))+(SUM('NORTH EAST EXTERIOR NE - Instal'!I35:I35)-SUM('NORTH EAST EXTERIOR NE - Instal'!I34:I34))+(SUM('NORTH ENTRY C - Install'!I35:I35)-SUM('NORTH ENTRY C - Install'!I34:I34))+(SUM('NORTH ENTRY C42 - Install'!I35:I35)-SUM('NORTH ENTRY C42 - Install'!I34:I34))+(SUM('NORTH ENTRY C43 - Install'!I35:I35)-SUM('NORTH ENTRY C43 - Install'!I34:I34))+(SUM('SOUTH EAST EXTERIOR SE - Instal'!I35:I35)-SUM('SOUTH EAST EXTERIOR SE - Instal'!I34:I34)) -> 7437054.3 | D7: =(SUM('TEAM ROOM - Install'!K35:K35)-SUM('TEAM ROOM - Install'!K34:K34))+(SUM('INCIDENT COMMANT - Install'!K35:K35)-SUM('INCIDENT COMMANT - Install'!K34:K34))+(SUM('DEF UNIT - Install'!K35:K35)-SUM('DEF UNIT - Install'!K34:K34))+(SUM('NORTH CORRIDOR - Install'!K35:K35)-SUM('NORTH CORRIDOR - Install'!K34:K34))+(SUM('SOUTH CORRIDOR - Install'!K35:K35)-SUM('SOUTH CORRIDOR - Install'!K34:K34))+(SUM('S.E. CORRIDOR (CEILING) - Insta'!K35:K35)-SUM('S.E. CORRIDOR (CEILING) - Insta'!K34:K34))+(SUM('S.E. CORRIDOR (CEILING7 - Insta'!K35:K35)-SUM('S.E. CORRIDOR (CEILING7 - Insta'!K34:K34))+(SUM('EAST CORRIDOR (CEILING) - Insta'!K35:K35)-SUM('EAST CORRIDOR (CEILING) - Insta'!K34:K34))+(SUM('N.E. CORRIDOR (CEILING) - Insta'!K35:K35)-SUM('N.E. CORRIDOR (CEILING) - Insta'!K34:K34))+(SUM('N.E. CORRIDOR (CEILING10 - Inst'!K35:K35)-SUM('N.E. CORRIDOR (CEILING10 - Inst'!K34:K34))+(SUM('LARGE ADMIN ROOM - Install'!K35:K35)-SUM('LARGE ADMIN ROOM - Install'!K34:K34))+(SUM('ELEV LOBBY - Install'!K35:K35)-SUM('ELEV LOBBY - Install'!K34:K34))+(SUM('NORTH CLUB - Install'!K35:K35)-SUM('NORTH CLUB - Install'!K34:K34))+(SUM('PANTHERS DEN - Install'!K35:K35)-SUM('PANTHERS DEN - Install'!K34:K34))+(SUM('PANTHERS DEN15 - Install'!K35:K35)-SUM('PANTHERS DEN15 - Install'!K34:K34))+(SUM('PANTHERS DEN16 - Install'!K35:K35)-SUM('PANTHERS DEN16 - Install'!K34:K34))+(SUM('PANTHERS DEN17 - Install'!K35:K35)-SUM('PANTHERS DEN17 - Install'!K34:K34))+(SUM('PANTHERS DEN18 - Install'!K35:K35)-SUM('PANTHERS DEN18 - Install'!K34:K34))+(SUM('PANTHERS DEN19 - Install'!K35:K35)-SUM('PANTHERS DEN19 - Install'!K34:K34))+(SUM('PANTHERS DEN20 - Install'!K35:K35)-SUM('PANTHERS DEN20 - Install'!K34:K34))+(SUM('SOUTH CLUB - Install'!K35:K35)-SUM('SOUTH CLUB - Install'!K34:K34))+(SUM('ELEV LOBBY22 - Install'!K35:K35)-SUM('ELEV LOBBY22 - Install'!K34:K34))+(SUM('SOUTH CLUB23 - Install'!K35:K35)-SUM('SOUTH CLUB23 - Install'!K34:K34))+(SUM('ELEV LOBBY24 - Install'!K35:K35)-SUM('ELEV LOBBY24 - Install'!K34:K34))+(SUM('ELEV LOBBY25 - Install'!K35:K35)-SUM('ELEV LOBBY25 - Install'!K34:K34))+(SUM('NORTH CLUB26 - Install'!K35:K35)-SUM('NORTH CLUB26 - Install'!K34:K34))+(SUM('RIBBON NW - Install'!K35:K35)-SUM('RIBBON NW - Install'!K34:K34))+(SUM('RIBBON NW28 - Install'!K35:K35)-SUM('RIBBON NW28 - Install'!K34:K34))+(SUM('RIBBON NW29 - Install'!K35:K35)-SUM('RIBBON NW29 - Install'!K34:K34))+(SUM('RIBBON NW30 - Install'!K35:K35)-SUM('RIBBON NW30 - Install'!K34:K34))+(SUM('RIBBON SW - Install'!K35:K35)-SUM('RIBBON SW - Install'!K34:K34))+(SUM('RIBBON SW32 - Install'!K35:K35)-SUM('RIBBON SW32 - Install'!K34:K34))+(SUM('RIBBON SW33 - Install'!K35:K35)-SUM('RIBBON SW33 - Install'!K34:K34))+(SUM('SCOREBOARD EAST - Install'!K35:K35)-SUM('SCOREBOARD EAST - Install'!K34:K34))+(SUM('SCOREBOARD WEST - Install'!K35:K35)-SUM('SCOREBOARD WEST - Install'!K34:K34))+(SUM('EAST ENTRY A - Install'!K35:K35)-SUM('EAST ENTRY A - Install'!K34:K34))+(SUM('EAST ENTRY B - Install'!K35:K35)-SUM('EAST ENTRY B - Install'!K34:K34))+(SUM('EAST ENTRY C - Install'!K35:K35)-SUM('EAST ENTRY C - Install'!K34:K34))+(SUM('EAST ENTRY D - Install'!K35:K35)-SUM('EAST ENTRY D - Install'!K34:K34))+(SUM('NORTH EAST EXTERIOR NE - Instal'!K35:K35)-SUM('NORTH EAST EXTERIOR NE - Instal'!K34:K34))+(SUM('NORTH ENTRY C - Install'!K35:K35)-SUM('NORTH ENTRY C - Install'!K34:K34))+(SUM('NORTH ENTRY C42 - Install'!K35:K35)-SUM('NORTH ENTRY C42 - Install'!K34:K34))+(SUM('NORTH ENTRY C43 - Install'!K35:K35)-SUM('NORTH ENTRY C43 - Install'!K34:K34))+(SUM('SOUTH EAST EXTERIOR SE - Instal'!K35:K35)-SUM('SOUTH EAST EXTERIOR SE - Instal'!K34:K34)) -> 8749475.7 | E7: =IFERROR(D7-C7,0) -> 1312421.4 | F7: 0.15 | G7: =IFERROR(C7/46207.810000000005,0) -> 160.95
B8: Electrical & Data | C8: =SUM('TEAM ROOM - Install'!I44:I44)+SUM('INCIDENT COMMANT - Install'!I44:I44)+SUM('DEF UNIT - Install'!I44:I44)+SUM('NORTH CORRIDOR - Install'!I44:I44)+SUM('SOUTH CORRIDOR - Install'!I44:I44)+SUM('S.E. CORRIDOR (CEILING) - Insta'!I44:I44)+SUM('S.E. CORRIDOR (CEILING7 - Insta'!I44:I44)+SUM('EAST CORRIDOR (CEILING) - Insta'!I44:I44)+SUM('N.E. CORRIDOR (CEILING) - Insta'!I44:I44)+SUM('N.E. CORRIDOR (CEILING10 - Inst'!I44:I44)+SUM('LARGE ADMIN ROOM - Install'!I44:I44)+SUM('ELEV LOBBY - Install'!I44:I44)+SUM('NORTH CLUB - Install'!I44:I44)+SUM('PANTHERS DEN - Install'!I44:I44)+SUM('PANTHERS DEN15 - Install'!I44:I44)+SUM('PANTHERS DEN16 - Install'!I44:I44)+SUM('PANTHERS DEN17 - Install'!I44:I44)+SUM('PANTHERS DEN18 - Install'!I44:I44)+SUM('PANTHERS DEN19 - Install'!I44:I44)+SUM('PANTHERS DEN20 - Install'!I44:I44)+SUM('SOUTH CLUB - Install'!I44:I44)+SUM('ELEV LOBBY22 - Install'!I44:I44)+SUM('SOUTH CLUB23 - Install'!I44:I44)+SUM('ELEV LOBBY24 - Install'!I44:I44)+SUM('ELEV LOBBY25 - Install'!I44:I44)+SUM('NORTH CLUB26 - Install'!I44:I44)+SUM('RIBBON NW - Install'!I44:I44)+SUM('RIBBON NW28 - Install'!I44:I44)+SUM('RIBBON NW29 - Install'!I44:I44)+SUM('RIBBON NW30 - Install'!I44:I44)+SUM('RIBBON SW - Install'!I44:I44)+SUM('RIBBON SW32 - Install'!I44:I44)+SUM('RIBBON SW33 - Install'!I44:I44)+SUM('SCOREBOARD EAST - Install'!I44:I44)+SUM('SCOREBOARD WEST - Install'!I44:I44)+SUM('EAST ENTRY A - Install'!I44:I44)+SUM('EAST ENTRY B - Install'!I44:I44)+SUM('EAST ENTRY C - Install'!I44:I44)+SUM('EAST ENTRY D - Install'!I44:I44)+SUM('NORTH EAST EXTERIOR NE - Instal'!I44:I44)+SUM('NORTH ENTRY C - Install'!I44:I44)+SUM('NORTH ENTRY C42 - Install'!I44:I44)+SUM('NORTH ENTRY C43 - Install'!I44:I44)+SUM('SOUTH EAST EXTERIOR SE - Instal'!I44:I44) -> 3070041.8 | D8: =SUM('TEAM ROOM - Install'!K44:K44)+SUM('INCIDENT COMMANT - Install'!K44:K44)+SUM('DEF UNIT - Install'!K44:K44)+SUM('NORTH CORRIDOR - Install'!K44:K44)+SUM('SOUTH CORRIDOR - Install'!K44:K44)+SUM('S.E. CORRIDOR (CEILING) - Insta'!K44:K44)+SUM('S.E. CORRIDOR (CEILING7 - Insta'!K44:K44)+SUM('EAST CORRIDOR (CEILING) - Insta'!K44:K44)+SUM('N.E. CORRIDOR (CEILING) - Insta'!K44:K44)+SUM('N.E. CORRIDOR (CEILING10 - Inst'!K44:K44)+SUM('LARGE ADMIN ROOM - Install'!K44:K44)+SUM('ELEV LOBBY - Install'!K44:K44)+SUM('NORTH CLUB - Install'!K44:K44)+SUM('PANTHERS DEN - Install'!K44:K44)+SUM('PANTHERS DEN15 - Install'!K44:K44)+SUM('PANTHERS DEN16 - Install'!K44:K44)+SUM('PANTHERS DEN17 - Install'!K44:K44)+SUM('PANTHERS DEN18 - Install'!K44:K44)+SUM('PANTHERS DEN19 - Install'!K44:K44)+SUM('PANTHERS DEN20 - Install'!K44:K44)+SUM('SOUTH CLUB - Install'!K44:K44)+SUM('ELEV LOBBY22 - Install'!K44:K44)+SUM('SOUTH CLUB23 - Install'!K44:K44)+SUM('ELEV LOBBY24 - Install'!K44:K44)+SUM('ELEV LOBBY25 - Install'!K44:K44)+SUM('NORTH CLUB26 - Install'!K44:K44)+SUM('RIBBON NW - Install'!K44:K44)+SUM('RIBBON NW28 - Install'!K44:K44)+SUM('RIBBON NW29 - Install'!K44:K44)+SUM('RIBBON NW30 - Install'!K44:K44)+SUM('RIBBON SW - Install'!K44:K44)+SUM('RIBBON SW32 - Install'!K44:K44)+SUM('RIBBON SW33 - Install'!K44:K44)+SUM('SCOREBOARD EAST - Install'!K44:K44)+SUM('SCOREBOARD WEST - Install'!K44:K44)+SUM('EAST ENTRY A - Install'!K44:K44)+SUM('EAST ENTRY B - Install'!K44:K44)+SUM('EAST ENTRY C - Install'!K44:K44)+SUM('EAST ENTRY D - Install'!K44:K44)+SUM('NORTH EAST EXTERIOR NE - Instal'!K44:K44)+SUM('NORTH ENTRY C - Install'!K44:K44)+SUM('NORTH ENTRY C42 - Install'!K44:K44)+SUM('NORTH ENTRY C43 - Install'!K44:K44)+SUM('SOUTH EAST EXTERIOR SE - Instal'!K44:K44) -> 3611813.9 | E8: =IFERROR(D8-C8,0) -> 541772.09 | F8: 0.15 | G8: =IFERROR(C8/46207.810000000005,0) -> 66.44
B9: PM / General Conditions / Travel | C9: =SUM('TEAM ROOM - Install'!I34:I34)+SUM('INCIDENT COMMANT - Install'!I34:I34)+SUM('DEF UNIT - Install'!I34:I34)+SUM('NORTH CORRIDOR - Install'!I34:I34)+SUM('SOUTH CORRIDOR - Install'!I34:I34)+SUM('S.E. CORRIDOR (CEILING) - Insta'!I34:I34)+SUM('S.E. CORRIDOR (CEILING7 - Insta'!I34:I34)+SUM('EAST CORRIDOR (CEILING) - Insta'!I34:I34)+SUM('N.E. CORRIDOR (CEILING) - Insta'!I34:I34)+SUM('N.E. CORRIDOR (CEILING10 - Inst'!I34:I34)+SUM('LARGE ADMIN ROOM - Install'!I34:I34)+SUM('ELEV LOBBY - Install'!I34:I34)+SUM('NORTH CLUB - Install'!I34:I34)+SUM('PANTHERS DEN - Install'!I34:I34)+SUM('PANTHERS DEN15 - Install'!I34:I34)+SUM('PANTHERS DEN16 - Install'!I34:I34)+SUM('PANTHERS DEN17 - Install'!I34:I34)+SUM('PANTHERS DEN18 - Install'!I34:I34)+SUM('PANTHERS DEN19 - Install'!I34:I34)+SUM('PANTHERS DEN20 - Install'!I34:I34)+SUM('SOUTH CLUB - Install'!I34:I34)+SUM('ELEV LOBBY22 - Install'!I34:I34)+SUM('SOUTH CLUB23 - Install'!I34:I34)+SUM('ELEV LOBBY24 - Install'!I34:I34)+SUM('ELEV LOBBY25 - Install'!I34:I34)+SUM('NORTH CLUB26 - Install'!I34:I34)+SUM('RIBBON NW - Install'!I34:I34)+SUM('RIBBON NW28 - Install'!I34:I34)+SUM('RIBBON NW29 - Install'!I34:I34)+SUM('RIBBON NW30 - Install'!I34:I34)+SUM('RIBBON SW - Install'!I34:I34)+SUM('RIBBON SW32 - Install'!I34:I34)+SUM('RIBBON SW33 - Install'!I34:I34)+SUM('SCOREBOARD EAST - Install'!I34:I34)+SUM('SCOREBOARD WEST - Install'!I34:I34)+SUM('EAST ENTRY A - Install'!I34:I34)+SUM('EAST ENTRY B - Install'!I34:I34)+SUM('EAST ENTRY C - Install'!I34:I34)+SUM('EAST ENTRY D - Install'!I34:I34)+SUM('NORTH EAST EXTERIOR NE - Instal'!I34:I34)+SUM('NORTH ENTRY C - Install'!I34:I34)+SUM('NORTH ENTRY C42 - Install'!I34:I34)+SUM('NORTH ENTRY C43 - Install'!I34:I34)+SUM('SOUTH EAST EXTERIOR SE - Instal'!I34:I34) -> 918823.4 | D9: =SUM('TEAM ROOM - Install'!K34:K34)+SUM('INCIDENT COMMANT - Install'!K34:K34)+SUM('DEF UNIT - Install'!K34:K34)+SUM('NORTH CORRIDOR - Install'!K34:K34)+SUM('SOUTH CORRIDOR - Install'!K34:K34)+SUM('S.E. CORRIDOR (CEILING) - Insta'!K34:K34)+SUM('S.E. CORRIDOR (CEILING7 - Insta'!K34:K34)+SUM('EAST CORRIDOR (CEILING) - Insta'!K34:K34)+SUM('N.E. CORRIDOR (CEILING) - Insta'!K34:K34)+SUM('N.E. CORRIDOR (CEILING10 - Inst'!K34:K34)+SUM('LARGE ADMIN ROOM - Install'!K34:K34)+SUM('ELEV LOBBY - Install'!K34:K34)+SUM('NORTH CLUB - Install'!K34:K34)+SUM('PANTHERS DEN - Install'!K34:K34)+SUM('PANTHERS DEN15 - Install'!K34:K34)+SUM('PANTHERS DEN16 - Install'!K34:K34)+SUM('PANTHERS DEN17 - Install'!K34:K34)+SUM('PANTHERS DEN18 - Install'!K34:K34)+SUM('PANTHERS DEN19 - Install'!K34:K34)+SUM('PANTHERS DEN20 - Install'!K34:K34)+SUM('SOUTH CLUB - Install'!K34:K34)+SUM('ELEV LOBBY22 - Install'!K34:K34)+SUM('SOUTH CLUB23 - Install'!K34:K34)+SUM('ELEV LOBBY24 - Install'!K34:K34)+SUM('ELEV LOBBY25 - Install'!K34:K34)+SUM('NORTH CLUB26 - Install'!K34:K34)+SUM('RIBBON NW - Install'!K34:K34)+SUM('RIBBON NW28 - Install'!K34:K34)+SUM('RIBBON NW29 - Install'!K34:K34)+SUM('RIBBON NW30 - Install'!K34:K34)+SUM('RIBBON SW - Install'!K34:K34)+SUM('RIBBON SW32 - Install'!K34:K34)+SUM('RIBBON SW33 - Install'!K34:K34)+SUM('SCOREBOARD EAST - Install'!K34:K34)+SUM('SCOREBOARD WEST - Install'!K34:K34)+SUM('EAST ENTRY A - Install'!K34:K34)+SUM('EAST ENTRY B - Install'!K34:K34)+SUM('EAST ENTRY C - Install'!K34:K34)+SUM('EAST ENTRY D - Install'!K34:K34)+SUM('NORTH EAST EXTERIOR NE - Instal'!K34:K34)+SUM('NORTH ENTRY C - Install'!K34:K34)+SUM('NORTH ENTRY C42 - Install'!K34:K34)+SUM('NORTH ENTRY C43 - Install'!K34:K34)+SUM('SOUTH EAST EXTERIOR SE - Instal'!K34:K34) -> 1080968.7 | E9: =IFERROR(D9-C9,0) -> 162145.31 | F9: 0.15
B10: Engineering & Permits | C10: =SUM('TEAM ROOM - Install'!I52:I52)+SUM('INCIDENT COMMANT - Install'!I52:I52)+SUM('DEF UNIT - Install'!I52:I52)+SUM('NORTH CORRIDOR - Install'!I52:I52)+SUM('SOUTH CORRIDOR - Install'!I52:I52)+SUM('S.E. CORRIDOR (CEILING) - Insta'!I52:I52)+SUM('S.E. CORRIDOR (CEILING7 - Insta'!I52:I52)+SUM('EAST CORRIDOR (CEILING) - Insta'!I52:I52)+SUM('N.E. CORRIDOR (CEILING) - Insta'!I52:I52)+SUM('N.E. CORRIDOR (CEILING10 - Inst'!I52:I52)+SUM('LARGE ADMIN ROOM - Install'!I52:I52)+SUM('ELEV LOBBY - Install'!I52:I52)+SUM('NORTH CLUB - Install'!I52:I52)+SUM('PANTHERS DEN - Install'!I52:I52)+SUM('PANTHERS DEN15 - Install'!I52:I52)+SUM('PANTHERS DEN16 - Install'!I52:I52)+SUM('PANTHERS DEN17 - Install'!I52:I52)+SUM('PANTHERS DEN18 - Install'!I52:I52)+SUM('PANTHERS DEN19 - Install'!I52:I52)+SUM('PANTHERS DEN20 - Install'!I52:I52)+SUM('SOUTH CLUB - Install'!I52:I52)+SUM('ELEV LOBBY22 - Install'!I52:I52)+SUM('SOUTH CLUB23 - Install'!I52:I52)+SUM('ELEV LOBBY24 - Install'!I52:I52)+SUM('ELEV LOBBY25 - Install'!I52:I52)+SUM('NORTH CLUB26 - Install'!I52:I52)+SUM('RIBBON NW - Install'!I52:I52)+SUM('RIBBON NW28 - Install'!I52:I52)+SUM('RIBBON NW29 - Install'!I52:I52)+SUM('RIBBON NW30 - Install'!I52:I52)+SUM('RIBBON SW - Install'!I52:I52)+SUM('RIBBON SW32 - Install'!I52:I52)+SUM('RIBBON SW33 - Install'!I52:I52)+SUM('SCOREBOARD EAST - Install'!I52:I52)+SUM('SCOREBOARD WEST - Install'!I52:I52)+SUM('EAST ENTRY A - Install'!I52:I52)+SUM('EAST ENTRY B - Install'!I52:I52)+SUM('EAST ENTRY C - Install'!I52:I52)+SUM('EAST ENTRY D - Install'!I52:I52)+SUM('NORTH EAST EXTERIOR NE - Instal'!I52:I52)+SUM('NORTH ENTRY C - Install'!I52:I52)+SUM('NORTH ENTRY C42 - Install'!I52:I52)+SUM('NORTH ENTRY C43 - Install'!I52:I52)+SUM('SOUTH EAST EXTERIOR SE - Instal'!I52:I52) -> 207058.72 | D10: =SUM('TEAM ROOM - Install'!K52:K52)+SUM('INCIDENT COMMANT - Install'!K52:K52)+SUM('DEF UNIT - Install'!K52:K52)+SUM('NORTH CORRIDOR - Install'!K52:K52)+SUM('SOUTH CORRIDOR - Install'!K52:K52)+SUM('S.E. CORRIDOR (CEILING) - Insta'!K52:K52)+SUM('S.E. CORRIDOR (CEILING7 - Insta'!K52:K52)+SUM('EAST CORRIDOR (CEILING) - Insta'!K52:K52)+SUM('N.E. CORRIDOR (CEILING) - Insta'!K52:K52)+SUM('N.E. CORRIDOR (CEILING10 - Inst'!K52:K52)+SUM('LARGE ADMIN ROOM - Install'!K52:K52)+SUM('ELEV LOBBY - Install'!K52:K52)+SUM('NORTH CLUB - Install'!K52:K52)+SUM('PANTHERS DEN - Install'!K52:K52)+SUM('PANTHERS DEN15 - Install'!K52:K52)+SUM('PANTHERS DEN16 - Install'!K52:K52)+SUM('PANTHERS DEN17 - Install'!K52:K52)+SUM('PANTHERS DEN18 - Install'!K52:K52)+SUM('PANTHERS DEN19 - Install'!K52:K52)+SUM('PANTHERS DEN20 - Install'!K52:K52)+SUM('SOUTH CLUB - Install'!K52:K52)+SUM('ELEV LOBBY22 - Install'!K52:K52)+SUM('SOUTH CLUB23 - Install'!K52:K52)+SUM('ELEV LOBBY24 - Install'!K52:K52)+SUM('ELEV LOBBY25 - Install'!K52:K52)+SUM('NORTH CLUB26 - Install'!K52:K52)+SUM('RIBBON NW - Install'!K52:K52)+SUM('RIBBON NW28 - Install'!K52:K52)+SUM('RIBBON NW29 - Install'!K52:K52)+SUM('RIBBON NW30 - Install'!K52:K52)+SUM('RIBBON SW - Install'!K52:K52)+SUM('RIBBON SW32 - Install'!K52:K52)+SUM('RIBBON SW33 - Install'!K52:K52)+SUM('SCOREBOARD EAST - Install'!K52:K52)+SUM('SCOREBOARD WEST - Install'!K52:K52)+SUM('EAST ENTRY A - Install'!K52:K52)+SUM('EAST ENTRY B - Install'!K52:K52)+SUM('EAST ENTRY C - Install'!K52:K52)+SUM('EAST ENTRY D - Install'!K52:K52)+SUM('NORTH EAST EXTERIOR NE - Instal'!K52:K52)+SUM('NORTH ENTRY C - Install'!K52:K52)+SUM('NORTH ENTRY C42 - Install'!K52:K52)+SUM('NORTH ENTRY C43 - Install'!K52:K52)+SUM('SOUTH EAST EXTERIOR SE - Instal'!K52:K52) -> 243598.49 | E10: =IFERROR(D10-C10,0) -> 36539.77 | F10: 0.15
B11: CMS (Content Management System) | C11: =SUM(CMS!F26:F26) -> 0 | D11: =SUM(CMS!H26:H26) -> 0 | E11: =IFERROR(D11-C11,0) -> 0 | F11: 0.15
B12: Scoring System | C12: =SUM(Scoring!F27:F27) -> 0 | D12: =SUM(Scoring!H27:H27) -> 0 | E12: =IFERROR(D12-C12,0) -> 0 | F12: 0.15
B13: Venue Services | C13: =SUM('Venue Services'!B17:B17) -> 0 | D13: =SUM('Venue Services'!C17:C17) -> 0 | E13: =IFERROR(D13-C13,0) -> 0 | F13: 0.15
B14: Game Clock | C14: =SUM('Additional Items'!F5:F5) -> 0 | D14: =SUM('Additional Items'!H5:H5) -> 0 | E14: =IFERROR(D14-C14,0) -> 0 | F14: 0.15
B15: Pitch Clocks | C15: =SUM('Additional Items'!F6:F6) -> 0 | D15: =SUM('Additional Items'!H6:H6) -> 0 | E15: =IFERROR(D15-C15,0) -> 0 | F15: 0.15
B16: OES / MIS / Timing | C16: =SUM('Additional Items'!F7:F7) -> 0 | D16: =SUM('Additional Items'!H7:H7) -> 0 | E16: =IFERROR(D16-C16,0) -> 0 | F16: 0.15
B17: DMX / Misc Equipment | C17: =SUM('Additional Items'!F8:F8) -> 0 | D17: =SUM('Additional Items'!H8:H8) -> 0 | E17: =IFERROR(D17-C17,0) -> 0 | F17: 0.15
B19: SUBTOTAL | C19: =SUM(C5:C17) -> 20352793 | D19: =SUM(D5:D17) -> 23399111 | E19: =IFERROR(D19-C19,0) -> 3046318.6 | F19: =IFERROR(1-C19/D19,0) -> 0.13 | G19: =IFERROR(C19/46207.810000000005,0) -> 440.46
B20: TAX | C20: 0 | D20: 0 | E20: 0 | F20: 0
B21: BOND | C21: 0 | D21: 0 | E21: 0 | F21: 0
B22: GRAND TOTAL | C22: =C19+C20+C21 -> 20352793 | D22: =D19+D20+D21 -> 23399111 | E22: =IFERROR(D22-C22,0) -> 3046318.6 | F22: =IFERROR(1-C22/D22,0) -> 0.13 | G22: =IFERROR(C22/46207.810000000005,0) -> 440.46

Sheet LED Cost Sheet
A1: Large Format LED — LED Cost Sheet
U2: LED Margin Override → | V2: 0.15
A3: Display | B3: RFP H (ft) | C3: RFP W (ft) | D3: RFP NITs | E3: Vendor | F3: Product | G3: Pitch | H3: H (ft) | I3: W (ft) | J3: H (px) | K3: W (px) | L3: Qty | M3: Total SqFt | N3: Product NITs | O3: Service | P3: $/SqFt | Q3: Display Cost | R3: Processor | S3: Shipping | T3: Total Cost | U3: Margin % | V3: Selling Price | W3: ANC Margin | X3: Weight (lbs) | Y3: Total Power (W) | Z3: BTU/hr
A4: TEAM ROOM — TEAM ROOM | B4: 8 | C4: 14 | D4: 4000 | E4: =IFERROR(VLOOKUP(F4,'_Products'!$A$1:$G$23,2,FALSE),"") -> Yaham | F4: Yaham Corona C4 Indoor | G4: =IFERROR(VLOOKUP(F4,'_Products'!$A$1:$G$23,3,FALSE),0) -> 4 | H4: 7.87 | I4: 14.17 | J4: =IFERROR(ROUND(H4*304.8/G4,0),0) -> 600 | K4: =IFERROR(ROUND(I4*304.8/G4,0),0) -> 1080 | L4: 1 | M4: =H4*I4*L4 -> 111.52 | N4: =IFERROR(VLOOKUP(F4,'_Products'!$A$1:$G$23,5,FALSE),0) -> 2000 | O4: Front | P4: 196.34 | Q4: =P4*M4 -> 21896.31 | R4: =SUM('Bundle Equipment'!E10:E10) -> 516.91 | S4: =MAX(M4*10,500) -> 1115.2 | T4: =Q4+R4+S4 -> 23528.42 | U4: =V$2 -> 0.15 | V4: =IFERROR(T4/(1-U4),0) -> 27680.49 | W4: =V4-T4 -> 4152.07 | X4: =IFERROR(ROUND(M4*0.092903*VLOOKUP(F4,'_Products'!$A$1:$G$23,6,FALSE),0),0) -> 483 | Y4: =IFERROR(ROUND(M4*0.092903*VLOOKUP(F4,'_Products'!$A$1:$G$23,7,FALSE),0),0) -> 4160 | Z4: =Y4*3.412 -> 14194
A5: INCIDENT COMMANT — INCIDENT COMMANT | B5: 5.33 | C5: 21.67 | D5: 4000 | E5: =IFERROR(VLOOKUP(F5,'_Products'!$A$1:$G$23,2,FALSE),"") -> Yaham | F5: Yaham Corona C4 Indoor | G5: =IFERROR(VLOOKUP(F5,'_Products'!$A$1:$G$23,3,FALSE),0) -> 4 | H5: 5.51 | I5: 22.05 | J5: =IFERROR(ROUND(H5*304.8/G5,0),0) -> 420 | K5: =IFERROR(ROUND(I5*304.8/G5,0),0) -> 1680 | L5: 1 | M5: =H5*I5*L5 -> 121.5 | N5: =IFERROR(VLOOKUP(F5,'_Products'!$A$1:$G$23,5,FALSE),0) -> 2000 | O5: Front | P5: 196.34 | Q5: =P5*M5 -> 23855.83 | R5: =SUM('Bundle Equipment'!E15:E15) -> 522.9 | S5: =MAX(M5*10,500) -> 1215 | T5: =Q5+R5+S5 -> 25593.73 | U5: =V$2 -> 0.15 | V5: =IFERROR(T5/(1-U5),0) -> 30110.27 | W5: =V5-T5 -> 4516.54 | X5: =IFERROR(ROUND(M5*0.092903*VLOOKUP(F5,'_Products'!$A$1:$G$23,6,FALSE),0),0) -> 526 | Y5: =IFERROR(ROUND(M5*0.092903*VLOOKUP(F5,'_Products'!$A$1:$G$23,7,FALSE),0),0) -> 4532 | Z5: =Y5*3.412 -> 15463
A6: DEF UNIT — DEF UNIT | B6: 6 | C6: 11 | D6: 4000 | E6: =IFERROR(VLOOKUP(F6,'_Products'!$A$1:$G$23,2,FALSE),"") -> Yaham | F6: Yaham Corona C4 Indoor | G6: =IFERROR(VLOOKUP(F6,'_Products'!$A$1:$G$23,3,FALSE),0) -> 4 | H6: 6.3 | I6: 11.02 | J6: =IFERROR(ROUND(H6*304.8/G6,0),0) -> 480 | K6: =IFERROR(ROUND(I6*304.8/G6,0),0) -> 840 | L6: 1 | M6: =H6*I6*L6 -> 69.43 | N6: =IFERROR(VLOOKUP(F6,'_Products'!$A$1:$G$23,5,FALSE),0) -> 2000 | O6: Front | P6: 196.34 | Q6: =P6*M6 -> 13632.18 | R6: =SUM('Bundle Equipment'!E20:E20) -> 491.66 | S6: =MAX(M6*10,500) -> 694.3 | T6: =Q6+R6+S6 -> 14818.14 | U6: =V$2 -> 0.15 | V6: =IFERROR(T6/(1-U6),0) -> 17433.11 | W6: =V6-T6 -> 2614.97 | X6: =IFERROR(ROUND(M6*0.092903*VLOOKUP(F6,'_Products'!$A$1:$G$23,6,FALSE),0),0) -> 301 | Y6: =IFERROR(ROUND(M6*0.092903*VLOOKUP(F6,'_Products'!$A$1:$G$23,7,FALSE),0),0) -> 2590 | Z6: =Y6*3.412 -> 8837
A7: NORTH CORRIDOR — NORTH CORRIDOR | B7: 11 | C7: 100 | D7: 4000 | E7: =IFERROR(VLOOKUP(F7,'_Products'!$A$1:$G$23,2,FALSE),"") -> Yaham | F7: Yaham Corona C4 Indoor | G7: =IFERROR(VLOOKUP(F7,'_Products'!$A$1:$G$23,3,FALSE),0) -> 4 | H7: 11.02 | I7: 100 | J7: =IFERROR(ROUND(H7*304.8/G7,0),0) -> 840 | K7: =IFERROR(ROUND(I7*304.8/G7,0),0) -> 7620 | L7: 1 | M7: =H7*I7*L7 -> 1102 | N7: =IFERROR(VLOOKUP(F7,'_Products'!$A$1:$G$23,5,FALSE),0) -> 2000 | O7: Front | P7: 196.34 | Q7: =P7*M7 -> 216371.34 | R7: =SUM('Bundle Equipment'!E26:E26) -> 21061.2 | S7: =MAX(M7*10,500) -> 11020 | T7: =Q7+R7+S7 -> 248452.54 | U7: =V$2 -> 0.15 | V7: =IFERROR(T7/(1-U7),0) -> 292297.11 | W7: =V7-T7 -> 43844.57 | X7: =IFERROR(ROUND(M7*0.092903*VLOOKUP(F7,'_Products'!$A$1:$G$23,6,FALSE),0),0) -> 4771 | Y7: =IFERROR(ROUND(M7*0.092903*VLOOKUP(F7,'_Products'!$A$1:$G$23,7,FALSE),0),0) -> 41105 | Z7: =Y7*3.412 -> 140250
A8: SOUTH CORRIDOR — SOUTH CORRIDOR | B8: 11 | C8: 85 | D8: 4000 | E8: =IFERROR(VLOOKUP(F8,'_Products'!$A$1:$G$23,2,FALSE),"") -> Yaham | F8: Yaham Corona C4 Indoor | G8: =IFERROR(VLOOKUP(F8,'_Products'!$A$1:$G$23,3,FALSE),0) -> 4 | H8: 11.02 | I8: 85.04 | J8: =IFERROR(ROUND(H8*304.8/G8,0),0) -> 840 | K8: =IFERROR(ROUND(I8*304.8/G8,0),0) -> 6480 | L8: 1 | M8: =H8*I8*L8 -> 937.14 | N8: =IFERROR(VLOOKUP(F8,'_Products'!$A$1:$G$23,5,FALSE),0) -> 2000 | O8: Front | P8: 196.34 | Q8: =P8*M8 -> 184002.02 | R8: =SUM('Bundle Equipment'!E32:E32) -> 20962.28 | S8: =MAX(M8*10,500) -> 9371.4 | T8: =Q8+R8+S8 -> 214335.7 | U8: =V$2 -> 0.15 | V8: =IFERROR(T8/(1-U8),0) -> 252159.65 | W8: =V8-T8 -> 37823.95 | X8: =IFERROR(ROUND(M8*0.092903*VLOOKUP(F8,'_Products'!$A$1:$G$23,6,FALSE),0),0) -> 4057 | Y8: =IFERROR(ROUND(M8*0.092903*VLOOKUP(F8,'_Products'!$A$1:$G$23,7,FALSE),0),0) -> 34956 | Z8: =Y8*3.412 -> 119270
A9: S.E. CORRIDOR (CEILING) — S.E. CORRIDOR (CEILING) | B9: 10 | C9: 34 | D9: 4000 | E9: =IFERROR(VLOOKUP(F9,'_Products'!$A$1:$G$23,2,FALSE),"") -> Yaham | F9: Yaham Corona C4 Indoor | G9: =IFERROR(VLOOKUP(F9,'_Products'!$A$1:$G$23,3,FALSE),0) -> 4 | H9: 10.24 | I9: 33.86 | J9: =IFERROR(ROUND(H9*304.8/G9,0),0) -> 780 | K9: =IFERROR(ROUND(I9*304.8/G9,0),0) -> 2580 | L9: 1 | M9: =H9*I9*L9 -> 346.73 | N9: =IFERROR(VLOOKUP(F9,'_Products'!$A$1:$G$23,5,FALSE),0) -> 2000 | O9: Front | P9: 196.34 | Q9: =P9*M9 -> 68078.44 | R9: =SUM('Bundle Equipment'!E38:E38) -> 12658.04 | S9: =MAX(M9*10,500) -> 3467.3 | T9: =Q9+R9+S9 -> 84203.78 | U9: =V$2 -> 0.15 | V9: =IFERROR(T9/(1-U9),0) -> 99063.27 | W9: =V9-T9 -> 14859.49 | X9: =IFERROR(ROUND(M9*0.092903*VLOOKUP(F9,'_Products'!$A$1:$G$23,6,FALSE),0),0) -> 1501 | Y9: =IFERROR(ROUND(M9*0.092903*VLOOKUP(F9,'_Products'!$A$1:$G$23,7,FALSE),0),0) -> 12933 | Z9: =Y9*3.412 -> 44127
A10: S.E. CORRIDOR (CEILING) — S.E. CORRIDOR (CEILING) | B10: 10 | C10: 34 | D10: 4000 | E10: =IFERROR(VLOOKUP(F10,'_Products'!$A$1:$G$23,2,FALSE),"") -> LG/Yaham | F10: Mesh P10 FM1921 3.9mm Indoor | G10: =IFERROR(VLOOKUP(F10,'_Products'!$A$1:$G$23,3,FALSE),0) -> 3.9 | H10: 10 | I10: 34 | J10: =IFERROR(ROUND(H10*304.8/G10,0),0) -> 782 | K10: =IFERROR(ROUND(I10*304.8/G10,0),0) -> 2657 | L10: 1 | M10: =H10*I10*L10 -> 340 | N10: =IFERROR(VLOOKUP(F10,'_Products'!$A$1:$G$23,5,FALSE),0) -> 6000 | O10: Front | P10: 256.36 | Q10: =P10*M10 -> 87163.87 | R10: =SUM('Bundle Equipment'!E44:E44) -> 12654 | S10: =MAX(M10*10,500) -> 3400 | T10: =Q10+R10+S10 -> 103217.87 | U10: =V$2 -> 0.15 | V10: =IFERROR(T10/(1-U10),0) -> 121432.79 | W10: =V10-T10 -> 18214.92 | X10: =IFERROR(ROUND(M10*0.092903*VLOOKUP(F10,'_Products'!$A$1:$G$23,6,FALSE),0),0) -> 1045 | Y10: =IFERROR(ROUND(M10*0.092903*VLOOKUP(F10,'_Products'!$A$1:$G$23,7,FALSE),0),0) -> 18952 | Z10: =Y10*3.412 -> 64664
A11: EAST CORRIDOR (CEILING) — EAST CORRIDOR (CEILING) | B11: 10 | C11: 36 | D11: 4000 | E11: =IFERROR(VLOOKUP(F11,'_Products'!$A$1:$G$23,2,FALSE),"") -> LG/Yaham | F11: Mesh P10 FM1921 3.9mm Indoor | G11: =IFERROR(VLOOKUP(F11,'_Products'!$A$1:$G$23,3,FALSE),0) -> 3.9 | H11: 10 | I11: 36 | J11: =IFERROR(ROUND(H11*304.8/G11,0),0) -> 782 | K11: =IFERROR(ROUND(I11*304.8/G11,0),0) -> 2814 | L11: 1 | M11: =H11*I11*L11 -> 360 | N11: =IFERROR(VLOOKUP(F11,'_Products'!$A$1:$G$23,5,FALSE),0) -> 6000 | O11: Front | P11: 256.36 | Q11: =P11*M11 -> 92291.16 | R11: =SUM('Bundle Equipment'!E50:E50) -> 12666 | S11: =MAX(M11*10,500) -> 3600 | T11: =Q11+R11+S11 -> 108557.16 | U11: =V$2 -> 0.15 | V11: =IFERROR(T11/(1-U11),0) -> 127714.31 | W11: =V11-T11 -> 19157.15 | X11: =IFERROR(ROUND(M11*0.092903*VLOOKUP(F11,'_Products'!$A$1:$G$23,6,FALSE),0),0) -> 1106 | Y11: =IFERROR(ROUND(M11*0.092903*VLOOKUP(F11,'_Products'!$A$1:$G$23,7,FALSE),0),0) -> 20067 | Z11: =Y11*3.412 -> 68469
A12: N.E. CORRIDOR (CEILING) — N.E. CORRIDOR (CEILING) | B12: 10 | C12: 34 | D12: 4000 | E12: =IFERROR(VLOOKUP(F12,'_Products'!$A$1:$G$23,2,FALSE),"") -> LG/Yaham | F12: Mesh P10 FM1921 3.9mm Indoor | G12: =IFERROR(VLOOKUP(F12,'_Products'!$A$1:$G$23,3,FALSE),0) -> 3.9 | H12: 10 | I12: 34 | J12: =IFERROR(ROUND(H12*304.8/G12,0),0) -> 782 | K12: =IFERROR(ROUND(I12*304.8/G12,0),0) -> 2657 | L12: 1 | M12: =H12*I12*L12 -> 340 | N12: =IFERROR(VLOOKUP(F12,'_Products'!$A$1:$G$23,5,FALSE),0) -> 6000 | O12: Front | P12: 256.36 | Q12: =P12*M12 -> 87163.87 | R12: =SUM('Bundle Equipment'!E56:E56) -> 12654 | S12: =MAX(M12*10,500) -> 3400 | T12: =Q12+R12+S12 -> 103217.87 | U12: =V$2 -> 0.15 | V12: =IFERROR(T12/(1-U12),0) -> 121432.79 | W12: =V12-T12 -> 18214.92 | X12: =IFERROR(ROUND(M12*0.092903*VLOOKUP(F12,'_Products'!$A$1:$G$23,6,FALSE),0),0) -> 1045 | Y12: =IFERROR(ROUND(M12*0.092903*VLOOKUP(F12,'_Products'!$A$1:$G$23,7,FALSE),0),0) -> 18952 | Z12: =Y12*3.412 -> 64664
A13: N.E. CORRIDOR (CEILING) — N.E. CORRIDOR (CEILING) | B13: 10 | C13: 34 | D13: 4000 | E13: =IFERROR(VLOOKUP(F13,'_Products'!$A$1:$G$23,2,FALSE),"") -> LG/Yaham | F13: Mesh P10 FM1921 3.9mm Indoor | G13: =IFERROR(VLOOKUP(F13,'_Products'!$A$1:$G$23,3,FALSE),0) -> 3.9 | H13: 10 | I13: 34 | J13: =IFERROR(ROUND(H13*304.8/G13,0),0) -> 782 | K13: =IFERROR(ROUND(I13*304.8/G13,0),0) -> 2657 | L13: 1 | M13: =H13*I13*L13 -> 340 | N13: =IFERROR(VLOOKUP(F13,'_Products'!$A$1:$G$23,5,FALSE),0) -> 6000 | O13: Front | P13: 256.36 | Q13: =P13*M13 -> 87163.87 | R13: =SUM('Bundle Equipment'!E62:E62) -> 12654 | S13: =MAX(M13*10,500) -> 3400 | T13: =Q13+R13+S13 -> 103217.87 | U13: =V$2 -> 0.15 | V13: =IFERROR(T13/(1-U13),0) -> 121432.79 | W13: =V13-T13 -> 18214.92 | X13: =IFERROR(ROUND(M13*0.092903*VLOOKUP(F13,'_Products'!$A$1:$G$23,6,FALSE),0),0) -> 1045 | Y13: =IFERROR(ROUND(M13*0.092903*VLOOKUP(F13,'_Products'!$A$1:$G$23,7,FALSE),0),0) -> 18952 | Z13: =Y13*3.412 -> 64664
A14: LARGE ADMIN ROOM — LARGE ADMIN ROOM | B14: 8 | C14: 28 | D14: 4000 | E14: =IFERROR(VLOOKUP(F14,'_Products'!$A$1:$G$23,2,FALSE),"") -> LG/Yaham | F14: Mesh P10 FM1921 3.9mm Indoor | G14: =IFERROR(VLOOKUP(F14,'_Products'!$A$1:$G$23,3,FALSE),0) -> 3.9 | H14: 8 | I14: 28 | J14: =IFERROR(ROUND(H14*304.8/G14,0),0) -> 625 | K14: =IFERROR(ROUND(I14*304.8/G14,0),0) -> 2188 | L14: 1 | M14: =H14*I14*L14 -> 224 | N14: =IFERROR(VLOOKUP(F14,'_Products'!$A$1:$G$23,5,FALSE),0) -> 6000 | O14: Front | P14: 256.36 | Q14: =P14*M14 -> 57425.61 | R14: =SUM('Bundle Equipment'!E67:E67) -> 584.4 | S14: =MAX(M14*10,500) -> 2240 | T14: =Q14+R14+S14 -> 60250.01 | U14: =V$2 -> 0.15 | V14: =IFERROR(T14/(1-U14),0) -> 70882.36 | W14: =V14-T14 -> 10632.35 | X14: =IFERROR(ROUND(M14*0.092903*VLOOKUP(F14,'_Products'!$A$1:$G$23,6,FALSE),0),0) -> 688 | Y14: =IFERROR(ROUND(M14*0.092903*VLOOKUP(F14,'_Products'!$A$1:$G$23,7,FALSE),0),0) -> 12486 | Z14: =Y14*3.412 -> 42602
A15: ELEV LOBBY — ELEV LOBBY | B15: 4 | C15: 6 | D15: 4000 | E15: =IFERROR(VLOOKUP(F15,'_Products'!$A$1:$G$23,2,FALSE),"") -> LG/Yaham | F15: Mesh P10 FM1921 3.9mm Indoor | G15: =IFERROR(VLOOKUP(F15,'_Products'!$A$1:$G$23,3,FALSE),0) -> 3.9 | H15: 4 | I15: 6 | J15: =IFERROR(ROUND(H15*304.8/G15,0),0) -> 313 | K15: =IFERROR(ROUND(I15*304.8/G15,0),0) -> 469 | L15: 1 | M15: =H15*I15*L15 -> 24 | N15: =IFERROR(VLOOKUP(F15,'_Products'!$A$1:$G$23,5,FALSE),0) -> 6000 | O15: Front | P15: 256.36 | Q15: =P15*M15 -> 6152.75 | R15: =SUM('Bundle Equipment'!E72:E72) -> 464.4 | S15: =MAX(M15*10,500) -> 500 | T15: =Q15+R15+S15 -> 7117.15 | U15: =V$2 -> 0.15 | V15: =IFERROR(T15/(1-U15),0) -> 8373.12 | W15: =V15-T15 -> 1255.97 | X15: =IFERROR(ROUND(M15*0.092903*VLOOKUP(F15,'_Products'!$A$1:$G$23,6,FALSE),0),0) -> 74 | Y15: =IFERROR(ROUND(M15*0.092903*VLOOKUP(F15,'_Products'!$A$1:$G$23,7,FALSE),0),0) -> 1338 | Z15: =Y15*3.412 -> 4565
A16: NORTH CLUB — NORTH CLUB | B16: 9 | C16: 16 | D16: 4000 | E16: =IFERROR(VLOOKUP(F16,'_Products'!$A$1:$G$23,2,FALSE),"") -> LG/Yaham | F16: Mesh P10 FM1921 3.9mm Indoor | G16: =IFERROR(VLOOKUP(F16,'_Products'!$A$1:$G$23,3,FALSE),0) -> 3.9 | H16: 9 | I16: 16 | J16: =IFERROR(ROUND(H16*304.8/G16,0),0) -> 703 | K16: =IFERROR(ROUND(I16*304.8/G16,0),0) -> 1250 | L16: 1 | M16: =H16*I16*L16 -> 144 | N16: =IFERROR(VLOOKUP(F16,'_Products'!$A$1:$G$23,5,FALSE),0) -> 6000 | O16: Front | P16: 256.36 | Q16: =P16*M16 -> 36916.47 | R16: =SUM('Bundle Equipment'!E77:E77) -> 536.4 | S16: =MAX(M16*10,500) -> 1440 | T16: =Q16+R16+S16 -> 38892.87 | U16: =V$2 -> 0.15 | V16: =IFERROR(T16/(1-U16),0) -> 45756.32 | W16: =V16-T16 -> 6863.45 | X16: =IFERROR(ROUND(M16*0.092903*VLOOKUP(F16,'_Products'!$A$1:$G$23,6,FALSE),0),0) -> 442 | Y16: =IFERROR(ROUND(M16*0.092903*VLOOKUP(F16,'_Products'!$A$1:$G$23,7,FALSE),0),0) -> 8027 | Z16: =Y16*3.412 -> 27388
A17: PANTHERS DEN — PANTHERS DEN | B17: 22 | C17: 3 | D17: 4000 | E17: =IFERROR(VLOOKUP(F17,'_Products'!$A$1:$G$23,2,FALSE),"") -> LG/Yaham | F17: Mesh P10 FM1921 3.9mm Indoor | G17: =IFERROR(VLOOKUP(F17,'_Products'!$A$1:$G$23,3,FALSE),0) -> 3.9 | H17: 22 | I17: 3 | J17: =IFERROR(ROUND(H17*304.8/G17,0),0) -> 1719 | K17: =IFERROR(ROUND(I17*304.8/G17,0),0) -> 234 | L17: 1 | M17: =H17*I17*L17 -> 66 | N17: =IFERROR(VLOOKUP(F17,'_Products'!$A$1:$G$23,5,FALSE),0) -> 6000 | O17: Front | P17: 256.36 | Q17: =P17*M17 -> 16920.05 | R17: =SUM('Bundle Equipment'!E82:E82) -> 489.6 | S17: =MAX(M17*10,500) -> 660 | T17: =Q17+R17+S17 -> 18069.65 | U17: =V$2 -> 0.15 | V17: =IFERROR(T17/(1-U17),0) -> 21258.41 | W17: =V17-T17 -> 3188.76 | X17: =IFERROR(ROUND(M17*0.092903*VLOOKUP(F17,'_Products'!$A$1:$G$23,6,FALSE),0),0) -> 203 | Y17: =IFERROR(ROUND(M17*0.092903*VLOOKUP(F17,'_Products'!$A$1:$G$23,7,FALSE),0),0) -> 3679 | Z17: =Y17*3.412 -> 12553
A18: PANTHERS DEN — PANTHERS DEN | B18: 19 | C18: 3.17 | D18: 4000 | E18: =IFERROR(VLOOKUP(F18,'_Products'!$A$1:$G$23,2,FALSE),"") -> LG/Yaham | F18: Mesh P10 FM1921 3.9mm Indoor | G18: =IFERROR(VLOOKUP(F18,'_Products'!$A$1:$G$23,3,FALSE),0) -> 3.9 | H18: 19 | I18: 3.17 | J18: =IFERROR(ROUND(H18*304.8/G18,0),0) -> 1485 | K18: =IFERROR(ROUND(I18*304.8/G18,0),0) -> 248 | L18: 1 | M18: =H18*I18*L18 -> 60.23 | N18: =IFERROR(VLOOKUP(F18,'_Products'!$A$1:$G$23,5,FALSE),0) -> 6000 | O18: Front | P18: 256.36 | Q18: =P18*M18 -> 15440.82 | R18: =SUM('Bundle Equipment'!E87:E87) -> 486.14 | S18: =MAX(M18*10,500) -> 602.3 | T18: =Q18+R18+S18 -> 16529.26 | U18: =V$2 -> 0.15 | V18: =IFERROR(T18/(1-U18),0) -> 19446.19 | W18: =V18-T18 -> 2916.93 | X18: =IFERROR(ROUND(M18*0.092903*VLOOKUP(F18,'_Products'!$A$1:$G$23,6,FALSE),0),0) -> 185 | Y18: =IFERROR(ROUND(M18*0.092903*VLOOKUP(F18,'_Products'!$A$1:$G$23,7,FALSE),0),0) -> 3357 | Z18: =Y18*3.412 -> 11454
A19: PANTHERS DEN — PANTHERS DEN | B19: 22 | C19: 3 | D19: 4000 | E19: =IFERROR(VLOOKUP(F19,'_Products'!$A$1:$G$23,2,FALSE),"") -> LG/Yaham | F19: Mesh P10 FM1921 3.9mm Indoor | G19: =IFERROR(VLOOKUP(F19,'_Products'!$A$1:$G$23,3,FALSE),0) -> 3.9 | H19: 22 | I19: 3 | J19: =IFERROR(ROUND(H19*304.8/G19,0),0) -> 1719 | K19: =IFERROR(ROUND(I19*304.8/G19,0),0) -> 234 | L19: 1 | M19: =H19*I19*L19 -> 66 | N19: =IFERROR(VLOOKUP(F19,'_Products'!$A$1:$G$23,5,FALSE),0) -> 6000 | O19: Front | P19: 256.36 | Q19: =P19*M19 -> 16920.05 | R19: =SUM('Bundle Equipment'!E92:E92) -> 489.6 | S19: =MAX(M19*10,500) -> 660 | T19: =Q19+R19+S19 -> 18069.65 | U19: =V$2 -> 0.15 | V19: =IFERROR(T19/(1-U19),0) -> 21258.41 | W19: =V19-T19 -> 3188.76 | X19: =IFERROR(ROUND(M19*0.092903*VLOOKUP(F19,'_Products'!$A$1:$G$23,6,FALSE),0),0) -> 203 | Y19: =IFERROR(ROUND(M19*0.092903*VLOOKUP(F19,'_Products'!$A$1:$G$23,7,FALSE),0),0) -> 3679 | Z19: =Y19*3.412 -> 12553
A20: PANTHERS DEN — PANTHERS DEN | B20: 22 | C20: 3 | D20: 4000 | E20: =IFERROR(VLOOKUP(F20,'_Products'!$A$1:$G$23,2,FALSE),"") -> LG/Yaham | F20: Mesh P10 FM1921 3.9mm Indoor | G20: =IFERROR(VLOOKUP(F20,'_Products'!$A$1:$G$23,3,FALSE),0) -> 3.9 | H20: 22 | I20: 3 | J20: =IFERROR(ROUND(H20*304.8/G20,0),0) -> 1719 | K20: =IFERROR(ROUND(I20*304.8/G20,0),0) -> 234 | L20: 1 | M20: =H20*I20*L20 -> 66 | N20: =IFERROR(VLOOKUP(F20,'_Products'!$A$1:$G$23,5,FALSE),0) -> 6000 | O20: Front | P20: 256.36 | Q20: =P20*M20 -> 16920.05 | R20: =SUM('Bundle Equipment'!E97:E97) -> 489.6 | S20: =MAX(M20*10,500) -> 660 | T20: =Q20+R20+S20 -> 18069.65 | U20: =V$2 -> 0.15 | V20: =IFERROR(T20/(1-U20),0) -> 21258.41 | W20: =V20-T20 -> 3188.76 | X20: =IFERROR(ROUND(M20*0.092903*VLOOKUP(F20,'_Products'!$A$1:$G$23,6,FALSE),0),0) -> 203 | Y20: =IFERROR(ROUND(M20*0.092903*VLOOKUP(F20,'_Products'!$A$1:$G$23,7,FALSE),0),0) -> 3679 | Z20: =Y20*3.412 -> 12553
A21: PANTHERS DEN — PANTHERS DEN | B21: 22 | C21: 3 | D21: 4000 | E21: =IFERROR(VLOOKUP(F21,'_Products'!$A$1:$G$23,2,FALSE),"") -> LG/Yaham | F21: Mesh P10 FM1921 3.9mm Indoor | G21: =IFERROR(VLOOKUP(F21,'_Products'!$A$1:$G$23,3,FALSE),0) -> 3.9 | H21: 22 | I21: 3 | J21: =IFERROR(ROUND(H21*304.8/G21,0),0) -> 1719 | K21: =IFERROR(ROUND(I21*304.8/G21,0),0) -> 234 | L21: 1 | M21: =H21*I21*L21 -> 66 | N21: =IFERROR(VLOOKUP(F21,'_Products'!$A$1:$G$23,5,FALSE),0) -> 6000 | O21: Front | P21: 256.36 | Q21: =P21*M21 -> 16920.05 | R21: =SUM('Bundle Equipment'!E102:E102) -> 489.6 | S21: =MAX(M21*10,500) -> 660 | T21: =Q21+R21+S21 -> 18069.65 | U21: =V$2 -> 0.15 | V21: =IFERROR(T21/(1-U21),0) -> 21258.41 | W21: =V21-T21 -> 3188.76 | X21: =IFERROR(ROUND(M21*0.092903*VLOOKUP(F21,'_Products'!$A$1:$G$23,6,FALSE),0),0) -> 203 | Y21: =IFERROR(ROUND(M21*0.092903*VLOOKUP(F21,'_Products'!$A$1:$G$23,7,FALSE),0),0) -> 3679 | Z21: =Y21*3.412 -> 12553
A22: PANTHERS DEN — PANTHERS DEN | B22: 8 | C22: 29 | D22: 4000 | E22: =IFERROR(VLOOKUP(F22,'_Products'!$A$1:$G$23,2,FALSE),"") -> LG/Yaham | F22: Mesh P10 FM1921 3.9mm Indoor | G22: =IFERROR(VLOOKUP(F22,'_Products'!$A$1:$G$23,3,FALSE),0) -> 3.9 | H22: 8 | I22: 29 | J22: =IFERROR(ROUND(H22*304.8/G22,0),0) -> 625 | K22: =IFERROR(ROUND(I22*304.8/G22,0),0) -> 2266 | L22: 1 | M22: =H22*I22*L22 -> 232 | N22: =IFERROR(VLOOKUP(F22,'_Products'!$A$1:$G$23,5,FALSE),0) -> 6000 | O22: Front | P22: 256.36 | Q22: =P22*M22 -> 59476.53 | R22: =SUM('Bundle Equipment'!E107:E107) -> 589.2 | S22: =MAX(M22*10,500) -> 2320 | T22: =Q22+R22+S22 -> 62385.73 | U22: =V$2 -> 0.15 | V22: =IFERROR(T22/(1-U22),0) -> 73394.98 | W22: =V22-T22 -> 11009.25 | X22: =IFERROR(ROUND(M22*0.092903*VLOOKUP(F22,'_Products'!$A$1:$G$23,6,FALSE),0),0) -> 713 | Y22: =IFERROR(ROUND(M22*0.092903*VLOOKUP(F22,'_Products'!$A$1:$G$23,7,FALSE),0),0) -> 12932 | Z22: =Y22*3.412 -> 44124
A23: PANTHERS DEN — PANTHERS DEN | B23: 4.08 | C23: 37.25 | D23: 4000 | E23: =IFERROR(VLOOKUP(F23,'_Products'!$A$1:$G$23,2,FALSE),"") -> LG/Yaham | F23: Mesh P10 FM1921 3.9mm Indoor | G23: =IFERROR(VLOOKUP(F23,'_Products'!$A$1:$G$23,3,FALSE),0) -> 3.9 | H23: 4.08 | I23: 37.25 | J23: =IFERROR(ROUND(H23*304.8/G23,0),0) -> 319 | K23: =IFERROR(ROUND(I23*304.8/G23,0),0) -> 2911 | L23: 1 | M23: =H23*I23*L23 -> 151.98 | N23: =IFERROR(VLOOKUP(F23,'_Products'!$A$1:$G$23,5,FALSE),0) -> 6000 | O23: Front | P23: 256.36 | Q23: =P23*M23 -> 38962.26 | R23: =SUM('Bundle Equipment'!E112:E112) -> 541.19 | S23: =MAX(M23*10,500) -> 1519.8 | T23: =Q23+R23+S23 -> 41023.25 | U23: =V$2 -> 0.15 | V23: =IFERROR(T23/(1-U23),0) -> 48262.65 | W23: =V23-T23 -> 7239.4 | X23: =IFERROR(ROUND(M23*0.092903*VLOOKUP(F23,'_Products'!$A$1:$G$23,6,FALSE),0),0) -> 467 | Y23: =IFERROR(ROUND(M23*0.092903*VLOOKUP(F23,'_Products'!$A$1:$G$23,7,FALSE),0),0) -> 8472 | Z23: =Y23*3.412 -> 28906
A24: SOUTH CLUB — SOUTH CLUB | B24: 9 | C24: 16 | D24: 4000 | E24: =IFERROR(VLOOKUP(F24,'_Products'!$A$1:$G$23,2,FALSE),"") -> LG/Yaham | F24: Mesh P10 FM1921 3.9mm Indoor | G24: =IFERROR(VLOOKUP(F24,'_Products'!$A$1:$G$23,3,FALSE),0) -> 3.9 | H24: 9 | I24: 16 | J24: =IFERROR(ROUND(H24*304.8/G24,0),0) -> 703 | K24: =IFERROR(ROUND(I24*304.8/G24,0),0) -> 1250 | L24: 1 | M24: =H24*I24*L24 -> 144 | N24: =IFERROR(VLOOKUP(F24,'_Products'!$A$1:$G$23,5,FALSE),0) -> 6000 | O24: Front | P24: 256.36 | Q24: =P24*M24 -> 36916.47 | R24: =SUM('Bundle Equipment'!E117:E117) -> 536.4 | S24: =MAX(M24*10,500) -> 1440 | T24: =Q24+R24+S24 -> 38892.87 | U24: =V$2 -> 0.15 | V24: =IFERROR(T24/(1-U24),0) -> 45756.32 | W24: =V24-T24 -> 6863.45 | X24: =IFERROR(ROUND(M24*0.092903*VLOOKUP(F24,'_Products'!$A$1:$G$23,6,FALSE),0),0) -> 442 | Y24: =IFERROR(ROUND(M24*0.092903*VLOOKUP(F24,'_Products'!$A$1:$G$23,7,FALSE),0),0) -> 8027 | Z24: =Y24*3.412 -> 27388
A25: ELEV LOBBY — ELEV LOBBY | B25: 4 | C25: 6 | D25: 4000 | E25: =IFERROR(VLOOKUP(F25,'_Products'!$A$1:$G$23,2,FALSE),"") -> LG/Yaham | F25: Mesh P10 FM1921 3.9mm Indoor | G25: =IFERROR(VLOOKUP(F25,'_Products'!$A$1:$G$23,3,FALSE),0) -> 3.9 | H25: 4 | I25: 6 | J25: =IFERROR(ROUND(H25*304.8/G25,0),0) -> 313 | K25: =IFERROR(ROUND(I25*304.8/G25,0),0) -> 469 | L25: 1 | M25: =H25*I25*L25 -> 24 | N25: =IFERROR(VLOOKUP(F25,'_Products'!$A$1:$G$23,5,FALSE),0) -> 6000 | O25: Front | P25: 256.36 | Q25: =P25*M25 -> 6152.75 | R25: =SUM('Bundle Equipment'!E122:E122) -> 464.4 | S25: =MAX(M25*10,500) -> 500 | T25: =Q25+R25+S25 -> 7117.15 | U25: =V$2 -> 0.15 | V25: =IFERROR(T25/(1-U25),0) -> 8373.12 | W25: =V25-T25 -> 1255.97 | X25: =IFERROR(ROUND(M25*0.092903*VLOOKUP(F25,'_Products'!$A$1:$G$23,6,FALSE),0),0) -> 74 | Y25: =IFERROR(ROUND(M25*0.092903*VLOOKUP(F25,'_Products'!$A$1:$G$23,7,FALSE),0),0) -> 1338 | Z25: =Y25*3.412 -> 4565
A26: SOUTH CLUB — SOUTH CLUB | B26: 9 | C26: 16 | D26: 4000 | E26: =IFERROR(VLOOKUP(F26,'_Products'!$A$1:$G$23,2,FALSE),"") -> LG/Yaham | F26: Mesh P10 FM1921 3.9mm Indoor | G26: =IFERROR(VLOOKUP(F26,'_Products'!$A$1:$G$23,3,FALSE),0) -> 3.9 | H26: 9 | I26: 16 | J26: =IFERROR(ROUND(H26*304.8/G26,0),0) -> 703 | K26: =IFERROR(ROUND(I26*304.8/G26,0),0) -> 1250 | L26: 1 | M26: =H26*I26*L26 -> 144 | N26: =IFERROR(VLOOKUP(F26,'_Products'!$A$1:$G$23,5,FALSE),0) -> 6000 | O26: Front | P26: 256.36 | Q26: =P26*M26 -> 36916.47 | R26: =SUM('Bundle Equipment'!E127:E127) -> 536.4 | S26: =MAX(M26*10,500) -> 1440 | T26: =Q26+R26+S26 -> 38892.87 | U26: =V$2 -> 0.15 | V26: =IFERROR(T26/(1-U26),0) -> 45756.32 | W26: =V26-T26 -> 6863.45 | X26: =IFERROR(ROUND(M26*0.092903*VLOOKUP(F26,'_Products'!$A$1:$G$23,6,FALSE),0),0) -> 442 | Y26: =IFERROR(ROUND(M26*0.092903*VLOOKUP(F26,'_Products'!$A$1:$G$23,7,FALSE),0),0) -> 8027 | Z26: =Y26*3.412 -> 27388
A27: ELEV LOBBY — ELEV LOBBY | B27: 4 | C27: 6 | D27: 4000 | E27: =IFERROR(VLOOKUP(F27,'_Products'!$A$1:$G$23,2,FALSE),"") -> LG/Yaham | F27: Mesh P10 FM1921 3.9mm Indoor | G27: =IFERROR(VLOOKUP(F27,'_Products'!$A$1:$G$23,3,FALSE),0) -> 3.9 | H27: 4 | I27: 6 | J27: =IFERROR(ROUND(H27*304.8/G27,0),0) -> 313 | K27: =IFERROR(ROUND(I27*304.8/G27,0),0) -> 469 | L27: 1 | M27: =H27*I27*L27 -> 24 | N27: =IFERROR(VLOOKUP(F27,'_Products'!$A$1:$G$23,5,FALSE),0) -> 6000 | O27: Front | P27: 256.36 | Q27: =P27*M27 -> 6152.75 | R27: =SUM('Bundle Equipment'!E132:E132) -> 464.4 | S27: =MAX(M27*10,500) -> 500 | T27: =Q27+R27+S27 -> 7117.15 | U27: =V$2 -> 0.15 | V27: =IFERROR(T27/(1-U27),0) -> 8373.12 | W27: =V27-T27 -> 1255.97 | X27: =IFERROR(ROUND(M27*0.092903*VLOOKUP(F27,'_Products'!$A$1:$G$23,6,FALSE),0),0) -> 74 | Y27: =IFERROR(ROUND(M27*0.092903*VLOOKUP(F27,'_Products'!$A$1:$G$23,7,FALSE),0),0) -> 1338 | Z27: =Y27*3.412 -> 4565
A28: ELEV LOBBY — ELEV LOBBY | B28: 4 | C28: 6 | D28: 4000 | E28: =IFERROR(VLOOKUP(F28,'_Products'!$A$1:$G$23,2,FALSE),"") -> LG/Yaham | F28: Mesh P10 FM1921 3.9mm Indoor | G28: =IFERROR(VLOOKUP(F28,'_Products'!$A$1:$G$23,3,FALSE),0) -> 3.9 | H28: 4 | I28: 6 | J28: =IFERROR(ROUND(H28*304.8/G28,0),0) -> 313 | K28: =IFERROR(ROUND(I28*304.8/G28,0),0) -> 469 | L28: 1 | M28: =H28*I28*L28 -> 24 | N28: =IFERROR(VLOOKUP(F28,'_Products'!$A$1:$G$23,5,FALSE),0) -> 6000 | O28: Front | P28: 256.36 | Q28: =P28*M28 -> 6152.75 | R28: =SUM('Bundle Equipment'!E137:E137) -> 464.4 | S28: =MAX(M28*10,500) -> 500 | T28: =Q28+R28+S28 -> 7117.15 | U28: =V$2 -> 0.15 | V28: =IFERROR(T28/(1-U28),0) -> 8373.12 | W28: =V28-T28 -> 1255.97 | X28: =IFERROR(ROUND(M28*0.092903*VLOOKUP(F28,'_Products'!$A$1:$G$23,6,FALSE),0),0) -> 74 | Y28: =IFERROR(ROUND(M28*0.092903*VLOOKUP(F28,'_Products'!$A$1:$G$23,7,FALSE),0),0) -> 1338 | Z28: =Y28*3.412 -> 4565
A29: NORTH CLUB — NORTH CLUB | B29: 9 | C29: 16 | D29: 4000 | E29: =IFERROR(VLOOKUP(F29,'_Products'!$A$1:$G$23,2,FALSE),"") -> LG/Yaham | F29: Mesh P10 FM1921 3.9mm Indoor | G29: =IFERROR(VLOOKUP(F29,'_Products'!$A$1:$G$23,3,FALSE),0) -> 3.9 | H29: 9 | I29: 16 | J29: =IFERROR(ROUND(H29*304.8/G29,0),0) -> 703 | K29: =IFERROR(ROUND(I29*304.8/G29,0),0) -> 1250 | L29: 1 | M29: =H29*I29*L29 -> 144 | N29: =IFERROR(VLOOKUP(F29,'_Products'!$A$1:$G$23,5,FALSE),0) -> 6000 | O29: Front | P29: 256.36 | Q29: =P29*M29 -> 36916.47 | R29: =SUM('Bundle Equipment'!E142:E142) -> 536.4 | S29: =MAX(M29*10,500) -> 1440 | T29: =Q29+R29+S29 -> 38892.87 | U29: =V$2 -> 0.15 | V29: =IFERROR(T29/(1-U29),0) -> 45756.32 | W29: =V29-T29 -> 6863.45 | X29: =IFERROR(ROUND(M29*0.092903*VLOOKUP(F29,'_Products'!$A$1:$G$23,6,FALSE),0),0) -> 442 | Y29: =IFERROR(ROUND(M29*0.092903*VLOOKUP(F29,'_Products'!$A$1:$G$23,7,FALSE),0),0) -> 8027 | Z29: =Y29*3.412 -> 27388
A30: RIBBON NW — RIBBON NW | B30: 3 | C30: 20 | D30: 8000 | E30: =IFERROR(VLOOKUP(F30,'_Products'!$A$1:$G$23,2,FALSE),"") -> Yaham | F30: Yaham Aura A10 Perimeter | G30: =IFERROR(VLOOKUP(F30,'_Products'!$A$1:$G$23,3,FALSE),0) -> 10 | H30: 3 | I30: 20 | J30: =IFERROR(ROUND(H30*304.8/G30,0),0) -> 0 | K30: =IFERROR(ROUND(I30*304.8/G30,0),0) -> 0 | L30: 1 | M30: =H30*I30*L30 -> 60 | N30: =IFERROR(VLOOKUP(F30,'_Products'!$A$1:$G$23,5,FALSE),0) -> 7500 | O30: Front | P30: 123.72 | Q30: =P30*M30 -> 7423.35 | R30: =SUM('Bundle Equipment'!E149:E149) -> 3706 | S30: =MAX(M30*10,500) -> 600 | T30: =Q30+R30+S30 -> 11729.35 | U30: =V$2 -> 0.15 | V30: =IFERROR(T30/(1-U30),0) -> 13799.24 | W30: =V30-T30 -> 2069.89 | X30: =IFERROR(ROUND(M30*0.092903*VLOOKUP(F30,'_Products'!$A$1:$G$23,6,FALSE),0),0) -> 469 | Y30: =IFERROR(ROUND(M30*0.092903*VLOOKUP(F30,'_Products'!$A$1:$G$23,7,FALSE),0),0) -> 2632 | Z30: =Y30*3.412 -> 8980
A31: RIBBON NW — RIBBON NW | B31: 3 | C31: 35 | D31: 8000 | E31: =IFERROR(VLOOKUP(F31,'_Products'!$A$1:$G$23,2,FALSE),"") -> Yaham | F31: Yaham Radiance R10 Outdoor | G31: =IFERROR(VLOOKUP(F31,'_Products'!$A$1:$G$23,3,FALSE),0) -> 10.417 | H31: 3 | I31: 35 | J31: =IFERROR(ROUND(H31*304.8/G31,0),0) -> 91 | K31: =IFERROR(ROUND(I31*304.8/G31,0),0) -> 1067 | L31: 1 | M31: =H31*I31*L31 -> 105 | N31: =IFERROR(VLOOKUP(F31,'_Products'!$A$1:$G$23,5,FALSE),0) -> 10000 | O31: Front | P31: 123.72 | Q31: =P31*M31 -> 12990.87 | R31: =SUM('Bundle Equipment'!E156:E156) -> 4273 | S31: =MAX(M31*10,500) -> 1050 | T31: =Q31+R31+S31 -> 18313.87 | U31: =V$2 -> 0.15 | V31: =IFERROR(T31/(1-U31),0) -> 21545.73 | W31: =V31-T31 -> 3231.86 | X31: =IFERROR(ROUND(M31*0.092903*VLOOKUP(F31,'_Products'!$A$1:$G$23,6,FALSE),0),0) -> 634 | Y31: =IFERROR(ROUND(M31*0.092903*VLOOKUP(F31,'_Products'!$A$1:$G$23,7,FALSE),0),0) -> 6341 | Z31: =Y31*3.412 -> 21635
A32: RIBBON NW — RIBBON NW | B32: 3 | C32: 35 | D32: 8000 | E32: =IFERROR(VLOOKUP(F32,'_Products'!$A$1:$G$23,2,FALSE),"") -> Yaham | F32: Yaham Radiance R10 Outdoor | G32: =IFERROR(VLOOKUP(F32,'_Products'!$A$1:$G$23,3,FALSE),0) -> 10.417 | H32: 3 | I32: 35 | J32: =IFERROR(ROUND(H32*304.8/G32,0),0) -> 91 | K32: =IFERROR(ROUND(I32*304.8/G32,0),0) -> 1067 | L32: 1 | M32: =H32*I32*L32 -> 105 | N32: =IFERROR(VLOOKUP(F32,'_Products'!$A$1:$G$23,5,FALSE),0) -> 10000 | O32: Front | P32: 123.72 | Q32: =P32*M32 -> 12990.87 | R32: =SUM('Bundle Equipment'!E163:E163) -> 4273 | S32: =MAX(M32*10,500) -> 1050 | T32: =Q32+R32+S32 -> 18313.87 | U32: =V$2 -> 0.15 | V32: =IFERROR(T32/(1-U32),0) -> 21545.73 | W32: =V32-T32 -> 3231.86 | X32: =IFERROR(ROUND(M32*0.092903*VLOOKUP(F32,'_Products'!$A$1:$G$23,6,FALSE),0),0) -> 634 | Y32: =IFERROR(ROUND(M32*0.092903*VLOOKUP(F32,'_Products'!$A$1:$G$23,7,FALSE),0),0) -> 6341 | Z32: =Y32*3.412 -> 21635
A33: RIBBON NW — RIBBON NW | B33: 3 | C33: 35 | D33: 8000 | E33: =IFERROR(VLOOKUP(F33,'_Products'!$A$1:$G$23,2,FALSE),"") -> Yaham | F33: Yaham Radiance R10 Outdoor | G33: =IFERROR(VLOOKUP(F33,'_Products'!$A$1:$G$23,3,FALSE),0) -> 10.417 | H33: 3 | I33: 35 | J33: =IFERROR(ROUND(H33*304.8/G33,0),0) -> 91 | K33: =IFERROR(ROUND(I33*304.8/G33,0),0) -> 1067 | L33: 1 | M33: =H33*I33*L33 -> 105 | N33: =IFERROR(VLOOKUP(F33,'_Products'!$A$1:$G$23,5,FALSE),0) -> 10000 | O33: Front | P33: 123.72 | Q33: =P33*M33 -> 12990.87 | R33: =SUM('Bundle Equipment'!E170:E170) -> 4273 | S33: =MAX(M33*10,500) -> 1050 | T33: =Q33+R33+S33 -> 18313.87 | U33: =V$2 -> 0.15 | V33: =IFERROR(T33/(1-U33),0) -> 21545.73 | W33: =V33-T33 -> 3231.86 | X33: =IFERROR(ROUND(M33*0.092903*VLOOKUP(F33,'_Products'!$A$1:$G$23,6,FALSE),0),0) -> 634 | Y33: =IFERROR(ROUND(M33*0.092903*VLOOKUP(F33,'_Products'!$A$1:$G$23,7,FALSE),0),0) -> 6341 | Z33: =Y33*3.412 -> 21635
A34: RIBBON SW — RIBBON SW | B34: 4 | C34: 20 | D34: 8000 | E34: =IFERROR(VLOOKUP(F34,'_Products'!$A$1:$G$23,2,FALSE),"") -> Yaham | F34: Yaham Aura A10 Perimeter | G34: =IFERROR(VLOOKUP(F34,'_Products'!$A$1:$G$23,3,FALSE),0) -> 10 | H34: 4 | I34: 20 | J34: =IFERROR(ROUND(H34*304.8/G34,0),0) -> 0 | K34: =IFERROR(ROUND(I34*304.8/G34,0),0) -> 0 | L34: 1 | M34: =H34*I34*L34 -> 80 | N34: =IFERROR(VLOOKUP(F34,'_Products'!$A$1:$G$23,5,FALSE),0) -> 7500 | O34: Front | P34: 123.72 | Q34: =P34*M34 -> 9897.8 | R34: =SUM('Bundle Equipment'!E177:E177) -> 3958 | S34: =MAX(M34*10,500) -> 800 | T34: =Q34+R34+S34 -> 14655.8 | U34: =V$2 -> 0.15 | V34: =IFERROR(T34/(1-U34),0) -> 17242.12 | W34: =V34-T34 -> 2586.32 | X34: =IFERROR(ROUND(M34*0.092903*VLOOKUP(F34,'_Products'!$A$1:$G$23,6,FALSE),0),0) -> 626 | Y34: =IFERROR(ROUND(M34*0.092903*VLOOKUP(F34,'_Products'!$A$1:$G$23,7,FALSE),0),0) -> 3510 | Z34: =Y34*3.412 -> 11976
